{
  "version": 8,
  "blockIdVersion": 11,
  "anchorX": 8,
  "anchorY": 1,
  "anchorZ": -3,
  "blocks": [
    {
      "x": -7,
      "y": -1,
      "z": -3,
      "name": "Rock_Ice"
    },
    {
      "x": -7,
      "y": 0,
      "z": -3,
      "name": "Rock_Basalt",
      "rotation": 3
    },
    {
      "x": -7,
      "y": 13,
      "z": -3,
      "name": "Rock_Basalt_Brick"
    },
    {
      "x": -7,
      "y": -1,
      "z": -2,
      "name": "Rock_Ice"
    },
    {
      "x": -7,
      "y": 0,
      "z": -2,
      "name": "Rock_Basalt",
      "rotation": 3
    },
    {
      "x": -7,
      "y": 1,
      "z": -2,
      "name": "Rubble_Basalt",
      "support": 15
    },
    {
      "x": -7,
      "y": 12,
      "z": -2,
      "name": "Rock_Basalt_Brick_Stairs",
      "rotation": 9
    },
    {
      "x": -7,
      "y": 13,
      "z": -2,
      "name": "Rock_Basalt_Brick"
    },
    {
      "x": -7,
      "y": -1,
      "z": -1,
      "name": "Rock_Ice"
    },
    {
      "x": -7,
      "y": 0,
      "z": -1,
      "name": "Rock_Basalt",
      "rotation": 3
    },
    {
      "x": -7,
      "y": 13,
      "z": -1,
      "name": "Rock_Basalt_Brick"
    },
    {
      "x": -7,
      "y": -1,
      "z": 0,
      "name": "Rock_Ice"
    },
    {
      "x": -7,
      "y": 0,
      "z": 0,
      "name": "Soil_Snow"
    },
    {
      "x": -7,
      "y": 6,
      "z": 0,
      "name": "Deco_Iron_Bars_Platforms"
    },
    {
      "x": -7,
      "y": 7,
      "z": 0,
      "name": "Deco_Bronze_Railing"
    },
    {
      "x": -7,
      "y": 13,
      "z": 0,
      "name": "Rock_Basalt_Brick"
    },
    {
      "x": -7,
      "y": -1,
      "z": 1,
      "name": "Rock_Ice"
    },
    {
      "x": -7,
      "y": 0,
      "z": 1,
      "name": "Soil_Snow"
    },
    {
      "x": -7,
      "y": 6,
      "z": 1,
      "name": "Deco_Iron_Bars_Platforms"
    },
    {
      "x": -7,
      "y": 13,
      "z": 1,
      "name": "Rock_Basalt_Brick"
    },
    {
      "x": -7,
      "y": -1,
      "z": 2,
      "name": "Rock_Ice"
    },
    {
      "x": -7,
      "y": 0,
      "z": 2,
      "name": "Soil_Snow"
    },
    {
      "x": -7,
      "y": 1,
      "z": 2,
      "name": "Rubble_Basalt",
      "support": 15
    },
    {
      "x": -7,
      "y": 6,
      "z": 2,
      "name": "Deco_Iron_Bars_Platforms"
    },
    {
      "x": -7,
      "y": 13,
      "z": 2,
      "name": "Rock_Basalt_Brick"
    },
    {
      "x": -7,
      "y": -1,
      "z": 3,
      "name": "Rock_Ice"
    },
    {
      "x": -7,
      "y": 0,
      "z": 3,
      "name": "Rock_Ice"
    },
    {
      "x": -7,
      "y": 6,
      "z": 3,
      "name": "Deco_Iron_Bars_Platforms"
    },
    {
      "x": -7,
      "y": 7,
      "z": 3,
      "name": "Deco_Bronze_Railing"
    },
    {
      "x": -7,
      "y": 13,
      "z": 3,
      "name": "Rock_Basalt_Brick"
    },
    {
      "x": -7,
      "y": -1,
      "z": 4,
      "name": "Rock_Ice"
    },
    {
      "x": -7,
      "y": 0,
      "z": 4,
      "name": "Rock_Ice"
    },
    {
      "x": -7,
      "y": 13,
      "z": 4,
      "name": "Rock_Basalt_Brick"
    },
    {
      "x": -7,
      "y": -1,
      "z": 5,
      "name": "Rock_Ice"
    },
    {
      "x": -7,
      "y": 0,
      "z": 5,
      "name": "Rock_Ice"
    },
    {
      "x": -7,
      "y": 1,
      "z": 5,
      "name": "Rock_Basalt_Brick"
    },
    {
      "x": -7,
      "y": 2,
      "z": 5,
      "name": "Rock_Basalt_Brick"
    },
    {
      "x": -7,
      "y": 3,
      "z": 5,
      "name": "Rock_Basalt_Brick"
    },
    {
      "x": -7,
      "y": 4,
      "z": 5,
      "name": "Rock_Basalt_Brick"
    },
    {
      "x": -7,
      "y": 5,
      "z": 5,
      "name": "Rock_Basalt_Brick"
    },
    {
      "x": -7,
      "y": 6,
      "z": 5,
      "name": "Rock_Basalt_Brick"
    },
    {
      "x": -7,
      "y": 7,
      "z": 5,
      "name": "Rock_Basalt_Brick"
    },
    {
      "x": -7,
      "y": 8,
      "z": 5,
      "name": "Rock_Basalt_Brick"
    },
    {
      "x": -7,
      "y": 9,
      "z": 5,
      "name": "Rock_Basalt_Brick"
    },
    {
      "x": -7,
      "y": 10,
      "z": 5,
      "name": "Rock_Basalt_Brick"
    },
    {
      "x": -7,
      "y": 11,
      "z": 5,
      "name": "Rock_Basalt_Brick"
    },
    {
      "x": -7,
      "y": 12,
      "z": 5,
      "name": "Rock_Basalt_Brick"
    },
    {
      "x": -7,
      "y": 13,
      "z": 5,
      "name": "Rock_Basalt_Brick"
    },
    {
      "x": -6,
      "y": -1,
      "z": -3,
      "name": "Rock_Ice"
    },
    {
      "x": -6,
      "y": 0,
      "z": -3,
      "name": "Rock_Basalt_Brick",
      "rotation": 3
    },
    {
      "x": -6,
      "y": 1,
      "z": -3,
      "name": "Rubble_Basalt",
      "support": 15
    },
    {
      "x": -6,
      "y": 13,
      "z": -3,
      "name": "Rock_Basalt_Brick"
    },
    {
      "x": -6,
      "y": -1,
      "z": -2,
      "name": "Rock_Ice"
    },
    {
      "x": -6,
      "y": 0,
      "z": -2,
      "name": "Rock_Basalt_Brick",
      "rotation": 3
    },
    {
      "x": -6,
      "y": 1,
      "z": -2,
      "name": "Rock_Basalt_Brick_Pillar_Base",
      "rotation": 3
    },
    {
      "x": -6,
      "y": 2,
      "z": -2,
      "name": "Rock_Basalt_Brick_Pillar_Middle",
      "rotation": 3
    },
    {
      "x": -6,
      "y": 3,
      "z": -2,
      "name": "Rock_Basalt_Brick_Pillar_Middle",
      "rotation": 3
    },
    {
      "x": -6,
      "y": 4,
      "z": -2,
      "name": "Rock_Basalt_Brick_Pillar_Middle",
      "rotation": 3
    },
    {
      "x": -6,
      "y": 5,
      "z": -2,
      "name": "Rock_Basalt_Brick_Pillar_Middle",
      "rotation": 3
    },
    {
      "x": -6,
      "y": 6,
      "z": -2,
      "name": "Rock_Basalt_Brick_Pillar_Middle",
      "rotation": 3
    },
    {
      "x": -6,
      "y": 7,
      "z": -2,
      "name": "Rock_Basalt_Brick_Pillar_Middle",
      "rotation": 3
    },
    {
      "x": -6,
      "y": 8,
      "z": -2,
      "name": "Rock_Basalt_Brick_Pillar_Middle",
      "rotation": 3
    },
    {
      "x": -6,
      "y": 9,
      "z": -2,
      "name": "Rock_Basalt_Brick_Pillar_Middle",
      "rotation": 3
    },
    {
      "x": -6,
      "y": 10,
      "z": -2,
      "name": "Rock_Basalt_Brick_Pillar_Middle",
      "rotation": 3
    },
    {
      "x": -6,
      "y": 11,
      "z": -2,
      "name": "Rock_Basalt_Brick_Pillar_Base",
      "rotation": 11
    },
    {
      "x": -6,
      "y": 12,
      "z": -2,
      "name": "Rock_Basalt_Brick",
      "rotation": 3
    },
    {
      "x": -6,
      "y": 13,
      "z": -2,
      "name": "Rock_Basalt_Brick"
    },
    {
      "x": -6,
      "y": -1,
      "z": -1,
      "name": "Rock_Ice"
    },
    {
      "x": -6,
      "y": 0,
      "z": -1,
      "name": "Soil_Snow"
    },
    {
      "x": -6,
      "y": 13,
      "z": -1,
      "name": "Rock_Basalt_Brick"
    },
    {
      "x": -6,
      "y": -1,
      "z": 0,
      "name": "Rock_Ice"
    },
    {
      "x": -6,
      "y": 0,
      "z": 0,
      "name": "Soil_Snow"
    },
    {
      "x": -6,
      "y": 6,
      "z": 0,
      "name": "Deco_Iron_Bars_Platforms"
    },
    {
      "x": -6,
      "y": 13,
      "z": 0,
      "name": "Rock_Basalt_Brick"
    },
    {
      "x": -6,
      "y": -1,
      "z": 1,
      "name": "Rock_Ice"
    },
    {
      "x": -6,
      "y": 0,
      "z": 1,
      "name": "Soil_Snow"
    },
    {
      "x": -6,
      "y": 1,
      "z": 1,
      "name": "Rock_Ice_Icicles"
    },
    {
      "x": -6,
      "y": 6,
      "z": 1,
      "name": "Deco_Iron_Bars_Platforms"
    },
    {
      "x": -6,
      "y": 13,
      "z": 1,
      "name": "Rock_Basalt_Brick"
    },
    {
      "x": -6,
      "y": -1,
      "z": 2,
      "name": "Rock_Ice"
    },
    {
      "x": -6,
      "y": 0,
      "z": 2,
      "name": "Rock_Ice"
    },
    {
      "x": -6,
      "y": 6,
      "z": 2,
      "name": "Deco_Iron_Bars_Platforms"
    },
    {
      "x": -6,
      "y": 13,
      "z": 2,
      "name": "Rock_Basalt_Brick"
    },
    {
      "x": -6,
      "y": -1,
      "z": 3,
      "name": "Rock_Ice"
    },
    {
      "x": -6,
      "y": 0,
      "z": 3,
      "name": "Rock_Ice"
    },
    {
      "x": -6,
      "y": 1,
      "z": 3,
      "name": "Rock_Ice_Icicles"
    },
    {
      "x": -6,
      "y": 6,
      "z": 3,
      "name": "Deco_Iron_Bars_Platforms"
    },
    {
      "x": -6,
      "y": 7,
      "z": 3,
      "name": "Deco_Bronze_Railing"
    },
    {
      "x": -6,
      "y": 13,
      "z": 3,
      "name": "Rock_Basalt_Brick"
    },
    {
      "x": -6,
      "y": -1,
      "z": 4,
      "name": "Rock_Ice"
    },
    {
      "x": -6,
      "y": 0,
      "z": 4,
      "name": "Rock_Ice"
    },
    {
      "x": -6,
      "y": 12,
      "z": 4,
      "name": "Rock_Ice_Icicles",
      "rotation": 8
    },
    {
      "x": -6,
      "y": 13,
      "z": 4,
      "name": "Rock_Basalt_Brick"
    },
    {
      "x": -6,
      "y": -1,
      "z": 5,
      "name": "Rock_Ice"
    },
    {
      "x": -6,
      "y": 0,
      "z": 5,
      "name": "Rock_Ice"
    },
    {
      "x": -6,
      "y": 1,
      "z": 5,
      "name": "Rock_Ice"
    },
    {
      "x": -6,
      "y": 2,
      "z": 5,
      "name": "Rock_Basalt_Brick"
    },
    {
      "x": -6,
      "y": 3,
      "z": 5,
      "name": "Rock_Basalt_Brick"
    },
    {
      "x": -6,
      "y": 4,
      "z": 5,
      "name": "Rock_Basalt_Brick"
    },
    {
      "x": -6,
      "y": 5,
      "z": 5,
      "name": "Rock_Basalt_Brick"
    },
    {
      "x": -6,
      "y": 6,
      "z": 5,
      "name": "Rock_Basalt_Brick"
    },
    {
      "x": -6,
      "y": 7,
      "z": 5,
      "name": "Rock_Basalt_Brick"
    },
    {
      "x": -6,
      "y": 8,
      "z": 5,
      "name": "Rock_Basalt_Brick"
    },
    {
      "x": -6,
      "y": 9,
      "z": 5,
      "name": "Rock_Basalt_Brick"
    },
    {
      "x": -6,
      "y": 10,
      "z": 5,
      "name": "Rock_Basalt_Brick"
    },
    {
      "x": -6,
      "y": 11,
      "z": 5,
      "name": "Rock_Basalt_Brick"
    },
    {
      "x": -6,
      "y": 12,
      "z": 5,
      "name": "Rock_Basalt_Brick"
    },
    {
      "x": -6,
      "y": 13,
      "z": 5,
      "name": "Rock_Basalt_Brick"
    },
    {
      "x": -5,
      "y": -1,
      "z": -3,
      "name": "Rock_Ice"
    },
    {
      "x": -5,
      "y": 0,
      "z": -3,
      "name": "Rock_Basalt",
      "rotation": 3
    },
    {
      "x": -5,
      "y": 13,
      "z": -3,
      "name": "Rock_Basalt_Brick"
    },
    {
      "x": -5,
      "y": -1,
      "z": -2,
      "name": "Rock_Ice"
    },
    {
      "x": -5,
      "y": 0,
      "z": -2,
      "name": "Soil_Snow"
    },
    {
      "x": -5,
      "y": 1,
      "z": -2,
      "name": "Rubble_Basalt_Medium",
      "support": 15
    },
    {
      "x": -5,
      "y": 12,
      "z": -2,
      "name": "Rock_Basalt_Brick_Stairs",
      "rotation": 11
    },
    {
      "x": -5,
      "y": 13,
      "z": -2,
      "name": "Rock_Basalt_Brick"
    },
    {
      "x": -5,
      "y": -1,
      "z": -1,
      "name": "Rock_Ice"
    },
    {
      "x": -5,
      "y": 0,
      "z": -1,
      "name": "Soil_Snow"
    },
    {
      "x": -5,
      "y": 13,
      "z": -1,
      "name": "Rock_Basalt_Brick"
    },
    {
      "x": -5,
      "y": -1,
      "z": 0,
      "name": "Rock_Ice"
    },
    {
      "x": -5,
      "y": 0,
      "z": 0,
      "name": "Rock_Ice"
    },
    {
      "x": -5,
      "y": 1,
      "z": 0,
      "name": "Rock_Ice_Stalactite_Large"
    },
    {
      "x": -5,
      "y": 2,
      "z": 0,
      "name": "Rock_Ice_Stalactite_Large",
      "filler": 1024
    },
    {
      "x": -5,
      "y": 13,
      "z": 0,
      "name": "Rock_Basalt_Brick"
    },
    {
      "x": -5,
      "y": -1,
      "z": 1,
      "name": "Rock_Ice"
    },
    {
      "x": -5,
      "y": 0,
      "z": 1,
      "name": "Rock_Ice"
    },
    {
      "x": -5,
      "y": 6,
      "z": 1,
      "name": "Deco_Iron_Bars_Platforms"
    },
    {
      "x": -5,
      "y": 13,
      "z": 1,
      "name": "Rock_Basalt_Brick"
    },
    {
      "x": -5,
      "y": -1,
      "z": 2,
      "name": "Rock_Ice"
    },
    {
      "x": -5,
      "y": 0,
      "z": 2,
      "name": "Rock_Ice"
    },
    {
      "x": -5,
      "y": 1,
      "z": 2,
      "name": "Rock_Ice_Icicles"
    },
    {
      "x": -5,
      "y": 6,
      "z": 2,
      "name": "Deco_Iron_Bars_Platforms"
    },
    {
      "x": -5,
      "y": 13,
      "z": 2,
      "name": "Rock_Basalt_Brick"
    },
    {
      "x": -5,
      "y": -1,
      "z": 3,
      "name": "Rock_Ice"
    },
    {
      "x": -5,
      "y": 0,
      "z": 3,
      "name": "Rock_Ice"
    },
    {
      "x": -5,
      "y": 6,
      "z": 3,
      "name": "Deco_Iron_Bars_Platforms"
    },
    {
      "x": -5,
      "y": 12,
      "z": 3,
      "name": "Rock_Ice_Icicles",
      "rotation": 8
    },
    {
      "x": -5,
      "y": 13,
      "z": 3,
      "name": "Rock_Ice"
    },
    {
      "x": -5,
      "y": -1,
      "z": 4,
      "name": "Rock_Ice"
    },
    {
      "x": -5,
      "y": 0,
      "z": 4,
      "name": "Rock_Ice"
    },
    {
      "x": -5,
      "y": 1,
      "z": 4,
      "name": "Rock_Ice_Stalactite_Large"
    },
    {
      "x": -5,
      "y": 2,
      "z": 4,
      "name": "Rock_Ice_Stalactite_Large",
      "filler": 1024
    },
    {
      "x": -5,
      "y": 11,
      "z": 4,
      "name": "Rock_Ice_Stalactite_Large",
      "filler": 31744,
      "rotation": 8
    },
    {
      "x": -5,
      "y": 12,
      "z": 4,
      "name": "Rock_Ice_Stalactite_Large",
      "rotation": 8
    },
    {
      "x": -5,
      "y": 13,
      "z": 4,
      "name": "Rock_Ice"
    },
    {
      "x": -5,
      "y": -1,
      "z": 5,
      "name": "Rock_Ice"
    },
    {
      "x": -5,
      "y": 0,
      "z": 5,
      "name": "Rock_Ice"
    },
    {
      "x": -5,
      "y": 1,
      "z": 5,
      "name": "Rock_Ice"
    },
    {
      "x": -5,
      "y": 2,
      "z": 5,
      "name": "Rock_Ice"
    },
    {
      "x": -5,
      "y": 3,
      "z": 5,
      "name": "Rock_Ice"
    },
    {
      "x": -5,
      "y": 4,
      "z": 5,
      "name": "Rock_Ice"
    },
    {
      "x": -5,
      "y": 5,
      "z": 5,
      "name": "Rock_Basalt_Brick"
    },
    {
      "x": -5,
      "y": 6,
      "z": 5,
      "name": "Rock_Basalt_Brick"
    },
    {
      "x": -5,
      "y": 7,
      "z": 5,
      "name": "Rock_Basalt_Brick"
    },
    {
      "x": -5,
      "y": 8,
      "z": 5,
      "name": "Rock_Basalt_Brick"
    },
    {
      "x": -5,
      "y": 9,
      "z": 5,
      "name": "Rock_Basalt_Brick"
    },
    {
      "x": -5,
      "y": 10,
      "z": 5,
      "name": "Rock_Basalt_Brick"
    },
    {
      "x": -5,
      "y": 11,
      "z": 5,
      "name": "Rock_Ice"
    },
    {
      "x": -5,
      "y": 12,
      "z": 5,
      "name": "Rock_Ice"
    },
    {
      "x": -5,
      "y": 13,
      "z": 5,
      "name": "Rock_Ice"
    },
    {
      "x": -4,
      "y": -1,
      "z": -3,
      "name": "Rock_Ice"
    },
    {
      "x": -4,
      "y": 0,
      "z": -3,
      "name": "Soil_Snow"
    },
    {
      "x": -4,
      "y": 13,
      "z": -3,
      "name": "Rock_Basalt_Brick"
    },
    {
      "x": -4,
      "y": -1,
      "z": -2,
      "name": "Rock_Ice"
    },
    {
      "x": -4,
      "y": 0,
      "z": -2,
      "name": "Soil_Snow"
    },
    {
      "x": -4,
      "y": 12,
      "z": -2,
      "name": "Rock_Basalt_Brick_Half",
      "rotation": 11
    },
    {
      "x": -4,
      "y": 13,
      "z": -2,
      "name": "Rock_Basalt_Brick"
    },
    {
      "x": -4,
      "y": -1,
      "z": -1,
      "name": "Rock_Ice"
    },
    {
      "x": -4,
      "y": 0,
      "z": -1,
      "name": "Rock_Ice"
    },
    {
      "x": -4,
      "y": 13,
      "z": -1,
      "name": "Rock_Basalt_Brick"
    },
    {
      "x": -4,
      "y": -1,
      "z": 0,
      "name": "Rock_Ice"
    },
    {
      "x": -4,
      "y": 0,
      "z": 0,
      "name": "Rock_Ice"
    },
    {
      "x": -4,
      "y": 1,
      "z": 0,
      "name": "Rock_Ice_Icicles"
    },
    {
      "x": -4,
      "y": 11,
      "z": 0,
      "name": "Deco_Iron_Chain_Small"
    },
    {
      "x": -4,
      "y": 12,
      "z": 0,
      "name": "Deco_Iron_Chain_Small"
    },
    {
      "x": -4,
      "y": 13,
      "z": 0,
      "name": "Rock_Basalt_Brick"
    },
    {
      "x": -4,
      "y": -1,
      "z": 1,
      "name": "Rock_Ice"
    },
    {
      "x": -4,
      "y": 0,
      "z": 1,
      "name": "Rock_Ice"
    },
    {
      "x": -4,
      "y": 1,
      "z": 1,
      "name": "Rock_Ice"
    },
    {
      "x": -4,
      "y": 13,
      "z": 1,
      "name": "Rock_Basalt_Brick"
    },
    {
      "x": -4,
      "y": -1,
      "z": 2,
      "name": "Rock_Ice"
    },
    {
      "x": -4,
      "y": 0,
      "z": 2,
      "name": "Rock_Ice"
    },
    {
      "x": -4,
      "y": 1,
      "z": 2,
      "name": "Rock_Ice"
    },
    {
      "x": -4,
      "y": 2,
      "z": 2,
      "name": "Rock_Ice_Icicles"
    },
    {
      "x": -4,
      "y": 12,
      "z": 2,
      "name": "Rock_Ice_Icicles",
      "rotation": 8
    },
    {
      "x": -4,
      "y": 13,
      "z": 2,
      "name": "Rock_Ice"
    },
    {
      "x": -4,
      "y": -1,
      "z": 3,
      "name": "Rock_Ice"
    },
    {
      "x": -4,
      "y": 0,
      "z": 3,
      "name": "Rock_Ice"
    },
    {
      "x": -4,
      "y": 1,
      "z": 3,
      "name": "Rock_Ice"
    },
    {
      "x": -4,
      "y": 2,
      "z": 3,
      "name": "Rock_Ice_Stalactite_Large"
    },
    {
      "x": -4,
      "y": 3,
      "z": 3,
      "name": "Rock_Ice_Stalactite_Large",
      "filler": 1024
    },
    {
      "x": -4,
      "y": 9,
      "z": 3,
      "name": "Deco_Iron_Chain_Small"
    },
    {
      "x": -4,
      "y": 10,
      "z": 3,
      "name": "Deco_Iron_Chain_Small"
    },
    {
      "x": -4,
      "y": 11,
      "z": 3,
      "name": "Deco_Iron_Chain_Small"
    },
    {
      "x": -4,
      "y": 12,
      "z": 3,
      "name": "Deco_Iron_Chain_Small"
    },
    {
      "x": -4,
      "y": 13,
      "z": 3,
      "name": "Rock_Ice"
    },
    {
      "x": -4,
      "y": -1,
      "z": 4,
      "name": "Rock_Ice"
    },
    {
      "x": -4,
      "y": 0,
      "z": 4,
      "name": "Rock_Ice"
    },
    {
      "x": -4,
      "y": 1,
      "z": 4,
      "name": "Rock_Ice"
    },
    {
      "x": -4,
      "y": 2,
      "z": 4,
      "name": "Rock_Ice_Icicles"
    },
    {
      "x": -4,
      "y": 9,
      "z": 4,
      "name": "Rock_Ice"
    },
    {
      "x": -4,
      "y": 10,
      "z": 4,
      "name": "Rock_Ice"
    },
    {
      "x": -4,
      "y": 11,
      "z": 4,
      "name": "Rock_Ice"
    },
    {
      "x": -4,
      "y": 12,
      "z": 4,
      "name": "Rock_Ice"
    },
    {
      "x": -4,
      "y": 13,
      "z": 4,
      "name": "Rock_Ice"
    },
    {
      "x": -4,
      "y": -1,
      "z": 5,
      "name": "Rock_Ice"
    },
    {
      "x": -4,
      "y": 0,
      "z": 5,
      "name": "Rock_Ice"
    },
    {
      "x": -4,
      "y": 1,
      "z": 5,
      "name": "Rock_Ice"
    },
    {
      "x": -4,
      "y": 2,
      "z": 5,
      "name": "Rock_Ice"
    },
    {
      "x": -4,
      "y": 3,
      "z": 5,
      "name": "Rock_Ice"
    },
    {
      "x": -4,
      "y": 4,
      "z": 5,
      "name": "Rock_Ice"
    },
    {
      "x": -4,
      "y": 5,
      "z": 5,
      "name": "Rock_Ice"
    },
    {
      "x": -4,
      "y": 6,
      "z": 5,
      "name": "Rock_Ice"
    },
    {
      "x": -4,
      "y": 7,
      "z": 5,
      "name": "Rock_Ice"
    },
    {
      "x": -4,
      "y": 8,
      "z": 5,
      "name": "Rock_Ice"
    },
    {
      "x": -4,
      "y": 9,
      "z": 5,
      "name": "Rock_Ice"
    },
    {
      "x": -4,
      "y": 10,
      "z": 5,
      "name": "Rock_Ice"
    },
    {
      "x": -4,
      "y": 11,
      "z": 5,
      "name": "Rock_Ice"
    },
    {
      "x": -4,
      "y": 12,
      "z": 5,
      "name": "Rock_Ice"
    },
    {
      "x": -4,
      "y": 13,
      "z": 5,
      "name": "Rock_Ice"
    },
    {
      "x": -3,
      "y": -1,
      "z": -3,
      "name": "Rock_Ice"
    },
    {
      "x": -3,
      "y": 0,
      "z": -3,
      "name": "Soil_Snow"
    },
    {
      "x": -3,
      "y": 13,
      "z": -3,
      "name": "Rock_Basalt_Brick"
    },
    {
      "x": -3,
      "y": -1,
      "z": -2,
      "name": "Rock_Ice"
    },
    {
      "x": -3,
      "y": 0,
      "z": -2,
      "name": "Rock_Ice"
    },
    {
      "x": -3,
      "y": 1,
      "z": -2,
      "name": "Rock_Ice_Icicles"
    },
    {
      "x": -3,
      "y": 12,
      "z": -2,
      "name": "Rock_Basalt_Brick_Stairs",
      "rotation": 9
    },
    {
      "x": -3,
      "y": 13,
      "z": -2,
      "name": "Rock_Basalt_Brick"
    },
    {
      "x": -3,
      "y": -1,
      "z": -1,
      "name": "Rock_Ice"
    },
    {
      "x": -3,
      "y": 0,
      "z": -1,
      "name": "Rock_Ice"
    },
    {
      "x": -3,
      "y": 1,
      "z": -1,
      "name": "Rock_Ice_Stalactite_Large"
    },
    {
      "x": -3,
      "y": 2,
      "z": -1,
      "name": "Rock_Ice_Stalactite_Large",
      "filler": 1024
    },
    {
      "x": -3,
      "y": 12,
      "z": -1,
      "name": "Rock_Ice_Icicles",
      "rotation": 8
    },
    {
      "x": -3,
      "y": 13,
      "z": -1,
      "name": "Rock_Basalt_Brick"
    },
    {
      "x": -3,
      "y": -1,
      "z": 0,
      "name": "Rock_Ice"
    },
    {
      "x": -3,
      "y": 0,
      "z": 0,
      "name": "Rock_Ice"
    },
    {
      "x": -3,
      "y": 1,
      "z": 0,
      "name": "Rock_Ice"
    },
    {
      "x": -3,
      "y": 13,
      "z": 0,
      "name": "Rock_Basalt_Brick"
    },
    {
      "x": -3,
      "y": -1,
      "z": 1,
      "name": "Rock_Ice"
    },
    {
      "x": -3,
      "y": 0,
      "z": 1,
      "name": "Rock_Ice"
    },
    {
      "x": -3,
      "y": 1,
      "z": 1,
      "name": "Rock_Ice"
    },
    {
      "x": -3,
      "y": 2,
      "z": 1,
      "name": "Rock_Ice_Icicles"
    },
    {
      "x": -3,
      "y": 12,
      "z": 1,
      "name": "Rock_Ice_Icicles",
      "rotation": 8
    },
    {
      "x": -3,
      "y": 13,
      "z": 1,
      "name": "Rock_Ice"
    },
    {
      "x": -3,
      "y": -1,
      "z": 2,
      "name": "Rock_Ice"
    },
    {
      "x": -3,
      "y": 0,
      "z": 2,
      "name": "Rock_Ice"
    },
    {
      "x": -3,
      "y": 1,
      "z": 2,
      "name": "Rock_Ice"
    },
    {
      "x": -3,
      "y": 2,
      "z": 2,
      "name": "Soil_Snow"
    },
    {
      "x": -3,
      "y": 3,
      "z": 2,
      "name": "Rubble_Basalt",
      "support": 15
    },
    {
      "x": -3,
      "y": 11,
      "z": 2,
      "name": "Rock_Ice_Icicles",
      "rotation": 8
    },
    {
      "x": -3,
      "y": 12,
      "z": 2,
      "name": "Rock_Ice"
    },
    {
      "x": -3,
      "y": 13,
      "z": 2,
      "name": "Rock_Ice"
    },
    {
      "x": -3,
      "y": -1,
      "z": 3,
      "name": "Rock_Ice"
    },
    {
      "x": -3,
      "y": 0,
      "z": 3,
      "name": "Rock_Ice"
    },
    {
      "x": -3,
      "y": 1,
      "z": 3,
      "name": "Rock_Ice"
    },
    {
      "x": -3,
      "y": 2,
      "z": 3,
      "name": "Soil_Snow"
    },
    {
      "x": -3,
      "y": 3,
      "z": 3,
      "name": "Soil_Snow"
    },
    {
      "x": -3,
      "y": 10,
      "z": 3,
      "name": "Rock_Ice"
    },
    {
      "x": -3,
      "y": 11,
      "z": 3,
      "name": "Rock_Ice"
    },
    {
      "x": -3,
      "y": 12,
      "z": 3,
      "name": "Rock_Ice"
    },
    {
      "x": -3,
      "y": 13,
      "z": 3,
      "name": "Rock_Ice"
    },
    {
      "x": -3,
      "y": -1,
      "z": 4,
      "name": "Rock_Ice"
    },
    {
      "x": -3,
      "y": 0,
      "z": 4,
      "name": "Rock_Ice"
    },
    {
      "x": -3,
      "y": 1,
      "z": 4,
      "name": "Rock_Ice"
    },
    {
      "x": -3,
      "y": 2,
      "z": 4,
      "name": "Rock_Ice"
    },
    {
      "x": -3,
      "y": 3,
      "z": 4,
      "name": "Rock_Ice"
    },
    {
      "x": -3,
      "y": 4,
      "z": 4,
      "name": "Rock_Ice"
    },
    {
      "x": -3,
      "y": 5,
      "z": 4,
      "name": "Rock_Ice"
    },
    {
      "x": -3,
      "y": 6,
      "z": 4,
      "name": "Rock_Ice"
    },
    {
      "x": -3,
      "y": 7,
      "z": 4,
      "name": "Rock_Ice"
    },
    {
      "x": -3,
      "y": 8,
      "z": 4,
      "name": "Rock_Ice"
    },
    {
      "x": -3,
      "y": 9,
      "z": 4,
      "name": "Rock_Ice"
    },
    {
      "x": -3,
      "y": 10,
      "z": 4,
      "name": "Rock_Ice"
    },
    {
      "x": -3,
      "y": 11,
      "z": 4,
      "name": "Rock_Ice"
    },
    {
      "x": -3,
      "y": 12,
      "z": 4,
      "name": "Rock_Ice"
    },
    {
      "x": -3,
      "y": 13,
      "z": 4,
      "name": "Rock_Ice"
    },
    {
      "x": -3,
      "y": -1,
      "z": 5,
      "name": "Rock_Ice"
    },
    {
      "x": -3,
      "y": 0,
      "z": 5,
      "name": "Rock_Ice"
    },
    {
      "x": -3,
      "y": 1,
      "z": 5,
      "name": "Rock_Ice"
    },
    {
      "x": -3,
      "y": 2,
      "z": 5,
      "name": "Rock_Ice"
    },
    {
      "x": -3,
      "y": 3,
      "z": 5,
      "name": "Rock_Ice"
    },
    {
      "x": -3,
      "y": 4,
      "z": 5,
      "name": "Rock_Ice"
    },
    {
      "x": -3,
      "y": 5,
      "z": 5,
      "name": "Rock_Ice"
    },
    {
      "x": -3,
      "y": 6,
      "z": 5,
      "name": "Rock_Ice"
    },
    {
      "x": -3,
      "y": 7,
      "z": 5,
      "name": "Rock_Ice"
    },
    {
      "x": -3,
      "y": 8,
      "z": 5,
      "name": "Rock_Ice"
    },
    {
      "x": -3,
      "y": 9,
      "z": 5,
      "name": "Rock_Ice"
    },
    {
      "x": -3,
      "y": 10,
      "z": 5,
      "name": "Rock_Ice"
    },
    {
      "x": -3,
      "y": 11,
      "z": 5,
      "name": "Rock_Ice"
    },
    {
      "x": -3,
      "y": 12,
      "z": 5,
      "name": "Rock_Ice"
    },
    {
      "x": -3,
      "y": 13,
      "z": 5,
      "name": "Rock_Ice"
    },
    {
      "x": -2,
      "y": -1,
      "z": -3,
      "name": "Rock_Ice"
    },
    {
      "x": -2,
      "y": 0,
      "z": -3,
      "name": "Soil_Snow"
    },
    {
      "x": -2,
      "y": 12,
      "z": -3,
      "name": "Rock_Basalt_Brick_Stairs",
      "rotation": 8
    },
    {
      "x": -2,
      "y": 13,
      "z": -3,
      "name": "Rock_Basalt_Brick"
    },
    {
      "x": -2,
      "y": -1,
      "z": -2,
      "name": "Rock_Ice"
    },
    {
      "x": -2,
      "y": 0,
      "z": -2,
      "name": "Rock_Ice"
    },
    {
      "x": -2,
      "y": 10,
      "z": -2,
      "name": "Rock_Basalt_Brick_Beam"
    },
    {
      "x": -2,
      "y": 11,
      "z": -2,
      "name": "Rock_Basalt_Brick_Pillar_Base",
      "rotation": 11
    },
    {
      "x": -2,
      "y": 12,
      "z": -2,
      "name": "Rock_Basalt_Brick",
      "rotation": 3
    },
    {
      "x": -2,
      "y": 13,
      "z": -2,
      "name": "Rock_Basalt_Brick"
    },
    {
      "x": -2,
      "y": -1,
      "z": -1,
      "name": "Rock_Ice"
    },
    {
      "x": -2,
      "y": 0,
      "z": -1,
      "name": "Rock_Ice"
    },
    {
      "x": -2,
      "y": 1,
      "z": -1,
      "name": "Rock_Ice"
    },
    {
      "x": -2,
      "y": 13,
      "z": -1,
      "name": "Rock_Basalt_Brick"
    },
    {
      "x": -2,
      "y": -1,
      "z": 0,
      "name": "Rock_Ice"
    },
    {
      "x": -2,
      "y": 0,
      "z": 0,
      "name": "Rock_Ice"
    },
    {
      "x": -2,
      "y": 1,
      "z": 0,
      "name": "Rock_Ice"
    },
    {
      "x": -2,
      "y": 2,
      "z": 0,
      "name": "Rock_Ice_Icicles"
    },
    {
      "x": -2,
      "y": 12,
      "z": 0,
      "name": "Rock_Ice_Icicles",
      "rotation": 8
    },
    {
      "x": -2,
      "y": 13,
      "z": 0,
      "name": "Rock_Ice"
    },
    {
      "x": -2,
      "y": -1,
      "z": 1,
      "name": "Rock_Ice"
    },
    {
      "x": -2,
      "y": 0,
      "z": 1,
      "name": "Rock_Ice"
    },
    {
      "x": -2,
      "y": 1,
      "z": 1,
      "name": "Rock_Ice"
    },
    {
      "x": -2,
      "y": 2,
      "z": 1,
      "name": "Rock_Ice"
    },
    {
      "x": -2,
      "y": 3,
      "z": 1,
      "name": "Soil_Snow"
    },
    {
      "x": -2,
      "y": 9,
      "z": 1,
      "name": "Rock_Ice_Stalactite_Large",
      "filler": 31744,
      "rotation": 8
    },
    {
      "x": -2,
      "y": 10,
      "z": 1,
      "name": "Rock_Ice_Stalactite_Large",
      "rotation": 8
    },
    {
      "x": -2,
      "y": 11,
      "z": 1,
      "name": "Rock_Ice"
    },
    {
      "x": -2,
      "y": 12,
      "z": 1,
      "name": "Rock_Ice"
    },
    {
      "x": -2,
      "y": 13,
      "z": 1,
      "name": "Rock_Ice"
    },
    {
      "x": -2,
      "y": -1,
      "z": 2,
      "name": "Rock_Ice"
    },
    {
      "x": -2,
      "y": 0,
      "z": 2,
      "name": "Rock_Ice"
    },
    {
      "x": -2,
      "y": 1,
      "z": 2,
      "name": "Rock_Ice"
    },
    {
      "x": -2,
      "y": 2,
      "z": 2,
      "name": "Rock_Ice"
    },
    {
      "x": -2,
      "y": 3,
      "z": 2,
      "name": "Soil_Snow"
    },
    {
      "x": -2,
      "y": 4,
      "z": 2,
      "name": "Soil_Snow"
    },
    {
      "x": -2,
      "y": 8,
      "z": 2,
      "name": "Rock_Ice_Stalactite_Large",
      "filler": 31744,
      "rotation": 8
    },
    {
      "x": -2,
      "y": 9,
      "z": 2,
      "name": "Rock_Ice_Stalactite_Large",
      "rotation": 8
    },
    {
      "x": -2,
      "y": 10,
      "z": 2,
      "name": "Rock_Ice"
    },
    {
      "x": -2,
      "y": 11,
      "z": 2,
      "name": "Rock_Ice"
    },
    {
      "x": -2,
      "y": 12,
      "z": 2,
      "name": "Rock_Ice"
    },
    {
      "x": -2,
      "y": 13,
      "z": 2,
      "name": "Rock_Ice"
    },
    {
      "x": -2,
      "y": -1,
      "z": 3,
      "name": "Rock_Ice"
    },
    {
      "x": -2,
      "y": 0,
      "z": 3,
      "name": "Rock_Ice"
    },
    {
      "x": -2,
      "y": 1,
      "z": 3,
      "name": "Rock_Ice"
    },
    {
      "x": -2,
      "y": 2,
      "z": 3,
      "name": "Rock_Ice"
    },
    {
      "x": -2,
      "y": 3,
      "z": 3,
      "name": "Rock_Ice"
    },
    {
      "x": -2,
      "y": 4,
      "z": 3,
      "name": "Soil_Snow"
    },
    {
      "x": -2,
      "y": 5,
      "z": 3,
      "name": "Soil_Snow"
    },
    {
      "x": -2,
      "y": 8,
      "z": 3,
      "name": "Rock_Ice"
    },
    {
      "x": -2,
      "y": 9,
      "z": 3,
      "name": "Rock_Ice"
    },
    {
      "x": -2,
      "y": 10,
      "z": 3,
      "name": "Rock_Ice"
    },
    {
      "x": -2,
      "y": 11,
      "z": 3,
      "name": "Rock_Ice"
    },
    {
      "x": -2,
      "y": 12,
      "z": 3,
      "name": "Rock_Ice"
    },
    {
      "x": -2,
      "y": 13,
      "z": 3,
      "name": "Rock_Ice"
    },
    {
      "x": -2,
      "y": -1,
      "z": 4,
      "name": "Rock_Ice"
    },
    {
      "x": -2,
      "y": 0,
      "z": 4,
      "name": "Rock_Ice"
    },
    {
      "x": -2,
      "y": 1,
      "z": 4,
      "name": "Rock_Ice"
    },
    {
      "x": -2,
      "y": 2,
      "z": 4,
      "name": "Rock_Ice"
    },
    {
      "x": -2,
      "y": 3,
      "z": 4,
      "name": "Rock_Ice"
    },
    {
      "x": -2,
      "y": 4,
      "z": 4,
      "name": "Rock_Ice"
    },
    {
      "x": -2,
      "y": 5,
      "z": 4,
      "name": "Rock_Ice"
    },
    {
      "x": -2,
      "y": 6,
      "z": 4,
      "name": "Rock_Ice"
    },
    {
      "x": -2,
      "y": 7,
      "z": 4,
      "name": "Rock_Ice"
    },
    {
      "x": -2,
      "y": 8,
      "z": 4,
      "name": "Rock_Ice"
    },
    {
      "x": -2,
      "y": 9,
      "z": 4,
      "name": "Rock_Ice"
    },
    {
      "x": -2,
      "y": 10,
      "z": 4,
      "name": "Rock_Ice"
    },
    {
      "x": -2,
      "y": 11,
      "z": 4,
      "name": "Rock_Ice"
    },
    {
      "x": -2,
      "y": 12,
      "z": 4,
      "name": "Rock_Ice"
    },
    {
      "x": -2,
      "y": 13,
      "z": 4,
      "name": "Rock_Ice"
    },
    {
      "x": -2,
      "y": -1,
      "z": 5,
      "name": "Rock_Ice"
    },
    {
      "x": -2,
      "y": 0,
      "z": 5,
      "name": "Rock_Ice"
    },
    {
      "x": -2,
      "y": 1,
      "z": 5,
      "name": "Rock_Ice"
    },
    {
      "x": -2,
      "y": 2,
      "z": 5,
      "name": "Rock_Ice"
    },
    {
      "x": -2,
      "y": 3,
      "z": 5,
      "name": "Rock_Ice"
    },
    {
      "x": -2,
      "y": 4,
      "z": 5,
      "name": "Rock_Ice"
    },
    {
      "x": -2,
      "y": 5,
      "z": 5,
      "name": "Rock_Ice"
    },
    {
      "x": -2,
      "y": 6,
      "z": 5,
      "name": "Rock_Ice"
    },
    {
      "x": -2,
      "y": 7,
      "z": 5,
      "name": "Rock_Ice"
    },
    {
      "x": -2,
      "y": 8,
      "z": 5,
      "name": "Rock_Ice"
    },
    {
      "x": -2,
      "y": 9,
      "z": 5,
      "name": "Rock_Ice"
    },
    {
      "x": -2,
      "y": 10,
      "z": 5,
      "name": "Rock_Ice"
    },
    {
      "x": -2,
      "y": 11,
      "z": 5,
      "name": "Rock_Ice"
    },
    {
      "x": -2,
      "y": 12,
      "z": 5,
      "name": "Rock_Ice"
    },
    {
      "x": -2,
      "y": 13,
      "z": 5,
      "name": "Rock_Ice"
    },
    {
      "x": -1,
      "y": -1,
      "z": -3,
      "name": "Rock_Ice"
    },
    {
      "x": -1,
      "y": 0,
      "z": -3,
      "name": "Soil_Snow"
    },
    {
      "x": -1,
      "y": 13,
      "z": -3,
      "name": "Rock_Basalt_Brick"
    },
    {
      "x": -1,
      "y": -1,
      "z": -2,
      "name": "Rock_Ice"
    },
    {
      "x": -1,
      "y": 0,
      "z": -2,
      "name": "Rock_Ice"
    },
    {
      "x": -1,
      "y": 1,
      "z": -2,
      "name": "Rock_Ice_Icicles"
    },
    {
      "x": -1,
      "y": 12,
      "z": -2,
      "name": "Rock_Basalt_Brick_Stairs",
      "rotation": 11
    },
    {
      "x": -1,
      "y": 13,
      "z": -2,
      "name": "Rock_Basalt_Brick"
    },
    {
      "x": -1,
      "y": -1,
      "z": -1,
      "name": "Rock_Ice"
    },
    {
      "x": -1,
      "y": 0,
      "z": -1,
      "name": "Rock_Ice"
    },
    {
      "x": -1,
      "y": 1,
      "z": -1,
      "name": "Rock_Ice_Stalactite_Large"
    },
    {
      "x": -1,
      "y": 2,
      "z": -1,
      "name": "Rock_Ice_Stalactite_Large",
      "filler": 1024
    },
    {
      "x": -1,
      "y": 5,
      "z": -1,
      "name": "Furniture_Ancient_Platform",
      "rotation": 1
    },
    {
      "x": -1,
      "y": 12,
      "z": -1,
      "name": "Rock_Ice_Icicles",
      "rotation": 8
    },
    {
      "x": -1,
      "y": 13,
      "z": -1,
      "name": "Rock_Ice"
    },
    {
      "x": -1,
      "y": -1,
      "z": 0,
      "name": "Rock_Ice"
    },
    {
      "x": -1,
      "y": 0,
      "z": 0,
      "name": "Rock_Ice"
    },
    {
      "x": -1,
      "y": 1,
      "z": 0,
      "name": "Soil_Snow"
    },
    {
      "x": -1,
      "y": 2,
      "z": 0,
      "name": "Soil_Snow"
    },
    {
      "x": -1,
      "y": 5,
      "z": 0,
      "name": "Trap_Ancient_Platform",
      "rotation": 1
    },
    {
      "x": -1,
      "y": 12,
      "z": 0,
      "name": "Rock_Ice"
    },
    {
      "x": -1,
      "y": 13,
      "z": 0,
      "name": "Rock_Ice"
    },
    {
      "x": -1,
      "y": -1,
      "z": 1,
      "name": "Rock_Ice"
    },
    {
      "x": -1,
      "y": 0,
      "z": 1,
      "name": "Rock_Ice"
    },
    {
      "x": -1,
      "y": 1,
      "z": 1,
      "name": "Rock_Ice"
    },
    {
      "x": -1,
      "y": 2,
      "z": 1,
      "name": "Rock_Ice"
    },
    {
      "x": -1,
      "y": 3,
      "z": 1,
      "name": "Rock_Ice"
    },
    {
      "x": -1,
      "y": 4,
      "z": 1,
      "name": "Soil_Snow"
    },
    {
      "x": -1,
      "y": 5,
      "z": 1,
      "name": "Trap_Ancient_Platform",
      "rotation": 1
    },
    {
      "x": -1,
      "y": 7,
      "z": 1,
      "name": "Rock_Ice_Stalactite_Large",
      "filler": 31744,
      "rotation": 8
    },
    {
      "x": -1,
      "y": 8,
      "z": 1,
      "name": "Rock_Ice_Stalactite_Large",
      "rotation": 8
    },
    {
      "x": -1,
      "y": 9,
      "z": 1,
      "name": "Rock_Ice"
    },
    {
      "x": -1,
      "y": 10,
      "z": 1,
      "name": "Rock_Ice"
    },
    {
      "x": -1,
      "y": 11,
      "z": 1,
      "name": "Rock_Ice"
    },
    {
      "x": -1,
      "y": 12,
      "z": 1,
      "name": "Rock_Ice"
    },
    {
      "x": -1,
      "y": 13,
      "z": 1,
      "name": "Rock_Ice"
    },
    {
      "x": -1,
      "y": -1,
      "z": 2,
      "name": "Rock_Ice"
    },
    {
      "x": -1,
      "y": 0,
      "z": 2,
      "name": "Rock_Ice"
    },
    {
      "x": -1,
      "y": 1,
      "z": 2,
      "name": "Rock_Ice"
    },
    {
      "x": -1,
      "y": 2,
      "z": 2,
      "name": "Rock_Ice"
    },
    {
      "x": -1,
      "y": 3,
      "z": 2,
      "name": "Rock_Ice"
    },
    {
      "x": -1,
      "y": 4,
      "z": 2,
      "name": "Rock_Ice"
    },
    {
      "x": -1,
      "y": 5,
      "z": 2,
      "name": "Rock_Ice"
    },
    {
      "x": -1,
      "y": 6,
      "z": 2,
      "name": "Rock_Ice"
    },
    {
      "x": -1,
      "y": 7,
      "z": 2,
      "name": "Rock_Ice"
    },
    {
      "x": -1,
      "y": 8,
      "z": 2,
      "name": "Rock_Ice"
    },
    {
      "x": -1,
      "y": 9,
      "z": 2,
      "name": "Rock_Ice"
    },
    {
      "x": -1,
      "y": 10,
      "z": 2,
      "name": "Rock_Ice"
    },
    {
      "x": -1,
      "y": 11,
      "z": 2,
      "name": "Rock_Ice"
    },
    {
      "x": -1,
      "y": 12,
      "z": 2,
      "name": "Rock_Ice"
    },
    {
      "x": -1,
      "y": 13,
      "z": 2,
      "name": "Rock_Ice"
    },
    {
      "x": -1,
      "y": -1,
      "z": 3,
      "name": "Rock_Ice"
    },
    {
      "x": -1,
      "y": 0,
      "z": 3,
      "name": "Rock_Ice"
    },
    {
      "x": -1,
      "y": 1,
      "z": 3,
      "name": "Rock_Ice"
    },
    {
      "x": -1,
      "y": 2,
      "z": 3,
      "name": "Rock_Ice"
    },
    {
      "x": -1,
      "y": 3,
      "z": 3,
      "name": "Rock_Ice"
    },
    {
      "x": -1,
      "y": 4,
      "z": 3,
      "name": "Rock_Ice"
    },
    {
      "x": -1,
      "y": 5,
      "z": 3,
      "name": "Rock_Ice"
    },
    {
      "x": -1,
      "y": 6,
      "z": 3,
      "name": "Rock_Ice"
    },
    {
      "x": -1,
      "y": 7,
      "z": 3,
      "name": "Rock_Ice"
    },
    {
      "x": -1,
      "y": 8,
      "z": 3,
      "name": "Rock_Ice"
    },
    {
      "x": -1,
      "y": 9,
      "z": 3,
      "name": "Rock_Ice"
    },
    {
      "x": -1,
      "y": 10,
      "z": 3,
      "name": "Rock_Ice"
    },
    {
      "x": -1,
      "y": 11,
      "z": 3,
      "name": "Rock_Ice"
    },
    {
      "x": -1,
      "y": 12,
      "z": 3,
      "name": "Rock_Ice"
    },
    {
      "x": -1,
      "y": 13,
      "z": 3,
      "name": "Rock_Ice"
    },
    {
      "x": -1,
      "y": -1,
      "z": 4,
      "name": "Rock_Ice"
    },
    {
      "x": -1,
      "y": 0,
      "z": 4,
      "name": "Rock_Ice"
    },
    {
      "x": -1,
      "y": 1,
      "z": 4,
      "name": "Rock_Ice"
    },
    {
      "x": -1,
      "y": 2,
      "z": 4,
      "name": "Rock_Ice"
    },
    {
      "x": -1,
      "y": 3,
      "z": 4,
      "name": "Rock_Ice"
    },
    {
      "x": -1,
      "y": 4,
      "z": 4,
      "name": "Rock_Ice"
    },
    {
      "x": -1,
      "y": 5,
      "z": 4,
      "name": "Rock_Ice"
    },
    {
      "x": -1,
      "y": 6,
      "z": 4,
      "name": "Rock_Ice"
    },
    {
      "x": -1,
      "y": 7,
      "z": 4,
      "name": "Rock_Ice"
    },
    {
      "x": -1,
      "y": 8,
      "z": 4,
      "name": "Rock_Ice"
    },
    {
      "x": -1,
      "y": 9,
      "z": 4,
      "name": "Rock_Ice"
    },
    {
      "x": -1,
      "y": 10,
      "z": 4,
      "name": "Rock_Ice"
    },
    {
      "x": -1,
      "y": 11,
      "z": 4,
      "name": "Rock_Ice"
    },
    {
      "x": -1,
      "y": 12,
      "z": 4,
      "name": "Rock_Ice"
    },
    {
      "x": -1,
      "y": 13,
      "z": 4,
      "name": "Rock_Ice"
    },
    {
      "x": -1,
      "y": -1,
      "z": 5,
      "name": "Rock_Ice"
    },
    {
      "x": -1,
      "y": 0,
      "z": 5,
      "name": "Rock_Ice"
    },
    {
      "x": -1,
      "y": 1,
      "z": 5,
      "name": "Rock_Ice"
    },
    {
      "x": -1,
      "y": 2,
      "z": 5,
      "name": "Rock_Ice"
    },
    {
      "x": -1,
      "y": 3,
      "z": 5,
      "name": "Rock_Ice"
    },
    {
      "x": -1,
      "y": 4,
      "z": 5,
      "name": "Rock_Ice"
    },
    {
      "x": -1,
      "y": 5,
      "z": 5,
      "name": "Rock_Ice"
    },
    {
      "x": -1,
      "y": 6,
      "z": 5,
      "name": "Rock_Ice"
    },
    {
      "x": -1,
      "y": 7,
      "z": 5,
      "name": "Rock_Ice"
    },
    {
      "x": -1,
      "y": 8,
      "z": 5,
      "name": "Rock_Ice"
    },
    {
      "x": -1,
      "y": 9,
      "z": 5,
      "name": "Rock_Ice"
    },
    {
      "x": -1,
      "y": 10,
      "z": 5,
      "name": "Rock_Ice"
    },
    {
      "x": -1,
      "y": 11,
      "z": 5,
      "name": "Rock_Ice"
    },
    {
      "x": -1,
      "y": 12,
      "z": 5,
      "name": "Rock_Ice"
    },
    {
      "x": -1,
      "y": 13,
      "z": 5,
      "name": "Rock_Ice"
    },
    {
      "x": 0,
      "y": -1,
      "z": -3,
      "name": "Rock_Ice"
    },
    {
      "x": 0,
      "y": 0,
      "z": -3,
      "name": "Soil_Snow"
    },
    {
      "x": 0,
      "y": 1,
      "z": -3,
      "name": "Rubble_Basalt",
      "support": 15
    },
    {
      "x": 0,
      "y": 13,
      "z": -3,
      "name": "Rock_Basalt_Brick"
    },
    {
      "x": 0,
      "y": -1,
      "z": -2,
      "name": "Rock_Ice"
    },
    {
      "x": 0,
      "y": 0,
      "z": -2,
      "name": "Rock_Ice"
    },
    {
      "x": 0,
      "y": 12,
      "z": -2,
      "name": "Rock_Basalt_Brick_Half",
      "rotation": 11
    },
    {
      "x": 0,
      "y": 13,
      "z": -2,
      "name": "Rock_Basalt_Brick"
    },
    {
      "x": 0,
      "y": -1,
      "z": -1,
      "name": "Rock_Ice"
    },
    {
      "x": 0,
      "y": 0,
      "z": -1,
      "name": "Rock_Ice"
    },
    {
      "x": 0,
      "y": 1,
      "z": -1,
      "name": "Rock_Ice_Icicles"
    },
    {
      "x": 0,
      "y": 5,
      "z": -1,
      "name": "Furniture_Ancient_Platform",
      "rotation": 1
    },
    {
      "x": 0,
      "y": 11,
      "z": -1,
      "name": "Rock_Ice_Stalactite_Large",
      "filler": 31744,
      "rotation": 8
    },
    {
      "x": 0,
      "y": 12,
      "z": -1,
      "name": "Rock_Ice_Stalactite_Large",
      "rotation": 8
    },
    {
      "x": 0,
      "y": 13,
      "z": -1,
      "name": "Rock_Ice"
    },
    {
      "x": 0,
      "y": -1,
      "z": 0,
      "name": "Rock_Ice"
    },
    {
      "x": 0,
      "y": 0,
      "z": 0,
      "name": "Rock_Ice"
    },
    {
      "x": 0,
      "y": 1,
      "z": 0,
      "name": "Soil_Snow"
    },
    {
      "x": 0,
      "y": 2,
      "z": 0,
      "name": "Rock_Ice_Stalactite_Large"
    },
    {
      "x": 0,
      "y": 3,
      "z": 0,
      "name": "Rock_Ice_Stalactite_Large",
      "filler": 1024
    },
    {
      "x": 0,
      "y": 5,
      "z": 0,
      "name": "Furniture_Ancient_Platform",
      "rotation": 1
    },
    {
      "x": 0,
      "y": 11,
      "z": 0,
      "name": "Rock_Ice_Icicles",
      "rotation": 8
    },
    {
      "x": 0,
      "y": 12,
      "z": 0,
      "name": "Rock_Ice"
    },
    {
      "x": 0,
      "y": 13,
      "z": 0,
      "name": "Rock_Ice"
    },
    {
      "x": 0,
      "y": -1,
      "z": 1,
      "name": "Rock_Ice"
    },
    {
      "x": 0,
      "y": 0,
      "z": 1,
      "name": "Rock_Ice"
    },
    {
      "x": 0,
      "y": 1,
      "z": 1,
      "name": "Rock_Ice"
    },
    {
      "x": 0,
      "y": 2,
      "z": 1,
      "name": "Rock_Ice"
    },
    {
      "x": 0,
      "y": 3,
      "z": 1,
      "name": "Soil_Snow"
    },
    {
      "x": 0,
      "y": 4,
      "z": 1,
      "name": "Soil_Snow"
    },
    {
      "x": 0,
      "y": 5,
      "z": 1,
      "name": "Trap_Ancient_Platform",
      "rotation": 1
    },
    {
      "x": 0,
      "y": 10,
      "z": 1,
      "name": "Rock_Ice"
    },
    {
      "x": 0,
      "y": 11,
      "z": 1,
      "name": "Rock_Ice"
    },
    {
      "x": 0,
      "y": 12,
      "z": 1,
      "name": "Rock_Ice"
    },
    {
      "x": 0,
      "y": 13,
      "z": 1,
      "name": "Rock_Ice"
    },
    {
      "x": 0,
      "y": -1,
      "z": 2,
      "name": "Rock_Ice"
    },
    {
      "x": 0,
      "y": 0,
      "z": 2,
      "name": "Rock_Ice"
    },
    {
      "x": 0,
      "y": 1,
      "z": 2,
      "name": "Rock_Ice"
    },
    {
      "x": 0,
      "y": 2,
      "z": 2,
      "name": "Rock_Ice"
    },
    {
      "x": 0,
      "y": 3,
      "z": 2,
      "name": "Rock_Ice"
    },
    {
      "x": 0,
      "y": 4,
      "z": 2,
      "name": "Rock_Ice"
    },
    {
      "x": 0,
      "y": 5,
      "z": 2,
      "name": "Rock_Ice"
    },
    {
      "x": 0,
      "y": 6,
      "z": 2,
      "name": "Rock_Ice"
    },
    {
      "x": 0,
      "y": 7,
      "z": 2,
      "name": "Furniture_Human_Ruins_Torch",
      "rotation": 2
    },
    {
      "x": 0,
      "y": 9,
      "z": 2,
      "name": "Rock_Ice"
    },
    {
      "x": 0,
      "y": 10,
      "z": 2,
      "name": "Rock_Ice"
    },
    {
      "x": 0,
      "y": 11,
      "z": 2,
      "name": "Rock_Ice"
    },
    {
      "x": 0,
      "y": 12,
      "z": 2,
      "name": "Rock_Ice"
    },
    {
      "x": 0,
      "y": 13,
      "z": 2,
      "name": "Rock_Ice"
    },
    {
      "x": 0,
      "y": -1,
      "z": 3,
      "name": "Rock_Ice"
    },
    {
      "x": 0,
      "y": 0,
      "z": 3,
      "name": "Rock_Ice"
    },
    {
      "x": 0,
      "y": 1,
      "z": 3,
      "name": "Rock_Ice"
    },
    {
      "x": 0,
      "y": 2,
      "z": 3,
      "name": "Rock_Ice"
    },
    {
      "x": 0,
      "y": 3,
      "z": 3,
      "name": "Rock_Ice"
    },
    {
      "x": 0,
      "y": 4,
      "z": 3,
      "name": "Rock_Ice"
    },
    {
      "x": 0,
      "y": 5,
      "z": 3,
      "name": "Rock_Ice"
    },
    {
      "x": 0,
      "y": 6,
      "z": 3,
      "name": "Rock_Ice"
    },
    {
      "x": 0,
      "y": 7,
      "z": 3,
      "name": "Rock_Ice"
    },
    {
      "x": 0,
      "y": 8,
      "z": 3,
      "name": "Rock_Ice"
    },
    {
      "x": 0,
      "y": 9,
      "z": 3,
      "name": "Rock_Ice"
    },
    {
      "x": 0,
      "y": 10,
      "z": 3,
      "name": "Rock_Ice"
    },
    {
      "x": 0,
      "y": 11,
      "z": 3,
      "name": "Rock_Ice"
    },
    {
      "x": 0,
      "y": 12,
      "z": 3,
      "name": "Rock_Ice"
    },
    {
      "x": 0,
      "y": 13,
      "z": 3,
      "name": "Rock_Ice"
    },
    {
      "x": 0,
      "y": -1,
      "z": 4,
      "name": "Rock_Ice"
    },
    {
      "x": 0,
      "y": 0,
      "z": 4,
      "name": "Rock_Ice"
    },
    {
      "x": 0,
      "y": 1,
      "z": 4,
      "name": "Rock_Ice"
    },
    {
      "x": 0,
      "y": 2,
      "z": 4,
      "name": "Rock_Ice"
    },
    {
      "x": 0,
      "y": 3,
      "z": 4,
      "name": "Rock_Ice"
    },
    {
      "x": 0,
      "y": 4,
      "z": 4,
      "name": "Rock_Ice"
    },
    {
      "x": 0,
      "y": 5,
      "z": 4,
      "name": "Rock_Ice"
    },
    {
      "x": 0,
      "y": 6,
      "z": 4,
      "name": "Rock_Ice"
    },
    {
      "x": 0,
      "y": 7,
      "z": 4,
      "name": "Rock_Ice"
    },
    {
      "x": 0,
      "y": 8,
      "z": 4,
      "name": "Rock_Ice"
    },
    {
      "x": 0,
      "y": 9,
      "z": 4,
      "name": "Rock_Ice"
    },
    {
      "x": 0,
      "y": 10,
      "z": 4,
      "name": "Rock_Ice"
    },
    {
      "x": 0,
      "y": 11,
      "z": 4,
      "name": "Rock_Ice"
    },
    {
      "x": 0,
      "y": 12,
      "z": 4,
      "name": "Rock_Ice"
    },
    {
      "x": 0,
      "y": 13,
      "z": 4,
      "name": "Rock_Ice"
    },
    {
      "x": 0,
      "y": -1,
      "z": 5,
      "name": "Rock_Ice"
    },
    {
      "x": 0,
      "y": 0,
      "z": 5,
      "name": "Rock_Ice"
    },
    {
      "x": 0,
      "y": 1,
      "z": 5,
      "name": "Rock_Ice"
    },
    {
      "x": 0,
      "y": 2,
      "z": 5,
      "name": "Rock_Ice"
    },
    {
      "x": 0,
      "y": 3,
      "z": 5,
      "name": "Rock_Ice"
    },
    {
      "x": 0,
      "y": 4,
      "z": 5,
      "name": "Rock_Ice"
    },
    {
      "x": 0,
      "y": 5,
      "z": 5,
      "name": "Rock_Ice"
    },
    {
      "x": 0,
      "y": 6,
      "z": 5,
      "name": "Rock_Ice"
    },
    {
      "x": 0,
      "y": 7,
      "z": 5,
      "name": "Rock_Ice"
    },
    {
      "x": 0,
      "y": 8,
      "z": 5,
      "name": "Rock_Ice"
    },
    {
      "x": 0,
      "y": 9,
      "z": 5,
      "name": "Rock_Ice"
    },
    {
      "x": 0,
      "y": 10,
      "z": 5,
      "name": "Rock_Ice"
    },
    {
      "x": 0,
      "y": 11,
      "z": 5,
      "name": "Rock_Ice"
    },
    {
      "x": 0,
      "y": 12,
      "z": 5,
      "name": "Rock_Ice"
    },
    {
      "x": 0,
      "y": 13,
      "z": 5,
      "name": "Rock_Ice"
    },
    {
      "x": 1,
      "y": -1,
      "z": -3,
      "name": "Rock_Ice"
    },
    {
      "x": 1,
      "y": 0,
      "z": -3,
      "name": "Soil_Snow"
    },
    {
      "x": 1,
      "y": 13,
      "z": -3,
      "name": "Rock_Basalt_Brick"
    },
    {
      "x": 1,
      "y": -1,
      "z": -2,
      "name": "Rock_Ice"
    },
    {
      "x": 1,
      "y": 0,
      "z": -2,
      "name": "Soil_Snow"
    },
    {
      "x": 1,
      "y": 12,
      "z": -2,
      "name": "Rock_Basalt_Brick_Stairs",
      "rotation": 9
    },
    {
      "x": 1,
      "y": 13,
      "z": -2,
      "name": "Rock_Basalt_Brick"
    },
    {
      "x": 1,
      "y": -1,
      "z": -1,
      "name": "Rock_Ice"
    },
    {
      "x": 1,
      "y": 1,
      "z": -1,
      "name": "Soil_Snow"
    },
    {
      "x": 1,
      "y": 13,
      "z": -1,
      "name": "Rock_Ice"
    },
    {
      "x": 1,
      "y": -1,
      "z": 0,
      "name": "Rock_Ice"
    },
    {
      "x": 1,
      "y": 0,
      "z": 0,
      "name": "Rock_Ice"
    },
    {
      "x": 1,
      "y": 1,
      "z": 0,
      "name": "Soil_Snow"
    },
    {
      "x": 1,
      "y": 2,
      "z": 0,
      "name": "Rock_Ice_Icicles"
    },
    {
      "x": 1,
      "y": 5,
      "z": 0,
      "name": "Furniture_Ancient_Platform",
      "rotation": 1
    },
    {
      "x": 1,
      "y": 12,
      "z": 0,
      "name": "Rock_Ice"
    },
    {
      "x": 1,
      "y": 13,
      "z": 0,
      "name": "Rock_Ice"
    },
    {
      "x": 1,
      "y": -1,
      "z": 1,
      "name": "Rock_Ice"
    },
    {
      "x": 1,
      "y": 0,
      "z": 1,
      "name": "Rock_Ice"
    },
    {
      "x": 1,
      "y": 1,
      "z": 1,
      "name": "Rock_Ice"
    },
    {
      "x": 1,
      "y": 2,
      "z": 1,
      "name": "Soil_Snow"
    },
    {
      "x": 1,
      "y": 3,
      "z": 1,
      "name": "Soil_Snow"
    },
    {
      "x": 1,
      "y": 5,
      "z": 1,
      "name": "Furniture_Ancient_Platform",
      "rotation": 1
    },
    {
      "x": 1,
      "y": 11,
      "z": 1,
      "name": "Rock_Ice"
    },
    {
      "x": 1,
      "y": 12,
      "z": 1,
      "name": "Rock_Ice"
    },
    {
      "x": 1,
      "y": 13,
      "z": 1,
      "name": "Rock_Ice"
    },
    {
      "x": 1,
      "y": -1,
      "z": 2,
      "name": "Rock_Ice"
    },
    {
      "x": 1,
      "y": 0,
      "z": 2,
      "name": "Rock_Ice"
    },
    {
      "x": 1,
      "y": 1,
      "z": 2,
      "name": "Rock_Ice"
    },
    {
      "x": 1,
      "y": 2,
      "z": 2,
      "name": "Rock_Ice"
    },
    {
      "x": 1,
      "y": 3,
      "z": 2,
      "name": "Rock_Ice"
    },
    {
      "x": 1,
      "y": 4,
      "z": 2,
      "name": "Rock_Ice"
    },
    {
      "x": 1,
      "y": 5,
      "z": 2,
      "name": "Rock_Ice"
    },
    {
      "x": 1,
      "y": 9,
      "z": 2,
      "name": "Rock_Ice_Stalactite_Large",
      "filler": 31744,
      "rotation": 8
    },
    {
      "x": 1,
      "y": 10,
      "z": 2,
      "name": "Rock_Ice_Stalactite_Large",
      "rotation": 8
    },
    {
      "x": 1,
      "y": 11,
      "z": 2,
      "name": "Rock_Ice"
    },
    {
      "x": 1,
      "y": 12,
      "z": 2,
      "name": "Rock_Ice"
    },
    {
      "x": 1,
      "y": 13,
      "z": 2,
      "name": "Rock_Ice"
    },
    {
      "x": 1,
      "y": -1,
      "z": 3,
      "name": "Rock_Ice"
    },
    {
      "x": 1,
      "y": 0,
      "z": 3,
      "name": "Rock_Ice"
    },
    {
      "x": 1,
      "y": 1,
      "z": 3,
      "name": "Rock_Ice"
    },
    {
      "x": 1,
      "y": 2,
      "z": 3,
      "name": "Rock_Ice"
    },
    {
      "x": 1,
      "y": 3,
      "z": 3,
      "name": "Rock_Ice"
    },
    {
      "x": 1,
      "y": 4,
      "z": 3,
      "name": "Rock_Ice"
    },
    {
      "x": 1,
      "y": 5,
      "z": 3,
      "name": "Rock_Ice"
    },
    {
      "x": 1,
      "y": 6,
      "z": 3,
      "name": "Rock_Ice"
    },
    {
      "x": 1,
      "y": 9,
      "z": 3,
      "name": "Rock_Ice_Icicles",
      "rotation": 8
    },
    {
      "x": 1,
      "y": 10,
      "z": 3,
      "name": "Rock_Ice"
    },
    {
      "x": 1,
      "y": 11,
      "z": 3,
      "name": "Rock_Ice"
    },
    {
      "x": 1,
      "y": 12,
      "z": 3,
      "name": "Rock_Ice"
    },
    {
      "x": 1,
      "y": 13,
      "z": 3,
      "name": "Rock_Ice"
    },
    {
      "x": 1,
      "y": -1,
      "z": 4,
      "name": "Rock_Ice"
    },
    {
      "x": 1,
      "y": 0,
      "z": 4,
      "name": "Rock_Ice"
    },
    {
      "x": 1,
      "y": 1,
      "z": 4,
      "name": "Rock_Ice"
    },
    {
      "x": 1,
      "y": 2,
      "z": 4,
      "name": "Rock_Ice"
    },
    {
      "x": 1,
      "y": 3,
      "z": 4,
      "name": "Rock_Ice"
    },
    {
      "x": 1,
      "y": 4,
      "z": 4,
      "name": "Rock_Ice"
    },
    {
      "x": 1,
      "y": 5,
      "z": 4,
      "name": "Rock_Ice"
    },
    {
      "x": 1,
      "y": 6,
      "z": 4,
      "name": "Rock_Ice"
    },
    {
      "x": 1,
      "y": 7,
      "z": 4,
      "name": "Rock_Ice"
    },
    {
      "x": 1,
      "y": 8,
      "z": 4,
      "name": "Rock_Ice"
    },
    {
      "x": 1,
      "y": 9,
      "z": 4,
      "name": "Rock_Ice"
    },
    {
      "x": 1,
      "y": 10,
      "z": 4,
      "name": "Rock_Ice"
    },
    {
      "x": 1,
      "y": 11,
      "z": 4,
      "name": "Rock_Ice"
    },
    {
      "x": 1,
      "y": 12,
      "z": 4,
      "name": "Rock_Ice"
    },
    {
      "x": 1,
      "y": 13,
      "z": 4,
      "name": "Rock_Ice"
    },
    {
      "x": 1,
      "y": -1,
      "z": 5,
      "name": "Rock_Ice"
    },
    {
      "x": 1,
      "y": 0,
      "z": 5,
      "name": "Rock_Ice"
    },
    {
      "x": 1,
      "y": 1,
      "z": 5,
      "name": "Rock_Ice"
    },
    {
      "x": 1,
      "y": 2,
      "z": 5,
      "name": "Rock_Ice"
    },
    {
      "x": 1,
      "y": 3,
      "z": 5,
      "name": "Rock_Ice"
    },
    {
      "x": 1,
      "y": 4,
      "z": 5,
      "name": "Rock_Ice"
    },
    {
      "x": 1,
      "y": 5,
      "z": 5,
      "name": "Rock_Ice"
    },
    {
      "x": 1,
      "y": 6,
      "z": 5,
      "name": "Rock_Ice"
    },
    {
      "x": 1,
      "y": 7,
      "z": 5,
      "name": "Rock_Ice"
    },
    {
      "x": 1,
      "y": 8,
      "z": 5,
      "name": "Rock_Ice"
    },
    {
      "x": 1,
      "y": 9,
      "z": 5,
      "name": "Rock_Ice"
    },
    {
      "x": 1,
      "y": 10,
      "z": 5,
      "name": "Rock_Ice"
    },
    {
      "x": 1,
      "y": 11,
      "z": 5,
      "name": "Rock_Ice"
    },
    {
      "x": 1,
      "y": 12,
      "z": 5,
      "name": "Rock_Ice"
    },
    {
      "x": 1,
      "y": 13,
      "z": 5,
      "name": "Rock_Ice"
    },
    {
      "x": 2,
      "y": -1,
      "z": -3,
      "name": "Rock_Ice"
    },
    {
      "x": 2,
      "y": 0,
      "z": -3,
      "name": "Rock_Basalt_Brick",
      "rotation": 3
    },
    {
      "x": 2,
      "y": 13,
      "z": -3,
      "name": "Rock_Basalt_Brick"
    },
    {
      "x": 2,
      "y": -1,
      "z": -2,
      "name": "Rock_Ice"
    },
    {
      "x": 2,
      "y": 0,
      "z": -2,
      "name": "Soil_Snow"
    },
    {
      "x": 2,
      "y": 1,
      "z": -2,
      "name": "Rock_Basalt_Brick_Pillar_Base"
    },
    {
      "x": 2,
      "y": 2,
      "z": -2,
      "name": "Rock_Basalt_Brick_Pillar_Middle"
    },
    {
      "x": 2,
      "y": 3,
      "z": -2,
      "name": "Rock_Basalt_Brick_Beam"
    },
    {
      "x": 2,
      "y": 8,
      "z": -2,
      "name": "Rock_Basalt_Brick_Beam"
    },
    {
      "x": 2,
      "y": 9,
      "z": -2,
      "name": "Rock_Basalt_Brick_Pillar_Middle"
    },
    {
      "x": 2,
      "y": 10,
      "z": -2,
      "name": "Rock_Basalt_Brick_Pillar_Middle",
      "rotation": 3
    },
    {
      "x": 2,
      "y": 11,
      "z": -2,
      "name": "Rock_Basalt_Brick_Pillar_Base",
      "rotation": 11
    },
    {
      "x": 2,
      "y": 12,
      "z": -2,
      "name": "Rock_Basalt_Brick",
      "rotation": 3
    },
    {
      "x": 2,
      "y": 13,
      "z": -2,
      "name": "Rock_Basalt_Brick"
    },
    {
      "x": 2,
      "y": -1,
      "z": -1,
      "name": "Rock_Ice"
    },
    {
      "x": 2,
      "y": 0,
      "z": -1,
      "name": "Rock_Ice"
    },
    {
      "x": 2,
      "y": 1,
      "z": -1,
      "name": "Soil_Snow"
    },
    {
      "x": 2,
      "y": 13,
      "z": -1,
      "name": "Rock_Ice"
    },
    {
      "x": 2,
      "y": -1,
      "z": 0,
      "name": "Rock_Ice"
    },
    {
      "x": 2,
      "y": 0,
      "z": 0,
      "name": "Rock_Ice"
    },
    {
      "x": 2,
      "y": 1,
      "z": 0,
      "name": "Rock_Ice"
    },
    {
      "x": 2,
      "y": 2,
      "z": 0,
      "name": "Rubble_Basalt",
      "support": 15
    },
    {
      "x": 2,
      "y": 12,
      "z": 0,
      "name": "Rock_Ice_Icicles",
      "rotation": 8
    },
    {
      "x": 2,
      "y": 13,
      "z": 0,
      "name": "Rock_Ice"
    },
    {
      "x": 2,
      "y": -1,
      "z": 1,
      "name": "Rock_Ice"
    },
    {
      "x": 2,
      "y": 0,
      "z": 1,
      "name": "Rock_Ice"
    },
    {
      "x": 2,
      "y": 1,
      "z": 1,
      "name": "Rock_Ice"
    },
    {
      "x": 2,
      "y": 2,
      "z": 1,
      "name": "Rock_Ice_Icicles"
    },
    {
      "x": 2,
      "y": 11,
      "z": 1,
      "name": "Rock_Ice_Icicles",
      "rotation": 8
    },
    {
      "x": 2,
      "y": 12,
      "z": 1,
      "name": "Rock_Ice"
    },
    {
      "x": 2,
      "y": 13,
      "z": 1,
      "name": "Rock_Ice"
    },
    {
      "x": 2,
      "y": -1,
      "z": 2,
      "name": "Rock_Ice"
    },
    {
      "x": 2,
      "y": 0,
      "z": 2,
      "name": "Rock_Ice"
    },
    {
      "x": 2,
      "y": 1,
      "z": 2,
      "name": "Rock_Ice"
    },
    {
      "x": 2,
      "y": 2,
      "z": 2,
      "name": "Rock_Ice"
    },
    {
      "x": 2,
      "y": 11,
      "z": 2,
      "name": "Rock_Ice"
    },
    {
      "x": 2,
      "y": 12,
      "z": 2,
      "name": "Rock_Ice"
    },
    {
      "x": 2,
      "y": 13,
      "z": 2,
      "name": "Rock_Ice"
    },
    {
      "x": 2,
      "y": -1,
      "z": 3,
      "name": "Rock_Ice"
    },
    {
      "x": 2,
      "y": 0,
      "z": 3,
      "name": "Rock_Ice"
    },
    {
      "x": 2,
      "y": 1,
      "z": 3,
      "name": "Rock_Ice"
    },
    {
      "x": 2,
      "y": 2,
      "z": 3,
      "name": "Rock_Ice"
    },
    {
      "x": 2,
      "y": 3,
      "z": 3,
      "name": "Rock_Ice"
    },
    {
      "x": 2,
      "y": 4,
      "z": 3,
      "name": "Rock_Ice_Stalactite_Large"
    },
    {
      "x": 2,
      "y": 5,
      "z": 3,
      "name": "Rock_Ice_Stalactite_Large",
      "filler": 1024
    },
    {
      "x": 2,
      "y": 10,
      "z": 3,
      "name": "Rock_Ice_Icicles",
      "rotation": 8
    },
    {
      "x": 2,
      "y": 11,
      "z": 3,
      "name": "Rock_Ice"
    },
    {
      "x": 2,
      "y": 12,
      "z": 3,
      "name": "Rock_Ice"
    },
    {
      "x": 2,
      "y": 13,
      "z": 3,
      "name": "Rock_Ice"
    },
    {
      "x": 2,
      "y": -1,
      "z": 4,
      "name": "Rock_Ice"
    },
    {
      "x": 2,
      "y": 0,
      "z": 4,
      "name": "Rock_Ice"
    },
    {
      "x": 2,
      "y": 1,
      "z": 4,
      "name": "Rock_Ice"
    },
    {
      "x": 2,
      "y": 2,
      "z": 4,
      "name": "Rock_Ice"
    },
    {
      "x": 2,
      "y": 3,
      "z": 4,
      "name": "Rock_Ice"
    },
    {
      "x": 2,
      "y": 4,
      "z": 4,
      "name": "Rock_Ice"
    },
    {
      "x": 2,
      "y": 5,
      "z": 4,
      "name": "Rock_Ice_Stalactite_Large"
    },
    {
      "x": 2,
      "y": 6,
      "z": 4,
      "name": "Rock_Ice_Stalactite_Large",
      "filler": 1024
    },
    {
      "x": 2,
      "y": 8,
      "z": 4,
      "name": "Rock_Ice_Stalactite_Large",
      "filler": 31744,
      "rotation": 8
    },
    {
      "x": 2,
      "y": 9,
      "z": 4,
      "name": "Rock_Ice_Stalactite_Large",
      "rotation": 8
    },
    {
      "x": 2,
      "y": 10,
      "z": 4,
      "name": "Rock_Ice"
    },
    {
      "x": 2,
      "y": 11,
      "z": 4,
      "name": "Rock_Ice"
    },
    {
      "x": 2,
      "y": 12,
      "z": 4,
      "name": "Rock_Ice"
    },
    {
      "x": 2,
      "y": 13,
      "z": 4,
      "name": "Rock_Ice"
    },
    {
      "x": 2,
      "y": -1,
      "z": 5,
      "name": "Rock_Ice"
    },
    {
      "x": 2,
      "y": 0,
      "z": 5,
      "name": "Rock_Ice"
    },
    {
      "x": 2,
      "y": 1,
      "z": 5,
      "name": "Rock_Ice"
    },
    {
      "x": 2,
      "y": 2,
      "z": 5,
      "name": "Rock_Ice"
    },
    {
      "x": 2,
      "y": 3,
      "z": 5,
      "name": "Rock_Ice"
    },
    {
      "x": 2,
      "y": 4,
      "z": 5,
      "name": "Rock_Ice"
    },
    {
      "x": 2,
      "y": 5,
      "z": 5,
      "name": "Rock_Ice"
    },
    {
      "x": 2,
      "y": 6,
      "z": 5,
      "name": "Rock_Ice"
    },
    {
      "x": 2,
      "y": 7,
      "z": 5,
      "name": "Rock_Ice"
    },
    {
      "x": 2,
      "y": 8,
      "z": 5,
      "name": "Rock_Ice"
    },
    {
      "x": 2,
      "y": 9,
      "z": 5,
      "name": "Rock_Ice"
    },
    {
      "x": 2,
      "y": 10,
      "z": 5,
      "name": "Rock_Ice"
    },
    {
      "x": 2,
      "y": 11,
      "z": 5,
      "name": "Rock_Ice"
    },
    {
      "x": 2,
      "y": 12,
      "z": 5,
      "name": "Rock_Ice"
    },
    {
      "x": 2,
      "y": 13,
      "z": 5,
      "name": "Rock_Ice"
    },
    {
      "x": 3,
      "y": -1,
      "z": -3,
      "name": "Rock_Ice"
    },
    {
      "x": 3,
      "y": 0,
      "z": -3,
      "name": "Rock_Basalt",
      "rotation": 3
    },
    {
      "x": 3,
      "y": 13,
      "z": -3,
      "name": "Rock_Basalt_Brick"
    },
    {
      "x": 3,
      "y": -1,
      "z": -2,
      "name": "Rock_Ice"
    },
    {
      "x": 3,
      "y": 0,
      "z": -2,
      "name": "Soil_Snow"
    },
    {
      "x": 3,
      "y": 12,
      "z": -2,
      "name": "Rock_Basalt_Brick_Stairs",
      "rotation": 11
    },
    {
      "x": 3,
      "y": 13,
      "z": -2,
      "name": "Rock_Basalt_Brick"
    },
    {
      "x": 3,
      "y": -1,
      "z": -1,
      "name": "Rock_Ice"
    },
    {
      "x": 3,
      "y": 0,
      "z": -1,
      "name": "Rock_Ice"
    },
    {
      "x": 3,
      "y": 1,
      "z": -1,
      "name": "Rock_Ice_Icicles"
    },
    {
      "x": 3,
      "y": 13,
      "z": -1,
      "name": "Rock_Basalt_Brick"
    },
    {
      "x": 3,
      "y": -1,
      "z": 0,
      "name": "Rock_Ice"
    },
    {
      "x": 3,
      "y": 0,
      "z": 0,
      "name": "Rock_Ice"
    },
    {
      "x": 3,
      "y": 1,
      "z": 0,
      "name": "Rock_Ice"
    },
    {
      "x": 3,
      "y": 2,
      "z": 0,
      "name": "Rock_Ice_Icicles"
    },
    {
      "x": 3,
      "y": 13,
      "z": 0,
      "name": "Rock_Ice"
    },
    {
      "x": 3,
      "y": -1,
      "z": 1,
      "name": "Rock_Ice"
    },
    {
      "x": 3,
      "y": 0,
      "z": 1,
      "name": "Rock_Ice"
    },
    {
      "x": 3,
      "y": 1,
      "z": 1,
      "name": "Rock_Ice"
    },
    {
      "x": 3,
      "y": 12,
      "z": 1,
      "name": "Rock_Ice_Icicles",
      "rotation": 8
    },
    {
      "x": 3,
      "y": 13,
      "z": 1,
      "name": "Rock_Ice"
    },
    {
      "x": 3,
      "y": -1,
      "z": 2,
      "name": "Rock_Ice"
    },
    {
      "x": 3,
      "y": 0,
      "z": 2,
      "name": "Rock_Ice"
    },
    {
      "x": 3,
      "y": 1,
      "z": 2,
      "name": "Rock_Ice"
    },
    {
      "x": 3,
      "y": 2,
      "z": 2,
      "name": "Rock_Ice_Icicles"
    },
    {
      "x": 3,
      "y": 11,
      "z": 2,
      "name": "Rock_Ice_Stalactite_Large",
      "filler": 31744,
      "rotation": 8
    },
    {
      "x": 3,
      "y": 12,
      "z": 2,
      "name": "Rock_Ice_Stalactite_Large",
      "rotation": 8
    },
    {
      "x": 3,
      "y": 13,
      "z": 2,
      "name": "Rock_Ice"
    },
    {
      "x": 3,
      "y": -1,
      "z": 3,
      "name": "Rock_Ice"
    },
    {
      "x": 3,
      "y": 0,
      "z": 3,
      "name": "Rock_Ice"
    },
    {
      "x": 3,
      "y": 1,
      "z": 3,
      "name": "Rock_Ice"
    },
    {
      "x": 3,
      "y": 2,
      "z": 3,
      "name": "Soil_Snow"
    },
    {
      "x": 3,
      "y": 11,
      "z": 3,
      "name": "Rock_Ice_Icicles",
      "rotation": 8
    },
    {
      "x": 3,
      "y": 12,
      "z": 3,
      "name": "Rock_Ice"
    },
    {
      "x": 3,
      "y": 13,
      "z": 3,
      "name": "Rock_Ice"
    },
    {
      "x": 3,
      "y": -1,
      "z": 4,
      "name": "Rock_Ice"
    },
    {
      "x": 3,
      "y": 0,
      "z": 4,
      "name": "Rock_Ice"
    },
    {
      "x": 3,
      "y": 1,
      "z": 4,
      "name": "Rock_Ice"
    },
    {
      "x": 3,
      "y": 2,
      "z": 4,
      "name": "Soil_Snow"
    },
    {
      "x": 3,
      "y": 3,
      "z": 4,
      "name": "Rock_Ice_Icicles"
    },
    {
      "x": 3,
      "y": 10,
      "z": 4,
      "name": "Rock_Ice_Stalactite_Large",
      "filler": 31744,
      "rotation": 8
    },
    {
      "x": 3,
      "y": 11,
      "z": 4,
      "name": "Rock_Ice_Stalactite_Large",
      "rotation": 8
    },
    {
      "x": 3,
      "y": 12,
      "z": 4,
      "name": "Rock_Ice"
    },
    {
      "x": 3,
      "y": 13,
      "z": 4,
      "name": "Rock_Ice"
    },
    {
      "x": 3,
      "y": -1,
      "z": 5,
      "name": "Rock_Ice"
    },
    {
      "x": 3,
      "y": 0,
      "z": 5,
      "name": "Rock_Ice"
    },
    {
      "x": 3,
      "y": 1,
      "z": 5,
      "name": "Rock_Ice"
    },
    {
      "x": 3,
      "y": 2,
      "z": 5,
      "name": "Rock_Ice"
    },
    {
      "x": 3,
      "y": 3,
      "z": 5,
      "name": "Rock_Ice"
    },
    {
      "x": 3,
      "y": 4,
      "z": 5,
      "name": "Rock_Ice"
    },
    {
      "x": 3,
      "y": 5,
      "z": 5,
      "name": "Rock_Ice"
    },
    {
      "x": 3,
      "y": 6,
      "z": 5,
      "name": "Rock_Ice"
    },
    {
      "x": 3,
      "y": 7,
      "z": 5,
      "name": "Rock_Ice"
    },
    {
      "x": 3,
      "y": 8,
      "z": 5,
      "name": "Rock_Ice"
    },
    {
      "x": 3,
      "y": 9,
      "z": 5,
      "name": "Rock_Ice"
    },
    {
      "x": 3,
      "y": 10,
      "z": 5,
      "name": "Rock_Ice"
    },
    {
      "x": 3,
      "y": 11,
      "z": 5,
      "name": "Rock_Ice"
    },
    {
      "x": 3,
      "y": 12,
      "z": 5,
      "name": "Rock_Ice"
    },
    {
      "x": 3,
      "y": 13,
      "z": 5,
      "name": "Rock_Ice"
    },
    {
      "x": 4,
      "y": -1,
      "z": -3,
      "name": "Rock_Ice"
    },
    {
      "x": 4,
      "y": 0,
      "z": -3,
      "name": "Rock_Basalt",
      "rotation": 3
    },
    {
      "x": 4,
      "y": 13,
      "z": -3,
      "name": "Rock_Basalt_Brick"
    },
    {
      "x": 4,
      "y": -1,
      "z": -2,
      "name": "Rock_Ice"
    },
    {
      "x": 4,
      "y": 0,
      "z": -2,
      "name": "Soil_Snow_Half"
    },
    {
      "x": 4,
      "y": 12,
      "z": -2,
      "name": "Rock_Basalt_Brick_Half",
      "rotation": 11
    },
    {
      "x": 4,
      "y": 13,
      "z": -2,
      "name": "Rock_Basalt_Brick"
    },
    {
      "x": 4,
      "y": -1,
      "z": -1,
      "name": "Rock_Ice"
    },
    {
      "x": 4,
      "y": 13,
      "z": -1,
      "name": "Rock_Basalt_Brick"
    },
    {
      "x": 4,
      "y": -1,
      "z": 0,
      "name": "Rock_Ice"
    },
    {
      "x": 4,
      "y": 0,
      "z": 0,
      "name": "Rock_Ice"
    },
    {
      "x": 4,
      "y": 1,
      "z": 0,
      "name": "Rock_Ice_Icicles"
    },
    {
      "x": 4,
      "y": 11,
      "z": 0,
      "name": "Deco_Iron_Chain_Small"
    },
    {
      "x": 4,
      "y": 12,
      "z": 0,
      "name": "Deco_Iron_Chain_Small"
    },
    {
      "x": 4,
      "y": 13,
      "z": 0,
      "name": "Rock_Basalt_Brick"
    },
    {
      "x": 4,
      "y": -1,
      "z": 1,
      "name": "Rock_Ice"
    },
    {
      "x": 4,
      "y": 0,
      "z": 1,
      "name": "Rock_Ice"
    },
    {
      "x": 4,
      "y": 1,
      "z": 1,
      "name": "Rock_Ice"
    },
    {
      "x": 4,
      "y": 13,
      "z": 1,
      "name": "Rock_Ice"
    },
    {
      "x": 4,
      "y": -1,
      "z": 2,
      "name": "Rock_Ice"
    },
    {
      "x": 4,
      "y": 0,
      "z": 2,
      "name": "Rock_Ice"
    },
    {
      "x": 4,
      "y": 1,
      "z": 2,
      "name": "Rock_Ice_Stalactite_Large"
    },
    {
      "x": 4,
      "y": 2,
      "z": 2,
      "name": "Rock_Ice_Stalactite_Large",
      "filler": 1024
    },
    {
      "x": 4,
      "y": 12,
      "z": 2,
      "name": "Rock_Ice_Icicles",
      "rotation": 8
    },
    {
      "x": 4,
      "y": 13,
      "z": 2,
      "name": "Rock_Ice"
    },
    {
      "x": 4,
      "y": -1,
      "z": 3,
      "name": "Rock_Ice"
    },
    {
      "x": 4,
      "y": 0,
      "z": 3,
      "name": "Rock_Ice"
    },
    {
      "x": 4,
      "y": 1,
      "z": 3,
      "name": "Rock_Ice"
    },
    {
      "x": 4,
      "y": 7,
      "z": 3,
      "name": "Deco_Iron_Chain_Small"
    },
    {
      "x": 4,
      "y": 8,
      "z": 3,
      "name": "Deco_Iron_Chain_Small"
    },
    {
      "x": 4,
      "y": 9,
      "z": 3,
      "name": "Deco_Iron_Chain_Small"
    },
    {
      "x": 4,
      "y": 10,
      "z": 3,
      "name": "Deco_Iron_Chain_Small"
    },
    {
      "x": 4,
      "y": 11,
      "z": 3,
      "name": "Deco_Iron_Chain_Small"
    },
    {
      "x": 4,
      "y": 12,
      "z": 3,
      "name": "Deco_Iron_Chain_Small"
    },
    {
      "x": 4,
      "y": 13,
      "z": 3,
      "name": "Rock_Ice"
    },
    {
      "x": 4,
      "y": -1,
      "z": 4,
      "name": "Rock_Ice"
    },
    {
      "x": 4,
      "y": 0,
      "z": 4,
      "name": "Rock_Ice"
    },
    {
      "x": 4,
      "y": 1,
      "z": 4,
      "name": "Soil_Snow"
    },
    {
      "x": 4,
      "y": 2,
      "z": 4,
      "name": "Rubble_Basalt",
      "support": 15
    },
    {
      "x": 4,
      "y": 11,
      "z": 4,
      "name": "Rock_Ice_Icicles",
      "rotation": 8
    },
    {
      "x": 4,
      "y": 12,
      "z": 4,
      "name": "Rock_Ice"
    },
    {
      "x": 4,
      "y": 13,
      "z": 4,
      "name": "Rock_Ice"
    },
    {
      "x": 4,
      "y": -1,
      "z": 5,
      "name": "Rock_Ice"
    },
    {
      "x": 4,
      "y": 0,
      "z": 5,
      "name": "Rock_Ice"
    },
    {
      "x": 4,
      "y": 1,
      "z": 5,
      "name": "Rock_Ice"
    },
    {
      "x": 4,
      "y": 2,
      "z": 5,
      "name": "Rock_Ice"
    },
    {
      "x": 4,
      "y": 3,
      "z": 5,
      "name": "Rock_Ice"
    },
    {
      "x": 4,
      "y": 4,
      "z": 5,
      "name": "Rock_Ice"
    },
    {
      "x": 4,
      "y": 5,
      "z": 5,
      "name": "Rock_Ice"
    },
    {
      "x": 4,
      "y": 6,
      "z": 5,
      "name": "Rock_Basalt_Brick"
    },
    {
      "x": 4,
      "y": 7,
      "z": 5,
      "name": "Rock_Basalt_Brick"
    },
    {
      "x": 4,
      "y": 8,
      "z": 5,
      "name": "Rock_Basalt_Brick"
    },
    {
      "x": 4,
      "y": 9,
      "z": 5,
      "name": "Rock_Ice"
    },
    {
      "x": 4,
      "y": 10,
      "z": 5,
      "name": "Rock_Ice"
    },
    {
      "x": 4,
      "y": 11,
      "z": 5,
      "name": "Rock_Ice"
    },
    {
      "x": 4,
      "y": 12,
      "z": 5,
      "name": "Rock_Ice"
    },
    {
      "x": 4,
      "y": 13,
      "z": 5,
      "name": "Rock_Ice"
    },
    {
      "x": 5,
      "y": -1,
      "z": -3,
      "name": "Rock_Ice"
    },
    {
      "x": 5,
      "y": 0,
      "z": -3,
      "name": "Rock_Basalt",
      "rotation": 3
    },
    {
      "x": 5,
      "y": 13,
      "z": -3,
      "name": "Rock_Basalt_Brick"
    },
    {
      "x": 5,
      "y": -1,
      "z": -2,
      "name": "Rock_Ice"
    },
    {
      "x": 5,
      "y": 0,
      "z": -2,
      "name": "Soil_Snow_Half"
    },
    {
      "x": 5,
      "y": 12,
      "z": -2,
      "name": "Rock_Basalt_Brick_Stairs",
      "rotation": 9
    },
    {
      "x": 5,
      "y": 13,
      "z": -2,
      "name": "Rock_Basalt_Brick"
    },
    {
      "x": 5,
      "y": -1,
      "z": -1,
      "name": "Rock_Ice"
    },
    {
      "x": 5,
      "y": 13,
      "z": -1,
      "name": "Rock_Basalt_Brick"
    },
    {
      "x": 5,
      "y": -1,
      "z": 0,
      "name": "Rock_Ice"
    },
    {
      "x": 5,
      "y": 13,
      "z": 0,
      "name": "Rock_Basalt_Brick"
    },
    {
      "x": 5,
      "y": -1,
      "z": 1,
      "name": "Rock_Ice"
    },
    {
      "x": 5,
      "y": 0,
      "z": 1,
      "name": "Rock_Ice"
    },
    {
      "x": 5,
      "y": 1,
      "z": 1,
      "name": "Rock_Ice_Icicles"
    },
    {
      "x": 5,
      "y": 6,
      "z": 1,
      "name": "Deco_Iron_Bars_Platforms"
    },
    {
      "x": 5,
      "y": 13,
      "z": 1,
      "name": "Rock_Basalt_Brick"
    },
    {
      "x": 5,
      "y": -1,
      "z": 2,
      "name": "Rock_Ice"
    },
    {
      "x": 5,
      "y": 0,
      "z": 2,
      "name": "Rock_Ice"
    },
    {
      "x": 5,
      "y": 13,
      "z": 2,
      "name": "Rock_Basalt_Brick"
    },
    {
      "x": 5,
      "y": -1,
      "z": 3,
      "name": "Rock_Ice"
    },
    {
      "x": 5,
      "y": 0,
      "z": 3,
      "name": "Rock_Ice"
    },
    {
      "x": 5,
      "y": 1,
      "z": 3,
      "name": "Rubble_Basalt_Medium",
      "support": 15
    },
    {
      "x": 5,
      "y": 13,
      "z": 3,
      "name": "Rock_Ice"
    },
    {
      "x": 5,
      "y": -1,
      "z": 4,
      "name": "Rock_Ice"
    },
    {
      "x": 5,
      "y": 0,
      "z": 4,
      "name": "Soil_Snow"
    },
    {
      "x": 5,
      "y": 1,
      "z": 4,
      "name": "Rock_Ice_Icicles"
    },
    {
      "x": 5,
      "y": 12,
      "z": 4,
      "name": "Rock_Ice_Icicles",
      "rotation": 8
    },
    {
      "x": 5,
      "y": 13,
      "z": 4,
      "name": "Rock_Ice"
    },
    {
      "x": 5,
      "y": -1,
      "z": 5,
      "name": "Rock_Ice"
    },
    {
      "x": 5,
      "y": 0,
      "z": 5,
      "name": "Rock_Ice"
    },
    {
      "x": 5,
      "y": 1,
      "z": 5,
      "name": "Rock_Ice"
    },
    {
      "x": 5,
      "y": 2,
      "z": 5,
      "name": "Rock_Ice"
    },
    {
      "x": 5,
      "y": 3,
      "z": 5,
      "name": "Rock_Ice"
    },
    {
      "x": 5,
      "y": 4,
      "z": 5,
      "name": "Rock_Basalt_Brick"
    },
    {
      "x": 5,
      "y": 5,
      "z": 5,
      "name": "Rock_Basalt_Brick"
    },
    {
      "x": 5,
      "y": 6,
      "z": 5,
      "name": "Rock_Basalt_Brick"
    },
    {
      "x": 5,
      "y": 7,
      "z": 5,
      "name": "Rock_Basalt_Brick"
    },
    {
      "x": 5,
      "y": 8,
      "z": 5,
      "name": "Rock_Basalt_Brick"
    },
    {
      "x": 5,
      "y": 9,
      "z": 5,
      "name": "Rock_Basalt_Brick"
    },
    {
      "x": 5,
      "y": 10,
      "z": 5,
      "name": "Rock_Basalt_Brick"
    },
    {
      "x": 5,
      "y": 11,
      "z": 5,
      "name": "Rock_Ice"
    },
    {
      "x": 5,
      "y": 12,
      "z": 5,
      "name": "Rock_Ice"
    },
    {
      "x": 5,
      "y": 13,
      "z": 5,
      "name": "Rock_Ice"
    },
    {
      "x": 6,
      "y": -1,
      "z": -3,
      "name": "Rock_Ice"
    },
    {
      "x": 6,
      "y": 0,
      "z": -3,
      "name": "Rock_Basalt_Brick",
      "rotation": 3
    },
    {
      "x": 6,
      "y": 13,
      "z": -3,
      "name": "Rock_Basalt_Brick"
    },
    {
      "x": 6,
      "y": -1,
      "z": -2,
      "name": "Rock_Ice"
    },
    {
      "x": 6,
      "y": 0,
      "z": -2,
      "name": "Rock_Basalt_Brick",
      "rotation": 3
    },
    {
      "x": 6,
      "y": 1,
      "z": -2,
      "name": "Rock_Basalt_Brick_Pillar_Base",
      "rotation": 3
    },
    {
      "x": 6,
      "y": 2,
      "z": -2,
      "name": "Rock_Basalt_Brick_Pillar_Middle",
      "rotation": 3
    },
    {
      "x": 6,
      "y": 3,
      "z": -2,
      "name": "Rock_Basalt_Brick_Pillar_Middle",
      "rotation": 3
    },
    {
      "x": 6,
      "y": 4,
      "z": -2,
      "name": "Rock_Basalt_Brick_Pillar_Middle",
      "rotation": 3
    },
    {
      "x": 6,
      "y": 5,
      "z": -2,
      "name": "Rock_Basalt_Brick_Pillar_Middle",
      "rotation": 3
    },
    {
      "x": 6,
      "y": 6,
      "z": -2,
      "name": "Rock_Basalt_Brick_Pillar_Middle",
      "rotation": 3
    },
    {
      "x": 6,
      "y": 7,
      "z": -2,
      "name": "Rock_Basalt_Brick_Pillar_Middle",
      "rotation": 3
    },
    {
      "x": 6,
      "y": 8,
      "z": -2,
      "name": "Rock_Basalt_Brick_Pillar_Middle",
      "rotation": 3
    },
    {
      "x": 6,
      "y": 9,
      "z": -2,
      "name": "Rock_Basalt_Brick_Pillar_Middle",
      "rotation": 3
    },
    {
      "x": 6,
      "y": 10,
      "z": -2,
      "name": "Rock_Basalt_Brick_Pillar_Middle",
      "rotation": 3
    },
    {
      "x": 6,
      "y": 11,
      "z": -2,
      "name": "Rock_Basalt_Brick_Pillar_Base",
      "rotation": 11
    },
    {
      "x": 6,
      "y": 12,
      "z": -2,
      "name": "Rock_Basalt_Brick",
      "rotation": 3
    },
    {
      "x": 6,
      "y": 13,
      "z": -2,
      "name": "Rock_Basalt_Brick"
    },
    {
      "x": 6,
      "y": -1,
      "z": -1,
      "name": "Rock_Ice"
    },
    {
      "x": 6,
      "y": 0,
      "z": -1,
      "name": "Soil_Snow_Half"
    },
    {
      "x": 6,
      "y": 13,
      "z": -1,
      "name": "Rock_Basalt_Brick"
    },
    {
      "x": 6,
      "y": -1,
      "z": 0,
      "name": "Rock_Ice"
    },
    {
      "x": 6,
      "y": 6,
      "z": 0,
      "name": "Deco_Iron_Bars_Platforms"
    },
    {
      "x": 6,
      "y": 7,
      "z": 0,
      "name": "Deco_Bronze_Railing"
    },
    {
      "x": 6,
      "y": 13,
      "z": 0,
      "name": "Rock_Basalt_Brick"
    },
    {
      "x": 6,
      "y": -1,
      "z": 1,
      "name": "Rock_Ice"
    },
    {
      "x": 6,
      "y": 0,
      "z": 1,
      "name": "Soil_Snow_Half"
    },
    {
      "x": 6,
      "y": 6,
      "z": 1,
      "name": "Deco_Iron_Bars_Platforms"
    },
    {
      "x": 6,
      "y": 13,
      "z": 1,
      "name": "Rock_Basalt_Brick"
    },
    {
      "x": 6,
      "y": -1,
      "z": 2,
      "name": "Rock_Ice"
    },
    {
      "x": 6,
      "y": 0,
      "z": 2,
      "name": "Rock_Ice"
    },
    {
      "x": 6,
      "y": 1,
      "z": 2,
      "name": "Rock_Ice_Icicles"
    },
    {
      "x": 6,
      "y": 6,
      "z": 2,
      "name": "Deco_Iron_Bars_Platforms"
    },
    {
      "x": 6,
      "y": 13,
      "z": 2,
      "name": "Rock_Basalt_Brick"
    },
    {
      "x": 6,
      "y": -1,
      "z": 3,
      "name": "Rock_Ice"
    },
    {
      "x": 6,
      "y": 0,
      "z": 3,
      "name": "Rock_Ice"
    },
    {
      "x": 6,
      "y": 6,
      "z": 3,
      "name": "Deco_Iron_Bars_Platforms"
    },
    {
      "x": 6,
      "y": 7,
      "z": 3,
      "name": "Deco_Bronze_Railing"
    },
    {
      "x": 6,
      "y": 13,
      "z": 3,
      "name": "Rock_Basalt_Brick"
    },
    {
      "x": 6,
      "y": -1,
      "z": 4,
      "name": "Rock_Ice"
    },
    {
      "x": 6,
      "y": 0,
      "z": 4,
      "name": "Rock_Basalt_Brick",
      "rotation": 3
    },
    {
      "x": 6,
      "y": 1,
      "z": 4,
      "name": "Rubble_Basalt",
      "support": 15
    },
    {
      "x": 6,
      "y": 13,
      "z": 4,
      "name": "Rock_Basalt_Brick"
    },
    {
      "x": 6,
      "y": -1,
      "z": 5,
      "name": "Rock_Ice"
    },
    {
      "x": 6,
      "y": 0,
      "z": 5,
      "name": "Rock_Ice"
    },
    {
      "x": 6,
      "y": 1,
      "z": 5,
      "name": "Rock_Ice"
    },
    {
      "x": 6,
      "y": 2,
      "z": 5,
      "name": "Rock_Ice"
    },
    {
      "x": 6,
      "y": 3,
      "z": 5,
      "name": "Rock_Basalt_Brick"
    },
    {
      "x": 6,
      "y": 4,
      "z": 5,
      "name": "Rock_Basalt_Brick"
    },
    {
      "x": 6,
      "y": 5,
      "z": 5,
      "name": "Rock_Basalt_Brick"
    },
    {
      "x": 6,
      "y": 6,
      "z": 5,
      "name": "Rock_Basalt_Brick"
    },
    {
      "x": 6,
      "y": 7,
      "z": 5,
      "name": "Rock_Basalt_Brick"
    },
    {
      "x": 6,
      "y": 8,
      "z": 5,
      "name": "Rock_Basalt_Brick"
    },
    {
      "x": 6,
      "y": 9,
      "z": 5,
      "name": "Rock_Basalt_Brick"
    },
    {
      "x": 6,
      "y": 10,
      "z": 5,
      "name": "Rock_Basalt_Brick"
    },
    {
      "x": 6,
      "y": 11,
      "z": 5,
      "name": "Rock_Basalt_Brick"
    },
    {
      "x": 6,
      "y": 12,
      "z": 5,
      "name": "Rock_Basalt_Brick"
    },
    {
      "x": 6,
      "y": 13,
      "z": 5,
      "name": "Rock_Basalt_Brick"
    },
    {
      "x": 7,
      "y": -1,
      "z": -3,
      "name": "Rock_Ice"
    },
    {
      "x": 7,
      "y": 0,
      "z": -3,
      "name": "Rock_Basalt",
      "rotation": 3
    },
    {
      "x": 7,
      "y": 13,
      "z": -3,
      "name": "Rock_Basalt_Brick"
    },
    {
      "x": 7,
      "y": -1,
      "z": -2,
      "name": "Rock_Ice"
    },
    {
      "x": 7,
      "y": 0,
      "z": -2,
      "name": "Rock_Basalt",
      "rotation": 3
    },
    {
      "x": 7,
      "y": 12,
      "z": -2,
      "name": "Rock_Basalt_Brick_Stairs",
      "rotation": 11
    },
    {
      "x": 7,
      "y": 13,
      "z": -2,
      "name": "Rock_Basalt_Brick"
    },
    {
      "x": 7,
      "y": -1,
      "z": -1,
      "name": "Rock_Ice"
    },
    {
      "x": 7,
      "y": 0,
      "z": -1,
      "name": "Rock_Basalt",
      "rotation": 3
    },
    {
      "x": 7,
      "y": 1,
      "z": -1,
      "name": "Rubble_Basalt_Medium",
      "support": 15
    },
    {
      "x": 7,
      "y": 13,
      "z": -1,
      "name": "Rock_Basalt_Brick"
    },
    {
      "x": 7,
      "y": -1,
      "z": 0,
      "name": "Rock_Ice"
    },
    {
      "x": 7,
      "y": 0,
      "z": 0,
      "name": "Soil_Snow_Half"
    },
    {
      "x": 7,
      "y": 6,
      "z": 0,
      "name": "Deco_Iron_Bars_Platforms"
    },
    {
      "x": 7,
      "y": 7,
      "z": 0,
      "name": "Deco_Bronze_Railing"
    },
    {
      "x": 7,
      "y": 13,
      "z": 0,
      "name": "Rock_Basalt_Brick"
    },
    {
      "x": 7,
      "y": -1,
      "z": 1,
      "name": "Rock_Ice"
    },
    {
      "x": 7,
      "y": 0,
      "z": 1,
      "name": "Soil_Snow_Half"
    },
    {
      "x": 7,
      "y": 6,
      "z": 1,
      "name": "Deco_Iron_Bars_Platforms"
    },
    {
      "x": 7,
      "y": 13,
      "z": 1,
      "name": "Rock_Basalt_Brick"
    },
    {
      "x": 7,
      "y": -1,
      "z": 2,
      "name": "Rock_Ice"
    },
    {
      "x": 7,
      "y": 0,
      "z": 2,
      "name": "Soil_Snow"
    },
    {
      "x": 7,
      "y": 6,
      "z": 2,
      "name": "Deco_Iron_Bars_Platforms"
    },
    {
      "x": 7,
      "y": 13,
      "z": 2,
      "name": "Rock_Basalt_Brick"
    },
    {
      "x": 7,
      "y": -1,
      "z": 3,
      "name": "Rock_Ice"
    },
    {
      "x": 7,
      "y": 0,
      "z": 3,
      "name": "Rock_Basalt",
      "rotation": 3
    },
    {
      "x": 7,
      "y": 1,
      "z": 3,
      "name": "Rubble_Basalt",
      "support": 15
    },
    {
      "x": 7,
      "y": 6,
      "z": 3,
      "name": "Deco_Iron_Bars_Platforms"
    },
    {
      "x": 7,
      "y": 7,
      "z": 3,
      "name": "Deco_Bronze_Railing"
    },
    {
      "x": 7,
      "y": 13,
      "z": 3,
      "name": "Rock_Basalt_Brick"
    },
    {
      "x": 7,
      "y": -1,
      "z": 4,
      "name": "Rock_Ice"
    },
    {
      "x": 7,
      "y": 0,
      "z": 4,
      "name": "Rock_Basalt",
      "rotation": 3
    },
    {
      "x": 7,
      "y": 13,
      "z": 4,
      "name": "Rock_Basalt_Brick"
    },
    {
      "x": 7,
      "y": -1,
      "z": 5,
      "name": "Rock_Ice"
    },
    {
      "x": 7,
      "y": 0,
      "z": 5,
      "name": "Rock_Ice"
    },
    {
      "x": 7,
      "y": 1,
      "z": 5,
      "name": "Rock_Basalt_Brick"
    },
    {
      "x": 7,
      "y": 2,
      "z": 5,
      "name": "Rock_Basalt_Brick"
    },
    {
      "x": 7,
      "y": 3,
      "z": 5,
      "name": "Rock_Basalt_Brick"
    },
    {
      "x": 7,
      "y": 4,
      "z": 5,
      "name": "Rock_Basalt_Brick"
    },
    {
      "x": 7,
      "y": 5,
      "z": 5,
      "name": "Rock_Basalt_Brick"
    },
    {
      "x": 7,
      "y": 6,
      "z": 5,
      "name": "Rock_Basalt_Brick"
    },
    {
      "x": 7,
      "y": 7,
      "z": 5,
      "name": "Rock_Basalt_Brick"
    },
    {
      "x": 7,
      "y": 8,
      "z": 5,
      "name": "Rock_Basalt_Brick"
    },
    {
      "x": 7,
      "y": 9,
      "z": 5,
      "name": "Rock_Basalt_Brick"
    },
    {
      "x": 7,
      "y": 10,
      "z": 5,
      "name": "Rock_Basalt_Brick"
    },
    {
      "x": 7,
      "y": 11,
      "z": 5,
      "name": "Rock_Basalt_Brick"
    },
    {
      "x": 7,
      "y": 12,
      "z": 5,
      "name": "Rock_Basalt_Brick"
    },
    {
      "x": 7,
      "y": 13,
      "z": 5,
      "name": "Rock_Basalt_Brick"
    },
    {
      "x": 8,
      "y": -1,
      "z": -3,
      "name": "Rock_Ice"
    },
    {
      "x": 8,
      "y": 0,
      "z": -3,
      "name": "Rock_Basalt",
      "rotation": 3
    },
    {
      "x": 8,
      "y": 1,
      "z": -3,
      "name": "Empty"
    },
    {
      "x": 8,
      "y": 13,
      "z": -3,
      "name": "Rock_Basalt_Brick"
    },
    {
      "x": 8,
      "y": -1,
      "z": -2,
      "name": "Rock_Ice"
    },
    {
      "x": 8,
      "y": 0,
      "z": -2,
      "name": "Rock_Basalt",
      "rotation": 3
    },
    {
      "x": 8,
      "y": 12,
      "z": -2,
      "name": "Rock_Basalt_Brick_Half",
      "rotation": 11
    },
    {
      "x": 8,
      "y": 13,
      "z": -2,
      "name": "Rock_Basalt_Brick"
    },
    {
      "x": 8,
      "y": -1,
      "z": -1,
      "name": "Rock_Ice"
    },
    {
      "x": 8,
      "y": 0,
      "z": -1,
      "name": "Rock_Basalt",
      "rotation": 3
    },
    {
      "x": 8,
      "y": 13,
      "z": -1,
      "name": "Rock_Basalt_Brick"
    },
    {
      "x": 8,
      "y": -1,
      "z": 0,
      "name": "Rock_Ice"
    },
    {
      "x": 8,
      "y": 0,
      "z": 0,
      "name": "Rock_Basalt",
      "rotation": 3
    },
    {
      "x": 8,
      "y": 6,
      "z": 0,
      "name": "Deco_Iron_Bars_Platforms"
    },
    {
      "x": 8,
      "y": 7,
      "z": 0,
      "name": "Deco_Bronze_Railing"
    },
    {
      "x": 8,
      "y": 13,
      "z": 0,
      "name": "Rock_Basalt_Brick"
    },
    {
      "x": 8,
      "y": -1,
      "z": 1,
      "name": "Rock_Ice"
    },
    {
      "x": 8,
      "y": 0,
      "z": 1,
      "name": "Rock_Basalt",
      "rotation": 3
    },
    {
      "x": 8,
      "y": 6,
      "z": 1,
      "name": "Deco_Iron_Bars_Platforms"
    },
    {
      "x": 8,
      "y": 13,
      "z": 1,
      "name": "Rock_Basalt_Brick"
    },
    {
      "x": 8,
      "y": -1,
      "z": 2,
      "name": "Rock_Ice"
    },
    {
      "x": 8,
      "y": 0,
      "z": 2,
      "name": "Rock_Basalt",
      "rotation": 3
    },
    {
      "x": 8,
      "y": 6,
      "z": 2,
      "name": "Deco_Iron_Bars_Platforms"
    },
    {
      "x": 8,
      "y": 13,
      "z": 2,
      "name": "Rock_Basalt_Brick"
    },
    {
      "x": 8,
      "y": -1,
      "z": 3,
      "name": "Rock_Ice"
    },
    {
      "x": 8,
      "y": 0,
      "z": 3,
      "name": "Rock_Basalt",
      "rotation": 3
    },
    {
      "x": 8,
      "y": 6,
      "z": 3,
      "name": "Deco_Iron_Bars_Platforms"
    },
    {
      "x": 8,
      "y": 7,
      "z": 3,
      "name": "Deco_Bronze_Railing"
    },
    {
      "x": 8,
      "y": 13,
      "z": 3,
      "name": "Rock_Basalt_Brick"
    },
    {
      "x": 8,
      "y": -1,
      "z": 4,
      "name": "Rock_Ice"
    },
    {
      "x": 8,
      "y": 0,
      "z": 4,
      "name": "Rock_Basalt",
      "rotation": 3
    },
    {
      "x": 8,
      "y": 13,
      "z": 4,
      "name": "Rock_Basalt_Brick"
    },
    {
      "x": 8,
      "y": -1,
      "z": 5,
      "name": "Rock_Ice"
    },
    {
      "x": 8,
      "y": 0,
      "z": 5,
      "name": "Rock_Ice"
    },
    {
      "x": 8,
      "y": 1,
      "z": 5,
      "name": "Rock_Basalt_Brick"
    },
    {
      "x": 8,
      "y": 2,
      "z": 5,
      "name": "Rock_Basalt_Brick"
    },
    {
      "x": 8,
      "y": 3,
      "z": 5,
      "name": "Rock_Basalt_Brick"
    },
    {
      "x": 8,
      "y": 4,
      "z": 5,
      "name": "Rock_Basalt_Brick"
    },
    {
      "x": 8,
      "y": 5,
      "z": 5,
      "name": "Rock_Basalt_Brick"
    },
    {
      "x": 8,
      "y": 6,
      "z": 5,
      "name": "Rock_Basalt_Brick"
    },
    {
      "x": 8,
      "y": 7,
      "z": 5,
      "name": "Rock_Basalt_Brick"
    },
    {
      "x": 8,
      "y": 8,
      "z": 5,
      "name": "Rock_Basalt_Brick"
    },
    {
      "x": 8,
      "y": 9,
      "z": 5,
      "name": "Rock_Basalt_Brick"
    },
    {
      "x": 8,
      "y": 10,
      "z": 5,
      "name": "Rock_Basalt_Brick"
    },
    {
      "x": 8,
      "y": 11,
      "z": 5,
      "name": "Rock_Basalt_Brick"
    },
    {
      "x": 8,
      "y": 12,
      "z": 5,
      "name": "Rock_Basalt_Brick"
    },
    {
      "x": 8,
      "y": 13,
      "z": 5,
      "name": "Rock_Basalt_Brick"
    }
  ]
}