{
  "version": 8,
  "blockIdVersion": 11,
  "anchorX": 8,
  "anchorY": 1,
  "anchorZ": -3,
  "blocks": [
    {
      "x": -7,
      "y": -1,
      "z": -3,
      "name": "Rock_Ice"
    },
    {
      "x": -7,
      "y": 0,
      "z": -3,
      "name": "Rock_Basalt",
      "rotation": 3
    },
    {
      "x": -7,
      "y": 13,
      "z": -3,
      "name": "Rock_Basalt_Brick"
    },
    {
      "x": -7,
      "y": -1,
      "z": -2,
      "name": "Rock_Ice"
    },
    {
      "x": -7,
      "y": 0,
      "z": -2,
      "name": "Rock_Basalt",
      "rotation": 3
    },
    {
      "x": -7,
      "y": 12,
      "z": -2,
      "name": "Rock_Basalt_Brick_Stairs",
      "rotation": 9
    },
    {
      "x": -7,
      "y": 13,
      "z": -2,
      "name": "Rock_Basalt_Brick"
    },
    {
      "x": -7,
      "y": -1,
      "z": -1,
      "name": "Rock_Ice"
    },
    {
      "x": -7,
      "y": 0,
      "z": -1,
      "name": "Rock_Basalt",
      "rotation": 3
    },
    {
      "x": -7,
      "y": 1,
      "z": -1,
      "name": "Rubble_Basalt",
      "support": 15
    },
    {
      "x": -7,
      "y": 13,
      "z": -1,
      "name": "Rock_Basalt_Brick"
    },
    {
      "x": -7,
      "y": -1,
      "z": 0,
      "name": "Rock_Ice"
    },
    {
      "x": -7,
      "y": 0,
      "z": 0,
      "name": "Rock_Basalt",
      "rotation": 3
    },
    {
      "x": -7,
      "y": 1,
      "z": 0,
      "name": "Rubble_Basalt_Medium",
      "support": 15
    },
    {
      "x": -7,
      "y": 6,
      "z": 0,
      "name": "Deco_Iron_Bars_Platforms"
    },
    {
      "x": -7,
      "y": 7,
      "z": 0,
      "name": "Deco_Bronze_Railing"
    },
    {
      "x": -7,
      "y": 13,
      "z": 0,
      "name": "Rock_Basalt_Brick"
    },
    {
      "x": -7,
      "y": -1,
      "z": 1,
      "name": "Rock_Ice"
    },
    {
      "x": -7,
      "y": 0,
      "z": 1,
      "name": "Rock_Basalt",
      "rotation": 3
    },
    {
      "x": -7,
      "y": 1,
      "z": 1,
      "name": "*Furniture_Human_Ruins_Torch_State_Definitions_Off",
      "rotation": 2
    },
    {
      "x": -7,
      "y": 6,
      "z": 1,
      "name": "Deco_Iron_Bars_Platforms"
    },
    {
      "x": -7,
      "y": 13,
      "z": 1,
      "name": "Rock_Basalt_Brick"
    },
    {
      "x": -7,
      "y": -1,
      "z": 2,
      "name": "Rock_Ice"
    },
    {
      "x": -7,
      "y": 0,
      "z": 2,
      "name": "Rock_Basalt",
      "rotation": 3
    },
    {
      "x": -7,
      "y": 1,
      "z": 2,
      "name": "Furniture_Ancient_Barrel"
    },
    {
      "x": -7,
      "y": 6,
      "z": 2,
      "name": "Deco_Iron_Bars_Platforms"
    },
    {
      "x": -7,
      "y": 13,
      "z": 2,
      "name": "Rock_Basalt_Brick"
    },
    {
      "x": -7,
      "y": -1,
      "z": 3,
      "name": "Rock_Ice"
    },
    {
      "x": -7,
      "y": 0,
      "z": 3,
      "name": "Rock_Basalt",
      "rotation": 3
    },
    {
      "x": -7,
      "y": 1,
      "z": 3,
      "name": "Furniture_Ancient_Crate",
      "rotation": 3
    },
    {
      "x": -7,
      "y": 2,
      "z": 3,
      "name": "Rock_Bronze_Smooth"
    },
    {
      "x": -7,
      "y": 3,
      "z": 3,
      "name": "Bronze_Pipe_Large"
    },
    {
      "x": -7,
      "y": 4,
      "z": 3,
      "name": "Bronze_Pipe_Large"
    },
    {
      "x": -7,
      "y": 5,
      "z": 3,
      "name": "Rock_Bronze_Smooth"
    },
    {
      "x": -7,
      "y": 6,
      "z": 3,
      "name": "Deco_Iron_Bars_Platforms"
    },
    {
      "x": -7,
      "y": 7,
      "z": 3,
      "name": "Deco_Bronze_Railing"
    },
    {
      "x": -7,
      "y": 13,
      "z": 3,
      "name": "Rock_Basalt_Brick"
    },
    {
      "x": -7,
      "y": -1,
      "z": 4,
      "name": "Rock_Ice"
    },
    {
      "x": -7,
      "y": 0,
      "z": 4,
      "name": "Rock_Basalt",
      "rotation": 3
    },
    {
      "x": -7,
      "y": 1,
      "z": 4,
      "name": "Furniture_Ancient_Crate",
      "rotation": 3
    },
    {
      "x": -7,
      "y": 13,
      "z": 4,
      "name": "Rock_Basalt_Brick"
    },
    {
      "x": -7,
      "y": -1,
      "z": 5,
      "name": "Rock_Ice"
    },
    {
      "x": -7,
      "y": 0,
      "z": 5,
      "name": "Rock_Basalt_Brick"
    },
    {
      "x": -7,
      "y": 1,
      "z": 5,
      "name": "Rock_Basalt_Brick"
    },
    {
      "x": -7,
      "y": 2,
      "z": 5,
      "name": "Rock_Basalt_Brick"
    },
    {
      "x": -7,
      "y": 3,
      "z": 5,
      "name": "Rock_Basalt_Brick"
    },
    {
      "x": -7,
      "y": 4,
      "z": 5,
      "name": "Rock_Basalt_Brick"
    },
    {
      "x": -7,
      "y": 5,
      "z": 5,
      "name": "Rock_Basalt_Brick"
    },
    {
      "x": -7,
      "y": 6,
      "z": 5,
      "name": "Rock_Basalt_Brick"
    },
    {
      "x": -7,
      "y": 7,
      "z": 5,
      "name": "Rock_Basalt_Brick"
    },
    {
      "x": -7,
      "y": 8,
      "z": 5,
      "name": "Rock_Basalt_Brick"
    },
    {
      "x": -7,
      "y": 9,
      "z": 5,
      "name": "Rock_Basalt_Brick"
    },
    {
      "x": -7,
      "y": 10,
      "z": 5,
      "name": "Rock_Basalt_Brick"
    },
    {
      "x": -7,
      "y": 11,
      "z": 5,
      "name": "Rock_Basalt_Brick"
    },
    {
      "x": -7,
      "y": 12,
      "z": 5,
      "name": "Rock_Basalt_Brick"
    },
    {
      "x": -7,
      "y": 13,
      "z": 5,
      "name": "Rock_Basalt_Brick"
    },
    {
      "x": -6,
      "y": -1,
      "z": -3,
      "name": "Rock_Ice"
    },
    {
      "x": -6,
      "y": 0,
      "z": -3,
      "name": "Rock_Basalt_Brick",
      "rotation": 3
    },
    {
      "x": -6,
      "y": 13,
      "z": -3,
      "name": "Rock_Basalt_Brick"
    },
    {
      "x": -6,
      "y": -1,
      "z": -2,
      "name": "Rock_Ice"
    },
    {
      "x": -6,
      "y": 0,
      "z": -2,
      "name": "Rock_Basalt_Brick",
      "rotation": 3
    },
    {
      "x": -6,
      "y": 1,
      "z": -2,
      "name": "Rock_Basalt_Brick_Pillar_Base",
      "rotation": 3
    },
    {
      "x": -6,
      "y": 2,
      "z": -2,
      "name": "Rock_Basalt_Brick_Pillar_Middle",
      "rotation": 3
    },
    {
      "x": -6,
      "y": 3,
      "z": -2,
      "name": "Rock_Basalt_Brick_Pillar_Middle",
      "rotation": 3
    },
    {
      "x": -6,
      "y": 4,
      "z": -2,
      "name": "Rock_Basalt_Brick_Pillar_Middle",
      "rotation": 3
    },
    {
      "x": -6,
      "y": 5,
      "z": -2,
      "name": "Rock_Basalt_Brick_Pillar_Middle",
      "rotation": 3
    },
    {
      "x": -6,
      "y": 6,
      "z": -2,
      "name": "Rock_Basalt_Brick_Pillar_Middle",
      "rotation": 3
    },
    {
      "x": -6,
      "y": 7,
      "z": -2,
      "name": "Rock_Basalt_Brick_Pillar_Middle",
      "rotation": 3
    },
    {
      "x": -6,
      "y": 8,
      "z": -2,
      "name": "Rock_Basalt_Brick_Pillar_Middle",
      "rotation": 3
    },
    {
      "x": -6,
      "y": 9,
      "z": -2,
      "name": "Rock_Basalt_Brick_Pillar_Middle",
      "rotation": 3
    },
    {
      "x": -6,
      "y": 10,
      "z": -2,
      "name": "Rock_Basalt_Brick_Pillar_Middle",
      "rotation": 3
    },
    {
      "x": -6,
      "y": 11,
      "z": -2,
      "name": "Rock_Basalt_Brick_Pillar_Base",
      "rotation": 11
    },
    {
      "x": -6,
      "y": 12,
      "z": -2,
      "name": "Rock_Basalt_Brick",
      "rotation": 3
    },
    {
      "x": -6,
      "y": 13,
      "z": -2,
      "name": "Rock_Basalt_Brick"
    },
    {
      "x": -6,
      "y": -1,
      "z": -1,
      "name": "Rock_Ice"
    },
    {
      "x": -6,
      "y": 0,
      "z": -1,
      "name": "Rock_Basalt_Brick",
      "rotation": 3
    },
    {
      "x": -6,
      "y": 1,
      "z": -1,
      "name": "Furniture_Basalt_Trough",
      "filler": 31,
      "rotation": 1
    },
    {
      "x": -6,
      "y": 13,
      "z": -1,
      "name": "Rock_Basalt_Brick"
    },
    {
      "x": -6,
      "y": -1,
      "z": 0,
      "name": "Rock_Ice"
    },
    {
      "x": -6,
      "y": 0,
      "z": 0,
      "name": "Rock_Basalt_Brick",
      "rotation": 3
    },
    {
      "x": -6,
      "y": 1,
      "z": 0,
      "name": "Furniture_Basalt_Trough",
      "filler": 63,
      "rotation": 1
    },
    {
      "x": -6,
      "y": 6,
      "z": 0,
      "name": "Deco_Iron_Bars_Platforms"
    },
    {
      "x": -6,
      "y": 7,
      "z": 0,
      "name": "Deco_Bronze_Railing"
    },
    {
      "x": -6,
      "y": 13,
      "z": 0,
      "name": "Rock_Basalt_Brick"
    },
    {
      "x": -6,
      "y": -1,
      "z": 1,
      "name": "Rock_Ice"
    },
    {
      "x": -6,
      "y": 0,
      "z": 1,
      "name": "Rock_Basalt_Brick",
      "rotation": 3
    },
    {
      "x": -6,
      "y": 1,
      "z": 1,
      "name": "Deco_Mystery_Machine_Large",
      "filler": 31
    },
    {
      "x": -6,
      "y": 2,
      "z": 1,
      "name": "Deco_Mystery_Machine_Large",
      "filler": 1055
    },
    {
      "x": -6,
      "y": 3,
      "z": 1,
      "name": "Deco_Mystery_Machine_Large",
      "filler": 2079
    },
    {
      "x": -6,
      "y": 4,
      "z": 1,
      "name": "Deco_Mystery_Machine_Large",
      "filler": 3103
    },
    {
      "x": -6,
      "y": 6,
      "z": 1,
      "name": "Deco_Iron_Bars_Platforms"
    },
    {
      "x": -6,
      "y": 12,
      "z": 1,
      "name": "Rock_Ice_Icicles",
      "rotation": 8
    },
    {
      "x": -6,
      "y": 13,
      "z": 1,
      "name": "Rock_Basalt_Brick"
    },
    {
      "x": -6,
      "y": -1,
      "z": 2,
      "name": "Rock_Ice"
    },
    {
      "x": -6,
      "y": 0,
      "z": 2,
      "name": "Rock_Basalt_Brick",
      "rotation": 3
    },
    {
      "x": -6,
      "y": 1,
      "z": 2,
      "name": "Deco_Mystery_Machine_Large",
      "filler": 63
    },
    {
      "x": -6,
      "y": 2,
      "z": 2,
      "name": "Deco_Mystery_Machine_Large",
      "filler": 1087
    },
    {
      "x": -6,
      "y": 3,
      "z": 2,
      "name": "Deco_Mystery_Machine_Large",
      "filler": 2111
    },
    {
      "x": -6,
      "y": 4,
      "z": 2,
      "name": "Deco_Mystery_Machine_Large",
      "filler": 3135
    },
    {
      "x": -6,
      "y": 6,
      "z": 2,
      "name": "Deco_Iron_Bars_Platforms"
    },
    {
      "x": -6,
      "y": 12,
      "z": 2,
      "name": "Rock_Bronze_Smooth"
    },
    {
      "x": -6,
      "y": 13,
      "z": 2,
      "name": "Rock_Basalt_Brick"
    },
    {
      "x": -6,
      "y": -1,
      "z": 3,
      "name": "Rock_Ice"
    },
    {
      "x": -6,
      "y": 0,
      "z": 3,
      "name": "Rock_Basalt_Brick"
    },
    {
      "x": -6,
      "y": 1,
      "z": 3,
      "name": "Deco_Mystery_Machine_Large",
      "filler": 95
    },
    {
      "x": -6,
      "y": 2,
      "z": 3,
      "name": "Deco_Mystery_Machine_Large",
      "filler": 1119
    },
    {
      "x": -6,
      "y": 3,
      "z": 3,
      "name": "Deco_Mystery_Machine_Large",
      "filler": 2143
    },
    {
      "x": -6,
      "y": 4,
      "z": 3,
      "name": "Deco_Mystery_Machine_Large",
      "filler": 3167
    },
    {
      "x": -6,
      "y": 5,
      "z": 3,
      "name": "Bronze_Pipe_Large",
      "rotation": 5
    },
    {
      "x": -6,
      "y": 6,
      "z": 3,
      "name": "Deco_Iron_Bars_Platforms"
    },
    {
      "x": -6,
      "y": 7,
      "z": 3,
      "name": "Deco_Bronze_Railing"
    },
    {
      "x": -6,
      "y": 12,
      "z": 3,
      "name": "Bronze_Pipe_Large",
      "rotation": 4
    },
    {
      "x": -6,
      "y": 13,
      "z": 3,
      "name": "Rock_Basalt_Brick"
    },
    {
      "x": -6,
      "y": -1,
      "z": 4,
      "name": "Rock_Ice"
    },
    {
      "x": -6,
      "y": 0,
      "z": 4,
      "name": "Rock_Basalt_Brick",
      "rotation": 3
    },
    {
      "x": -6,
      "y": 1,
      "z": 4,
      "name": "Deco_Mystery_Machine_Large",
      "filler": 127
    },
    {
      "x": -6,
      "y": 2,
      "z": 4,
      "name": "Deco_Mystery_Machine_Large",
      "filler": 1151
    },
    {
      "x": -6,
      "y": 3,
      "z": 4,
      "name": "Deco_Mystery_Machine_Large",
      "filler": 2175
    },
    {
      "x": -6,
      "y": 4,
      "z": 4,
      "name": "Deco_Mystery_Machine_Large",
      "filler": 3199
    },
    {
      "x": -6,
      "y": 12,
      "z": 4,
      "name": "Bronze_Pipe_Large",
      "rotation": 4
    },
    {
      "x": -6,
      "y": 13,
      "z": 4,
      "name": "Rock_Basalt_Brick"
    },
    {
      "x": -6,
      "y": -1,
      "z": 5,
      "name": "Rock_Ice"
    },
    {
      "x": -6,
      "y": 0,
      "z": 5,
      "name": "Rock_Basalt_Brick"
    },
    {
      "x": -6,
      "y": 1,
      "z": 5,
      "name": "Rock_Basalt_Brick"
    },
    {
      "x": -6,
      "y": 2,
      "z": 5,
      "name": "Rock_Basalt_Brick"
    },
    {
      "x": -6,
      "y": 3,
      "z": 5,
      "name": "Rock_Basalt_Brick"
    },
    {
      "x": -6,
      "y": 4,
      "z": 5,
      "name": "Rock_Basalt_Brick"
    },
    {
      "x": -6,
      "y": 5,
      "z": 5,
      "name": "Rock_Basalt_Brick"
    },
    {
      "x": -6,
      "y": 6,
      "z": 5,
      "name": "Rock_Basalt_Brick"
    },
    {
      "x": -6,
      "y": 7,
      "z": 5,
      "name": "Rock_Basalt_Brick"
    },
    {
      "x": -6,
      "y": 8,
      "z": 5,
      "name": "Rock_Basalt_Brick_Half",
      "rotation": 6
    },
    {
      "x": -6,
      "y": 9,
      "z": 5,
      "name": "Rock_Basalt_Brick"
    },
    {
      "x": -6,
      "y": 10,
      "z": 5,
      "name": "Rock_Basalt_Brick"
    },
    {
      "x": -6,
      "y": 11,
      "z": 5,
      "name": "Rock_Basalt_Brick"
    },
    {
      "x": -6,
      "y": 12,
      "z": 5,
      "name": "Rock_Basalt_Brick"
    },
    {
      "x": -6,
      "y": 13,
      "z": 5,
      "name": "Rock_Basalt_Brick"
    },
    {
      "x": -5,
      "y": -1,
      "z": -3,
      "name": "Rock_Ice"
    },
    {
      "x": -5,
      "y": 0,
      "z": -3,
      "name": "Rock_Basalt",
      "rotation": 3
    },
    {
      "x": -5,
      "y": 13,
      "z": -3,
      "name": "Rock_Basalt_Brick"
    },
    {
      "x": -5,
      "y": -1,
      "z": -2,
      "name": "Rock_Ice"
    },
    {
      "x": -5,
      "y": 0,
      "z": -2,
      "name": "Rock_Basalt",
      "rotation": 3
    },
    {
      "x": -5,
      "y": 1,
      "z": -2,
      "name": "Rubble_Basalt",
      "support": 15
    },
    {
      "x": -5,
      "y": 12,
      "z": -2,
      "name": "Rock_Basalt_Brick_Stairs",
      "rotation": 11
    },
    {
      "x": -5,
      "y": 13,
      "z": -2,
      "name": "Rock_Basalt_Brick"
    },
    {
      "x": -5,
      "y": -1,
      "z": -1,
      "name": "Rock_Ice"
    },
    {
      "x": -5,
      "y": 0,
      "z": -1,
      "name": "Rock_Basalt",
      "rotation": 3
    },
    {
      "x": -5,
      "y": 1,
      "z": -1,
      "name": "Furniture_Basalt_Trough",
      "rotation": 1
    },
    {
      "x": -5,
      "y": 11,
      "z": -1,
      "name": "Rock_Ice_Stalactite_Large",
      "filler": 31744,
      "rotation": 8
    },
    {
      "x": -5,
      "y": 12,
      "z": -1,
      "name": "Rock_Ice_Stalactite_Large",
      "rotation": 8
    },
    {
      "x": -5,
      "y": 13,
      "z": -1,
      "name": "Rock_Basalt_Brick"
    },
    {
      "x": -5,
      "y": -1,
      "z": 0,
      "name": "Rock_Ice"
    },
    {
      "x": -5,
      "y": 0,
      "z": 0,
      "name": "Rock_Basalt",
      "rotation": 3
    },
    {
      "x": -5,
      "y": 1,
      "z": 0,
      "name": "Furniture_Basalt_Trough",
      "filler": 32,
      "rotation": 1
    },
    {
      "x": -5,
      "y": 6,
      "z": 0,
      "name": "Deco_Iron_Bars_Platforms"
    },
    {
      "x": -5,
      "y": 7,
      "z": 0,
      "name": "Deco_Bronze_Railing"
    },
    {
      "x": -5,
      "y": 13,
      "z": 0,
      "name": "Rock_Basalt_Brick"
    },
    {
      "x": -5,
      "y": -1,
      "z": 1,
      "name": "Rock_Ice"
    },
    {
      "x": -5,
      "y": 0,
      "z": 1,
      "name": "Rock_Basalt",
      "rotation": 3
    },
    {
      "x": -5,
      "y": 1,
      "z": 1,
      "name": "Deco_Mystery_Machine_Large"
    },
    {
      "x": -5,
      "y": 2,
      "z": 1,
      "name": "Deco_Mystery_Machine_Large",
      "filler": 1024
    },
    {
      "x": -5,
      "y": 3,
      "z": 1,
      "name": "Deco_Mystery_Machine_Large",
      "filler": 2048
    },
    {
      "x": -5,
      "y": 4,
      "z": 1,
      "name": "Deco_Mystery_Machine_Large",
      "filler": 3072
    },
    {
      "x": -5,
      "y": 6,
      "z": 1,
      "name": "Deco_Iron_Bars_Platforms"
    },
    {
      "x": -5,
      "y": 13,
      "z": 1,
      "name": "Rock_Basalt_Brick"
    },
    {
      "x": -5,
      "y": -1,
      "z": 2,
      "name": "Rock_Ice"
    },
    {
      "x": -5,
      "y": 0,
      "z": 2,
      "name": "Rock_Basalt",
      "rotation": 3
    },
    {
      "x": -5,
      "y": 1,
      "z": 2,
      "name": "Deco_Mystery_Machine_Large",
      "filler": 32
    },
    {
      "x": -5,
      "y": 2,
      "z": 2,
      "name": "Deco_Mystery_Machine_Large",
      "filler": 1056
    },
    {
      "x": -5,
      "y": 3,
      "z": 2,
      "name": "Deco_Mystery_Machine_Large",
      "filler": 2080
    },
    {
      "x": -5,
      "y": 4,
      "z": 2,
      "name": "Deco_Mystery_Machine_Large",
      "filler": 3104
    },
    {
      "x": -5,
      "y": 6,
      "z": 2,
      "name": "Deco_Iron_Bars_Platforms"
    },
    {
      "x": -5,
      "y": 12,
      "z": 2,
      "name": "Bronze_Pipe_Large",
      "rotation": 5
    },
    {
      "x": -5,
      "y": 13,
      "z": 2,
      "name": "Rock_Basalt_Brick"
    },
    {
      "x": -5,
      "y": -1,
      "z": 3,
      "name": "Rock_Ice"
    },
    {
      "x": -5,
      "y": 0,
      "z": 3,
      "name": "Rock_Basalt",
      "rotation": 3
    },
    {
      "x": -5,
      "y": 1,
      "z": 3,
      "name": "Deco_Mystery_Machine_Large",
      "filler": 64
    },
    {
      "x": -5,
      "y": 2,
      "z": 3,
      "name": "Deco_Mystery_Machine_Large",
      "filler": 1088
    },
    {
      "x": -5,
      "y": 3,
      "z": 3,
      "name": "Deco_Mystery_Machine_Large",
      "filler": 2112
    },
    {
      "x": -5,
      "y": 4,
      "z": 3,
      "name": "Deco_Mystery_Machine_Large",
      "filler": 3136
    },
    {
      "x": -5,
      "y": 5,
      "z": 3,
      "name": "Bronze_Pipe_Large",
      "rotation": 5
    },
    {
      "x": -5,
      "y": 6,
      "z": 3,
      "name": "Deco_Iron_Bars_Platforms"
    },
    {
      "x": -5,
      "y": 7,
      "z": 3,
      "name": "Deco_Bronze_Railing"
    },
    {
      "x": -5,
      "y": 13,
      "z": 3,
      "name": "Rock_Basalt_Brick"
    },
    {
      "x": -5,
      "y": -1,
      "z": 4,
      "name": "Rock_Ice"
    },
    {
      "x": -5,
      "y": 0,
      "z": 4,
      "name": "Rock_Basalt",
      "rotation": 3
    },
    {
      "x": -5,
      "y": 1,
      "z": 4,
      "name": "Deco_Mystery_Machine_Large",
      "filler": 96
    },
    {
      "x": -5,
      "y": 2,
      "z": 4,
      "name": "Deco_Mystery_Machine_Large",
      "filler": 1120
    },
    {
      "x": -5,
      "y": 3,
      "z": 4,
      "name": "Deco_Mystery_Machine_Large",
      "filler": 2144
    },
    {
      "x": -5,
      "y": 4,
      "z": 4,
      "name": "Deco_Mystery_Machine_Large",
      "filler": 3168
    },
    {
      "x": -5,
      "y": 13,
      "z": 4,
      "name": "Rock_Basalt_Brick"
    },
    {
      "x": -5,
      "y": -1,
      "z": 5,
      "name": "Rock_Ice"
    },
    {
      "x": -5,
      "y": 0,
      "z": 5,
      "name": "Rock_Basalt_Brick"
    },
    {
      "x": -5,
      "y": 1,
      "z": 5,
      "name": "Rock_Basalt_Brick"
    },
    {
      "x": -5,
      "y": 2,
      "z": 5,
      "name": "Rock_Basalt_Brick"
    },
    {
      "x": -5,
      "y": 3,
      "z": 5,
      "name": "Rock_Basalt_Brick"
    },
    {
      "x": -5,
      "y": 4,
      "z": 5,
      "name": "Rock_Basalt_Brick"
    },
    {
      "x": -5,
      "y": 5,
      "z": 5,
      "name": "Rock_Basalt_Brick"
    },
    {
      "x": -5,
      "y": 6,
      "z": 5,
      "name": "Rock_Basalt_Brick"
    },
    {
      "x": -5,
      "y": 7,
      "z": 5,
      "name": "Rock_Basalt_Brick_Half",
      "rotation": 6
    },
    {
      "x": -5,
      "y": 8,
      "z": 5,
      "name": "Rock_Basalt_Brick_Half",
      "rotation": 6
    },
    {
      "x": -5,
      "y": 9,
      "z": 5,
      "name": "Rock_Basalt_Brick_Half",
      "rotation": 6
    },
    {
      "x": -5,
      "y": 10,
      "z": 5,
      "name": "Rock_Basalt_Brick"
    },
    {
      "x": -5,
      "y": 11,
      "z": 5,
      "name": "Rock_Basalt_Brick"
    },
    {
      "x": -5,
      "y": 12,
      "z": 5,
      "name": "Rock_Basalt_Brick"
    },
    {
      "x": -5,
      "y": 13,
      "z": 5,
      "name": "Rock_Basalt_Brick"
    },
    {
      "x": -4,
      "y": -1,
      "z": -3,
      "name": "Rock_Ice"
    },
    {
      "x": -4,
      "y": 0,
      "z": -3,
      "name": "Rock_Basalt",
      "rotation": 3
    },
    {
      "x": -4,
      "y": 13,
      "z": -3,
      "name": "Rock_Basalt_Brick"
    },
    {
      "x": -4,
      "y": -1,
      "z": -2,
      "name": "Rock_Ice"
    },
    {
      "x": -4,
      "y": 0,
      "z": -2,
      "name": "Rock_Basalt",
      "rotation": 3
    },
    {
      "x": -4,
      "y": 12,
      "z": -2,
      "name": "Rock_Basalt_Brick_Half",
      "rotation": 11
    },
    {
      "x": -4,
      "y": 13,
      "z": -2,
      "name": "Rock_Basalt_Brick"
    },
    {
      "x": -4,
      "y": -1,
      "z": -1,
      "name": "Rock_Ice"
    },
    {
      "x": -4,
      "y": 0,
      "z": -1,
      "name": "Rock_Basalt",
      "rotation": 3
    },
    {
      "x": -4,
      "y": 1,
      "z": -1,
      "name": "Deco_Scroll"
    },
    {
      "x": -4,
      "y": 13,
      "z": -1,
      "name": "Rock_Basalt_Brick"
    },
    {
      "x": -4,
      "y": -1,
      "z": 0,
      "name": "Rock_Ice"
    },
    {
      "x": -4,
      "y": 0,
      "z": 0,
      "name": "Rock_Basalt",
      "rotation": 3
    },
    {
      "x": -4,
      "y": 1,
      "z": 0,
      "name": "Rubble_Basalt_Medium",
      "support": 15
    },
    {
      "x": -4,
      "y": 6,
      "z": 0,
      "name": "Deco_Iron_Bars_Platforms"
    },
    {
      "x": -4,
      "y": 7,
      "z": 0,
      "name": "Deco_Bronze_Railing"
    },
    {
      "x": -4,
      "y": 8,
      "z": 0,
      "name": "Deco_Iron_Chain_Small"
    },
    {
      "x": -4,
      "y": 9,
      "z": 0,
      "name": "Deco_Iron_Chain_Small"
    },
    {
      "x": -4,
      "y": 10,
      "z": 0,
      "name": "Deco_Iron_Chain_Small"
    },
    {
      "x": -4,
      "y": 11,
      "z": 0,
      "name": "Deco_Iron_Chain_Small"
    },
    {
      "x": -4,
      "y": 12,
      "z": 0,
      "name": "Deco_Iron_Chain_Small"
    },
    {
      "x": -4,
      "y": 13,
      "z": 0,
      "name": "Rock_Basalt_Brick"
    },
    {
      "x": -4,
      "y": -1,
      "z": 1,
      "name": "Rock_Ice"
    },
    {
      "x": -4,
      "y": 0,
      "z": 1,
      "name": "Rock_Basalt",
      "rotation": 3
    },
    {
      "x": -4,
      "y": 1,
      "z": 1,
      "name": "Deco_Mystery_Machine_Large",
      "filler": 1
    },
    {
      "x": -4,
      "y": 2,
      "z": 1,
      "name": "Deco_Mystery_Machine_Large",
      "filler": 1025
    },
    {
      "x": -4,
      "y": 3,
      "z": 1,
      "name": "Deco_Mystery_Machine_Large",
      "filler": 2049
    },
    {
      "x": -4,
      "y": 4,
      "z": 1,
      "name": "Deco_Mystery_Machine_Large",
      "filler": 3073
    },
    {
      "x": -4,
      "y": 6,
      "z": 1,
      "name": "Deco_Iron_Bars_Platforms"
    },
    {
      "x": -4,
      "y": 13,
      "z": 1,
      "name": "Rock_Basalt_Brick"
    },
    {
      "x": -4,
      "y": -1,
      "z": 2,
      "name": "Rock_Ice"
    },
    {
      "x": -4,
      "y": 0,
      "z": 2,
      "name": "Rock_Basalt",
      "rotation": 3
    },
    {
      "x": -4,
      "y": 1,
      "z": 2,
      "name": "Deco_Mystery_Machine_Large",
      "filler": 33
    },
    {
      "x": -4,
      "y": 2,
      "z": 2,
      "name": "Deco_Mystery_Machine_Large",
      "filler": 1057
    },
    {
      "x": -4,
      "y": 3,
      "z": 2,
      "name": "Deco_Mystery_Machine_Large",
      "filler": 2081
    },
    {
      "x": -4,
      "y": 4,
      "z": 2,
      "name": "Deco_Mystery_Machine_Large",
      "filler": 3105
    },
    {
      "x": -4,
      "y": 6,
      "z": 2,
      "name": "Deco_Iron_Bars_Platforms"
    },
    {
      "x": -4,
      "y": 12,
      "z": 2,
      "name": "Bronze_Pipe_Large",
      "rotation": 5
    },
    {
      "x": -4,
      "y": 13,
      "z": 2,
      "name": "Rock_Basalt_Brick"
    },
    {
      "x": -4,
      "y": -1,
      "z": 3,
      "name": "Rock_Ice"
    },
    {
      "x": -4,
      "y": 0,
      "z": 3,
      "name": "Rock_Basalt",
      "rotation": 3
    },
    {
      "x": -4,
      "y": 1,
      "z": 3,
      "name": "Deco_Mystery_Machine_Large",
      "filler": 65
    },
    {
      "x": -4,
      "y": 2,
      "z": 3,
      "name": "Deco_Mystery_Machine_Large",
      "filler": 1089
    },
    {
      "x": -4,
      "y": 3,
      "z": 3,
      "name": "Deco_Mystery_Machine_Large",
      "filler": 2113
    },
    {
      "x": -4,
      "y": 4,
      "z": 3,
      "name": "Deco_Mystery_Machine_Large",
      "filler": 3137
    },
    {
      "x": -4,
      "y": 5,
      "z": 3,
      "name": "Bronze_Pipe_Large",
      "rotation": 5
    },
    {
      "x": -4,
      "y": 6,
      "z": 3,
      "name": "Deco_Iron_Bars_Platforms"
    },
    {
      "x": -4,
      "y": 7,
      "z": 3,
      "name": "Deco_Bronze_Railing"
    },
    {
      "x": -4,
      "y": 8,
      "z": 3,
      "name": "Deco_Iron_Chain_Small"
    },
    {
      "x": -4,
      "y": 9,
      "z": 3,
      "name": "Deco_Iron_Chain_Small"
    },
    {
      "x": -4,
      "y": 10,
      "z": 3,
      "name": "Deco_Iron_Chain_Small"
    },
    {
      "x": -4,
      "y": 11,
      "z": 3,
      "name": "Deco_Iron_Chain_Small"
    },
    {
      "x": -4,
      "y": 12,
      "z": 3,
      "name": "Deco_Iron_Chain_Small"
    },
    {
      "x": -4,
      "y": 13,
      "z": 3,
      "name": "Rock_Basalt_Brick"
    },
    {
      "x": -4,
      "y": -1,
      "z": 4,
      "name": "Rock_Ice"
    },
    {
      "x": -4,
      "y": 0,
      "z": 4,
      "name": "Rock_Basalt",
      "rotation": 3
    },
    {
      "x": -4,
      "y": 1,
      "z": 4,
      "name": "Deco_Mystery_Machine_Large",
      "filler": 97
    },
    {
      "x": -4,
      "y": 2,
      "z": 4,
      "name": "Deco_Mystery_Machine_Large",
      "filler": 1121
    },
    {
      "x": -4,
      "y": 3,
      "z": 4,
      "name": "Deco_Mystery_Machine_Large",
      "filler": 2145
    },
    {
      "x": -4,
      "y": 4,
      "z": 4,
      "name": "Deco_Mystery_Machine_Large",
      "filler": 3169
    },
    {
      "x": -4,
      "y": 13,
      "z": 4,
      "name": "Rock_Basalt_Brick"
    },
    {
      "x": -4,
      "y": -1,
      "z": 5,
      "name": "Rock_Ice"
    },
    {
      "x": -4,
      "y": 0,
      "z": 5,
      "name": "Rock_Basalt_Brick"
    },
    {
      "x": -4,
      "y": 1,
      "z": 5,
      "name": "Rock_Basalt_Brick"
    },
    {
      "x": -4,
      "y": 2,
      "z": 5,
      "name": "Rock_Basalt_Brick"
    },
    {
      "x": -4,
      "y": 3,
      "z": 5,
      "name": "Rock_Basalt_Brick"
    },
    {
      "x": -4,
      "y": 4,
      "z": 5,
      "name": "Rock_Basalt_Brick"
    },
    {
      "x": -4,
      "y": 5,
      "z": 5,
      "name": "Rock_Basalt_Brick"
    },
    {
      "x": -4,
      "y": 6,
      "z": 5,
      "name": "Rock_Basalt_Brick"
    },
    {
      "x": -4,
      "y": 7,
      "z": 5,
      "name": "Rock_Basalt_Brick"
    },
    {
      "x": -4,
      "y": 8,
      "z": 5,
      "name": "Rock_Basalt_Brick_Half",
      "rotation": 6
    },
    {
      "x": -4,
      "y": 9,
      "z": 5,
      "name": "Rock_Basalt_Brick_Half",
      "rotation": 6
    },
    {
      "x": -4,
      "y": 10,
      "z": 5,
      "name": "Rock_Basalt_Brick"
    },
    {
      "x": -4,
      "y": 11,
      "z": 5,
      "name": "Rock_Basalt_Brick"
    },
    {
      "x": -4,
      "y": 12,
      "z": 5,
      "name": "Rock_Basalt_Brick"
    },
    {
      "x": -4,
      "y": 13,
      "z": 5,
      "name": "Rock_Basalt_Brick"
    },
    {
      "x": -3,
      "y": -1,
      "z": -3,
      "name": "Rock_Ice"
    },
    {
      "x": -3,
      "y": 0,
      "z": -3,
      "name": "Rock_Basalt",
      "rotation": 3
    },
    {
      "x": -3,
      "y": 13,
      "z": -3,
      "name": "Rock_Basalt_Brick"
    },
    {
      "x": -3,
      "y": -1,
      "z": -2,
      "name": "Rock_Ice"
    },
    {
      "x": -3,
      "y": 0,
      "z": -2,
      "name": "Rock_Basalt",
      "rotation": 3
    },
    {
      "x": -3,
      "y": 1,
      "z": -2,
      "name": "Furniture_Ancient_Barrel"
    },
    {
      "x": -3,
      "y": 12,
      "z": -2,
      "name": "Rock_Basalt_Brick_Stairs",
      "rotation": 9
    },
    {
      "x": -3,
      "y": 13,
      "z": -2,
      "name": "Rock_Basalt_Brick"
    },
    {
      "x": -3,
      "y": -1,
      "z": -1,
      "name": "Rock_Ice"
    },
    {
      "x": -3,
      "y": 0,
      "z": -1,
      "name": "Rock_Basalt",
      "rotation": 3
    },
    {
      "x": -3,
      "y": 13,
      "z": -1,
      "name": "Rock_Basalt_Brick"
    },
    {
      "x": -3,
      "y": -1,
      "z": 0,
      "name": "Rock_Ice"
    },
    {
      "x": -3,
      "y": 0,
      "z": 0,
      "name": "Rock_Basalt",
      "rotation": 3
    },
    {
      "x": -3,
      "y": 6,
      "z": 0,
      "name": "Deco_Iron_Bars_Platforms"
    },
    {
      "x": -3,
      "y": 7,
      "z": 0,
      "name": "Deco_Bronze_Railing"
    },
    {
      "x": -3,
      "y": 13,
      "z": 0,
      "name": "Rock_Basalt_Brick"
    },
    {
      "x": -3,
      "y": -1,
      "z": 1,
      "name": "Rock_Ice"
    },
    {
      "x": -3,
      "y": 0,
      "z": 1,
      "name": "Rock_Basalt",
      "rotation": 3
    },
    {
      "x": -3,
      "y": 6,
      "z": 1,
      "name": "Deco_Iron_Bars_Platforms"
    },
    {
      "x": -3,
      "y": 13,
      "z": 1,
      "name": "Rock_Basalt_Brick"
    },
    {
      "x": -3,
      "y": -1,
      "z": 2,
      "name": "Rock_Ice"
    },
    {
      "x": -3,
      "y": 0,
      "z": 2,
      "name": "Rock_Basalt",
      "rotation": 3
    },
    {
      "x": -3,
      "y": 6,
      "z": 2,
      "name": "Deco_Iron_Bars_Platforms"
    },
    {
      "x": -3,
      "y": 12,
      "z": 2,
      "name": "Bronze_Pipe_Large",
      "rotation": 5
    },
    {
      "x": -3,
      "y": 13,
      "z": 2,
      "name": "Rock_Basalt_Brick"
    },
    {
      "x": -3,
      "y": -1,
      "z": 3,
      "name": "Rock_Ice"
    },
    {
      "x": -3,
      "y": 0,
      "z": 3,
      "name": "Rock_Basalt",
      "rotation": 3
    },
    {
      "x": -3,
      "y": 5,
      "z": 3,
      "name": "Bronze_Pipe_Large",
      "rotation": 5
    },
    {
      "x": -3,
      "y": 6,
      "z": 3,
      "name": "Deco_Iron_Bars_Platforms"
    },
    {
      "x": -3,
      "y": 7,
      "z": 3,
      "name": "Deco_Bronze_Railing"
    },
    {
      "x": -3,
      "y": 13,
      "z": 3,
      "name": "Rock_Basalt_Brick"
    },
    {
      "x": -3,
      "y": -1,
      "z": 4,
      "name": "Rock_Ice"
    },
    {
      "x": -3,
      "y": 0,
      "z": 4,
      "name": "Rock_Basalt",
      "rotation": 3
    },
    {
      "x": -3,
      "y": 1,
      "z": 4,
      "name": "Furniture_Ancient_Barrel"
    },
    {
      "x": -3,
      "y": 13,
      "z": 4,
      "name": "Rock_Basalt_Brick"
    },
    {
      "x": -3,
      "y": -1,
      "z": 5,
      "name": "Rock_Ice"
    },
    {
      "x": -3,
      "y": 0,
      "z": 5,
      "name": "Rock_Basalt_Brick"
    },
    {
      "x": -3,
      "y": 1,
      "z": 5,
      "name": "Rock_Basalt_Brick"
    },
    {
      "x": -3,
      "y": 2,
      "z": 5,
      "name": "Rock_Basalt_Brick"
    },
    {
      "x": -3,
      "y": 3,
      "z": 5,
      "name": "Rock_Basalt_Brick"
    },
    {
      "x": -3,
      "y": 4,
      "z": 5,
      "name": "Rock_Basalt_Brick"
    },
    {
      "x": -3,
      "y": 5,
      "z": 5,
      "name": "Rock_Basalt_Brick"
    },
    {
      "x": -3,
      "y": 6,
      "z": 5,
      "name": "Rock_Basalt_Brick"
    },
    {
      "x": -3,
      "y": 7,
      "z": 5,
      "name": "Rock_Basalt_Brick"
    },
    {
      "x": -3,
      "y": 8,
      "z": 5,
      "name": "Rock_Basalt_Brick"
    },
    {
      "x": -3,
      "y": 9,
      "z": 5,
      "name": "Rock_Basalt_Brick_Half",
      "rotation": 6
    },
    {
      "x": -3,
      "y": 10,
      "z": 5,
      "name": "Rock_Basalt_Brick"
    },
    {
      "x": -3,
      "y": 11,
      "z": 5,
      "name": "Rock_Basalt_Brick"
    },
    {
      "x": -3,
      "y": 12,
      "z": 5,
      "name": "Rock_Basalt_Brick"
    },
    {
      "x": -3,
      "y": 13,
      "z": 5,
      "name": "Rock_Basalt_Brick"
    },
    {
      "x": -2,
      "y": -1,
      "z": -3,
      "name": "Rock_Ice"
    },
    {
      "x": -2,
      "y": 0,
      "z": -3,
      "name": "Rock_Basalt_Brick",
      "rotation": 3
    },
    {
      "x": -2,
      "y": 1,
      "z": -3,
      "name": "Rubble_Basalt",
      "support": 15
    },
    {
      "x": -2,
      "y": 12,
      "z": -3,
      "name": "Rock_Basalt_Brick_Stairs",
      "rotation": 8
    },
    {
      "x": -2,
      "y": 13,
      "z": -3,
      "name": "Rock_Basalt_Brick"
    },
    {
      "x": -2,
      "y": -1,
      "z": -2,
      "name": "Rock_Ice"
    },
    {
      "x": -2,
      "y": 0,
      "z": -2,
      "name": "Rock_Basalt_Brick",
      "rotation": 3
    },
    {
      "x": -2,
      "y": 1,
      "z": -2,
      "name": "Rock_Basalt_Brick_Pillar_Base",
      "rotation": 3
    },
    {
      "x": -2,
      "y": 2,
      "z": -2,
      "name": "Rock_Basalt_Brick_Pillar_Middle",
      "rotation": 3
    },
    {
      "x": -2,
      "y": 3,
      "z": -2,
      "name": "Rock_Basalt_Brick_Pillar_Middle",
      "rotation": 3
    },
    {
      "x": -2,
      "y": 4,
      "z": -2,
      "name": "Rock_Basalt_Brick_Pillar_Middle",
      "rotation": 3
    },
    {
      "x": -2,
      "y": 5,
      "z": -2,
      "name": "Rock_Basalt_Brick_Pillar_Middle",
      "rotation": 3
    },
    {
      "x": -2,
      "y": 6,
      "z": -2,
      "name": "Rock_Basalt_Brick_Pillar_Middle",
      "rotation": 3
    },
    {
      "x": -2,
      "y": 7,
      "z": -2,
      "name": "Rock_Basalt_Brick_Pillar_Middle",
      "rotation": 3
    },
    {
      "x": -2,
      "y": 8,
      "z": -2,
      "name": "Rock_Basalt_Brick_Pillar_Middle",
      "rotation": 3
    },
    {
      "x": -2,
      "y": 9,
      "z": -2,
      "name": "Rock_Basalt_Brick_Pillar_Middle",
      "rotation": 3
    },
    {
      "x": -2,
      "y": 10,
      "z": -2,
      "name": "Rock_Basalt_Brick_Pillar_Middle",
      "rotation": 3
    },
    {
      "x": -2,
      "y": 11,
      "z": -2,
      "name": "Rock_Basalt_Brick_Pillar_Base",
      "rotation": 11
    },
    {
      "x": -2,
      "y": 12,
      "z": -2,
      "name": "Rock_Basalt_Brick",
      "rotation": 3
    },
    {
      "x": -2,
      "y": 13,
      "z": -2,
      "name": "Rock_Basalt_Brick"
    },
    {
      "x": -2,
      "y": -1,
      "z": -1,
      "name": "Rock_Ice"
    },
    {
      "x": -2,
      "y": 0,
      "z": -1,
      "name": "Rock_Basalt_Brick",
      "rotation": 3
    },
    {
      "x": -2,
      "y": 13,
      "z": -1,
      "name": "Rock_Basalt_Brick"
    },
    {
      "x": -2,
      "y": -1,
      "z": 0,
      "name": "Rock_Ice"
    },
    {
      "x": -2,
      "y": 0,
      "z": 0,
      "name": "Rock_Basalt_Brick",
      "rotation": 3
    },
    {
      "x": -2,
      "y": 1,
      "z": 0,
      "name": "Deco_Campfire_Off"
    },
    {
      "x": -2,
      "y": 6,
      "z": 0,
      "name": "Deco_Iron_Bars_Platforms"
    },
    {
      "x": -2,
      "y": 7,
      "z": 0,
      "name": "Deco_Bronze_Railing"
    },
    {
      "x": -2,
      "y": 12,
      "z": 0,
      "name": "Rock_Ice_Icicles",
      "rotation": 8
    },
    {
      "x": -2,
      "y": 13,
      "z": 0,
      "name": "Rock_Basalt_Brick"
    },
    {
      "x": -2,
      "y": -1,
      "z": 1,
      "name": "Rock_Ice"
    },
    {
      "x": -2,
      "y": 0,
      "z": 1,
      "name": "Rock_Basalt_Brick",
      "rotation": 3
    },
    {
      "x": -2,
      "y": 6,
      "z": 1,
      "name": "Deco_Iron_Bars_Platforms"
    },
    {
      "x": -2,
      "y": 13,
      "z": 1,
      "name": "Rock_Basalt_Brick"
    },
    {
      "x": -2,
      "y": -1,
      "z": 2,
      "name": "Rock_Ice"
    },
    {
      "x": -2,
      "y": 0,
      "z": 2,
      "name": "Rock_Basalt_Brick",
      "rotation": 3
    },
    {
      "x": -2,
      "y": 6,
      "z": 2,
      "name": "Deco_Iron_Bars_Platforms"
    },
    {
      "x": -2,
      "y": 12,
      "z": 2,
      "name": "Bronze_Pipe_Large",
      "rotation": 5
    },
    {
      "x": -2,
      "y": 13,
      "z": 2,
      "name": "Rock_Basalt_Brick"
    },
    {
      "x": -2,
      "y": -1,
      "z": 3,
      "name": "Rock_Ice"
    },
    {
      "x": -2,
      "y": 0,
      "z": 3,
      "name": "Rock_Basalt_Brick",
      "rotation": 3
    },
    {
      "x": -2,
      "y": 1,
      "z": 3,
      "name": "Rubble_Basalt_Medium",
      "support": 15
    },
    {
      "x": -2,
      "y": 5,
      "z": 3,
      "name": "Bronze_Pipe_Large",
      "rotation": 5
    },
    {
      "x": -2,
      "y": 6,
      "z": 3,
      "name": "Deco_Iron_Bars_Platforms"
    },
    {
      "x": -2,
      "y": 7,
      "z": 3,
      "name": "Deco_Bronze_Railing"
    },
    {
      "x": -2,
      "y": 13,
      "z": 3,
      "name": "Rock_Basalt_Brick"
    },
    {
      "x": -2,
      "y": -1,
      "z": 4,
      "name": "Rock_Ice"
    },
    {
      "x": -2,
      "y": 0,
      "z": 4,
      "name": "Rock_Basalt_Brick",
      "rotation": 3
    },
    {
      "x": -2,
      "y": 1,
      "z": 4,
      "name": "Bench_Furnace",
      "components": {
        "Components": {
          "processingBench": {
            "TierLevel": 1,
            "UpgradeItems": [],
            "InputContainer": {
              "Id": "Simple",
              "Capacity": 2,
              "Items": {}
            },
            "FuelContainer": {
              "Id": "Simple",
              "Capacity": 1,
              "Items": {}
            },
            "OutputContainer": {
              "Id": "Simple",
              "Capacity": 4,
              "Items": {}
            },
            "Progress": 0.0,
            "FuelTime": 0.0,
            "Active": false,
            "NextExtra": 2
          },
          "PlacedByInteraction": {
            "WhoPlacedUuid": {
              "$binary": "B1yBGZcjQ2KREo5yyLGY0g==",
              "$type": "04"
            }
          }
        }
      },
      "rotation": 2
    },
    {
      "x": -2,
      "y": 2,
      "z": 4,
      "name": "Bench_Furnace",
      "filler": 1024,
      "rotation": 2
    },
    {
      "x": -2,
      "y": 5,
      "z": 4,
      "name": "Wood_Deadwood_Planks_Half",
      "rotation": 6
    },
    {
      "x": -2,
      "y": 13,
      "z": 4,
      "name": "Rock_Basalt_Brick"
    },
    {
      "x": -2,
      "y": -1,
      "z": 5,
      "name": "Rock_Ice"
    },
    {
      "x": -2,
      "y": 0,
      "z": 5,
      "name": "Rock_Basalt_Brick"
    },
    {
      "x": -2,
      "y": 1,
      "z": 5,
      "name": "Rock_Basalt_Brick"
    },
    {
      "x": -2,
      "y": 2,
      "z": 5,
      "name": "Rock_Basalt_Brick"
    },
    {
      "x": -2,
      "y": 3,
      "z": 5,
      "name": "Rock_Basalt_Brick"
    },
    {
      "x": -2,
      "y": 4,
      "z": 5,
      "name": "Rock_Basalt_Brick"
    },
    {
      "x": -2,
      "y": 5,
      "z": 5,
      "name": "Rock_Basalt_Brick"
    },
    {
      "x": -2,
      "y": 6,
      "z": 5,
      "name": "Rock_Basalt_Brick"
    },
    {
      "x": -2,
      "y": 7,
      "z": 5,
      "name": "Rock_Basalt_Brick"
    },
    {
      "x": -2,
      "y": 8,
      "z": 5,
      "name": "Rock_Basalt_Brick"
    },
    {
      "x": -2,
      "y": 9,
      "z": 5,
      "name": "Rock_Basalt_Brick"
    },
    {
      "x": -2,
      "y": 10,
      "z": 5,
      "name": "Rock_Basalt_Brick"
    },
    {
      "x": -2,
      "y": 11,
      "z": 5,
      "name": "Rock_Basalt_Brick"
    },
    {
      "x": -2,
      "y": 12,
      "z": 5,
      "name": "Rock_Basalt_Brick"
    },
    {
      "x": -2,
      "y": 13,
      "z": 5,
      "name": "Rock_Basalt_Brick"
    },
    {
      "x": -1,
      "y": -1,
      "z": -3,
      "name": "Rock_Ice"
    },
    {
      "x": -1,
      "y": 0,
      "z": -3,
      "name": "Rock_Basalt",
      "rotation": 3
    },
    {
      "x": -1,
      "y": 13,
      "z": -3,
      "name": "Rock_Basalt_Brick"
    },
    {
      "x": -1,
      "y": -1,
      "z": -2,
      "name": "Rock_Ice"
    },
    {
      "x": -1,
      "y": 0,
      "z": -2,
      "name": "Rock_Basalt",
      "rotation": 3
    },
    {
      "x": -1,
      "y": 12,
      "z": -2,
      "name": "Rock_Basalt_Brick_Stairs",
      "rotation": 11
    },
    {
      "x": -1,
      "y": 13,
      "z": -2,
      "name": "Rock_Basalt_Brick"
    },
    {
      "x": -1,
      "y": -1,
      "z": -1,
      "name": "Rock_Ice"
    },
    {
      "x": -1,
      "y": 0,
      "z": -1,
      "name": "Rock_Basalt",
      "rotation": 3
    },
    {
      "x": -1,
      "y": 13,
      "z": -1,
      "name": "Rock_Basalt_Brick"
    },
    {
      "x": -1,
      "y": -1,
      "z": 0,
      "name": "Rock_Ice"
    },
    {
      "x": -1,
      "y": 0,
      "z": 0,
      "name": "Rock_Basalt",
      "rotation": 3
    },
    {
      "x": -1,
      "y": 6,
      "z": 0,
      "name": "Deco_Iron_Bars_Platforms"
    },
    {
      "x": -1,
      "y": 7,
      "z": 0,
      "name": "Deco_Bronze_Railing"
    },
    {
      "x": -1,
      "y": 13,
      "z": 0,
      "name": "Rock_Basalt_Brick"
    },
    {
      "x": -1,
      "y": -1,
      "z": 1,
      "name": "Rock_Ice"
    },
    {
      "x": -1,
      "y": 0,
      "z": 1,
      "name": "Rock_Basalt",
      "rotation": 3
    },
    {
      "x": -1,
      "y": 6,
      "z": 1,
      "name": "Deco_Iron_Bars_Platforms"
    },
    {
      "x": -1,
      "y": 13,
      "z": 1,
      "name": "Rock_Basalt_Brick"
    },
    {
      "x": -1,
      "y": -1,
      "z": 2,
      "name": "Rock_Ice"
    },
    {
      "x": -1,
      "y": 0,
      "z": 2,
      "name": "Rock_Basalt",
      "rotation": 3
    },
    {
      "x": -1,
      "y": 1,
      "z": 2,
      "name": "Rubble_Basalt",
      "support": 15
    },
    {
      "x": -1,
      "y": 6,
      "z": 2,
      "name": "Deco_Iron_Bars_Platforms"
    },
    {
      "x": -1,
      "y": 12,
      "z": 2,
      "name": "Bronze_Pipe_Large",
      "rotation": 5
    },
    {
      "x": -1,
      "y": 13,
      "z": 2,
      "name": "Rock_Basalt_Brick"
    },
    {
      "x": -1,
      "y": -1,
      "z": 3,
      "name": "Rock_Ice"
    },
    {
      "x": -1,
      "y": 0,
      "z": 3,
      "name": "Rock_Basalt",
      "rotation": 3
    },
    {
      "x": -1,
      "y": 5,
      "z": 3,
      "name": "Bronze_Pipe_Large",
      "rotation": 5
    },
    {
      "x": -1,
      "y": 6,
      "z": 3,
      "name": "Deco_Iron_Bars_Platforms"
    },
    {
      "x": -1,
      "y": 7,
      "z": 3,
      "name": "Deco_Bronze_Railing"
    },
    {
      "x": -1,
      "y": 12,
      "z": 3,
      "name": "Rock_Ice_Icicles",
      "rotation": 8
    },
    {
      "x": -1,
      "y": 13,
      "z": 3,
      "name": "Rock_Basalt_Brick"
    },
    {
      "x": -1,
      "y": -1,
      "z": 4,
      "name": "Rock_Ice"
    },
    {
      "x": -1,
      "y": 0,
      "z": 4,
      "name": "Rock_Basalt",
      "rotation": 3
    },
    {
      "x": -1,
      "y": 1,
      "z": 4,
      "name": "Bench_Furnace",
      "filler": 1,
      "rotation": 2
    },
    {
      "x": -1,
      "y": 2,
      "z": 4,
      "name": "Bench_Furnace",
      "filler": 1025,
      "rotation": 2
    },
    {
      "x": -1,
      "y": 5,
      "z": 4,
      "name": "Wood_Deadwood_Planks_Half",
      "rotation": 6
    },
    {
      "x": -1,
      "y": 13,
      "z": 4,
      "name": "Rock_Basalt_Brick"
    },
    {
      "x": -1,
      "y": -1,
      "z": 5,
      "name": "Rock_Ice"
    },
    {
      "x": -1,
      "y": 0,
      "z": 5,
      "name": "Rock_Basalt_Brick"
    },
    {
      "x": -1,
      "y": 1,
      "z": 5,
      "name": "Rock_Basalt_Brick"
    },
    {
      "x": -1,
      "y": 2,
      "z": 5,
      "name": "Rock_Basalt_Brick"
    },
    {
      "x": -1,
      "y": 3,
      "z": 5,
      "name": "Rock_Basalt_Brick"
    },
    {
      "x": -1,
      "y": 4,
      "z": 5,
      "name": "Rock_Basalt_Brick"
    },
    {
      "x": -1,
      "y": 5,
      "z": 5,
      "name": "Rock_Basalt_Brick"
    },
    {
      "x": -1,
      "y": 6,
      "z": 5,
      "name": "Rock_Basalt_Brick"
    },
    {
      "x": -1,
      "y": 7,
      "z": 5,
      "name": "Rock_Basalt_Brick_Half",
      "rotation": 6
    },
    {
      "x": -1,
      "y": 8,
      "z": 5,
      "name": "Rock_Basalt_Brick_Half",
      "rotation": 6
    },
    {
      "x": -1,
      "y": 9,
      "z": 5,
      "name": "Rock_Basalt_Brick"
    },
    {
      "x": -1,
      "y": 10,
      "z": 5,
      "name": "Rock_Basalt_Brick"
    },
    {
      "x": -1,
      "y": 11,
      "z": 5,
      "name": "Rock_Basalt_Brick"
    },
    {
      "x": -1,
      "y": 12,
      "z": 5,
      "name": "Rock_Basalt_Brick"
    },
    {
      "x": -1,
      "y": 13,
      "z": 5,
      "name": "Rock_Basalt_Brick"
    },
    {
      "x": 0,
      "y": -1,
      "z": -3,
      "name": "Rock_Ice"
    },
    {
      "x": 0,
      "y": 0,
      "z": -3,
      "name": "Rock_Basalt",
      "rotation": 3
    },
    {
      "x": 0,
      "y": 13,
      "z": -3,
      "name": "Rock_Basalt_Brick"
    },
    {
      "x": 0,
      "y": -1,
      "z": -2,
      "name": "Rock_Ice"
    },
    {
      "x": 0,
      "y": 0,
      "z": -2,
      "name": "Rock_Basalt",
      "rotation": 3
    },
    {
      "x": 0,
      "y": 12,
      "z": -2,
      "name": "Rock_Basalt_Brick_Half",
      "rotation": 11
    },
    {
      "x": 0,
      "y": 13,
      "z": -2,
      "name": "Rock_Basalt_Brick"
    },
    {
      "x": 0,
      "y": -1,
      "z": -1,
      "name": "Rock_Ice"
    },
    {
      "x": 0,
      "y": 0,
      "z": -1,
      "name": "Rock_Basalt",
      "rotation": 3
    },
    {
      "x": 0,
      "y": 1,
      "z": -1,
      "name": "Rubble_Basalt",
      "support": 15
    },
    {
      "x": 0,
      "y": 5,
      "z": -1,
      "name": "Rock_Bronze_Smooth"
    },
    {
      "x": 0,
      "y": 6,
      "z": -1,
      "name": "Bronze_Pipe_Large"
    },
    {
      "x": 0,
      "y": 7,
      "z": -1,
      "name": "Bronze_Pipe_Large"
    },
    {
      "x": 0,
      "y": 8,
      "z": -1,
      "name": "Bronze_Pipe_Large"
    },
    {
      "x": 0,
      "y": 9,
      "z": -1,
      "name": "Bronze_Pipe_Large"
    },
    {
      "x": 0,
      "y": 10,
      "z": -1,
      "name": "Bronze_Pipe_Large"
    },
    {
      "x": 0,
      "y": 11,
      "z": -1,
      "name": "Bronze_Pipe_Large"
    },
    {
      "x": 0,
      "y": 12,
      "z": -1,
      "name": "Rock_Bronze_Smooth"
    },
    {
      "x": 0,
      "y": 13,
      "z": -1,
      "name": "Rock_Basalt_Brick"
    },
    {
      "x": 0,
      "y": -1,
      "z": 0,
      "name": "Rock_Ice"
    },
    {
      "x": 0,
      "y": 0,
      "z": 0,
      "name": "Rock_Basalt",
      "rotation": 3
    },
    {
      "x": 0,
      "y": 5,
      "z": 0,
      "name": "Bronze_Pipe_Large",
      "rotation": 4
    },
    {
      "x": 0,
      "y": 6,
      "z": 0,
      "name": "Deco_Iron_Bars_Platforms"
    },
    {
      "x": 0,
      "y": 7,
      "z": 0,
      "name": "Deco_Bronze_Railing"
    },
    {
      "x": 0,
      "y": 12,
      "z": 0,
      "name": "Bronze_Pipe_Large",
      "rotation": 4
    },
    {
      "x": 0,
      "y": 13,
      "z": 0,
      "name": "Rock_Basalt_Brick"
    },
    {
      "x": 0,
      "y": -1,
      "z": 1,
      "name": "Rock_Ice"
    },
    {
      "x": 0,
      "y": 0,
      "z": 1,
      "name": "Rock_Basalt",
      "rotation": 3
    },
    {
      "x": 0,
      "y": 5,
      "z": 1,
      "name": "Bronze_Pipe_Large",
      "rotation": 4
    },
    {
      "x": 0,
      "y": 6,
      "z": 1,
      "name": "Deco_Iron_Bars_Platforms"
    },
    {
      "x": 0,
      "y": 12,
      "z": 1,
      "name": "Bronze_Pipe_Large",
      "rotation": 4
    },
    {
      "x": 0,
      "y": 13,
      "z": 1,
      "name": "Rock_Basalt_Brick"
    },
    {
      "x": 0,
      "y": -1,
      "z": 2,
      "name": "Rock_Ice"
    },
    {
      "x": 0,
      "y": 0,
      "z": 2,
      "name": "Rock_Basalt",
      "rotation": 3
    },
    {
      "x": 0,
      "y": 1,
      "z": 2,
      "name": "Furniture_Ancient_Table",
      "filler": 1023,
      "rotation": 2
    },
    {
      "x": 0,
      "y": 2,
      "z": 2,
      "name": "Deco_Bucket"
    },
    {
      "x": 0,
      "y": 5,
      "z": 2,
      "name": "Bronze_Pipe_Large",
      "rotation": 4
    },
    {
      "x": 0,
      "y": 6,
      "z": 2,
      "name": "Deco_Iron_Bars_Platforms"
    },
    {
      "x": 0,
      "y": 12,
      "z": 2,
      "name": "Rock_Bronze_Smooth"
    },
    {
      "x": 0,
      "y": 13,
      "z": 2,
      "name": "Rock_Basalt_Brick"
    },
    {
      "x": 0,
      "y": -1,
      "z": 3,
      "name": "Rock_Ice"
    },
    {
      "x": 0,
      "y": 0,
      "z": 3,
      "name": "Rock_Basalt",
      "rotation": 3
    },
    {
      "x": 0,
      "y": 1,
      "z": 3,
      "name": "Furniture_Ancient_Table",
      "filler": 31,
      "rotation": 2
    },
    {
      "x": 0,
      "y": 2,
      "z": 3,
      "name": "Rock_Bronze_Smooth"
    },
    {
      "x": 0,
      "y": 3,
      "z": 3,
      "name": "Bronze_Pipe_Large"
    },
    {
      "x": 0,
      "y": 4,
      "z": 3,
      "name": "Bronze_Pipe_Large"
    },
    {
      "x": 0,
      "y": 5,
      "z": 3,
      "name": "Rock_Bronze_Smooth"
    },
    {
      "x": 0,
      "y": 6,
      "z": 3,
      "name": "Deco_Iron_Bars_Platforms"
    },
    {
      "x": 0,
      "y": 7,
      "z": 3,
      "name": "Deco_Bronze_Railing"
    },
    {
      "x": 0,
      "y": 13,
      "z": 3,
      "name": "Rock_Basalt_Brick"
    },
    {
      "x": 0,
      "y": -1,
      "z": 4,
      "name": "Rock_Ice"
    },
    {
      "x": 0,
      "y": 0,
      "z": 4,
      "name": "Rock_Basalt",
      "rotation": 3
    },
    {
      "x": 0,
      "y": 1,
      "z": 4,
      "name": "Wood_Deadwood_Planks_Half",
      "rotation": 6
    },
    {
      "x": 0,
      "y": 2,
      "z": 4,
      "name": "Wood_Deadwood_Planks_Half",
      "rotation": 6
    },
    {
      "x": 0,
      "y": 3,
      "z": 4,
      "name": "Wood_Deadwood_Planks_Half",
      "rotation": 6
    },
    {
      "x": 0,
      "y": 4,
      "z": 4,
      "name": "Wood_Deadwood_Planks_Half",
      "rotation": 6
    },
    {
      "x": 0,
      "y": 5,
      "z": 4,
      "name": "Wood_Deadwood_Planks_Half",
      "rotation": 6
    },
    {
      "x": 0,
      "y": 6,
      "z": 4,
      "name": "Wood_Deadwood_Planks_Half",
      "rotation": 6
    },
    {
      "x": 0,
      "y": 11,
      "z": 4,
      "name": "Rock_Ice_Stalactite_Large",
      "filler": 31744,
      "rotation": 8
    },
    {
      "x": 0,
      "y": 12,
      "z": 4,
      "name": "Rock_Ice_Stalactite_Large",
      "rotation": 8
    },
    {
      "x": 0,
      "y": 13,
      "z": 4,
      "name": "Rock_Basalt_Brick"
    },
    {
      "x": 0,
      "y": -1,
      "z": 5,
      "name": "Rock_Ice"
    },
    {
      "x": 0,
      "y": 0,
      "z": 5,
      "name": "Rock_Basalt_Brick"
    },
    {
      "x": 0,
      "y": 1,
      "z": 5,
      "name": "Rock_Basalt_Brick"
    },
    {
      "x": 0,
      "y": 2,
      "z": 5,
      "name": "Rock_Basalt_Brick"
    },
    {
      "x": 0,
      "y": 3,
      "z": 5,
      "name": "Rock_Basalt_Brick"
    },
    {
      "x": 0,
      "y": 4,
      "z": 5,
      "name": "Rock_Basalt_Brick"
    },
    {
      "x": 0,
      "y": 5,
      "z": 5,
      "name": "Rock_Basalt_Brick"
    },
    {
      "x": 0,
      "y": 6,
      "z": 5,
      "name": "Rock_Basalt_Brick"
    },
    {
      "x": 0,
      "y": 7,
      "z": 5,
      "name": "Rock_Basalt_Brick_Half",
      "rotation": 6
    },
    {
      "x": 0,
      "y": 8,
      "z": 5,
      "name": "Rock_Basalt_Brick_Half",
      "rotation": 6
    },
    {
      "x": 0,
      "y": 9,
      "z": 5,
      "name": "Rock_Basalt_Brick"
    },
    {
      "x": 0,
      "y": 10,
      "z": 5,
      "name": "Rock_Basalt_Brick"
    },
    {
      "x": 0,
      "y": 11,
      "z": 5,
      "name": "Rock_Basalt_Brick"
    },
    {
      "x": 0,
      "y": 12,
      "z": 5,
      "name": "Rock_Basalt_Brick"
    },
    {
      "x": 0,
      "y": 13,
      "z": 5,
      "name": "Rock_Basalt_Brick"
    },
    {
      "x": 1,
      "y": -1,
      "z": -3,
      "name": "Rock_Ice"
    },
    {
      "x": 1,
      "y": 0,
      "z": -3,
      "name": "Rock_Basalt",
      "rotation": 3
    },
    {
      "x": 1,
      "y": 13,
      "z": -3,
      "name": "Rock_Basalt_Brick"
    },
    {
      "x": 1,
      "y": -1,
      "z": -2,
      "name": "Rock_Ice"
    },
    {
      "x": 1,
      "y": 0,
      "z": -2,
      "name": "Rock_Basalt",
      "rotation": 3
    },
    {
      "x": 1,
      "y": 1,
      "z": -2,
      "name": "Rubble_Basalt_Medium",
      "support": 15
    },
    {
      "x": 1,
      "y": 12,
      "z": -2,
      "name": "Rock_Basalt_Brick_Stairs",
      "rotation": 9
    },
    {
      "x": 1,
      "y": 13,
      "z": -2,
      "name": "Rock_Basalt_Brick"
    },
    {
      "x": 1,
      "y": -1,
      "z": -1,
      "name": "Rock_Ice"
    },
    {
      "x": 1,
      "y": 0,
      "z": -1,
      "name": "Rock_Basalt",
      "rotation": 3
    },
    {
      "x": 1,
      "y": 11,
      "z": -1,
      "name": "Rock_Ice_Stalactite_Large",
      "filler": 31744,
      "rotation": 8
    },
    {
      "x": 1,
      "y": 12,
      "z": -1,
      "name": "Rock_Ice_Stalactite_Large",
      "rotation": 8
    },
    {
      "x": 1,
      "y": 13,
      "z": -1,
      "name": "Rock_Basalt_Brick"
    },
    {
      "x": 1,
      "y": -1,
      "z": 0,
      "name": "Rock_Ice"
    },
    {
      "x": 1,
      "y": 0,
      "z": 0,
      "name": "Rock_Basalt",
      "rotation": 3
    },
    {
      "x": 1,
      "y": 1,
      "z": 0,
      "name": "Furniture_Human_Ruins_Torch",
      "rotation": 3
    },
    {
      "x": 1,
      "y": 6,
      "z": 0,
      "name": "Deco_Iron_Bars_Platforms"
    },
    {
      "x": 1,
      "y": 7,
      "z": 0,
      "name": "Deco_Bronze_Railing"
    },
    {
      "x": 1,
      "y": 13,
      "z": 0,
      "name": "Rock_Basalt_Brick"
    },
    {
      "x": 1,
      "y": -1,
      "z": 1,
      "name": "Rock_Ice"
    },
    {
      "x": 1,
      "y": 0,
      "z": 1,
      "name": "Rock_Basalt",
      "rotation": 3
    },
    {
      "x": 1,
      "y": 1,
      "z": 1,
      "name": "Block_Spawner_Block",
      "components": {
        "Components": {
          "PlacedByInteraction": {
            "WhoPlacedUuid": {
              "$binary": "B1yBGZcjQ2KREo5yyLGY0g==",
              "$type": "04"
            }
          },
          "BlockSpawner": {
            "BlockSpawnerId": "Zone3_Outlander_Tier2"
          }
        }
      },
      "rotation": 3
    },
    {
      "x": 1,
      "y": 6,
      "z": 1,
      "name": "Deco_Iron_Bars_Platforms"
    },
    {
      "x": 1,
      "y": 13,
      "z": 1,
      "name": "Rock_Basalt_Brick"
    },
    {
      "x": 1,
      "y": -1,
      "z": 2,
      "name": "Rock_Ice"
    },
    {
      "x": 1,
      "y": 0,
      "z": 2,
      "name": "Rock_Basalt",
      "rotation": 3
    },
    {
      "x": 1,
      "y": 1,
      "z": 2,
      "name": "Furniture_Ancient_Table",
      "filler": 992,
      "rotation": 2
    },
    {
      "x": 1,
      "y": 2,
      "z": 2,
      "name": "Deco_Book_Pile_Small",
      "rotation": 2
    },
    {
      "x": 1,
      "y": 6,
      "z": 2,
      "name": "Deco_Iron_Bars_Platforms"
    },
    {
      "x": 1,
      "y": 12,
      "z": 2,
      "name": "Bronze_Pipe_Large",
      "rotation": 5
    },
    {
      "x": 1,
      "y": 13,
      "z": 2,
      "name": "Rock_Basalt_Brick"
    },
    {
      "x": 1,
      "y": -1,
      "z": 3,
      "name": "Rock_Ice"
    },
    {
      "x": 1,
      "y": 0,
      "z": 3,
      "name": "Rock_Basalt",
      "rotation": 3
    },
    {
      "x": 1,
      "y": 1,
      "z": 3,
      "name": "Furniture_Ancient_Table",
      "rotation": 2
    },
    {
      "x": 1,
      "y": 2,
      "z": 3,
      "name": "Bronze_Pipe_Large",
      "rotation": 5
    },
    {
      "x": 1,
      "y": 6,
      "z": 3,
      "name": "Deco_Iron_Bars_Platforms"
    },
    {
      "x": 1,
      "y": 7,
      "z": 3,
      "name": "Deco_Bronze_Railing"
    },
    {
      "x": 1,
      "y": 13,
      "z": 3,
      "name": "Rock_Basalt_Brick"
    },
    {
      "x": 1,
      "y": -1,
      "z": 4,
      "name": "Rock_Ice"
    },
    {
      "x": 1,
      "y": 0,
      "z": 4,
      "name": "Rock_Basalt",
      "rotation": 3
    },
    {
      "x": 1,
      "y": 5,
      "z": 4,
      "name": "Wood_Deadwood_Planks_Half",
      "rotation": 6
    },
    {
      "x": 1,
      "y": 13,
      "z": 4,
      "name": "Rock_Basalt_Brick"
    },
    {
      "x": 1,
      "y": -1,
      "z": 5,
      "name": "Rock_Ice"
    },
    {
      "x": 1,
      "y": 0,
      "z": 5,
      "name": "Rock_Basalt_Brick"
    },
    {
      "x": 1,
      "y": 1,
      "z": 5,
      "name": "Rock_Basalt_Brick"
    },
    {
      "x": 1,
      "y": 2,
      "z": 5,
      "name": "Rock_Basalt_Brick"
    },
    {
      "x": 1,
      "y": 3,
      "z": 5,
      "name": "Rock_Basalt_Brick"
    },
    {
      "x": 1,
      "y": 4,
      "z": 5,
      "name": "Rock_Basalt_Brick"
    },
    {
      "x": 1,
      "y": 5,
      "z": 5,
      "name": "Rock_Basalt_Brick"
    },
    {
      "x": 1,
      "y": 6,
      "z": 5,
      "name": "Rock_Basalt_Brick"
    },
    {
      "x": 1,
      "y": 7,
      "z": 5,
      "name": "Rock_Basalt_Brick"
    },
    {
      "x": 1,
      "y": 8,
      "z": 5,
      "name": "Rock_Basalt_Brick_Half",
      "rotation": 6
    },
    {
      "x": 1,
      "y": 9,
      "z": 5,
      "name": "Rock_Basalt_Brick"
    },
    {
      "x": 1,
      "y": 10,
      "z": 5,
      "name": "Rock_Basalt_Brick"
    },
    {
      "x": 1,
      "y": 11,
      "z": 5,
      "name": "Rock_Basalt_Brick"
    },
    {
      "x": 1,
      "y": 12,
      "z": 5,
      "name": "Rock_Basalt_Brick"
    },
    {
      "x": 1,
      "y": 13,
      "z": 5,
      "name": "Rock_Basalt_Brick"
    },
    {
      "x": 2,
      "y": -1,
      "z": -3,
      "name": "Rock_Ice"
    },
    {
      "x": 2,
      "y": 0,
      "z": -3,
      "name": "Rock_Basalt_Brick",
      "rotation": 3
    },
    {
      "x": 2,
      "y": 1,
      "z": -3,
      "name": "Rubble_Basalt",
      "support": 15
    },
    {
      "x": 2,
      "y": 13,
      "z": -3,
      "name": "Rock_Basalt_Brick"
    },
    {
      "x": 2,
      "y": -1,
      "z": -2,
      "name": "Rock_Ice"
    },
    {
      "x": 2,
      "y": 0,
      "z": -2,
      "name": "Rock_Basalt_Brick",
      "rotation": 3
    },
    {
      "x": 2,
      "y": 1,
      "z": -2,
      "name": "Rock_Basalt_Brick_Pillar_Base",
      "rotation": 3
    },
    {
      "x": 2,
      "y": 2,
      "z": -2,
      "name": "Rock_Basalt_Brick_Pillar_Middle",
      "rotation": 3
    },
    {
      "x": 2,
      "y": 3,
      "z": -2,
      "name": "Rock_Basalt_Brick_Pillar_Middle",
      "rotation": 3
    },
    {
      "x": 2,
      "y": 4,
      "z": -2,
      "name": "Rock_Basalt_Brick_Pillar_Middle",
      "rotation": 3
    },
    {
      "x": 2,
      "y": 5,
      "z": -2,
      "name": "Rock_Basalt_Brick_Pillar_Middle",
      "rotation": 3
    },
    {
      "x": 2,
      "y": 6,
      "z": -2,
      "name": "Rock_Basalt_Brick_Pillar_Middle",
      "rotation": 3
    },
    {
      "x": 2,
      "y": 7,
      "z": -2,
      "name": "Rock_Basalt_Brick_Pillar_Middle",
      "rotation": 3
    },
    {
      "x": 2,
      "y": 8,
      "z": -2,
      "name": "Rock_Basalt_Brick_Pillar_Middle",
      "rotation": 3
    },
    {
      "x": 2,
      "y": 9,
      "z": -2,
      "name": "Rock_Basalt_Brick_Pillar_Middle",
      "rotation": 3
    },
    {
      "x": 2,
      "y": 10,
      "z": -2,
      "name": "Rock_Basalt_Brick_Pillar_Middle",
      "rotation": 3
    },
    {
      "x": 2,
      "y": 11,
      "z": -2,
      "name": "Rock_Basalt_Brick_Pillar_Base",
      "rotation": 11
    },
    {
      "x": 2,
      "y": 12,
      "z": -2,
      "name": "Rock_Basalt_Brick",
      "rotation": 3
    },
    {
      "x": 2,
      "y": 13,
      "z": -2,
      "name": "Rock_Basalt_Brick"
    },
    {
      "x": 2,
      "y": -1,
      "z": -1,
      "name": "Rock_Ice"
    },
    {
      "x": 2,
      "y": 0,
      "z": -1,
      "name": "Rock_Basalt_Brick",
      "rotation": 3
    },
    {
      "x": 2,
      "y": 1,
      "z": -1,
      "name": "Furniture_Basalt_Trough",
      "filler": 31,
      "rotation": 1
    },
    {
      "x": 2,
      "y": 13,
      "z": -1,
      "name": "Rock_Basalt_Brick"
    },
    {
      "x": 2,
      "y": -1,
      "z": 0,
      "name": "Rock_Ice"
    },
    {
      "x": 2,
      "y": 0,
      "z": 0,
      "name": "Rock_Basalt_Brick",
      "rotation": 3
    },
    {
      "x": 2,
      "y": 1,
      "z": 0,
      "name": "Furniture_Basalt_Trough",
      "filler": 63,
      "rotation": 1
    },
    {
      "x": 2,
      "y": 6,
      "z": 0,
      "name": "Deco_Iron_Bars_Platforms"
    },
    {
      "x": 2,
      "y": 7,
      "z": 0,
      "name": "Deco_Bronze_Railing"
    },
    {
      "x": 2,
      "y": 12,
      "z": 0,
      "name": "Rock_Ice_Icicles",
      "rotation": 8
    },
    {
      "x": 2,
      "y": 13,
      "z": 0,
      "name": "Rock_Basalt_Brick"
    },
    {
      "x": 2,
      "y": -1,
      "z": 1,
      "name": "Rock_Ice"
    },
    {
      "x": 2,
      "y": 0,
      "z": 1,
      "name": "Rock_Basalt_Brick",
      "rotation": 3
    },
    {
      "x": 2,
      "y": 1,
      "z": 1,
      "name": "Deco_Mystery_Machine_Large",
      "filler": 31
    },
    {
      "x": 2,
      "y": 2,
      "z": 1,
      "name": "Deco_Mystery_Machine_Large",
      "filler": 1055
    },
    {
      "x": 2,
      "y": 3,
      "z": 1,
      "name": "Deco_Mystery_Machine_Large",
      "filler": 2079
    },
    {
      "x": 2,
      "y": 4,
      "z": 1,
      "name": "Deco_Mystery_Machine_Large",
      "filler": 3103
    },
    {
      "x": 2,
      "y": 6,
      "z": 1,
      "name": "Deco_Iron_Bars_Platforms"
    },
    {
      "x": 2,
      "y": 13,
      "z": 1,
      "name": "Rock_Basalt_Brick"
    },
    {
      "x": 2,
      "y": -1,
      "z": 2,
      "name": "Rock_Ice"
    },
    {
      "x": 2,
      "y": 0,
      "z": 2,
      "name": "Rock_Basalt_Brick",
      "rotation": 3
    },
    {
      "x": 2,
      "y": 1,
      "z": 2,
      "name": "Deco_Mystery_Machine_Large",
      "filler": 63
    },
    {
      "x": 2,
      "y": 2,
      "z": 2,
      "name": "Deco_Mystery_Machine_Large",
      "filler": 1087
    },
    {
      "x": 2,
      "y": 3,
      "z": 2,
      "name": "Deco_Mystery_Machine_Large",
      "filler": 2111
    },
    {
      "x": 2,
      "y": 4,
      "z": 2,
      "name": "Deco_Mystery_Machine_Large",
      "filler": 3135
    },
    {
      "x": 2,
      "y": 6,
      "z": 2,
      "name": "Deco_Iron_Bars_Platforms"
    },
    {
      "x": 2,
      "y": 12,
      "z": 2,
      "name": "Bronze_Pipe_Large",
      "rotation": 5
    },
    {
      "x": 2,
      "y": 13,
      "z": 2,
      "name": "Rock_Basalt_Brick"
    },
    {
      "x": 2,
      "y": -1,
      "z": 3,
      "name": "Rock_Ice"
    },
    {
      "x": 2,
      "y": 0,
      "z": 3,
      "name": "Rock_Basalt_Brick",
      "rotation": 3
    },
    {
      "x": 2,
      "y": 1,
      "z": 3,
      "name": "Deco_Mystery_Machine_Large",
      "filler": 95
    },
    {
      "x": 2,
      "y": 2,
      "z": 3,
      "name": "Deco_Mystery_Machine_Large",
      "filler": 1119
    },
    {
      "x": 2,
      "y": 3,
      "z": 3,
      "name": "Deco_Mystery_Machine_Large",
      "filler": 2143
    },
    {
      "x": 2,
      "y": 4,
      "z": 3,
      "name": "Deco_Mystery_Machine_Large",
      "filler": 3167
    },
    {
      "x": 2,
      "y": 6,
      "z": 3,
      "name": "Deco_Iron_Bars_Platforms"
    },
    {
      "x": 2,
      "y": 7,
      "z": 3,
      "name": "Deco_Bronze_Railing"
    },
    {
      "x": 2,
      "y": 13,
      "z": 3,
      "name": "Rock_Basalt_Brick"
    },
    {
      "x": 2,
      "y": -1,
      "z": 4,
      "name": "Rock_Ice"
    },
    {
      "x": 2,
      "y": 0,
      "z": 4,
      "name": "Rock_Basalt_Brick",
      "rotation": 3
    },
    {
      "x": 2,
      "y": 1,
      "z": 4,
      "name": "Deco_Mystery_Machine_Large",
      "filler": 127
    },
    {
      "x": 2,
      "y": 2,
      "z": 4,
      "name": "Deco_Mystery_Machine_Large",
      "filler": 1151
    },
    {
      "x": 2,
      "y": 3,
      "z": 4,
      "name": "Deco_Mystery_Machine_Large",
      "filler": 2175
    },
    {
      "x": 2,
      "y": 4,
      "z": 4,
      "name": "Deco_Mystery_Machine_Large",
      "filler": 3199
    },
    {
      "x": 2,
      "y": 5,
      "z": 4,
      "name": "Wood_Deadwood_Planks_Half",
      "rotation": 6
    },
    {
      "x": 2,
      "y": 13,
      "z": 4,
      "name": "Rock_Basalt_Brick"
    },
    {
      "x": 2,
      "y": -1,
      "z": 5,
      "name": "Rock_Ice"
    },
    {
      "x": 2,
      "y": 0,
      "z": 5,
      "name": "Rock_Basalt_Brick"
    },
    {
      "x": 2,
      "y": 1,
      "z": 5,
      "name": "Rock_Basalt_Brick"
    },
    {
      "x": 2,
      "y": 2,
      "z": 5,
      "name": "Rock_Basalt_Brick"
    },
    {
      "x": 2,
      "y": 3,
      "z": 5,
      "name": "Rock_Basalt_Brick"
    },
    {
      "x": 2,
      "y": 4,
      "z": 5,
      "name": "Rock_Basalt_Brick"
    },
    {
      "x": 2,
      "y": 5,
      "z": 5,
      "name": "Rock_Basalt_Brick"
    },
    {
      "x": 2,
      "y": 6,
      "z": 5,
      "name": "Rock_Basalt_Brick"
    },
    {
      "x": 2,
      "y": 7,
      "z": 5,
      "name": "Rock_Basalt_Brick"
    },
    {
      "x": 2,
      "y": 8,
      "z": 5,
      "name": "Rock_Basalt_Brick_Half",
      "rotation": 6
    },
    {
      "x": 2,
      "y": 9,
      "z": 5,
      "name": "Rock_Basalt_Brick_Half",
      "rotation": 6
    },
    {
      "x": 2,
      "y": 10,
      "z": 5,
      "name": "Rock_Basalt_Brick"
    },
    {
      "x": 2,
      "y": 11,
      "z": 5,
      "name": "Rock_Basalt_Brick"
    },
    {
      "x": 2,
      "y": 12,
      "z": 5,
      "name": "Rock_Basalt_Brick"
    },
    {
      "x": 2,
      "y": 13,
      "z": 5,
      "name": "Rock_Basalt_Brick"
    },
    {
      "x": 3,
      "y": -1,
      "z": -3,
      "name": "Rock_Ice"
    },
    {
      "x": 3,
      "y": 0,
      "z": -3,
      "name": "Rock_Basalt",
      "rotation": 3
    },
    {
      "x": 3,
      "y": 13,
      "z": -3,
      "name": "Rock_Basalt_Brick"
    },
    {
      "x": 3,
      "y": -1,
      "z": -2,
      "name": "Rock_Ice"
    },
    {
      "x": 3,
      "y": 0,
      "z": -2,
      "name": "Rock_Basalt",
      "rotation": 3
    },
    {
      "x": 3,
      "y": 12,
      "z": -2,
      "name": "Rock_Basalt_Brick_Stairs",
      "rotation": 11
    },
    {
      "x": 3,
      "y": 13,
      "z": -2,
      "name": "Rock_Basalt_Brick"
    },
    {
      "x": 3,
      "y": -1,
      "z": -1,
      "name": "Rock_Ice"
    },
    {
      "x": 3,
      "y": 0,
      "z": -1,
      "name": "Rock_Basalt",
      "rotation": 3
    },
    {
      "x": 3,
      "y": 1,
      "z": -1,
      "name": "Furniture_Basalt_Trough",
      "rotation": 1
    },
    {
      "x": 3,
      "y": 13,
      "z": -1,
      "name": "Rock_Basalt_Brick"
    },
    {
      "x": 3,
      "y": -1,
      "z": 0,
      "name": "Rock_Ice"
    },
    {
      "x": 3,
      "y": 0,
      "z": 0,
      "name": "Rock_Basalt",
      "rotation": 3
    },
    {
      "x": 3,
      "y": 1,
      "z": 0,
      "name": "Furniture_Basalt_Trough",
      "filler": 32,
      "rotation": 1
    },
    {
      "x": 3,
      "y": 6,
      "z": 0,
      "name": "Deco_Iron_Bars_Platforms"
    },
    {
      "x": 3,
      "y": 7,
      "z": 0,
      "name": "Deco_Bronze_Railing"
    },
    {
      "x": 3,
      "y": 13,
      "z": 0,
      "name": "Rock_Basalt_Brick"
    },
    {
      "x": 3,
      "y": -1,
      "z": 1,
      "name": "Rock_Ice"
    },
    {
      "x": 3,
      "y": 0,
      "z": 1,
      "name": "Rock_Basalt",
      "rotation": 3
    },
    {
      "x": 3,
      "y": 1,
      "z": 1,
      "name": "Deco_Mystery_Machine_Large"
    },
    {
      "x": 3,
      "y": 2,
      "z": 1,
      "name": "Deco_Mystery_Machine_Large",
      "filler": 1024
    },
    {
      "x": 3,
      "y": 3,
      "z": 1,
      "name": "Deco_Mystery_Machine_Large",
      "filler": 2048
    },
    {
      "x": 3,
      "y": 4,
      "z": 1,
      "name": "Deco_Mystery_Machine_Large",
      "filler": 3072
    },
    {
      "x": 3,
      "y": 6,
      "z": 1,
      "name": "Deco_Iron_Bars_Platforms"
    },
    {
      "x": 3,
      "y": 13,
      "z": 1,
      "name": "Rock_Basalt_Brick"
    },
    {
      "x": 3,
      "y": -1,
      "z": 2,
      "name": "Rock_Ice"
    },
    {
      "x": 3,
      "y": 0,
      "z": 2,
      "name": "Rock_Basalt",
      "rotation": 3
    },
    {
      "x": 3,
      "y": 1,
      "z": 2,
      "name": "Deco_Mystery_Machine_Large",
      "filler": 32
    },
    {
      "x": 3,
      "y": 2,
      "z": 2,
      "name": "Deco_Mystery_Machine_Large",
      "filler": 1056
    },
    {
      "x": 3,
      "y": 3,
      "z": 2,
      "name": "Deco_Mystery_Machine_Large",
      "filler": 2080
    },
    {
      "x": 3,
      "y": 4,
      "z": 2,
      "name": "Deco_Mystery_Machine_Large",
      "filler": 3104
    },
    {
      "x": 3,
      "y": 6,
      "z": 2,
      "name": "Deco_Iron_Bars_Platforms"
    },
    {
      "x": 3,
      "y": 12,
      "z": 2,
      "name": "Bronze_Pipe_Large",
      "rotation": 5
    },
    {
      "x": 3,
      "y": 13,
      "z": 2,
      "name": "Rock_Basalt_Brick"
    },
    {
      "x": 3,
      "y": -1,
      "z": 3,
      "name": "Rock_Ice"
    },
    {
      "x": 3,
      "y": 0,
      "z": 3,
      "name": "Rock_Basalt",
      "rotation": 3
    },
    {
      "x": 3,
      "y": 1,
      "z": 3,
      "name": "Deco_Mystery_Machine_Large",
      "filler": 64
    },
    {
      "x": 3,
      "y": 2,
      "z": 3,
      "name": "Deco_Mystery_Machine_Large",
      "filler": 1088
    },
    {
      "x": 3,
      "y": 3,
      "z": 3,
      "name": "Deco_Mystery_Machine_Large",
      "filler": 2112
    },
    {
      "x": 3,
      "y": 4,
      "z": 3,
      "name": "Deco_Mystery_Machine_Large",
      "filler": 3136
    },
    {
      "x": 3,
      "y": 6,
      "z": 3,
      "name": "Deco_Iron_Bars_Platforms"
    },
    {
      "x": 3,
      "y": 7,
      "z": 3,
      "name": "Deco_Bronze_Railing"
    },
    {
      "x": 3,
      "y": 13,
      "z": 3,
      "name": "Rock_Basalt_Brick"
    },
    {
      "x": 3,
      "y": -1,
      "z": 4,
      "name": "Rock_Ice"
    },
    {
      "x": 3,
      "y": 0,
      "z": 4,
      "name": "Rock_Basalt",
      "rotation": 3
    },
    {
      "x": 3,
      "y": 1,
      "z": 4,
      "name": "Deco_Mystery_Machine_Large",
      "filler": 96
    },
    {
      "x": 3,
      "y": 2,
      "z": 4,
      "name": "Deco_Mystery_Machine_Large",
      "filler": 1120
    },
    {
      "x": 3,
      "y": 3,
      "z": 4,
      "name": "Deco_Mystery_Machine_Large",
      "filler": 2144
    },
    {
      "x": 3,
      "y": 4,
      "z": 4,
      "name": "Deco_Mystery_Machine_Large",
      "filler": 3168
    },
    {
      "x": 3,
      "y": 5,
      "z": 4,
      "name": "Wood_Deadwood_Planks_Half",
      "rotation": 6
    },
    {
      "x": 3,
      "y": 12,
      "z": 4,
      "name": "Rock_Ice_Icicles",
      "rotation": 8
    },
    {
      "x": 3,
      "y": 13,
      "z": 4,
      "name": "Rock_Basalt_Brick"
    },
    {
      "x": 3,
      "y": -1,
      "z": 5,
      "name": "Rock_Ice"
    },
    {
      "x": 3,
      "y": 0,
      "z": 5,
      "name": "Rock_Basalt_Brick"
    },
    {
      "x": 3,
      "y": 1,
      "z": 5,
      "name": "Rock_Basalt_Brick"
    },
    {
      "x": 3,
      "y": 2,
      "z": 5,
      "name": "Rock_Basalt_Brick"
    },
    {
      "x": 3,
      "y": 3,
      "z": 5,
      "name": "Rock_Basalt_Brick"
    },
    {
      "x": 3,
      "y": 4,
      "z": 5,
      "name": "Rock_Basalt_Brick"
    },
    {
      "x": 3,
      "y": 5,
      "z": 5,
      "name": "Rock_Basalt_Brick"
    },
    {
      "x": 3,
      "y": 6,
      "z": 5,
      "name": "Rock_Basalt_Brick"
    },
    {
      "x": 3,
      "y": 7,
      "z": 5,
      "name": "Rock_Basalt_Brick"
    },
    {
      "x": 3,
      "y": 8,
      "z": 5,
      "name": "Rock_Basalt_Brick_Half",
      "rotation": 6
    },
    {
      "x": 3,
      "y": 9,
      "z": 5,
      "name": "Rock_Basalt_Brick_Half",
      "rotation": 6
    },
    {
      "x": 3,
      "y": 10,
      "z": 5,
      "name": "Rock_Basalt_Brick_Half",
      "rotation": 6
    },
    {
      "x": 3,
      "y": 11,
      "z": 5,
      "name": "Rock_Basalt_Brick"
    },
    {
      "x": 3,
      "y": 12,
      "z": 5,
      "name": "Rock_Basalt_Brick"
    },
    {
      "x": 3,
      "y": 13,
      "z": 5,
      "name": "Rock_Basalt_Brick"
    },
    {
      "x": 4,
      "y": -1,
      "z": -3,
      "name": "Rock_Ice"
    },
    {
      "x": 4,
      "y": 0,
      "z": -3,
      "name": "Rock_Basalt",
      "rotation": 3
    },
    {
      "x": 4,
      "y": 13,
      "z": -3,
      "name": "Rock_Basalt_Brick"
    },
    {
      "x": 4,
      "y": -1,
      "z": -2,
      "name": "Rock_Ice"
    },
    {
      "x": 4,
      "y": 0,
      "z": -2,
      "name": "Rock_Basalt",
      "rotation": 3
    },
    {
      "x": 4,
      "y": 12,
      "z": -2,
      "name": "Rock_Basalt_Brick_Half",
      "rotation": 11
    },
    {
      "x": 4,
      "y": 13,
      "z": -2,
      "name": "Rock_Basalt_Brick"
    },
    {
      "x": 4,
      "y": -1,
      "z": -1,
      "name": "Rock_Ice"
    },
    {
      "x": 4,
      "y": 0,
      "z": -1,
      "name": "Rock_Basalt",
      "rotation": 3
    },
    {
      "x": 4,
      "y": 13,
      "z": -1,
      "name": "Rock_Basalt_Brick"
    },
    {
      "x": 4,
      "y": -1,
      "z": 0,
      "name": "Rock_Ice"
    },
    {
      "x": 4,
      "y": 0,
      "z": 0,
      "name": "Rock_Basalt",
      "rotation": 3
    },
    {
      "x": 4,
      "y": 6,
      "z": 0,
      "name": "Deco_Iron_Bars_Platforms"
    },
    {
      "x": 4,
      "y": 7,
      "z": 0,
      "name": "Deco_Bronze_Railing"
    },
    {
      "x": 4,
      "y": 8,
      "z": 0,
      "name": "Deco_Iron_Chain_Small"
    },
    {
      "x": 4,
      "y": 9,
      "z": 0,
      "name": "Deco_Iron_Chain_Small"
    },
    {
      "x": 4,
      "y": 10,
      "z": 0,
      "name": "Deco_Iron_Chain_Small"
    },
    {
      "x": 4,
      "y": 11,
      "z": 0,
      "name": "Deco_Iron_Chain_Small"
    },
    {
      "x": 4,
      "y": 12,
      "z": 0,
      "name": "Deco_Iron_Chain_Small"
    },
    {
      "x": 4,
      "y": 13,
      "z": 0,
      "name": "Rock_Basalt_Brick"
    },
    {
      "x": 4,
      "y": -1,
      "z": 1,
      "name": "Rock_Ice"
    },
    {
      "x": 4,
      "y": 0,
      "z": 1,
      "name": "Rock_Basalt",
      "rotation": 3
    },
    {
      "x": 4,
      "y": 1,
      "z": 1,
      "name": "Deco_Mystery_Machine_Large",
      "filler": 1
    },
    {
      "x": 4,
      "y": 2,
      "z": 1,
      "name": "Deco_Mystery_Machine_Large",
      "filler": 1025
    },
    {
      "x": 4,
      "y": 3,
      "z": 1,
      "name": "Deco_Mystery_Machine_Large",
      "filler": 2049
    },
    {
      "x": 4,
      "y": 4,
      "z": 1,
      "name": "Deco_Mystery_Machine_Large",
      "filler": 3073
    },
    {
      "x": 4,
      "y": 6,
      "z": 1,
      "name": "Deco_Iron_Bars_Platforms"
    },
    {
      "x": 4,
      "y": 13,
      "z": 1,
      "name": "Rock_Basalt_Brick"
    },
    {
      "x": 4,
      "y": -1,
      "z": 2,
      "name": "Rock_Ice"
    },
    {
      "x": 4,
      "y": 0,
      "z": 2,
      "name": "Rock_Basalt",
      "rotation": 3
    },
    {
      "x": 4,
      "y": 1,
      "z": 2,
      "name": "Deco_Mystery_Machine_Large",
      "filler": 33
    },
    {
      "x": 4,
      "y": 2,
      "z": 2,
      "name": "Deco_Mystery_Machine_Large",
      "filler": 1057
    },
    {
      "x": 4,
      "y": 3,
      "z": 2,
      "name": "Deco_Mystery_Machine_Large",
      "filler": 2081
    },
    {
      "x": 4,
      "y": 4,
      "z": 2,
      "name": "Deco_Mystery_Machine_Large",
      "filler": 3105
    },
    {
      "x": 4,
      "y": 6,
      "z": 2,
      "name": "Deco_Iron_Bars_Platforms"
    },
    {
      "x": 4,
      "y": 12,
      "z": 2,
      "name": "Bronze_Pipe_Large",
      "rotation": 5
    },
    {
      "x": 4,
      "y": 13,
      "z": 2,
      "name": "Rock_Basalt_Brick"
    },
    {
      "x": 4,
      "y": -1,
      "z": 3,
      "name": "Rock_Ice"
    },
    {
      "x": 4,
      "y": 0,
      "z": 3,
      "name": "Rock_Basalt",
      "rotation": 3
    },
    {
      "x": 4,
      "y": 1,
      "z": 3,
      "name": "Deco_Mystery_Machine_Large",
      "filler": 65
    },
    {
      "x": 4,
      "y": 2,
      "z": 3,
      "name": "Deco_Mystery_Machine_Large",
      "filler": 1089
    },
    {
      "x": 4,
      "y": 3,
      "z": 3,
      "name": "Deco_Mystery_Machine_Large",
      "filler": 2113
    },
    {
      "x": 4,
      "y": 4,
      "z": 3,
      "name": "Deco_Mystery_Machine_Large",
      "filler": 3137
    },
    {
      "x": 4,
      "y": 6,
      "z": 3,
      "name": "Deco_Iron_Bars_Platforms"
    },
    {
      "x": 4,
      "y": 7,
      "z": 3,
      "name": "Deco_Bronze_Railing"
    },
    {
      "x": 4,
      "y": 8,
      "z": 3,
      "name": "Deco_Iron_Chain_Small"
    },
    {
      "x": 4,
      "y": 9,
      "z": 3,
      "name": "Deco_Iron_Chain_Small"
    },
    {
      "x": 4,
      "y": 10,
      "z": 3,
      "name": "Deco_Iron_Chain_Small"
    },
    {
      "x": 4,
      "y": 11,
      "z": 3,
      "name": "Deco_Iron_Chain_Small"
    },
    {
      "x": 4,
      "y": 12,
      "z": 3,
      "name": "Deco_Iron_Chain_Small"
    },
    {
      "x": 4,
      "y": 13,
      "z": 3,
      "name": "Rock_Basalt_Brick"
    },
    {
      "x": 4,
      "y": -1,
      "z": 4,
      "name": "Rock_Ice"
    },
    {
      "x": 4,
      "y": 0,
      "z": 4,
      "name": "Rock_Basalt",
      "rotation": 3
    },
    {
      "x": 4,
      "y": 1,
      "z": 4,
      "name": "Deco_Mystery_Machine_Large",
      "filler": 97
    },
    {
      "x": 4,
      "y": 2,
      "z": 4,
      "name": "Deco_Mystery_Machine_Large",
      "filler": 1121
    },
    {
      "x": 4,
      "y": 3,
      "z": 4,
      "name": "Deco_Mystery_Machine_Large",
      "filler": 2145
    },
    {
      "x": 4,
      "y": 4,
      "z": 4,
      "name": "Deco_Mystery_Machine_Large",
      "filler": 3169
    },
    {
      "x": 4,
      "y": 5,
      "z": 4,
      "name": "Wood_Deadwood_Planks_Half",
      "rotation": 6
    },
    {
      "x": 4,
      "y": 13,
      "z": 4,
      "name": "Rock_Basalt_Brick"
    },
    {
      "x": 4,
      "y": -1,
      "z": 5,
      "name": "Rock_Ice"
    },
    {
      "x": 4,
      "y": 0,
      "z": 5,
      "name": "Rock_Basalt_Brick"
    },
    {
      "x": 4,
      "y": 1,
      "z": 5,
      "name": "Rock_Basalt_Brick"
    },
    {
      "x": 4,
      "y": 2,
      "z": 5,
      "name": "Rock_Basalt_Brick"
    },
    {
      "x": 4,
      "y": 3,
      "z": 5,
      "name": "Rock_Basalt_Brick"
    },
    {
      "x": 4,
      "y": 4,
      "z": 5,
      "name": "Rock_Basalt_Brick"
    },
    {
      "x": 4,
      "y": 5,
      "z": 5,
      "name": "Rock_Basalt_Brick"
    },
    {
      "x": 4,
      "y": 6,
      "z": 5,
      "name": "Rock_Basalt_Brick"
    },
    {
      "x": 4,
      "y": 7,
      "z": 5,
      "name": "Rock_Basalt_Brick"
    },
    {
      "x": 4,
      "y": 8,
      "z": 5,
      "name": "Rock_Basalt_Brick_Half",
      "rotation": 6
    },
    {
      "x": 4,
      "y": 9,
      "z": 5,
      "name": "Rock_Basalt_Brick"
    },
    {
      "x": 4,
      "y": 10,
      "z": 5,
      "name": "Rock_Basalt_Brick"
    },
    {
      "x": 4,
      "y": 11,
      "z": 5,
      "name": "Rock_Basalt_Brick"
    },
    {
      "x": 4,
      "y": 12,
      "z": 5,
      "name": "Rock_Basalt_Brick"
    },
    {
      "x": 4,
      "y": 13,
      "z": 5,
      "name": "Rock_Basalt_Brick"
    },
    {
      "x": 5,
      "y": -1,
      "z": -3,
      "name": "Rock_Ice"
    },
    {
      "x": 5,
      "y": 0,
      "z": -3,
      "name": "Rock_Basalt",
      "rotation": 3
    },
    {
      "x": 5,
      "y": 13,
      "z": -3,
      "name": "Rock_Basalt_Brick"
    },
    {
      "x": 5,
      "y": -1,
      "z": -2,
      "name": "Rock_Ice"
    },
    {
      "x": 5,
      "y": 0,
      "z": -2,
      "name": "Rock_Basalt",
      "rotation": 3
    },
    {
      "x": 5,
      "y": 1,
      "z": -2,
      "name": "Rubble_Basalt",
      "support": 15
    },
    {
      "x": 5,
      "y": 12,
      "z": -2,
      "name": "Rock_Basalt_Brick_Stairs",
      "rotation": 9
    },
    {
      "x": 5,
      "y": 13,
      "z": -2,
      "name": "Rock_Basalt_Brick"
    },
    {
      "x": 5,
      "y": -1,
      "z": -1,
      "name": "Rock_Ice"
    },
    {
      "x": 5,
      "y": 0,
      "z": -1,
      "name": "Rock_Basalt",
      "rotation": 3
    },
    {
      "x": 5,
      "y": 1,
      "z": -1,
      "name": "Furniture_Ancient_Barrel"
    },
    {
      "x": 5,
      "y": 13,
      "z": -1,
      "name": "Rock_Basalt_Brick"
    },
    {
      "x": 5,
      "y": -1,
      "z": 0,
      "name": "Rock_Ice"
    },
    {
      "x": 5,
      "y": 0,
      "z": 0,
      "name": "Rock_Basalt",
      "rotation": 3
    },
    {
      "x": 5,
      "y": 1,
      "z": 0,
      "name": "Furniture_Ancient_Barrel"
    },
    {
      "x": 5,
      "y": 6,
      "z": 0,
      "name": "Deco_Iron_Bars_Platforms"
    },
    {
      "x": 5,
      "y": 7,
      "z": 0,
      "name": "Deco_Bronze_Railing"
    },
    {
      "x": 5,
      "y": 13,
      "z": 0,
      "name": "Rock_Basalt_Brick"
    },
    {
      "x": 5,
      "y": -1,
      "z": 1,
      "name": "Rock_Ice"
    },
    {
      "x": 5,
      "y": 0,
      "z": 1,
      "name": "Rock_Basalt",
      "rotation": 3
    },
    {
      "x": 5,
      "y": 6,
      "z": 1,
      "name": "Deco_Iron_Bars_Platforms"
    },
    {
      "x": 5,
      "y": 13,
      "z": 1,
      "name": "Rock_Basalt_Brick"
    },
    {
      "x": 5,
      "y": -1,
      "z": 2,
      "name": "Rock_Ice"
    },
    {
      "x": 5,
      "y": 0,
      "z": 2,
      "name": "Rock_Basalt",
      "rotation": 3
    },
    {
      "x": 5,
      "y": 6,
      "z": 2,
      "name": "Deco_Iron_Bars_Platforms"
    },
    {
      "x": 5,
      "y": 12,
      "z": 2,
      "name": "Bronze_Pipe_Large",
      "rotation": 5
    },
    {
      "x": 5,
      "y": 13,
      "z": 2,
      "name": "Rock_Basalt_Brick"
    },
    {
      "x": 5,
      "y": -1,
      "z": 3,
      "name": "Rock_Ice"
    },
    {
      "x": 5,
      "y": 0,
      "z": 3,
      "name": "Rock_Basalt",
      "rotation": 3
    },
    {
      "x": 5,
      "y": 6,
      "z": 3,
      "name": "Deco_Iron_Bars_Platforms"
    },
    {
      "x": 5,
      "y": 7,
      "z": 3,
      "name": "Deco_Bronze_Railing"
    },
    {
      "x": 5,
      "y": 11,
      "z": 3,
      "name": "Rock_Ice_Stalactite_Large",
      "filler": 31744,
      "rotation": 8
    },
    {
      "x": 5,
      "y": 12,
      "z": 3,
      "name": "Rock_Ice_Stalactite_Large",
      "rotation": 8
    },
    {
      "x": 5,
      "y": 13,
      "z": 3,
      "name": "Rock_Basalt_Brick"
    },
    {
      "x": 5,
      "y": -1,
      "z": 4,
      "name": "Rock_Ice"
    },
    {
      "x": 5,
      "y": 0,
      "z": 4,
      "name": "Rock_Basalt",
      "rotation": 3
    },
    {
      "x": 5,
      "y": 1,
      "z": 4,
      "name": "Wood_Deadwood_Planks_Half",
      "rotation": 6
    },
    {
      "x": 5,
      "y": 2,
      "z": 4,
      "name": "Wood_Deadwood_Planks_Half",
      "rotation": 6
    },
    {
      "x": 5,
      "y": 3,
      "z": 4,
      "name": "Wood_Deadwood_Planks_Half",
      "rotation": 6
    },
    {
      "x": 5,
      "y": 4,
      "z": 4,
      "name": "Wood_Deadwood_Planks_Half",
      "rotation": 6
    },
    {
      "x": 5,
      "y": 5,
      "z": 4,
      "name": "Wood_Deadwood_Planks_Half",
      "rotation": 6
    },
    {
      "x": 5,
      "y": 6,
      "z": 4,
      "name": "Wood_Deadwood_Planks_Half",
      "rotation": 6
    },
    {
      "x": 5,
      "y": 13,
      "z": 4,
      "name": "Rock_Basalt_Brick"
    },
    {
      "x": 5,
      "y": -1,
      "z": 5,
      "name": "Rock_Ice"
    },
    {
      "x": 5,
      "y": 0,
      "z": 5,
      "name": "Rock_Basalt_Brick"
    },
    {
      "x": 5,
      "y": 1,
      "z": 5,
      "name": "Rock_Basalt_Brick"
    },
    {
      "x": 5,
      "y": 2,
      "z": 5,
      "name": "Rock_Basalt_Brick"
    },
    {
      "x": 5,
      "y": 3,
      "z": 5,
      "name": "Rock_Basalt_Brick"
    },
    {
      "x": 5,
      "y": 4,
      "z": 5,
      "name": "Rock_Basalt_Brick"
    },
    {
      "x": 5,
      "y": 5,
      "z": 5,
      "name": "Rock_Basalt_Brick"
    },
    {
      "x": 5,
      "y": 6,
      "z": 5,
      "name": "Rock_Basalt_Brick"
    },
    {
      "x": 5,
      "y": 7,
      "z": 5,
      "name": "Rock_Basalt_Brick"
    },
    {
      "x": 5,
      "y": 8,
      "z": 5,
      "name": "Rock_Basalt_Brick"
    },
    {
      "x": 5,
      "y": 9,
      "z": 5,
      "name": "Rock_Basalt_Brick"
    },
    {
      "x": 5,
      "y": 10,
      "z": 5,
      "name": "Rock_Basalt_Brick"
    },
    {
      "x": 5,
      "y": 11,
      "z": 5,
      "name": "Rock_Basalt_Brick"
    },
    {
      "x": 5,
      "y": 12,
      "z": 5,
      "name": "Rock_Basalt_Brick"
    },
    {
      "x": 5,
      "y": 13,
      "z": 5,
      "name": "Rock_Basalt_Brick"
    },
    {
      "x": 6,
      "y": -1,
      "z": -3,
      "name": "Rock_Ice"
    },
    {
      "x": 6,
      "y": 0,
      "z": -3,
      "name": "Rock_Basalt_Brick",
      "rotation": 3
    },
    {
      "x": 6,
      "y": 13,
      "z": -3,
      "name": "Rock_Basalt_Brick"
    },
    {
      "x": 6,
      "y": -1,
      "z": -2,
      "name": "Rock_Ice"
    },
    {
      "x": 6,
      "y": 0,
      "z": -2,
      "name": "Rock_Basalt_Brick",
      "rotation": 3
    },
    {
      "x": 6,
      "y": 1,
      "z": -2,
      "name": "Rock_Basalt_Brick_Pillar_Base",
      "rotation": 3
    },
    {
      "x": 6,
      "y": 2,
      "z": -2,
      "name": "Rock_Basalt_Brick_Pillar_Middle",
      "rotation": 3
    },
    {
      "x": 6,
      "y": 3,
      "z": -2,
      "name": "Rock_Basalt_Brick_Pillar_Middle",
      "rotation": 3
    },
    {
      "x": 6,
      "y": 4,
      "z": -2,
      "name": "Rock_Basalt_Brick_Pillar_Middle",
      "rotation": 3
    },
    {
      "x": 6,
      "y": 5,
      "z": -2,
      "name": "Rock_Basalt_Brick_Pillar_Middle",
      "rotation": 3
    },
    {
      "x": 6,
      "y": 6,
      "z": -2,
      "name": "Rock_Basalt_Brick_Pillar_Middle",
      "rotation": 3
    },
    {
      "x": 6,
      "y": 7,
      "z": -2,
      "name": "Rock_Basalt_Brick_Pillar_Middle",
      "rotation": 3
    },
    {
      "x": 6,
      "y": 8,
      "z": -2,
      "name": "Rock_Basalt_Brick_Pillar_Middle",
      "rotation": 3
    },
    {
      "x": 6,
      "y": 9,
      "z": -2,
      "name": "Rock_Basalt_Brick_Pillar_Middle",
      "rotation": 3
    },
    {
      "x": 6,
      "y": 10,
      "z": -2,
      "name": "Rock_Basalt_Brick_Pillar_Middle",
      "rotation": 3
    },
    {
      "x": 6,
      "y": 11,
      "z": -2,
      "name": "Rock_Basalt_Brick_Pillar_Base",
      "rotation": 11
    },
    {
      "x": 6,
      "y": 12,
      "z": -2,
      "name": "Rock_Basalt_Brick",
      "rotation": 3
    },
    {
      "x": 6,
      "y": 13,
      "z": -2,
      "name": "Rock_Basalt_Brick"
    },
    {
      "x": 6,
      "y": -1,
      "z": -1,
      "name": "Rock_Ice"
    },
    {
      "x": 6,
      "y": 0,
      "z": -1,
      "name": "Rock_Basalt_Brick",
      "rotation": 3
    },
    {
      "x": 6,
      "y": 1,
      "z": -1,
      "name": "Furniture_Ancient_Barrel"
    },
    {
      "x": 6,
      "y": 13,
      "z": -1,
      "name": "Rock_Basalt_Brick"
    },
    {
      "x": 6,
      "y": -1,
      "z": 0,
      "name": "Rock_Ice"
    },
    {
      "x": 6,
      "y": 0,
      "z": 0,
      "name": "Rock_Basalt_Brick",
      "rotation": 3
    },
    {
      "x": 6,
      "y": 1,
      "z": 0,
      "name": "Halloween_Wagon",
      "filler": 1023,
      "rotation": 2
    },
    {
      "x": 6,
      "y": 2,
      "z": 0,
      "name": "Rock_Basalt_Cobble_Half"
    },
    {
      "x": 6,
      "y": 6,
      "z": 0,
      "name": "Deco_Iron_Bars_Platforms"
    },
    {
      "x": 6,
      "y": 7,
      "z": 0,
      "name": "Deco_Bronze_Railing"
    },
    {
      "x": 6,
      "y": 13,
      "z": 0,
      "name": "Rock_Basalt_Brick"
    },
    {
      "x": 6,
      "y": -1,
      "z": 1,
      "name": "Rock_Ice"
    },
    {
      "x": 6,
      "y": 0,
      "z": 1,
      "name": "Rock_Basalt_Brick",
      "rotation": 3
    },
    {
      "x": 6,
      "y": 1,
      "z": 1,
      "name": "Halloween_Wagon",
      "filler": 31,
      "rotation": 2
    },
    {
      "x": 6,
      "y": 2,
      "z": 1,
      "name": "Rock_Basalt_Cobble_Half"
    },
    {
      "x": 6,
      "y": 6,
      "z": 1,
      "name": "Deco_Iron_Bars_Platforms"
    },
    {
      "x": 6,
      "y": 12,
      "z": 1,
      "name": "Rock_Ice_Icicles",
      "rotation": 8
    },
    {
      "x": 6,
      "y": 13,
      "z": 1,
      "name": "Rock_Basalt_Brick"
    },
    {
      "x": 6,
      "y": -1,
      "z": 2,
      "name": "Rock_Ice"
    },
    {
      "x": 6,
      "y": 0,
      "z": 2,
      "name": "Rock_Basalt_Brick",
      "rotation": 3
    },
    {
      "x": 6,
      "y": 6,
      "z": 2,
      "name": "Deco_Iron_Bars_Platforms"
    },
    {
      "x": 6,
      "y": 12,
      "z": 2,
      "name": "Bronze_Pipe_Large",
      "rotation": 5
    },
    {
      "x": 6,
      "y": 13,
      "z": 2,
      "name": "Rock_Basalt_Brick"
    },
    {
      "x": 6,
      "y": -1,
      "z": 3,
      "name": "Rock_Ice"
    },
    {
      "x": 6,
      "y": 0,
      "z": 3,
      "name": "Rock_Basalt_Brick",
      "rotation": 3
    },
    {
      "x": 6,
      "y": 1,
      "z": 3,
      "name": "Rubble_Basalt",
      "support": 15
    },
    {
      "x": 6,
      "y": 6,
      "z": 3,
      "name": "Deco_Iron_Bars_Platforms"
    },
    {
      "x": 6,
      "y": 7,
      "z": 3,
      "name": "Deco_Bronze_Railing"
    },
    {
      "x": 6,
      "y": 13,
      "z": 3,
      "name": "Rock_Basalt_Brick"
    },
    {
      "x": 6,
      "y": -1,
      "z": 4,
      "name": "Rock_Ice"
    },
    {
      "x": 6,
      "y": 0,
      "z": 4,
      "name": "Rock_Basalt_Brick",
      "rotation": 3
    },
    {
      "x": 6,
      "y": 1,
      "z": 4,
      "name": "Deco_Map"
    },
    {
      "x": 6,
      "y": 5,
      "z": 4,
      "name": "Wood_Deadwood_Planks_Half",
      "rotation": 6
    },
    {
      "x": 6,
      "y": 13,
      "z": 4,
      "name": "Rock_Basalt_Brick"
    },
    {
      "x": 6,
      "y": -1,
      "z": 5,
      "name": "Rock_Ice"
    },
    {
      "x": 6,
      "y": 0,
      "z": 5,
      "name": "Rock_Basalt_Brick"
    },
    {
      "x": 6,
      "y": 1,
      "z": 5,
      "name": "Rock_Basalt_Brick"
    },
    {
      "x": 6,
      "y": 2,
      "z": 5,
      "name": "Rock_Basalt_Brick"
    },
    {
      "x": 6,
      "y": 3,
      "z": 5,
      "name": "Rock_Basalt_Brick"
    },
    {
      "x": 6,
      "y": 4,
      "z": 5,
      "name": "Rock_Basalt_Brick"
    },
    {
      "x": 6,
      "y": 5,
      "z": 5,
      "name": "Rock_Basalt_Brick"
    },
    {
      "x": 6,
      "y": 6,
      "z": 5,
      "name": "Rock_Basalt_Brick"
    },
    {
      "x": 6,
      "y": 7,
      "z": 5,
      "name": "Rock_Basalt_Brick"
    },
    {
      "x": 6,
      "y": 8,
      "z": 5,
      "name": "Rock_Basalt_Brick"
    },
    {
      "x": 6,
      "y": 9,
      "z": 5,
      "name": "Rock_Basalt_Brick"
    },
    {
      "x": 6,
      "y": 10,
      "z": 5,
      "name": "Rock_Basalt_Brick"
    },
    {
      "x": 6,
      "y": 11,
      "z": 5,
      "name": "Rock_Basalt_Brick"
    },
    {
      "x": 6,
      "y": 12,
      "z": 5,
      "name": "Rock_Basalt_Brick"
    },
    {
      "x": 6,
      "y": 13,
      "z": 5,
      "name": "Rock_Basalt_Brick"
    },
    {
      "x": 7,
      "y": -1,
      "z": -3,
      "name": "Rock_Ice"
    },
    {
      "x": 7,
      "y": 0,
      "z": -3,
      "name": "Rock_Basalt",
      "rotation": 3
    },
    {
      "x": 7,
      "y": 13,
      "z": -3,
      "name": "Rock_Basalt_Brick"
    },
    {
      "x": 7,
      "y": -1,
      "z": -2,
      "name": "Rock_Ice"
    },
    {
      "x": 7,
      "y": 0,
      "z": -2,
      "name": "Rock_Basalt",
      "rotation": 3
    },
    {
      "x": 7,
      "y": 12,
      "z": -2,
      "name": "Rock_Basalt_Brick_Stairs",
      "rotation": 11
    },
    {
      "x": 7,
      "y": 13,
      "z": -2,
      "name": "Rock_Basalt_Brick"
    },
    {
      "x": 7,
      "y": -1,
      "z": -1,
      "name": "Rock_Ice"
    },
    {
      "x": 7,
      "y": 0,
      "z": -1,
      "name": "Rock_Basalt",
      "rotation": 3
    },
    {
      "x": 7,
      "y": 1,
      "z": -1,
      "name": "Rubble_Basalt",
      "support": 15
    },
    {
      "x": 7,
      "y": 12,
      "z": -1,
      "name": "Rock_Ice_Icicles",
      "rotation": 8
    },
    {
      "x": 7,
      "y": 13,
      "z": -1,
      "name": "Rock_Basalt_Brick"
    },
    {
      "x": 7,
      "y": -1,
      "z": 0,
      "name": "Rock_Ice"
    },
    {
      "x": 7,
      "y": 0,
      "z": 0,
      "name": "Rock_Basalt",
      "rotation": 3
    },
    {
      "x": 7,
      "y": 1,
      "z": 0,
      "name": "Halloween_Wagon",
      "filler": 992,
      "rotation": 2
    },
    {
      "x": 7,
      "y": 2,
      "z": 0,
      "name": "Rock_Basalt_Cobble_Half"
    },
    {
      "x": 7,
      "y": 6,
      "z": 0,
      "name": "Deco_Iron_Bars_Platforms"
    },
    {
      "x": 7,
      "y": 7,
      "z": 0,
      "name": "Deco_Bronze_Railing"
    },
    {
      "x": 7,
      "y": 13,
      "z": 0,
      "name": "Rock_Basalt_Brick"
    },
    {
      "x": 7,
      "y": -1,
      "z": 1,
      "name": "Rock_Ice"
    },
    {
      "x": 7,
      "y": 0,
      "z": 1,
      "name": "Rock_Basalt",
      "rotation": 3
    },
    {
      "x": 7,
      "y": 1,
      "z": 1,
      "name": "Halloween_Wagon",
      "rotation": 2
    },
    {
      "x": 7,
      "y": 2,
      "z": 1,
      "name": "Rock_Basalt_Cobble_Half"
    },
    {
      "x": 7,
      "y": 6,
      "z": 1,
      "name": "Deco_Iron_Bars_Platforms"
    },
    {
      "x": 7,
      "y": 13,
      "z": 1,
      "name": "Rock_Basalt_Brick"
    },
    {
      "x": 7,
      "y": -1,
      "z": 2,
      "name": "Rock_Ice"
    },
    {
      "x": 7,
      "y": 0,
      "z": 2,
      "name": "Rock_Basalt",
      "rotation": 3
    },
    {
      "x": 7,
      "y": 6,
      "z": 2,
      "name": "Deco_Iron_Bars_Platforms"
    },
    {
      "x": 7,
      "y": 12,
      "z": 2,
      "name": "Rock_Bronze_Smooth"
    },
    {
      "x": 7,
      "y": 13,
      "z": 2,
      "name": "Rock_Basalt_Brick"
    },
    {
      "x": 7,
      "y": -1,
      "z": 3,
      "name": "Rock_Ice"
    },
    {
      "x": 7,
      "y": 0,
      "z": 3,
      "name": "Rock_Basalt",
      "rotation": 3
    },
    {
      "x": 7,
      "y": 1,
      "z": 3,
      "name": "Rubble_Basalt_Medium",
      "support": 15
    },
    {
      "x": 7,
      "y": 6,
      "z": 3,
      "name": "Deco_Iron_Bars_Platforms"
    },
    {
      "x": 7,
      "y": 7,
      "z": 3,
      "name": "Deco_Bronze_Railing"
    },
    {
      "x": 7,
      "y": 12,
      "z": 3,
      "name": "Bronze_Pipe_Large",
      "rotation": 4
    },
    {
      "x": 7,
      "y": 13,
      "z": 3,
      "name": "Rock_Basalt_Brick"
    },
    {
      "x": 7,
      "y": -1,
      "z": 4,
      "name": "Rock_Ice"
    },
    {
      "x": 7,
      "y": 0,
      "z": 4,
      "name": "Rock_Basalt",
      "rotation": 3
    },
    {
      "x": 7,
      "y": 1,
      "z": 4,
      "name": "Furniture_Ancient_Crate",
      "rotation": 2
    },
    {
      "x": 7,
      "y": 2,
      "z": 4,
      "name": "Furniture_Ancient_Crate",
      "rotation": 2
    },
    {
      "x": 7,
      "y": 5,
      "z": 4,
      "name": "Wood_Deadwood_Planks_Half",
      "rotation": 6
    },
    {
      "x": 7,
      "y": 12,
      "z": 4,
      "name": "Bronze_Pipe_Large",
      "rotation": 4
    },
    {
      "x": 7,
      "y": 13,
      "z": 4,
      "name": "Rock_Basalt_Brick"
    },
    {
      "x": 7,
      "y": -1,
      "z": 5,
      "name": "Rock_Ice"
    },
    {
      "x": 7,
      "y": 0,
      "z": 5,
      "name": "Rock_Basalt_Brick"
    },
    {
      "x": 7,
      "y": 1,
      "z": 5,
      "name": "Rock_Basalt_Brick"
    },
    {
      "x": 7,
      "y": 2,
      "z": 5,
      "name": "Rock_Basalt_Brick"
    },
    {
      "x": 7,
      "y": 3,
      "z": 5,
      "name": "Rock_Basalt_Brick"
    },
    {
      "x": 7,
      "y": 4,
      "z": 5,
      "name": "Rock_Basalt_Brick"
    },
    {
      "x": 7,
      "y": 5,
      "z": 5,
      "name": "Rock_Basalt_Brick"
    },
    {
      "x": 7,
      "y": 6,
      "z": 5,
      "name": "Rock_Basalt_Brick"
    },
    {
      "x": 7,
      "y": 7,
      "z": 5,
      "name": "Rock_Basalt_Brick"
    },
    {
      "x": 7,
      "y": 8,
      "z": 5,
      "name": "Rock_Basalt_Brick"
    },
    {
      "x": 7,
      "y": 9,
      "z": 5,
      "name": "Rock_Basalt_Brick"
    },
    {
      "x": 7,
      "y": 10,
      "z": 5,
      "name": "Rock_Basalt_Brick"
    },
    {
      "x": 7,
      "y": 11,
      "z": 5,
      "name": "Rock_Basalt_Brick"
    },
    {
      "x": 7,
      "y": 12,
      "z": 5,
      "name": "Rock_Basalt_Brick"
    },
    {
      "x": 7,
      "y": 13,
      "z": 5,
      "name": "Rock_Basalt_Brick"
    },
    {
      "x": 8,
      "y": -1,
      "z": -3,
      "name": "Rock_Ice"
    },
    {
      "x": 8,
      "y": 0,
      "z": -3,
