{
  "version": 8,
  "blockIdVersion": 11,
  "anchorX": 8,
  "anchorY": 1,
  "anchorZ": -3,
  "blocks": [
    {
      "x": -7,
      "y": -1,
      "z": -3,
      "name": "Rock_Ice"
    },
    {
      "x": -7,
      "y": 0,
      "z": -3,
      "name": "Rock_Basalt",
      "rotation": 3
    },
    {
      "x": -7,
      "y": 13,
      "z": -3,
      "name": "Rock_Basalt_Brick"
    },
    {
      "x": -7,
      "y": -1,
      "z": -2,
      "name": "Rock_Ice"
    },
    {
      "x": -7,
      "y": 0,
      "z": -2,
      "name": "Rock_Basalt",
      "rotation": 3
    },
    {
      "x": -7,
      "y": 12,
      "z": -2,
      "name": "Rock_Basalt_Brick_Stairs",
      "rotation": 9
    },
    {
      "x": -7,
      "y": 13,
      "z": -2,
      "name": "Rock_Basalt_Brick"
    },
    {
      "x": -7,
      "y": -1,
      "z": -1,
      "name": "Rock_Ice"
    },
    {
      "x": -7,
      "y": 0,
      "z": -1,
      "name": "Rock_Basalt",
      "rotation": 3
    },
    {
      "x": -7,
      "y": 13,
      "z": -1,
      "name": "Rock_Basalt_Brick"
    },
    {
      "x": -7,
      "y": -1,
      "z": 0,
      "name": "Rock_Ice"
    },
    {
      "x": -7,
      "y": 0,
      "z": 0,
      "name": "Rock_Basalt",
      "rotation": 3
    },
    {
      "x": -7,
      "y": 6,
      "z": 0,
      "name": "Deco_Iron_Bars_Platforms"
    },
    {
      "x": -7,
      "y": 7,
      "z": 0,
      "name": "Deco_Bronze_Railing"
    },
    {
      "x": -7,
      "y": 13,
      "z": 0,
      "name": "Rock_Basalt_Brick"
    },
    {
      "x": -7,
      "y": -1,
      "z": 1,
      "name": "Rock_Ice"
    },
    {
      "x": -7,
      "y": 0,
      "z": 1,
      "name": "Rock_Basalt",
      "rotation": 3
    },
    {
      "x": -7,
      "y": 1,
      "z": 1,
      "name": "Rubble_Basalt",
      "support": 15
    },
    {
      "x": -7,
      "y": 6,
      "z": 1,
      "name": "Deco_Iron_Bars_Platforms"
    },
    {
      "x": -7,
      "y": 13,
      "z": 1,
      "name": "Rock_Basalt_Brick"
    },
    {
      "x": -7,
      "y": -1,
      "z": 2,
      "name": "Rock_Ice"
    },
    {
      "x": -7,
      "y": 0,
      "z": 2,
      "name": "Rock_Basalt",
      "rotation": 3
    },
    {
      "x": -7,
      "y": 1,
      "z": 2,
      "name": "Furniture_Ancient_Barrel"
    },
    {
      "x": -7,
      "y": 6,
      "z": 2,
      "name": "Deco_Iron_Bars_Platforms"
    },
    {
      "x": -7,
      "y": 13,
      "z": 2,
      "name": "Rock_Basalt_Brick"
    },
    {
      "x": -7,
      "y": -1,
      "z": 3,
      "name": "Rock_Ice"
    },
    {
      "x": -7,
      "y": 0,
      "z": 3,
      "name": "Rock_Basalt",
      "rotation": 3
    },
    {
      "x": -7,
      "y": 1,
      "z": 3,
      "name": "Furniture_Ancient_Crate",
      "rotation": 2
    },
    {
      "x": -7,
      "y": 6,
      "z": 3,
      "name": "Deco_Iron_Bars_Platforms"
    },
    {
      "x": -7,
      "y": 7,
      "z": 3,
      "name": "Deco_Bronze_Railing"
    },
    {
      "x": -7,
      "y": 13,
      "z": 3,
      "name": "Rock_Basalt_Brick"
    },
    {
      "x": -7,
      "y": -1,
      "z": 4,
      "name": "Rock_Ice"
    },
    {
      "x": -7,
      "y": 0,
      "z": 4,
      "name": "Rock_Basalt",
      "rotation": 3
    },
    {
      "x": -7,
      "y": 1,
      "z": 4,
      "name": "Furniture_Ancient_Crate",
      "rotation": 2
    },
    {
      "x": -7,
      "y": 13,
      "z": 4,
      "name": "Rock_Basalt_Brick"
    },
    {
      "x": -7,
      "y": -1,
      "z": 5,
      "name": "Rock_Ice"
    },
    {
      "x": -7,
      "y": 0,
      "z": 5,
      "name": "Rock_Basalt_Brick"
    },
    {
      "x": -7,
      "y": 1,
      "z": 5,
      "name": "Rock_Basalt_Brick"
    },
    {
      "x": -7,
      "y": 2,
      "z": 5,
      "name": "Rock_Basalt_Brick"
    },
    {
      "x": -7,
      "y": 3,
      "z": 5,
      "name": "Rock_Basalt_Brick"
    },
    {
      "x": -7,
      "y": 4,
      "z": 5,
      "name": "Rock_Basalt_Brick"
    },
    {
      "x": -7,
      "y": 5,
      "z": 5,
      "name": "Rock_Basalt_Brick"
    },
    {
      "x": -7,
      "y": 6,
      "z": 5,
      "name": "Rock_Basalt_Brick"
    },
    {
      "x": -7,
      "y": 7,
      "z": 5,
      "name": "Rock_Basalt_Brick"
    },
    {
      "x": -7,
      "y": 8,
      "z": 5,
      "name": "Rock_Basalt_Brick"
    },
    {
      "x": -7,
      "y": 9,
      "z": 5,
      "name": "Rock_Basalt_Brick"
    },
    {
      "x": -7,
      "y": 10,
      "z": 5,
      "name": "Rock_Basalt_Brick"
    },
    {
      "x": -7,
      "y": 11,
      "z": 5,
      "name": "Rock_Basalt_Brick"
    },
    {
      "x": -7,
      "y": 12,
      "z": 5,
      "name": "Rock_Basalt_Brick"
    },
    {
      "x": -7,
      "y": 13,
      "z": 5,
      "name": "Rock_Basalt_Brick"
    },
    {
      "x": -6,
      "y": -1,
      "z": -3,
      "name": "Rock_Ice"
    },
    {
      "x": -6,
      "y": 0,
      "z": -3,
      "name": "Rock_Basalt_Brick",
      "rotation": 3
    },
    {
      "x": -6,
      "y": 13,
      "z": -3,
      "name": "Rock_Basalt_Brick"
    },
    {
      "x": -6,
      "y": -1,
      "z": -2,
      "name": "Rock_Ice"
    },
    {
      "x": -6,
      "y": 0,
      "z": -2,
      "name": "Rock_Basalt_Brick",
      "rotation": 3
    },
    {
      "x": -6,
      "y": 1,
      "z": -2,
      "name": "Rock_Basalt_Brick_Pillar_Base",
      "rotation": 3
    },
    {
      "x": -6,
      "y": 2,
      "z": -2,
      "name": "Rock_Basalt_Brick_Pillar_Middle",
      "rotation": 3
    },
    {
      "x": -6,
      "y": 3,
      "z": -2,
      "name": "Rock_Basalt_Brick_Pillar_Middle",
      "rotation": 3
    },
    {
      "x": -6,
      "y": 4,
      "z": -2,
      "name": "Rock_Basalt_Brick_Pillar_Middle",
      "rotation": 3
    },
    {
      "x": -6,
      "y": 5,
      "z": -2,
      "name": "Rock_Basalt_Brick_Pillar_Middle",
      "rotation": 3
    },
    {
      "x": -6,
      "y": 6,
      "z": -2,
      "name": "Rock_Basalt_Brick_Pillar_Middle",
      "rotation": 3
    },
    {
      "x": -6,
      "y": 7,
      "z": -2,
      "name": "Rock_Basalt_Brick_Pillar_Middle",
      "rotation": 3
    },
    {
      "x": -6,
      "y": 8,
      "z": -2,
      "name": "Rock_Basalt_Brick_Pillar_Middle",
      "rotation": 3
    },
    {
      "x": -6,
      "y": 9,
      "z": -2,
      "name": "Rock_Basalt_Brick_Pillar_Middle",
      "rotation": 3
    },
    {
      "x": -6,
      "y": 10,
      "z": -2,
      "name": "Rock_Basalt_Brick_Pillar_Middle",
      "rotation": 3
    },
    {
      "x": -6,
      "y": 11,
      "z": -2,
      "name": "Rock_Basalt_Brick_Pillar_Base",
      "rotation": 11
    },
    {
      "x": -6,
      "y": 12,
      "z": -2,
      "name": "Rock_Basalt_Brick",
      "rotation": 3
    },
    {
      "x": -6,
      "y": 13,
      "z": -2,
      "name": "Rock_Basalt_Brick"
    },
    {
      "x": -6,
      "y": -1,
      "z": -1,
      "name": "Rock_Ice"
    },
    {
      "x": -6,
      "y": 0,
      "z": -1,
      "name": "Rock_Basalt_Brick",
      "rotation": 3
    },
    {
      "x": -6,
      "y": 13,
      "z": -1,
      "name": "Rock_Basalt_Brick"
    },
    {
      "x": -6,
      "y": -1,
      "z": 0,
      "name": "Rock_Ice"
    },
    {
      "x": -6,
      "y": 0,
      "z": 0,
      "name": "Rock_Basalt_Brick",
      "rotation": 3
    },
    {
      "x": -6,
      "y": 6,
      "z": 0,
      "name": "Deco_Iron_Bars_Platforms"
    },
    {
      "x": -6,
      "y": 7,
      "z": 0,
      "name": "Deco_Bronze_Railing"
    },
    {
      "x": -6,
      "y": 13,
      "z": 0,
      "name": "Rock_Basalt_Brick"
    },
    {
      "x": -6,
      "y": -1,
      "z": 1,
      "name": "Rock_Ice"
    },
    {
      "x": -6,
      "y": 0,
      "z": 1,
      "name": "Rock_Basalt_Brick",
      "rotation": 3
    },
    {
      "x": -6,
      "y": 6,
      "z": 1,
      "name": "Deco_Iron_Bars_Platforms"
    },
    {
      "x": -6,
      "y": 13,
      "z": 1,
      "name": "Rock_Basalt_Brick"
    },
    {
      "x": -6,
      "y": -1,
      "z": 2,
      "name": "Rock_Ice"
    },
    {
      "x": -6,
      "y": 0,
      "z": 2,
      "name": "Rock_Basalt_Brick",
      "rotation": 3
    },
    {
      "x": -6,
      "y": 1,
      "z": 2,
      "name": "Rubble_Basalt_Medium",
      "support": 15
    },
    {
      "x": -6,
      "y": 6,
      "z": 2,
      "name": "Deco_Iron_Bars_Platforms"
    },
    {
      "x": -6,
      "y": 13,
      "z": 2,
      "name": "Rock_Basalt_Brick"
    },
    {
      "x": -6,
      "y": -1,
      "z": 3,
      "name": "Rock_Ice"
    },
    {
      "x": -6,
      "y": 0,
      "z": 3,
      "name": "Rock_Basalt_Brick"
    },
    {
      "x": -6,
      "y": 1,
      "z": 3,
      "name": "Furniture_Ancient_Crate",
      "rotation": 2
    },
    {
      "x": -6,
      "y": 6,
      "z": 3,
      "name": "Deco_Iron_Bars_Platforms"
    },
    {
      "x": -6,
      "y": 7,
      "z": 3,
      "name": "Deco_Bronze_Railing"
    },
    {
      "x": -6,
      "y": 11,
      "z": 3,
      "name": "Rock_Ice_Stalactite_Large",
      "filler": 31744,
      "rotation": 8
    },
    {
      "x": -6,
      "y": 12,
      "z": 3,
      "name": "Rock_Ice_Stalactite_Large",
      "rotation": 8
    },
    {
      "x": -6,
      "y": 13,
      "z": 3,
      "name": "Rock_Basalt_Brick"
    },
    {
      "x": -6,
      "y": -1,
      "z": 4,
      "name": "Rock_Ice"
    },
    {
      "x": -6,
      "y": 0,
      "z": 4,
      "name": "Rock_Basalt_Brick",
      "rotation": 3
    },
    {
      "x": -6,
      "y": 1,
      "z": 4,
      "name": "Furniture_Ancient_Crate",
      "rotation": 2
    },
    {
      "x": -6,
      "y": 2,
      "z": 4,
      "name": "Furniture_Ancient_Crate",
      "rotation": 2
    },
    {
      "x": -6,
      "y": 3,
      "z": 4,
      "name": "Deco_SpiderWeb",
      "support": 15,
      "rotation": 2
    },
    {
      "x": -6,
      "y": 13,
      "z": 4,
      "name": "Rock_Basalt_Brick"
    },
    {
      "x": -6,
      "y": -1,
      "z": 5,
      "name": "Rock_Ice"
    },
    {
      "x": -6,
      "y": 0,
      "z": 5,
      "name": "Rock_Basalt_Brick"
    },
    {
      "x": -6,
      "y": 1,
      "z": 5,
      "name": "Rock_Basalt_Brick"
    },
    {
      "x": -6,
      "y": 2,
      "z": 5,
      "name": "Rock_Basalt_Brick"
    },
    {
      "x": -6,
      "y": 3,
      "z": 5,
      "name": "Rock_Basalt_Brick"
    },
    {
      "x": -6,
      "y": 4,
      "z": 5,
      "name": "Rock_Basalt_Brick"
    },
    {
      "x": -6,
      "y": 5,
      "z": 5,
      "name": "Rock_Basalt_Brick"
    },
    {
      "x": -6,
      "y": 6,
      "z": 5,
      "name": "Rock_Basalt_Brick"
    },
    {
      "x": -6,
      "y": 7,
      "z": 5,
      "name": "Rock_Basalt_Brick"
    },
    {
      "x": -6,
      "y": 8,
      "z": 5,
      "name": "Rock_Basalt_Brick"
    },
    {
      "x": -6,
      "y": 9,
      "z": 5,
      "name": "Rock_Basalt_Brick"
    },
    {
      "x": -6,
      "y": 10,
      "z": 5,
      "name": "Rock_Basalt_Brick"
    },
    {
      "x": -6,
      "y": 11,
      "z": 5,
      "name": "Rock_Basalt_Brick"
    },
    {
      "x": -6,
      "y": 12,
      "z": 5,
      "name": "Rock_Basalt_Brick"
    },
    {
      "x": -6,
      "y": 13,
      "z": 5,
      "name": "Rock_Basalt_Brick"
    },
    {
      "x": -5,
      "y": -1,
      "z": -3,
      "name": "Rock_Ice"
    },
    {
      "x": -5,
      "y": 0,
      "z": -3,
      "name": "Rock_Basalt",
      "rotation": 3
    },
    {
      "x": -5,
      "y": 13,
      "z": -3,
      "name": "Rock_Basalt_Brick"
    },
    {
      "x": -5,
      "y": -1,
      "z": -2,
      "name": "Rock_Ice"
    },
    {
      "x": -5,
      "y": 0,
      "z": -2,
      "name": "Rock_Basalt",
      "rotation": 3
    },
    {
      "x": -5,
      "y": 1,
      "z": -2,
      "name": "Rubble_Basalt",
      "support": 15
    },
    {
      "x": -5,
      "y": 12,
      "z": -2,
      "name": "Rock_Basalt_Brick_Stairs",
      "rotation": 11
    },
    {
      "x": -5,
      "y": 13,
      "z": -2,
      "name": "Rock_Basalt_Brick"
    },
    {
      "x": -5,
      "y": -1,
      "z": -1,
      "name": "Rock_Ice"
    },
    {
      "x": -5,
      "y": 0,
      "z": -1,
      "name": "Rock_Basalt",
      "rotation": 3
    },
    {
      "x": -5,
      "y": 13,
      "z": -1,
      "name": "Rock_Basalt_Brick"
    },
    {
      "x": -5,
      "y": -1,
      "z": 0,
      "name": "Rock_Ice"
    },
    {
      "x": -5,
      "y": 0,
      "z": 0,
      "name": "Rock_Basalt",
      "rotation": 3
    },
    {
      "x": -5,
      "y": 6,
      "z": 0,
      "name": "Deco_Iron_Bars_Platforms"
    },
    {
      "x": -5,
      "y": 7,
      "z": 0,
      "name": "Deco_Bronze_Railing"
    },
    {
      "x": -5,
      "y": 13,
      "z": 0,
      "name": "Rock_Basalt_Brick"
    },
    {
      "x": -5,
      "y": -1,
      "z": 1,
      "name": "Rock_Ice"
    },
    {
      "x": -5,
      "y": 0,
      "z": 1,
      "name": "Rock_Basalt",
      "rotation": 3
    },
    {
      "x": -5,
      "y": 6,
      "z": 1,
      "name": "Deco_Iron_Bars_Platforms"
    },
    {
      "x": -5,
      "y": 13,
      "z": 1,
      "name": "Rock_Basalt_Brick"
    },
    {
      "x": -5,
      "y": -1,
      "z": 2,
      "name": "Rock_Ice"
    },
    {
      "x": -5,
      "y": 0,
      "z": 2,
      "name": "Rock_Basalt",
      "rotation": 3
    },
    {
      "x": -5,
      "y": 1,
      "z": 2,
      "name": "Furniture_Ancient_Barrel"
    },
    {
      "x": -5,
      "y": 6,
      "z": 2,
      "name": "Deco_Iron_Bars_Platforms"
    },
    {
      "x": -5,
      "y": 13,
      "z": 2,
      "name": "Rock_Basalt_Brick"
    },
    {
      "x": -5,
      "y": -1,
      "z": 3,
      "name": "Rock_Ice"
    },
    {
      "x": -5,
      "y": 0,
      "z": 3,
      "name": "Rock_Basalt",
      "rotation": 3
    },
    {
      "x": -5,
      "y": 1,
      "z": 3,
      "name": "Rubble_Basalt",
      "support": 15
    },
    {
      "x": -5,
      "y": 6,
      "z": 3,
      "name": "Deco_Iron_Bars_Platforms"
    },
    {
      "x": -5,
      "y": 7,
      "z": 3,
      "name": "Deco_Bronze_Railing"
    },
    {
      "x": -5,
      "y": 13,
      "z": 3,
      "name": "Rock_Basalt_Brick"
    },
    {
      "x": -5,
      "y": -1,
      "z": 4,
      "name": "Rock_Ice"
    },
    {
      "x": -5,
      "y": 0,
      "z": 4,
      "name": "Rock_Basalt",
      "rotation": 3
    },
    {
      "x": -5,
      "y": 1,
      "z": 4,
      "name": "Furniture_Ancient_Crate",
      "rotation": 2
    },
    {
      "x": -5,
      "y": 2,
      "z": 4,
      "name": "Furniture_Ancient_Crate",
      "rotation": 2
    },
    {
      "x": -5,
      "y": 13,
      "z": 4,
      "name": "Rock_Basalt_Brick"
    },
    {
      "x": -5,
      "y": -1,
      "z": 5,
      "name": "Rock_Ice"
    },
    {
      "x": -5,
      "y": 0,
      "z": 5,
      "name": "Rock_Basalt_Brick"
    },
    {
      "x": -5,
      "y": 1,
      "z": 5,
      "name": "Rock_Basalt_Brick"
    },
    {
      "x": -5,
      "y": 2,
      "z": 5,
      "name": "Rock_Basalt_Brick"
    },
    {
      "x": -5,
      "y": 3,
      "z": 5,
      "name": "Rock_Basalt_Brick"
    },
    {
      "x": -5,
      "y": 4,
      "z": 5,
      "name": "Rock_Basalt_Brick"
    },
    {
      "x": -5,
      "y": 5,
      "z": 5,
      "name": "Rock_Basalt_Brick"
    },
    {
      "x": -5,
      "y": 6,
      "z": 5,
      "name": "Rock_Basalt_Brick"
    },
    {
      "x": -5,
      "y": 7,
      "z": 5,
      "name": "Rock_Basalt_Brick"
    },
    {
      "x": -5,
      "y": 8,
      "z": 5,
      "name": "Rock_Basalt_Brick"
    },
    {
      "x": -5,
      "y": 9,
      "z": 5,
      "name": "Rock_Basalt_Brick"
    },
    {
      "x": -5,
      "y": 10,
      "z": 5,
      "name": "Rock_Basalt_Brick"
    },
    {
      "x": -5,
      "y": 11,
      "z": 5,
      "name": "Rock_Basalt_Brick"
    },
    {
      "x": -5,
      "y": 12,
      "z": 5,
      "name": "Rock_Basalt_Brick"
    },
    {
      "x": -5,
      "y": 13,
      "z": 5,
      "name": "Rock_Basalt_Brick"
    },
    {
      "x": -4,
      "y": -1,
      "z": -3,
      "name": "Rock_Ice"
    },
    {
      "x": -4,
      "y": 0,
      "z": -3,
      "name": "Rock_Basalt",
      "rotation": 3
    },
    {
      "x": -4,
      "y": 13,
      "z": -3,
      "name": "Rock_Basalt_Brick"
    },
    {
      "x": -4,
      "y": -1,
      "z": -2,
      "name": "Rock_Ice"
    },
    {
      "x": -4,
      "y": 0,
      "z": -2,
      "name": "Rock_Basalt",
      "rotation": 3
    },
    {
      "x": -4,
      "y": 12,
      "z": -2,
      "name": "Rock_Basalt_Brick_Half",
      "rotation": 11
    },
    {
      "x": -4,
      "y": 13,
      "z": -2,
      "name": "Rock_Basalt_Brick"
    },
    {
      "x": -4,
      "y": -1,
      "z": -1,
      "name": "Rock_Ice"
    },
    {
      "x": -4,
      "y": 0,
      "z": -1,
      "name": "Rock_Basalt",
      "rotation": 3
    },
    {
      "x": -4,
      "y": 13,
      "z": -1,
      "name": "Rock_Basalt_Brick"
    },
    {
      "x": -4,
      "y": -1,
      "z": 0,
      "name": "Rock_Ice"
    },
    {
      "x": -4,
      "y": 0,
      "z": 0,
      "name": "Rock_Basalt",
      "rotation": 3
    },
    {
      "x": -4,
      "y": 6,
      "z": 0,
      "name": "Deco_Iron_Bars_Platforms"
    },
    {
      "x": -4,
      "y": 7,
      "z": 0,
      "name": "Deco_Bronze_Railing"
    },
    {
      "x": -4,
      "y": 8,
      "z": 0,
      "name": "Deco_Iron_Chain_Small"
    },
    {
      "x": -4,
      "y": 9,
      "z": 0,
      "name": "Deco_Iron_Chain_Small"
    },
    {
      "x": -4,
      "y": 10,
      "z": 0,
      "name": "Deco_Iron_Chain_Small"
    },
    {
      "x": -4,
      "y": 11,
      "z": 0,
      "name": "Deco_Iron_Chain_Small"
    },
    {
      "x": -4,
      "y": 12,
      "z": 0,
      "name": "Deco_Iron_Chain_Small"
    },
    {
      "x": -4,
      "y": 13,
      "z": 0,
      "name": "Rock_Basalt_Brick"
    },
    {
      "x": -4,
      "y": -1,
      "z": 1,
      "name": "Rock_Ice"
    },
    {
      "x": -4,
      "y": 0,
      "z": 1,
      "name": "Rock_Basalt",
      "rotation": 3
    },
    {
      "x": -4,
      "y": 6,
      "z": 1,
      "name": "Deco_Iron_Bars_Platforms"
    },
    {
      "x": -4,
      "y": 13,
      "z": 1,
      "name": "Rock_Basalt_Brick"
    },
    {
      "x": -4,
      "y": -1,
      "z": 2,
      "name": "Rock_Ice"
    },
    {
      "x": -4,
      "y": 0,
      "z": 2,
      "name": "Rock_Basalt",
      "rotation": 3
    },
    {
      "x": -4,
      "y": 6,
      "z": 2,
      "name": "Deco_Iron_Bars_Platforms"
    },
    {
      "x": -4,
      "y": 13,
      "z": 2,
      "name": "Rock_Basalt_Brick"
    },
    {
      "x": -4,
      "y": -1,
      "z": 3,
      "name": "Rock_Ice"
    },
    {
      "x": -4,
      "y": 0,
      "z": 3,
      "name": "Rock_Basalt",
      "rotation": 3
    },
    {
      "x": -4,
      "y": 6,
      "z": 3,
      "name": "Deco_Iron_Bars_Platforms"
    },
    {
      "x": -4,
      "y": 7,
      "z": 3,
      "name": "Deco_Bronze_Railing"
    },
    {
      "x": -4,
      "y": 8,
      "z": 3,
      "name": "Deco_Iron_Chain_Small"
    },
    {
      "x": -4,
      "y": 9,
      "z": 3,
      "name": "Deco_Iron_Chain_Small"
    },
    {
      "x": -4,
      "y": 10,
      "z": 3,
      "name": "Deco_Iron_Chain_Small"
    },
    {
      "x": -4,
      "y": 11,
      "z": 3,
      "name": "Deco_Iron_Chain_Small"
    },
    {
      "x": -4,
      "y": 12,
      "z": 3,
      "name": "Deco_Iron_Chain_Small"
    },
    {
      "x": -4,
      "y": 13,
      "z": 3,
      "name": "Rock_Basalt_Brick"
    },
    {
      "x": -4,
      "y": -1,
      "z": 4,
      "name": "Rock_Ice"
    },
    {
      "x": -4,
      "y": 0,
      "z": 4,
      "name": "Rock_Basalt",
      "rotation": 3
    },
    {
      "x": -4,
      "y": 1,
      "z": 4,
      "name": "Furniture_Ancient_Barrel"
    },
    {
      "x": -4,
      "y": 13,
      "z": 4,
      "name": "Rock_Basalt_Brick"
    },
    {
      "x": -4,
      "y": -1,
      "z": 5,
      "name": "Rock_Ice"
    },
    {
      "x": -4,
      "y": 0,
      "z": 5,
      "name": "Rock_Basalt_Brick"
    },
    {
      "x": -4,
      "y": 1,
      "z": 5,
      "name": "Rock_Basalt_Brick"
    },
    {
      "x": -4,
      "y": 2,
      "z": 5,
      "name": "Rock_Basalt_Brick"
    },
    {
      "x": -4,
      "y": 3,
      "z": 5,
      "name": "Rock_Basalt_Brick"
    },
    {
      "x": -4,
      "y": 4,
      "z": 5,
      "name": "Rock_Basalt_Brick"
    },
    {
      "x": -4,
      "y": 5,
      "z": 5,
      "name": "Rock_Basalt_Brick"
    },
    {
      "x": -4,
      "y": 6,
      "z": 5,
      "name": "Rock_Basalt_Brick"
    },
    {
      "x": -4,
      "y": 7,
      "z": 5,
      "name": "Rock_Basalt_Brick"
    },
    {
      "x": -4,
      "y": 8,
      "z": 5,
      "name": "Rock_Basalt_Brick"
    },
    {
      "x": -4,
      "y": 9,
      "z": 5,
      "name": "Rock_Basalt_Brick"
    },
    {
      "x": -4,
      "y": 10,
      "z": 5,
      "name": "Rock_Basalt_Brick"
    },
    {
      "x": -4,
      "y": 11,
      "z": 5,
      "name": "Rock_Basalt_Brick"
    },
    {
      "x": -4,
      "y": 12,
      "z": 5,
      "name": "Rock_Basalt_Brick"
    },
    {
      "x": -4,
      "y": 13,
      "z": 5,
      "name": "Rock_Basalt_Brick"
    },
    {
      "x": -3,
      "y": -1,
      "z": -3,
      "name": "Rock_Ice"
    },
    {
      "x": -3,
      "y": 0,
      "z": -3,
      "name": "Rock_Basalt",
      "rotation": 3
    },
    {
      "x": -3,
      "y": 13,
      "z": -3,
      "name": "Rock_Basalt_Brick"
    },
    {
      "x": -3,
      "y": -1,
      "z": -2,
      "name": "Rock_Ice"
    },
    {
      "x": -3,
      "y": 0,
      "z": -2,
      "name": "Rock_Basalt",
      "rotation": 3
    },
    {
      "x": -3,
      "y": 12,
      "z": -2,
      "name": "Rock_Basalt_Brick_Stairs",
      "rotation": 9
    },
    {
      "x": -3,
      "y": 13,
      "z": -2,
      "name": "Rock_Basalt_Brick"
    },
    {
      "x": -3,
      "y": -1,
      "z": -1,
      "name": "Rock_Ice"
    },
    {
      "x": -3,
      "y": 0,
      "z": -1,
      "name": "Rock_Basalt",
      "rotation": 3
    },
    {
      "x": -3,
      "y": 13,
      "z": -1,
      "name": "Rock_Basalt_Brick"
    },
    {
      "x": -3,
      "y": -1,
      "z": 0,
      "name": "Rock_Ice"
    },
    {
      "x": -3,
      "y": 0,
      "z": 0,
      "name": "Rock_Basalt",
      "rotation": 3
    },
    {
      "x": -3,
      "y": 1,
      "z": 0,
      "name": "Furniture_Human_Ruins_Torch",
      "rotation": 2
    },
    {
      "x": -3,
      "y": 6,
      "z": 0,
      "name": "Deco_Iron_Bars_Platforms"
    },
    {
      "x": -3,
      "y": 7,
      "z": 0,
      "name": "Deco_Bronze_Railing"
    },
    {
      "x": -3,
      "y": 12,
      "z": 0,
      "name": "Rock_Ice_Icicles",
      "rotation": 8
    },
    {
      "x": -3,
      "y": 13,
      "z": 0,
      "name": "Rock_Basalt_Brick"
    },
    {
      "x": -3,
      "y": -1,
      "z": 1,
      "name": "Rock_Ice"
    },
    {
      "x": -3,
      "y": 0,
      "z": 1,
      "name": "Rock_Basalt",
      "rotation": 3
    },
    {
      "x": -3,
      "y": 4,
      "z": 1,
      "name": "Wood_Deadwood_Planks_Half",
      "rotation": 7
    },
    {
      "x": -3,
      "y": 6,
      "z": 1,
      "name": "Deco_Iron_Bars_Platforms"
    },
    {
      "x": -3,
      "y": 13,
      "z": 1,
      "name": "Rock_Basalt_Brick"
    },
    {
      "x": -3,
      "y": -1,
      "z": 2,
      "name": "Rock_Ice"
    },
    {
      "x": -3,
      "y": 0,
      "z": 2,
      "name": "Rock_Basalt",
      "rotation": 3
    },
    {
      "x": -3,
      "y": 4,
      "z": 2,
      "name": "Wood_Deadwood_Planks_Half",
      "rotation": 7
    },
    {
      "x": -3,
      "y": 6,
      "z": 2,
      "name": "Deco_Iron_Bars_Platforms"
    },
    {
      "x": -3,
      "y": 13,
      "z": 2,
      "name": "Rock_Basalt_Brick"
    },
    {
      "x": -3,
      "y": -1,
      "z": 3,
      "name": "Rock_Ice"
    },
    {
      "x": -3,
      "y": 0,
      "z": 3,
      "name": "Rock_Basalt",
      "rotation": 3
    },
    {
      "x": -3,
      "y": 4,
      "z": 3,
      "name": "Wood_Deadwood_Planks_Half",
      "rotation": 7
    },
    {
      "x": -3,
      "y": 6,
      "z": 3,
      "name": "Deco_Iron_Bars_Platforms"
    },
    {
      "x": -3,
      "y": 7,
      "z": 3,
      "name": "Deco_Bronze_Railing"
    },
    {
      "x": -3,
      "y": 12,
      "z": 3,
      "name": "Rock_Ice_Icicles",
      "rotation": 8
    },
    {
      "x": -3,
      "y": 13,
      "z": 3,
      "name": "Rock_Basalt_Brick"
    },
    {
      "x": -3,
      "y": -1,
      "z": 4,
      "name": "Rock_Ice"
    },
    {
      "x": -3,
      "y": 0,
      "z": 4,
      "name": "Rock_Basalt",
      "rotation": 3
    },
    {
      "x": -3,
      "y": 1,
      "z": 4,
      "name": "Rubble_Basalt",
      "support": 15
    },
    {
      "x": -3,
      "y": 4,
      "z": 4,
      "name": "Wood_Deadwood_Planks_Half",
      "rotation": 7
    },
    {
      "x": -3,
      "y": 13,
      "z": 4,
      "name": "Rock_Basalt_Brick"
    },
    {
      "x": -3,
      "y": -1,
      "z": 5,
      "name": "Rock_Ice"
    },
    {
      "x": -3,
      "y": 0,
      "z": 5,
      "name": "Rock_Basalt_Brick"
    },
    {
      "x": -3,
      "y": 1,
      "z": 5,
      "name": "Rock_Basalt_Brick"
    },
    {
      "x": -3,
      "y": 2,
      "z": 5,
      "name": "Rock_Basalt_Brick"
    },
    {
      "x": -3,
      "y": 3,
      "z": 5,
      "name": "Rock_Basalt_Brick"
    },
    {
      "x": -3,
      "y": 4,
      "z": 5,
      "name": "Rock_Basalt_Brick"
    },
    {
      "x": -3,
      "y": 5,
      "z": 5,
      "name": "Rock_Basalt_Brick"
    },
    {
      "x": -3,
      "y": 6,
      "z": 5,
      "name": "Rock_Basalt_Brick"
    },
    {
      "x": -3,
      "y": 7,
      "z": 5,
      "name": "Rock_Basalt_Brick"
    },
    {
      "x": -3,
      "y": 8,
      "z": 5,
      "name": "Rock_Basalt_Brick"
    },
    {
      "x": -3,
      "y": 9,
      "z": 5,
      "name": "Rock_Basalt_Brick"
    },
    {
      "x": -3,
      "y": 10,
      "z": 5,
      "name": "Rock_Basalt_Brick"
    },
    {
      "x": -3,
      "y": 11,
      "z": 5,
      "name": "Rock_Basalt_Brick"
    },
    {
      "x": -3,
      "y": 12,
      "z": 5,
      "name": "Rock_Basalt_Brick"
    },
    {
      "x": -3,
      "y": 13,
      "z": 5,
      "name": "Rock_Basalt_Brick"
    },
    {
      "x": -2,
      "y": -1,
      "z": -3,
      "name": "Rock_Ice"
    },
    {
      "x": -2,
      "y": 0,
      "z": -3,
      "name": "Rock_Basalt_Brick",
      "rotation": 3
    },
    {
      "x": -2,
      "y": 12,
      "z": -3,
      "name": "Rock_Basalt_Brick_Stairs",
      "rotation": 8
    },
    {
      "x": -2,
      "y": 13,
      "z": -3,
      "name": "Rock_Basalt_Brick"
    },
    {
      "x": -2,
      "y": -1,
      "z": -2,
      "name": "Rock_Ice"
    },
    {
      "x": -2,
      "y": 0,
      "z": -2,
      "name": "Rock_Basalt_Brick",
      "rotation": 3
    },
    {
      "x": -2,
      "y": 1,
      "z": -2,
      "name": "Rock_Basalt_Brick_Pillar_Base",
      "rotation": 3
    },
    {
      "x": -2,
      "y": 2,
      "z": -2,
      "name": "Rock_Basalt_Brick_Pillar_Middle",
      "rotation": 3
    },
    {
      "x": -2,
      "y": 3,
      "z": -2,
      "name": "Rock_Basalt_Brick_Pillar_Middle",
      "rotation": 3
    },
    {
      "x": -2,
      "y": 4,
      "z": -2,
      "name": "Rock_Basalt_Brick_Pillar_Middle",
      "rotation": 3
    },
    {
      "x": -2,
      "y": 5,
      "z": -2,
      "name": "Rock_Basalt_Brick_Pillar_Middle",
      "rotation": 3
    },
    {
      "x": -2,
      "y": 6,
      "z": -2,
      "name": "Rock_Basalt_Brick_Pillar_Middle",
      "rotation": 3
    },
    {
      "x": -2,
      "y": 7,
      "z": -2,
      "name": "Rock_Basalt_Brick_Pillar_Middle",
      "rotation": 3
    },
    {
      "x": -2,
      "y": 8,
      "z": -2,
      "name": "Rock_Basalt_Brick_Pillar_Middle",
      "rotation": 3
    },
    {
      "x": -2,
      "y": 9,
      "z": -2,
      "name": "Rock_Basalt_Brick_Pillar_Middle",
      "rotation": 3
    },
    {
      "x": -2,
      "y": 10,
      "z": -2,
      "name": "Rock_Basalt_Brick_Pillar_Middle",
      "rotation": 3
    },
    {
      "x": -2,
      "y": 11,
      "z": -2,
      "name": "Rock_Basalt_Brick_Pillar_Base",
      "rotation": 11
    },
    {
      "x": -2,
      "y": 12,
      "z": -2,
      "name": "Rock_Basalt_Brick",
      "rotation": 3
    },
    {
      "x": -2,
      "y": 13,
      "z": -2,
      "name": "Rock_Basalt_Brick"
    },
    {
      "x": -2,
      "y": -1,
      "z": -1,
      "name": "Rock_Ice"
    },
    {
      "x": -2,
      "y": 0,
      "z": -1,
      "name": "Rock_Basalt_Brick",
      "rotation": 3
    },
    {
      "x": -2,
      "y": 1,
      "z": -1,
      "name": "Rubble_Basalt",
      "support": 15
    },
    {
      "x": -2,
      "y": 13,
      "z": -1,
      "name": "Rock_Basalt_Brick"
    },
    {
      "x": -2,
      "y": -1,
      "z": 0,
      "name": "Rock_Ice"
    },
    {
      "x": -2,
      "y": 0,
      "z": 0,
      "name": "Rock_Basalt_Brick",
      "rotation": 3
    },
    {
      "x": -2,
      "y": 1,
      "z": 0,
      "name": "Rock_Basalt_Brick"
    },
    {
      "x": -2,
      "y": 2,
      "z": 0,
      "name": "Rock_Basalt_Brick"
    },
    {
      "x": -2,
      "y": 3,
      "z": 0,
      "name": "Rock_Basalt_Brick"
    },
    {
      "x": -2,
      "y": 4,
      "z": 0,
      "name": "Rock_Basalt_Brick"
    },
    {
      "x": -2,
      "y": 5,
      "z": 0,
      "name": "Rock_Basalt_Brick_Half"
    },
    {
      "x": -2,
      "y": 6,
      "z": 0,
      "name": "Deco_Iron_Bars_Platforms"
    },
    {
      "x": -2,
      "y": 7,
      "z": 0,
      "name": "Deco_Bronze_Railing"
    },
    {
      "x": -2,
      "y": 13,
      "z": 0,
      "name": "Rock_Basalt_Brick"
    },
    {
      "x": -2,
      "y": -1,
      "z": 1,
      "name": "Rock_Ice"
    },
    {
      "x": -2,
      "y": 0,
      "z": 1,
      "name": "Rock_Basalt_Brick",
      "rotation": 3
    },
    {
      "x": -2,
      "y": 1,
      "z": 1,
      "name": "*Furniture_Frostbitten_Factory_Vault_Medium_State_Definitions_CloseDoorOut",
      "rotation": 3
    },
    {
      "x": -2,
      "y": 2,
      "z": 1,
      "name": "*Furniture_Frostbitten_Factory_Vault_Medium_State_Definitions_CloseDoorOut",
      "filler": 1024,
      "rotation": 3
    },
    {
      "x": -2,
      "y": 3,
      "z": 1,
      "name": "*Furniture_Frostbitten_Factory_Vault_Medium_State_Definitions_CloseDoorOut",
      "filler": 2048,
      "rotation": 3
    },
    {
      "x": -2,
      "y": 4,
      "z": 1,
      "name": "Rock_Basalt_Brick"
    },
    {
      "x": -2,
      "y": 5,
      "z": 1,
      "name": "Rock_Basalt_Brick_Half"
    },
    {
      "x": -2,
      "y": 6,
      "z": 1,
      "name": "Deco_Iron_Bars_Platforms"
    },
    {
      "x": -2,
      "y": 13,
      "z": 1,
      "name": "Rock_Basalt_Brick"
    },
    {
      "x": -2,
      "y": -1,
      "z": 2,
      "name": "Rock_Ice"
    },
    {
      "x": -2,
      "y": 0,
      "z": 2,
      "name": "Rock_Basalt_Brick",
      "rotation": 3
    },
    {
      "x": -2,
      "y": 1,
      "z": 2,
      "name": "*Furniture_Frostbitten_Factory_Vault_Medium_State_Definitions_CloseDoorOut",
      "filler": 32,
      "rotation": 3
    },
    {
      "x": -2,
      "y": 2,
      "z": 2,
      "name": "*Furniture_Frostbitten_Factory_Vault_Medium_State_Definitions_CloseDoorOut",
      "filler": 1056,
      "rotation": 3
    },
    {
      "x": -2,
      "y": 3,
      "z": 2,
      "name": "*Furniture_Frostbitten_Factory_Vault_Medium_State_Definitions_CloseDoorOut",
      "filler": 2080,
      "rotation": 3
    },
    {
      "x": -2,
      "y": 4,
      "z": 2,
      "name": "Rock_Basalt_Brick"
    },
    {
      "x": -2,
      "y": 5,
      "z": 2,
      "name": "Rock_Basalt_Brick_Half"
    },
    {
      "x": -2,
      "y": 6,
      "z": 2,
      "name": "Deco_Iron_Bars_Platforms"
    },
    {
      "x": -2,
      "y": 11,
      "z": 2,
      "name": "Rock_Ice_Stalactite_Large",
      "filler": 31744,
      "rotation": 8
    },
    {
      "x": -2,
      "y": 12,
      "z": 2,
      "name": "Rock_Ice_Stalactite_Large",
      "rotation": 8
    },
    {
      "x": -2,
      "y": 13,
      "z": 2,
      "name": "Rock_Basalt_Brick"
    },
    {
      "x": -2,
      "y": -1,
      "z": 3,
      "name": "Rock_Ice"
    },
    {
      "x": -2,
      "y": 0,
      "z": 3,
      "name": "Rock_Basalt_Brick",
      "rotation": 3
    },
    {
      "x": -2,
      "y": 1,
      "z": 3,
      "name": "*Furniture_Frostbitten_Factory_Vault_Medium_State_Definitions_CloseDoorOut",
      "filler": 64,
      "rotation": 3
    },
    {
      "x": -2,
      "y": 2,
      "z": 3,
      "name": "*Furniture_Frostbitten_Factory_Vault_Medium_State_Definitions_CloseDoorOut",
      "filler": 1088,
      "rotation": 3
    },
    {
      "x": -2,
      "y": 3,
      "z": 3,
      "name": "*Furniture_Frostbitten_Factory_Vault_Medium_State_Definitions_CloseDoorOut",
      "filler": 2112,
      "rotation": 3
    },
    {
      "x": -2,
      "y": 4,
      "z": 3,
      "name": "Rock_Basalt_Brick"
    },
    {
      "x": -2,
      "y": 5,
      "z": 3,
      "name": "Rock_Basalt_Brick_Half"
    },
    {
      "x": -2,
      "y": 6,
      "z": 3,
      "name": "Deco_Iron_Bars_Platforms"
    },
    {
      "x": -2,
      "y": 7,
      "z": 3,
      "name": "Deco_Bronze_Railing"
    },
    {
      "x": -2,
      "y": 13,
      "z": 3,
      "name": "Rock_Basalt_Brick"
    },
    {
      "x": -2,
      "y": -1,
      "z": 4,
      "name": "Rock_Ice"
    },
    {
      "x": -2,
      "y": 0,
      "z": 4,
      "name": "Rock_Basalt_Brick",
      "rotation": 3
    },
    {
      "x": -2,
      "y": 1,
      "z": 4,
      "name": "Rock_Basalt_Brick"
    },
    {
      "x": -2,
      "y": 2,
      "z": 4,
      "name": "Rock_Basalt_Brick"
    },
    {
      "x": -2,
      "y": 3,
      "z": 4,
      "name": "Rock_Basalt_Brick"
    },
    {
      "x": -2,
      "y": 4,
      "z": 4,
      "name": "Rock_Basalt_Brick"
    },
    {
      "x": -2,
      "y": 5,
      "z": 4,
      "name": "Rock_Basalt_Brick_Half"
    },
    {
      "x": -2,
      "y": 13,
      "z": 4,
      "name": "Rock_Basalt_Brick"
    },
    {
      "x": -2,
      "y": -1,
      "z": 5,
      "name": "Rock_Ice"
    },
    {
      "x": -2,
      "y": 0,
      "z": 5,
      "name": "Rock_Basalt_Brick"
    },
    {
      "x": -2,
      "y": 1,
      "z": 5,
      "name": "Rock_Basalt_Brick"
    },
    {
      "x": -2,
      "y": 2,
      "z": 5,
      "name": "Rock_Basalt_Brick"
    },
    {
      "x": -2,
      "y": 3,
      "z": 5,
      "name": "Rock_Basalt_Brick"
    },
    {
      "x": -2,
      "y": 4,
      "z": 5,
      "name": "Rock_Basalt_Brick"
    },
    {
      "x": -2,
      "y": 5,
      "z": 5,
      "name": "Rock_Basalt_Brick"
    },
    {
      "x": -2,
      "y": 6,
      "z": 5,
      "name": "Rock_Basalt_Brick"
    },
    {
      "x": -2,
      "y": 7,
      "z": 5,
      "name": "Rock_Basalt_Brick"
    },
    {
      "x": -2,
      "y": 8,
      "z": 5,
      "name": "Rock_Basalt_Brick"
    },
    {
      "x": -2,
      "y": 9,
      "z": 5,
      "name": "Rock_Basalt_Brick"
    },
    {
      "x": -2,
      "y": 10,
      "z": 5,
      "name": "Rock_Basalt_Brick"
    },
    {
      "x": -2,
      "y": 11,
      "z": 5,
      "name": "Rock_Basalt_Brick"
    },
    {
      "x": -2,
      "y": 12,
      "z": 5,
      "name": "Rock_Basalt_Brick"
    },
    {
      "x": -2,
      "y": 13,
      "z": 5,
      "name": "Rock_Basalt_Brick"
    },
    {
      "x": -1,
      "y": -1,
      "z": -3,
      "name": "Rock_Ice"
    },
    {
      "x": -1,
      "y": 0,
      "z": -3,
      "name": "Rock_Basalt",
      "rotation": 3
    },
    {
      "x": -1,
      "y": 13,
      "z": -3,
      "name": "Rock_Basalt_Brick"
    },
    {
      "x": -1,
      "y": -1,
      "z": -2,
      "name": "Rock_Ice"
    },
    {
      "x": -1,
      "y": 0,
      "z": -2,
      "name": "Rock_Basalt",
      "rotation": 3
    },
    {
      "x": -1,
      "y": 12,
      "z": -2,
      "name": "Rock_Basalt_Brick_Stairs",
      "rotation": 11
    },
    {
      "x": -1,
      "y": 13,
      "z": -2,
      "name": "Rock_Basalt_Brick"
    },
    {
      "x": -1,
      "y": -1,
      "z": -1,
      "name": "Rock_Ice"
    },
    {
      "x": -1,
      "y": 0,
      "z": -1,
      "name": "Rock_Basalt",
      "rotation": 3
    },
    {
      "x": -1,
      "y": 1,
      "z": -1,
      "name": "Furniture_Ancient_Barrel"
    },
    {
      "x": -1,
      "y": 11,
      "z": -1,
      "name": "Rock_Ice_Stalactite_Large",
      "filler": 31744,
      "rotation": 8
    },
    {
      "x": -1,
      "y": 12,
      "z": -1,
      "name": "Rock_Ice_Stalactite_Large",
      "rotation": 8
    },
    {
      "x": -1,
      "y": 13,
      "z": -1,
      "name": "Rock_Basalt_Brick"
    },
    {
      "x": -1,
      "y": -1,
      "z": 0,
      "name": "Rock_Ice"
    },
    {
      "x": -1,
      "y": 0,
      "z": 0,
      "name": "Rock_Basalt",
      "rotation": 3
    },
    {
      "x": -1,
      "y": 1,
      "z": 0,
      "name": "Rock_Basalt_Brick"
    },
    {
      "x": -1,
      "y": 2,
      "z": 0,
      "name": "Rock_Basalt_Brick"
    },
    {
      "x": -1,
      "y": 3,
      "z": 0,
      "name": "Rock_Basalt_Brick"
    },
    {
      "x": -1,
      "y": 4,
      "z": 0,
      "name": "Rock_Basalt_Brick"
    },
    {
      "x": -1,
      "y": 5,
      "z": 0,
      "name": "Rock_Basalt_Brick_Half"
    },
    {
      "x": -1,
      "y": 6,
      "z": 0,
      "name": "Deco_Iron_Bars_Platforms"
    },
    {
      "x": -1,
      "y": 7,
      "z": 0,
      "name": "Deco_Bronze_Railing"
    },
    {
      "x": -1,
      "y": 13,
      "z": 0,
      "name": "Rock_Basalt_Brick"
    },
    {
      "x": -1,
      "y": -1,
      "z": 1,
      "name": "Rock_Ice"
    },
    {
      "x": -1,
      "y": 0,
      "z": 1,
      "name": "Rock_Basalt",
      "rotation": 3
    },
    {
      "x": -1,
      "y": 1,
      "z": 1,
      "name": "Rubble_Basalt",
      "support": 15
    },
    {
      "x": -1,
      "y": 5,
      "z": 1,
      "name": "Rock_Basalt_Cobble_Half"
    },
    {
      "x": -1,
      "y": 6,
      "z": 1,
      "name": "Deco_Iron_Bars_Platforms"
    },
    {
      "x": -1,
      "y": 12,
      "z": 1,
      "name": "Rock_Ice_Icicles",
      "rotation": 8
    },
    {
      "x": -1,
      "y": 13,
      "z": 1,
      "name": "Rock_Basalt_Brick"
    },
    {
      "x": -1,
      "y": -1,
      "z": 2,
      "name": "Rock_Ice"
    },
    {
      "x": -1,
      "y": 0,
      "z": 2,
      "name": "Rock_Basalt",
      "rotation": 3
    },
    {
      "x": -1,
      "y": 5,
      "z": 2,
      "name": "Rock_Basalt_Cobble_Half"
    },
    {
      "x": -1,
      "y": 6,
      "z": 2,
      "name": "Deco_Iron_Bars_Platforms"
    },
    {
      "x": -1,
      "y": 13,
      "z": 2,
      "name": "Rock_Basalt_Brick"
    },
    {
      "x": -1,
      "y": -1,
      "z": 3,
      "name": "Rock_Ice"
    },
    {
      "x": -1,
      "y": 0,
      "z": 3,
      "name": "Rock_Basalt",
      "rotation": 3
    },
    {
      "x": -1,
      "y": 5,
      "z": 3,
      "name": "Rock_Basalt_Cobble_Half"
    },
    {
      "x": -1,
      "y": 6,
      "z": 3,
      "name": "Deco_Iron_Bars_Platforms"
    },
    {
      "x": -1,
      "y": 7,
      "z": 3,
      "name": "Deco_Bronze_Railing"
    },
    {
      "x": -1,
      "y": 13,
      "z": 3,
      "name": "Rock_Basalt_Brick"
    },
    {
      "x": -1,
      "y": -1,
      "z": 4,
      "name": "Rock_Ice"
    },
    {
      "x": -1,
      "y": 0,
      "z": 4,
      "name": "Rock_Basalt",
      "rotation": 3
    },
    {
      "x": -1,
      "y": 1,
      "z": 4,
      "name": "Furniture_Ancient_Crate",
      "rotation": 1
    },
    {
      "x": -1,
      "y": 2,
      "z": 4,
      "name": "Furniture_Ancient_Crate",
      "rotation": 2
    },
    {
      "x": -1,
      "y": 5,
      "z": 4,
      "name": "Rock_Basalt_Cobble_Half"
    },
    {
      "x": -1,
      "y": 13,
      "z": 4,
      "name": "Rock_Basalt_Brick"
    },
    {
      "x": -1,
      "y": -1,
      "z": 5,
      "name": "Rock_Ice"
    },
    {
      "x": -1,
      "y": 0,
      "z": 5,
      "name": "Rock_Basalt_Brick"
    },
    {
      "x": -1,
      "y": 1,
      "z": 5,
      "name": "Rock_Basalt_Brick"
    },
    {
      "x": -1,
      "y": 2,
      "z": 5,
      "name": "Rock_Basalt_Brick"
    },
    {
      "x": -1,
      "y": 3,
      "z": 5,
      "name": "Rock_Basalt_Brick"
    },
    {
      "x": -1,
      "y": 4,
      "z": 5,
      "name": "Rock_Basalt_Brick"
    },
    {
      "x": -1,
      "y": 5,
      "z": 5,
      "name": "Rock_Basalt_Brick"
    },
    {
      "x": -1,
      "y": 6,
      "z": 5,
      "name": "Rock_Basalt_Brick"
    },
    {
      "x": -1,
      "y": 7,
      "z": 5,
      "name": "Rock_Basalt_Brick"
    },
    {
      "x": -1,
      "y": 8,
      "z": 5,
      "name": "Rock_Basalt_Brick"
    },
    {
      "x": -1,
      "y": 9,
      "z": 5,
      "name": "Rock_Basalt_Brick"
    },
    {
      "x": -1,
      "y": 10,
      "z": 5,
      "name": "Rock_Basalt_Brick"
    },
    {
      "x": -1,
      "y": 11,
      "z": 5,
      "name": "Rock_Basalt_Brick"
    },
    {
      "x": -1,
      "y": 12,
      "z": 5,
      "name": "Rock_Basalt_Brick"
    },
    {
      "x": -1,
      "y": 13,
      "z": 5,
      "name": "Rock_Basalt_Brick"
    },
    {
      "x": 0,
      "y": -1,
      "z": -3,
      "name": "Rock_Ice"
    },
    {
      "x": 0,
      "y": 0,
      "z": -3,
      "name": "Rock_Basalt",
      "rotation": 3
    },
    {
      "x": 0,
      "y": 13,
      "z": -3,
      "name": "Rock_Basalt_Brick"
    },
    {
      "x": 0,
      "y": -1,
      "z": -2,
      "name": "Rock_Ice"
    },
    {
      "x": 0,
      "y": 0,
      "z": -2,
      "name": "Rock_Basalt",
      "rotation": 3
    },
    {
      "x": 0,
      "y": 12,
      "z": -2,
      "name": "Rock_Basalt_Brick_Half",
      "rotation": 11
    },
    {
      "x": 0,
      "y": 13,
      "z": -2,
      "name": "Rock_Basalt_Brick"
    },
    {
      "x": 0,
      "y": -1,
      "z": -1,
      "name": "Rock_Ice"
    },
    {
      "x": 0,
      "y": 0,
      "z": -1,
      "name": "Rock_Basalt",
      "rotation": 3
    },
    {
      "x": 0,
      "y": 1,
      "z": -1,
      "name": "Deco_SpiderWeb",
      "support": 15,
      "rotation": 2
    },
    {
      "x": 0,
      "y": 13,
      "z": -1,
      "name": "Rock_Basalt_Brick"
    },
    {
      "x": 0,
      "y": -1,
      "z": 0,
      "name": "Rock_Ice"
    },
    {
      "x": 0,
      "y": 0,
      "z": 0,
      "name": "Rock_Basalt",
      "rotation": 3
    },
    {
      "x": 0,
      "y": 1,
      "z": 0,
      "name": "Rock_Basalt_Brick"
    },
    {
      "x": 0,
      "y": 2,
      "z": 0,
      "name": "Rock_Basalt_Brick"
    },
    {
      "x": 0,
      "y": 3,
      "z": 0,
      "name": "Rock_Basalt_Brick"
    },
    {
      "x": 0,
      "y": 4,
      "z": 0,
      "name": "Rock_Basalt_Brick"
    },
    {
      "x": 0,
      "y": 5,
      "z": 0,
      "name": "Rock_Basalt_Brick_Half"
    },
    {
      "x": 0,
      "y": 6,
      "z": 0,
      "name": "Deco_Iron_Bars_Platforms"
    },
    {
      "x": 0,
      "y": 7,
      "z": 0,
      "name": "Deco_Bronze_Railing"
    },
    {
      "x": 0,
      "y": 13,
      "z": 0,
      "name": "Rock_Basalt_Brick"
    },
    {
      "x": 0,
      "y": -1,
      "z": 1,
      "name": "Rock_Ice"
    },
    {
      "x": 0,
      "y": 0,
      "z": 1,
      "name": "Rock_Basalt",
      "rotation": 3
    },
    {
      "x": 0,
      "y": 1,
      "z": 1,
      "name": "Deco_Treasure"
    },
    {
      "x": 0,
      "y": 4,
      "z": 1,
      "name": "Wood_Deadwood_Planks_Half",
      "rotation": 8
    },
    {
      "x": 0,
      "y": 5,
      "z": 1,
      "name": "Rock_Basalt_Cobble_Half"
    },
    {
      "x": 0,
      "y": 6,
      "z": 1,
      "name": "Deco_Iron_Bars_Platforms"
    },
    {
      "x": 0,
      "y": 13,
      "z": 1,
      "name": "Rock_Basalt_Brick"
    },
    {
      "x": 0,
      "y": -1,
      "z": 2,
      "name": "Rock_Ice"
    },
    {
      "x": 0,
      "y": 0,
      "z": 2,
      "name": "Rock_Basalt",
      "rotation": 3
    },
    {
      "x": 0,
      "y": 4,
      "z": 2,
      "name": "Wood_Deadwood_Planks_Half",
      "rotation": 8
    },
    {
      "x": 0,
      "y": 5,
      "z": 2,
      "name": "Rock_Basalt_Cobble_Half"
    },
    {
      "x": 0,
      "y": 6,
      "z": 2,
      "name": "Deco_Iron_Bars_Platforms"
    },
    {
      "x": 0,
      "y": 13,
      "z": 2,
      "name": "Rock_Basalt_Brick"
    },
    {
      "x": 0,
      "y": -1,
      "z": 3,
      "name": "Rock_Ice"
    },
    {
      "x": 0,
      "y": 0,
      "z": 3,
      "name": "Rock_Basalt",
      "rotation": 3
    },
    {
      "x": 0,
      "y": 4,
      "z": 3,
      "name": "Wood_Deadwood_Planks_Half",
      "rotation": 8
    },
    {
      "x": 0,
      "y": 5,
      "z": 3,
      "name": "Rock_Basalt_Cobble_Half"
    },
    {
      "x": 0,
      "y": 6,
      "z": 3,
      "name": "Deco_Iron_Bars_Platforms"
    },
    {
      "x": 0,
      "y": 7,
      "z": 3,
      "name": "Deco_Bronze_Railing"
    },
    {
      "x": 0,
      "y": 13,
      "z": 3,
      "name": "Rock_Basalt_Brick"
    },
    {
      "x": 0,
      "y": -1,
      "z": 4,
      "name": "Rock_Ice"
    },
    {
      "x": 0,
      "y": 0,
      "z": 4,
      "name": "Rock_Basalt",
      "rotation": 3
    },
    {
      "x": 0,
      "y": 1,
      "z": 4,
      "name": "Furniture_Ancient_Crate",
      "rotation": 2
    },
    {
      "x": 0,
      "y": 2,
      "z": 4,
      "name": "Furniture_Ancient_Crate",
      "rotation": 1
    },
    {
      "x": 0,
      "y": 4,
      "z": 4,
      "name": "Wood_Deadwood_Planks_Half",
      "rotation": 8
    },
    {
      "x": 0,
      "y": 5,
      "z": 4,
      "name": "Rock_Basalt_Cobble_Half"
    },
    {
      "x": 0,
      "y": 13,
      "z": 4,
      "name": "Rock_Basalt_Brick"
    },
    {
      "x": 0,
      "y": -1,
      "z": 5,
      "name": "Rock_Ice"
    },
    {
      "x": 0,
      "y": 0,
      "z": 5,
      "name": "Rock_Basalt_Brick"
    },
    {
      "x": 0,
      "y": 1,
      "z": 5,
      "name": "Rock_Basalt_Brick"
    },
    {
      "x": 0,
      "y": 2,
      "z": 5,
      "name": "Rock_Basalt_Brick"
    },
    {
      "x": 0,
      "y": 3,
      "z": 5,
      "name": "Rock_Basalt_Brick"
    },
    {
      "x": 0,
      "y": 4,
      "z": 5,
      "name": "Rock_Basalt_Brick"
    },
    {
      "x": 0,
      "y": 5,
      "z": 5,
      "name": "Rock_Basalt_Brick"
    },
    {
      "x": 0,
      "y": 6,
      "z": 5,
      "name": "Rock_Basalt_Brick"
    },
    {
      "x": 0,
      "y": 7,
      "z": 5,
      "name": "Rock_Basalt_Brick"
    },
    {
      "x": 0,
      "y": 8,
      "z": 5,
      "name": "Rock_Basalt_Brick"
    },
    {
      "x": 0,
      "y": 9,
      "z": 5,
      "name": "Rock_Basalt_Brick"
    },
    {
      "x": 0,
      "y": 10,
      "z": 5,
      "name": "Rock_Basalt_Brick"
    },
    {
      "x": 0,
      "y": 11,
      "z": 5,
      "name": "Rock_Basalt_Brick"
    },
    {
      "x": 0,
      "y": 12,
      "z": 5,
      "name": "Rock_Basalt_Brick"
    },
    {
      "x": 0,
      "y": 13,
      "z": 5,
      "name": "Rock_Basalt_Brick"
    },
    {
      "x": 1,
      "y": -1,
      "z": -3,
      "name": "Rock_Ice"
    },
    {
      "x": 1,
      "y": 0,
      "z": -3,
      "name": "Rock_Basalt",
      "rotation": 3
    },
    {
      "x": 1,
      "y": 13,
      "z": -3,
      "name": "Rock_Basalt_Brick"
    },
    {
      "x": 1,
      "y": -1,
      "z": -2,
      "name": "Rock_Ice"
    },
    {
      "x": 1,
      "y": 0,
      "z": -2,
      "name": "Rock_Basalt",
      "rotation": 3
    },
    {
      "x": 1,
      "y": 1,
      "z": -2,
      "name": "Rubble_Basalt",
      "support": 15
    },
    {
      "x": 1,
      "y": 12,
      "z": -2,
      "name": "Rock_Basalt_Brick_Stairs",
      "rotation": 9
    },
    {
      "x": 1,
      "y": 13,
      "z": -2,
      "name": "Rock_Basalt_Brick"
    },
    {
      "x": 1,
      "y": -1,
      "z": -1,
      "name": "Rock_Ice"
    },
    {
      "x": 1,
      "y": 0,
      "z": -1,
      "name": "Rock_Basalt",
      "rotation": 3
    },
    {
      "x": 1,
      "y": 1,
      "z": -1,
      "name": "Furniture_Ancient_Crate",
      "rotation": 2
    },
    {
      "x": 1,
      "y": 13,
      "z": -1,
      "name": "Rock_Basalt_Brick"
    },
    {
      "x": 1,
      "y": -1,
      "z": 0,
      "name": "Rock_Ice"
    },
    {
      "x": 1,
      "y": 0,
      "z": 0,
      "name": "Rock_Basalt",
      "rotation": 3
    },
    {
      "x": 1,
      "y": 1,
      "z": 0,
      "name": "Rock_Basalt_Brick"
    },
    {
      "x": 1,
      "y": 2,
      "z": 0,
      "name": "Rock_Basalt_Brick"
    },
    {
      "x": 1,
      "y": 3,
      "z": 0,
      "name": "Rock_Basalt_Brick"
    },
    {
      "x": 1,
      "y": 4,
      "z": 0,
      "name": "Rock_Basalt_Brick"
    },
    {
      "x": 1,
      "y": 5,
      "z": 0,
      "name": "Rock_Basalt_Brick_Half"
    },
    {
      "x": 1,
      "y": 6,
      "z": 0,
      "name": "Deco_Iron_Bars_Platforms"
    },
    {
      "x": 1,
      "y": 7,
      "z": 0,
      "name": "Deco_Bronze_Railing"
    },
    {
      "x": 1,
      "y": 13,
      "z": 0,
      "name": "Rock_Basalt_Brick"
    },
    {
      "x": 1,
      "y": -1,
      "z": 1,
      "name": "Rock_Ice"
    },
    {
      "x": 1,
      "y": 0,
      "z": 1,
      "name": "Rock_Basalt",
      "rotation": 3
    },
    {
      "x": 1,
      "y": 1,
      "z": 1,
      "name": "Furniture_Ancient_Bench",
      "filler": 31
    },
    {
      "x": 1,
      "y": 5,
      "z": 1,
      "name": "Rock_Basalt_Cobble_Half"
    },
    {
      "x": 1,
      "y": 6,
      "z": 1,
      "name": "Deco_Iron_Bars_Platforms"
    },
    {
      "x": 1,
      "y": 13,
      "z": 1,
      "name": "Rock_Basalt_Brick"
    },
    {
      "x": 1,
      "y": -1,
      "z": 2,
      "name": "Rock_Ice"
    },
    {
      "x": 1,
      "y": 0,
      "z": 2,
      "name": "Rock_Basalt",
      "rotation": 3
    },
    {
      "x": 1,
      "y": 5,
      "z": 2,
      "name": "Rock_Basalt_Cobble_Half"
    },
    {
      "x": 1,
      "y": 6,
      "z": 2,
      "name": "Deco_Iron_Bars_Platforms"
    },
    {
      "x": 1,
      "y": 13,
      "z": 2,
      "name": "Rock_Basalt_Brick"
    },
    {
      "x": 1,
      "y": -1,
      "z": 3,
      "name": "Rock_Ice"
    },
    {
      "x": 1,
      "y": 0,
      "z": 3,
      "name": "Rock_Basalt",
      "rotation": 3
    },
    {
      "x": 1,
      "y": 1,
      "z": 3,
      "name": "Rubble_Basalt",
      "support": 15
    },
    {
      "x": 1,
      "y": 5,
      "z": 3,
      "name": "Rock_Basalt_Cobble_Half"
    },
    {
      "x": 1,
      "y": 6,
      "z": 3,
      "name": "Deco_Iron_Bars_Platforms"
    },
    {
      "x": 1,
      "y": 7,
      "z": 3,
      "name": "Deco_Bronze_Railing"
    },
    {
      "x": 1,
      "y": 12,
      "z": 3,
      "name": "Rock_Ice_Icicles",
      "rotation": 8
    },
    {
      "x": 1,
      "y": 13,
      "z": 3,
      "name": "Rock_Basalt_Brick"
    },
    {
      "x": 1,
      "y": -1,
      "z": 4,
      "name": "Rock_Ice"
    },
    {
      "x": 1,
      "y": 0,
      "z": 4,
      "name": "Rock_Basalt",
      "rotation": 3
    },
    {
      "x": 1,
      "y": 1,
      "z": 4,
      "name": "Furniture_Ancient_Crate",
      "rotation": 2
    },
    {
      "x": 1,
      "y": 5,
      "z": 4,
      "name": "Rock_Basalt_Cobble_Half"
    },
    {
      "x": 1,
      "y": 13,
      "z": 4,
      "name": "Rock_Basalt_Brick"
    },
    {
      "x": 1,
      "y": -1,
      "z": 5,
      "name": "Rock_Ice"
    },
    {
      "x": 1,
      "y": 0,
      "z": 5,
      "name": "Rock_Basalt_Brick"
    },
    {
      "x": 1,
      "y": 1,
      "z": 5,
      "name": "Rock_Basalt_Brick"
    },
    {
      "x": 1,
      "y": 2,
      "z": 5,
      "name": "Rock_Basalt_Brick"
    },
    {
      "x": 1,
      "y": 3,
      "z": 5,
      "name": "Rock_Basalt_Brick"
    },
    {
      "x": 1,
      "y": 4,
      "z": 5,
      "name": "Rock_Basalt_Brick"
    },
    {
      "x": 1,
      "y": 5,
      "z": 5,
      "name": "Rock_Basalt_Brick"
    },
    {
      "x": 1,
      "y": 6,
      "z": 5,
      "name": "Rock_Basalt_Brick"
    },
    {
      "x": 1,
      "y": 7,
      "z": 5,
      "name": "Rock_Basalt_Brick"
    },
    {
      "x": 1,
      "y": 8,
      "z": 5,
      "name": "Rock_Basalt_Brick"
    },
    {
      "x": 1,
      "y": 9,
      "z": 5,
      "name": "Rock_Basalt_Brick"
    },
    {
      "x": 1,
      "y": 10,
      "z": 5,
      "name": "Rock_Basalt_Brick"
    },
    {
      "x": 1,
      "y": 11,
      "z": 5,
      "name": "Rock_Basalt_Brick"
    },
    {
      "x": 1,
      "y": 12,
      "z": 5,
      "name": "Rock_Basalt_Brick"
    },
    {
      "x": 1,
      "y": 13,
      "z": 5,
      "name": "Rock_Basalt_Brick"
    },
    {
      "x": 2,
      "y": -1,
      "z": -3,
      "name": "Rock_Ice"
    },
    {
      "x": 2,
      "y": 0,
      "z": -3,
      "name": "Rock_Basalt_Brick",
      "rotation": 3
    },
    {
      "x": 2,
      "y": 13,
      "z": -3,
      "name": "Rock_Basalt_Brick"
    },
    {
      "x": 2,
      "y": -1,
      "z": -2,
      "name": "Rock_Ice"
    },
    {
      "x": 2,
      "y": 0,
      "z": -2,
      "name": "Rock_Basalt_Brick",
      "rotation": 3
    },
    {
      "x": 2,
      "y": 1,
      "z": -2,
      "name": "Rock_Basalt_Brick_Pillar_Base",
      "rotation": 3
    },
    {
      "x": 2,
      "y": 2,
      "z": -2,
      "name": "Rock_Basalt_Brick_Pillar_Middle",
      "rotation": 3
    },
    {
      "x": 2,
      "y": 3,
      "z": -2,
      "name": "Rock_Basalt_Brick_Pillar_Middle",
      "rotation": 3
    },
    {
      "x": 2,
      "y": 4,
      "z": -2,
      "name": "Rock_Basalt_Brick_Pillar_Middle",
      "rotation": 3
    },
    {
      "x": 2,
      "y": 5,
      "z": -2,
      "name": "Rock_Basalt_Brick_Pillar_Middle",
      "rotation": 3
    },
    {
      "x": 2,
      "y": 6,
      "z": -2,
      "name": "Rock_Basalt_Brick_Pillar_Middle",
      "rotation": 3
    },
    {
      "x": 2,
      "y": 7,
      "z": -2,
      "name": "Rock_Basalt_Brick_Pillar_Middle",
      "rotation": 3
    },
    {
      "x": 2,
      "y": 8,
      "z": -2,
      "name": "Rock_Basalt_Brick_Pillar_Middle",
      "rotation": 3
    },
    {
      "x": 2,
      "y": 9,
      "z": -2,
      "name": "Rock_Basalt_Brick_Pillar_Middle",
      "rotation": 3
    },
    {
      "x": 2,
      "y": 10,
      "z": -2,
      "name": "Rock_Basalt_Brick_Pillar_Middle",
      "rotation": 3
    },
    {
      "x": 2,
      "y": 11,
      "z": -2,
      "name": "Rock_Basalt_Brick_Pillar_Base",
      "rotation": 11
    },
    {
      "x": 2,
      "y": 12,
      "z": -2,
      "name": "Rock_Basalt_Brick",
      "rotation": 3
    },
    {
      "x": 2,
      "y": 13,
      "z": -2,
      "name": "Rock_Basalt_Brick"
    },
    {
      "x": 2,
      "y": -1,
      "z": -1,
      "name": "Rock_Ice"
    },
    {
      "x": 2,
      "y": 0,
      "z": -1,
      "name": "Rock_Basalt_Brick",
      "rotation": 3
    },
    {
      "x": 2,
      "y": 1,
      "z": -1,
      "name": "Furniture_Ancient_Crate",
      "rotation": 1
    },
    {
      "x": 2,
      "y": 13,
      "z": -1,
      "name": "Rock_Basalt_Brick"
    },
    {
      "x": 2,
      "y": -1,
      "z": 0,
      "name": "Rock_Ice"
    },
    {
      "x": 2,
      "y": 0,
      "z": 0,
      "name": "Rock_Basalt_Brick",
      "rotation": 3
    },
    {
      "x": 2,
      "y": 1,
      "z": 0,
      "name": "Rock_Basalt_Brick"
    },
    {
      "x": 2,
      "y": 2,
      "z": 0,
      "name": "Rock_Basalt_Brick"
    },
    {
      "x": 2,
      "y": 3,
      "z": 0,
      "name": "Rock_Basalt_Brick"
    },
    {
      "x": 2,
      "y": 4,
      "z": 0,
      "name": "Rock_Basalt_Brick"
    },
    {
      "x": 2,
      "y": 5,
      "z": 0,
      "name": "Rock_Basalt_Brick_Half"
    },
    {
      "x": 2,
      "y": 6,
      "z": 0,
      "name": "Deco_Iron_Bars_Platforms"
    },
    {
      "x": 2,
      "y": 7,
      "z": 0,
      "name": "Deco_Bronze_Railing"
    },
    {
      "x": 2,
      "y": 11,
      "z": 0,
      "name": "Rock_Ice_Stalactite_Large",
      "filler": 31744,
      "rotation": 8
    },
    {
      "x": 2,
      "y": 12,
      "z": 0,
      "name": "Rock_Ice_Stalactite_Large",
      "rotation": 8
    },
    {
      "x": 2,
      "y": 13,
      "z": 0,
      "name": "Rock_Basalt_Brick"
    },
    {
      "x": 2,
      "y": -1,
      "z": 1,
      "name": "Rock_Ice"
    },
    {
      "x": 2,
      "y": 0,
      "z": 1,
      "name": "Rock_Basalt_Brick",
      "rotation": 3
    },
    {
      "x": 2,
      "y": 1,
      "z": 1,
      "name": "Furniture_Ancient_Bench"
    },
    {
      "x": 2,
      "y": 5,
      "z": 1,
      "name": "Rock_Basalt_Cobble_Half"
    },
    {
      "x": 2,
      "y": 6,
      "z": 1,
      "name": "Deco_Iron_Bars_Platforms"
    },
    {
      "x": 2,
      "y": 13,
      "z": 1,
      "name": "Rock_Basalt_Brick"
    },
    {
      "x": 2,
      "y": -1,
      "z": 2,
      "name": "Rock_Ice"
    },
    {
      "x": 2,
      "y": 0,
      "z": 2,
      "name": "Rock_Basalt_Brick",
      "rotation": 3
    },
    {
      "x": 2,
      "y": 5,
      "z": 2,
      "name": "Rock_Basalt_Cobble_Half"
    },
    {
      "x": 2,
      "y": 6,
      "z": 2,
      "name": "Deco_Iron_Bars_Platforms"
    },
    {
      "x": 2,
      "y": 13,
      "z": 2,
      "name": "Rock_Basalt_Brick"
    },
    {
      "x": 2,
      "y": -1,
      "z": 3,
      "name": "Rock_Ice"
    },
    {
      "x": 2,
      "y": 0,
      "z": 3,
      "name": "Rock_Basalt_Brick",
      "rotation": 3
    },
    {
      "x": 2,
      "y": 1,
      "z": 3,
      "name": "Rubble_Basalt_Medium",
      "support": 15
    },
    {
      "x": 2,
      "y": 5,
      "z": 3,
      "name": "Rock_Basalt_Cobble_Half"
    },
    {
      "x": 2,
      "y": 6,
      "z": 3,
      "name": "Deco_Iron_Bars_Platforms"
    },
    {
      "x": 2,
      "y": 7,
      "z": 3,
      "name": "Deco_Bronze_Railing"
    },
    {
      "x": 2,
      "y": 13,
      "z": 3,
      "name": "Rock_Basalt_Brick"
    },
    {
      "x": 2,
      "y": -1,
      "z": 4,
      "name": "Rock_Ice"
    },
    {
      "x": 2,
      "y": 0,
      "z": 4,
      "name": "Rock_Basalt_Brick",
      "rotation": 3
    },
    {
      "x": 2,
      "y": 1,
      "z": 4,
      "name": "Deco_Treasure_Pile_Small",
      "rotation": 2
    },
    {
      "x": 2,
      "y": 5,
      "z": 4,
      "name": "Rock_Basalt_Cobble_Half"
    },
    {
      "x": 2,
      "y": 11,
      "z": 4,
      "name": "Rock_Ice_Stalactite_Large",
      "filler": 31744,
      "rotation": 8
    },
    {
      "x": 2,
      "y": 12,
      "z": 4,
      "name": "Rock_Ice_Stalactite_Large",
      "rotation": 8
    },
    {
      "x": 2,
      "y": 13,
      "z": 4,
      "name": "Rock_Basalt_Brick"
    },
    {
      "x": 2,
      "y": -1,
      "z": 5,
      "name": "Rock_Ice"
    },
    {
      "x": 2,
      "y": 0,
      "z": 5,
      "name": "Rock_Basalt_Brick"
    },
    {
      "x": 2,
      "y": 1,
      "z": 5,
      "name": "Rock_Basalt_Brick"
    },
    {
      "x": 2,
      "y": 2,
      "z": 5,
      "name": "Rock_Basalt_Brick"
    },
    {
      "x": 2,
      "y": 3,
      "z": 5,
      "name": "Rock_Basalt_Brick"
    },
    {
      "x": 2,
      "y": 4,
      "z": 5,
      "name": "Rock_Basalt_Brick"
    },
    {
      "x": 2,
      "y": 5,
      "z": 5,
      "name": "Rock_Basalt_Brick"
    },
    {
      "x": 2,
      "y": 6,
      "z": 5,
      "name": "Rock_Basalt_Brick"
    },
    {
      "x": 2,
      "y": 7,
      "z": 5,
      "name": "Rock_Basalt_Brick"
    },
    {
      "x": 2,
      "y": 8,
      "z": 5,
      "name": "Rock_Basalt_Brick"
    },
    {
      "x": 2,
      "y": 9,
      "z": 5,
      "name": "Rock_Basalt_Brick"
    },
    {
      "x": 2,
      "y": 10,
      "z": 5,
      "name": "Rock_Basalt_Brick"
    },
    {
      "x": 2,
      "y": 11,
      "z": 5,
      "name": "Rock_Basalt_Brick"
    },
    {
      "x": 2,
      "y": 12,
      "z": 5,
      "name": "Rock_Basalt_Brick"
    },
    {
      "x": 2,
      "y": 13,
      "z": 5,
      "name": "Rock_Basalt_Brick"
    },
    {
      "x": 3,
      "y": -1,
      "z": -3,
      "name": "Rock_Ice"
    },
    {
      "x": 3,
      "y": 0,
      "z": -3,
      "name": "Rock_Basalt",
      "rotation": 3
    },
    {
      "x": 3,
      "y": 13,
      "z": -3,
      "name": "Rock_Basalt_Brick"
    },
    {
      "x": 3,
      "y": -1,
      "z": -2,
      "name": "Rock_Ice"
    },
    {
      "x": 3,
      "y": 0,
      "z": -2,
      "name": "Rock_Basalt",
      "rotation": 3
    },
    {
      "x": 3,
      "y": 1,
      "z": -2,
      "name": "Furniture_Ancient_Barrel"
    },
    {
      "x": 3,
      "y": 12,
      "z": -2,
      "name": "Rock_Basalt_Brick_Stairs",
      "rotation": 11
    },
    {
      "x": 3,
      "y": 13,
      "z": -2,
      "name": "Rock_Basalt_Brick"
    },
    {
      "x": 3,
      "y": -1,
      "z": -1,
      "name": "Rock_Ice"
    },
    {
      "x": 3,
      "y": 0,
      "z": -1,
      "name": "Rock_Basalt",
      "rotation": 3
    },
    {
      "x": 3,
      "y": 1,
      "z": -1,
      "name": "Furniture_Ancient_Crate",
      "rotation": 1
    },
    {
      "x": 3,
      "y": 2,
      "z": -1,
      "name": "Furniture_Ancient_Crate",
      "rotation": 1
    },
    {
      "x": 3,
      "y": 12,
      "z": -1,
      "name": "Rock_Ice_Icicles",
      "rotation": 8
    },
    {
      "x": 3,
      "y": 13,
      "z": -1,
      "name": "Rock_Basalt_Brick"
    },
    {
      "x": 3,
      "y": -1,
      "z": 0,
      "name": "Rock_Ice"
    },
    {
      "x": 3,
      "y": 0,
      "z": 0,
      "name": "Rock_Basalt",
      "rotation": 3
    },
    {
      "x": 3,
      "y": 1,
      "z": 0,
      "name": "Rock_Basalt_Brick"
    },
    {
      "x": 3,
      "y": 2,
      "z": 0,
      "name": "Rock_Basalt_Brick"
    },
    {
      "x": 3,
      "y": 3,
      "z": 0,
      "name": "Rock_Basalt_Brick"
    },
    {
      "x": 3,
      "y": 4,
      "z": 0,
      "name": "Rock_Basalt_Brick"
    },
    {
      "x": 3,
      "y": 5,
      "z": 0,
      "name": "Rock_Basalt_Brick_Half"
    },
    {
      "x": 3,
      "y": 6,
      "z": 0,
      "name": "Deco_Iron_Bars_Platforms"
    },
    {
      "x": 3,
      "y": 7,
      "z": 0,
      "name": "Deco_Bronze_Railing"
    },
    {
      "x": 3,
      "y": 13,
      "z": 0,
      "name": "Rock_Basalt_Brick"
    },
    {
      "x": 3,
      "y": -1,
      "z": 1,
      "name": "Rock_Ice"
    },
    {
      "x": 3,
      "y": 0,
      "z": 1,
      "name": "Rock_Basalt",
      "rotation": 3
    },
    {
      "x": 3,
      "y": 1,
      "z": 1,
      "name": "Deco_Treasure_Pile_Small",
      "rotation": 3
    },
    {
      "x": 3,
      "y": 5,
      "z": 1,
      "name": "Rock_Basalt_Cobble_Half"
    },
    {
      "x": 3,
      "y": 6,
      "z": 1,
      "name": "Deco_Iron_Bars_Platforms"
    },
    {
      "x": 3,
      "y": 11,
      "z": 1,
      "name": "Rock_Ice_Stalactite_Large",
      "filler": 31744,
      "rotation": 8
    },
    {
      "x": 3,
      "y": 12,
      "z": 1,
      "name": "Rock_Ice_Stalactite_Large",
      "rotation": 8
    },
    {
      "x": 3,
      "y": 13,
      "z": 1,
      "name": "Rock_Basalt_Brick"
    },
    {
      "x": 3,
      "y": -1,
      "z": 2,
      "name": "Rock_Ice"
    },
    {
      "x": 3,
      "y": 0,
      "z": 2,
      "name": "Rock_Basalt",
      "rotation": 3
    },
    {
      "x": 3,
      "y": 1,
      "z": 2,
      "name": "Deco_Treasure",
      "rotation": 3
    },
    {
      "x": 3,
      "y": 5,
      "z": 2,
      "name": "Rock_Basalt_Cobble_Half"
    },
    {
      "x": 3,
      "y": 6,
      "z": 2,
      "name": "Deco_Iron_Bars_Platforms"
    },
    {
      "x": 3,
      "y": 13,
      "z": 2,
      "name": "Rock_Basalt_Brick"
    },
    {
      "x": 3,
      "y": -1,
      "z": 3,
      "name": "Rock_Ice"
    },
    {
      "x": 3,
      "y": 0,
      "z": 3,
      "name": "Rock_Basalt",
      "rotation": 3
    },
    {
      "x": 3,
      "y": 1,
      "z": 3,
      "name": "Deco_Bone_Pile"
    },
    {
      "x": 3,
      "y": 5,
      "z": 3,
      "name": "Rock_Basalt_Cobble_Half"
    },
    {
      "x": 3,
      "y": 6,
      "z": 3,
      "name": "Deco_Iron_Bars_Platforms"
    },
    {
      "x": 3,
      "y": 7,
      "z": 3,
      "name": "Deco_Bronze_Railing"
    },
    {
      "x": 3,
      "y": 13,
      "z": 3,
      "name": "Rock_Basalt_Brick"
    },
    {
      "x": 3,
      "y": -1,
      "z": 4,
      "name": "Rock_Ice"
    },
    {
      "x": 3,
      "y": 0,
      "z": 4,
      "name": "Rock_Basalt",
      "rotation": 3
    },
    {
      "x": 3,
      "y": 5,
      "z": 4,
      "name": "Rock_Basalt_Cobble_Half"
    },
    {
      "x": 3,
      "y": 12,
      "z": 4,
      "name": "Rock_Ice_Icicles",
      "rotation": 8
    },
    {
      "x": 3,
      "y": 13,
      "z": 4,
      "name": "Rock_Basalt_Brick"
    },
    {
      "x": 3,
      "y": -1,
      "z": 5,
      "name": "Rock_Ice"
    },
    {
      "x": 3,
      "y": 0,
      "z": 5,
      "name": "Rock_Basalt_Brick"
    },
    {
      "x": 3,
      "y": 1,
      "z": 5,
      "name": "Rock_Basalt_Brick"
    },
    {
      "x": 3,
      "y": 2,
      "z": 5,
      "name": "Rock_Basalt_Brick"
    },
    {
      "x": 3,
      "y": 3,
      "z": 5,
      "name": "Rock_Basalt_Brick"
    },
    {
      "x": 3,
      "y": 4,
      "z": 5,
      "name": "Rock_Basalt_Brick"
    },
    {
      "x": 3,
      "y": 5,
      "z": 5,
      "name": "Rock_Basalt_Brick"
    },
    {
      "x": 3,
      "y": 6,
      "z": 5,
      "name": "Rock_Basalt_Brick"
    },
    {
      "x": 3,
      "y": 7,
      "z": 5,
      "name": "Rock_Basalt_Brick"
    },
    {
      "x": 3,
      "y": 8,
      "z": 5,
      "name": "Rock_Basalt_Brick"
    },
    {
      "x": 3,
      "y": 9,
      "z": 5,
      "name": "Rock_Basalt_Brick"
    },
    {
      "x": 3,
      "y": 10,
      "z": 5,
      "name": "Rock_Basalt_Brick"
    },
    {
      "x": 3,
      "y": 11,
      "z": 5,
      "name": "Rock_Basalt_Brick"
    },
    {
      "x": 3,
      "y": 12,
      "z": 5,
      "name": "Rock_Basalt_Brick"
    },
    {
      "x": 3,
      "y": 13,
      "z": 5,
      "name": "Rock_Basalt_Brick"
    },
    {
      "x": 4,
      "y": -1,
      "z": -3,
      "name": "Rock_Ice"
    },
    {
      "x": 4,
      "y": 0,
      "z": -3,
      "name": "Rock_Basalt",
      "rotation": 3
    },
    {
      "x": 4,
      "y": 13,
      "z": -3,
      "name": "Rock_Basalt_Brick"
    },
    {
      "x": 4,
      "y": -1,
      "z": -2,
      "name": "Rock_Ice"
    },
    {
      "x": 4,
      "y": 0,
      "z": -2,
      "name": "Rock_Basalt",
      "rotation": 3
    },
    {
      "x": 4,
      "y": 1,
      "z": -2,
      "name": "Rubble_Basalt",
      "support": 15
    },
    {
      "x": 4,
      "y": 12,
      "z": -2,
      "name": "Rock_Basalt_Brick_Half",
      "rotation": 11
    },
    {
      "x": 4,
      "y": 13,
      "z": -2,
      "name": "Rock_Basalt_Brick"
    },
    {
      "x": 4,
      "y": -1,
      "z": -1,
      "name": "Rock_Ice"
    },
    {
      "x": 4,
      "y": 0,
      "z": -1,
      "name": "Rock_Basalt",
      "rotation": 3
    },
    {
      "x": 4,
      "y": 1,
      "z": -1,
      "name": "Furniture_Ancient_Crate",
      "rotation": 2
    },
    {
      "x": 4,
      "y": 13,
      "z": -1,
      "name": "Rock_Basalt_Brick"
    },
    {
      "x": 4,
      "y": -1,
      "z": 0,
      "name": "Rock_Ice"
    },
    {
      "x": 4,
      "y": 0,
      "z": 0,
      "name": "Rock_Basalt",
      "rotation": 3
    },
    {
      "x": 4,
      "y": 1,
      "z": 0,
      "name": "Rock_Basalt_Brick"
    },
    {
      "x": 4,
      "y": 2,
      "z": 0,
      "name": "Rock_Basalt_Brick"
    },
    {
      "x": 4,
      "y": 3,
      "z": 0,
      "name": "Rock_Basalt_Brick"
    },
    {
      "x": 4,
      "y": 4,
      "z": 0,
      "name": "Rock_Basalt_Brick"
    },
    {
      "x": 4,
      "y": 5,
      "z": 0,
      "name": "Rock_Basalt_Brick_Half"
    },
    {
      "x": 4,
      "y": 6,
      "z": 0,
      "name": "Deco_Iron_Bars_Platforms"
    },
    {
      "x": 4,
      "y": 7,
      "z": 0,
      "name": "Deco_Bronze_Railing"
    },
    {
      "x": 4,
      "y": 8,
      "z": 0,
      "name": "Deco_Iron_Chain_Small"
    },
    {
      "x": 4,
      "y": 9,
      "z": 0,
      "name": "Deco_Iron_Chain_Small"
    },
    {
      "x": 4,
      "y": 10,
      "z": 0,
      "name": "Deco_Iron_Chain_Small"
    },
    {
      "x": 4,
      "y": 11,
      "z": 0,
      "name": "Deco_Iron_Chain_Small"
    },
    {
      "x": 4,
      "y": 12,
      "z": 0,
      "name": "Deco_Iron_Chain_Small"
    },
    {
      "x": 4,
      "y": 13,
      "z": 0,
      "name": "Rock_Basalt_Brick"
    },
    {
      "x": 4,
      "y": -1,
      "z": 1,
      "name": "Rock_Ice"
    },
    {
      "x": 4,
      "y": 0,
      "z": 1,
      "name": "Rock_Basalt",
      "rotation": 3
    },
    {
      "x": 4,
      "y": 1,
      "z": 1,
      "name": "Furniture_Human_Ruins_Brazier"
    },
    {
      "x": 4,
      "y": 4,
      "z": 1,
      "name": "Wood_Deadwood_Planks_Half",
      "rotation": 8
    },
    {
      "x": 4,
      "y": 5,
      "z": 1,
      "name": "Rock_Basalt_Cobble_Half"
    },
    {
      "x": 4,
      "y": 6,
      "z": 1,
      "name": "Deco_Iron_Bars_Platforms"
    },
    {
      "x": 4,
      "y": 13,
      "z": 1,
      "name": "Rock_Basalt_Brick"
    },
    {
      "x": 4,
      "y": -1,
      "z": 2,
      "name": "Rock_Ice"
    },
    {
      "x": 4,
      "y": 0,
      "z": 2,
      "name": "Rock_Basalt",
      "rotation": 3
    },
    {
      "x": 4,
      "y": 1,
      "z": 2,
      "name": "Deco_Bone_Pile"
    },
    {
      "x": 4,
      "y": 4,
      "z": 2,
      "name": "Wood_Deadwood_Planks_Half",
      "rotation": 8
    },
    {
      "x": 4,
      "y": 5,
      "z": 2,
      "name": "Rock_Basalt_Cobble_Half"
    },
    {
      "x": 4,
      "y": 6,
      "z": 2,
      "name": "Deco_Iron_Bars_Platforms"
    },
    {
      "x": 4,
      "y": 13,
      "z": 2,
      "name": "Rock_Basalt_Brick"
    },
    {
      "x": 4,
      "y": -1,
      "z": 3,
      "name": "Rock_Ice"
    },
    {
      "x": 4,
      "y": 0,
      "z": 3,
      "name": "Rock_Basalt",
      "rotation": 3
    },
    {
      "x": 4,
      "y": 1,
      "z": 3,
      "name": "Deco_Bone_Skulls"
    },
    {
      "x": 4,
      "y": 4,
      "z": 3,
      "name": "Wood_Deadwood_Planks_Half",
      "rotation": 8
    },
    {
      "x": 4,
      "y": 5,
      "z": 3,
      "name": "Rock_Basalt_Cobble_Half"
    },
    {
      "x": 4,
      "y": 6,
      "z": 3,
      "name": "Deco_Iron_Bars_Platforms"
    },
    {
      "x": 4,
      "y": 7,
      "z": 3,
      "name": "Deco_Bronze_Railing"
    },
    {
      "x": 4,
      "y": 8,
      "z": 3,
      "name": "Deco_Iron_Chain_Small"
    },
    {
      "x": 4,
      "y": 9,
      "z": 3,
      "name": "Deco_Iron_Chain_Small"
    },
    {
      "x": 4,
      "y": 10,
      "z": 3,
      "name": "Deco_Iron_Chain_Small"
    },
    {
      "x": 4,
      "y": 11,
      "z": 3,
      "name": "Deco_Iron_Chain_Small"
    },
    {
      "x": 4,
      "y": 12,
      "z": 3,
      "name": "Deco_Iron_Chain_Small"
    },
    {
      "x": 4,
      "y": 13,
      "z": 3,
      "name": "Rock_Basalt_Brick"
    },
    {
      "x": 4,
      "y": -1,
      "z": 4,
      "name": "Rock_Ice"
    },
    {
      "x": 4,
      "y": 0,
      "z": 4,
      "name": "Rock_Basalt",
      "rotation": 3
    },
    {
      "x": 4,
      "y": 1,
      "z": 4,
      "name": "Deco_Treasure_Pile_Small",
      "rotation": 2
    },
    {
      "x": 4,
      "y": 4,
      "z": 4,
      "name": "Wood_Deadwood_Planks_Half",
      "rotation": 8
    },
    {
      "x": 4,
      "y": 5,
      "z": 4,
      "name": "Rock_Basalt_Cobble_Half"
    },
    {
      "x": 4,
      "y": 13,
      "z": 4,
      "name": "Rock_Basalt_Brick"
    },
    {
      "x": 4,
      "y": -1,
      "z": 5,
      "name": "Rock_Ice"
    },
    {
      "x": 4,
      "y": 0,
      "z": 5,
      "name": "Rock_Basalt_Brick"
    },
    {
      "x": 4,
      "y": 1,
      "z": 5,
      "name": "Rock_Basalt_Brick"
    },
    {
      "x": 4,
      "y": 2,
      "z": 5,
      "name": "Rock_Basalt_Brick"
    },
    {
      "x": 4,
      "y": 3,
      "z": 5,
      "name": "Rock_Basalt_Brick"
    },
    {
      "x": 4,
      "y": 4,
      "z": 5,
      "name": "Rock_Basalt_Brick"
    },
    {
      "x": 4,
      "y": 5,
      "z": 5,
      "name": "Rock_Basalt_Brick"
    },
    {
      "x": 4,
      "y": 6,
      "z": 5,
      "name": "Rock_Basalt_Brick"
    },
    {
      "x": 4,
      "y": 7,
      "z": 5,
      "name": "Rock_Basalt_Brick"
    },
    {
      "x": 4,
      "y": 8,
      "z": 5,
      "name": "Rock_Basalt_Brick"
    },
    {
      "x": 4,
      "y": 9,
      "z": 5,
      "name": "Rock_Basalt_Brick"
    },
    {
      "x": 4,
      "y": 10,
      "z": 5,
      "name": "Rock_Basalt_Brick"
    },
    {
      "x": 4,
      "y": 11,
      "z": 5,
      "name": "Rock_Basalt_Brick"
    },
    {
      "x": 4,
      "y": 12,
      "z": 5,
      "name": "Rock_Basalt_Brick"
    },
    {
      "x": 4,
      "y": 13,
      "z": 5,
      "name": "Rock_Basalt_Brick"
    },
    {
      "x": 5,
      "y": -1,
      "z": -3,
      "name": "Rock_Ice"
    },
    {
      "x": 5,
      "y": 0,
      "z": -3,
      "name": "Rock_Basalt",
      "rotation": 3
    },
    {
      "x": 5,
      "y": 13,
      "z": -3,
      "name": "Rock_Basalt_Brick"
    },
    {
      "x": 5,
      "y": -1,
      "z": -2,
      "name": "Rock_Ice"
    },
    {
      "x": 5,
      "y": 0,
      "z": -2,
      "name": "Rock_Basalt",
      "rotation": 3
    },
    {
      "x": 5,
      "y": 12,
      "z": -2,
      "name": "Rock_Basalt_Brick_Stairs",
      "rotation": 9
    },
    {
      "x": 5,
      "y": 13,
      "z": -2,
      "name": "Rock_Basalt_Brick"
    },
    {
      "x": 5,
      "y": -1,
      "z": -1,
      "name": "Rock_Ice"
    },
    {
      "x": 5,
      "y": 0,
      "z": -1,
      "name": "Rock_Basalt",
      "rotation": 3
    },
    {
      "x": 5,
      "y": 1,
      "z": -1,
      "name": "Rubble_Basalt_Medium",
      "support": 15
    },
    {
      "x": 5,
      "y": 13,
      "z": -1,
      "name": "Rock_Basalt_Brick"
    },
    {
      "x": 5,
      "y": -1,
      "z": 0,
      "name": "Rock_Ice"
    },
    {
      "x": 5,
      "y": 0,
      "z": 0,
      "name": "Rock_Basalt",
      "rotation": 3
    },
    {
      "x": 5,
      "y": 1,
      "z": 0,
      "name": "Rock_Basalt_Brick"
    },
    {
      "x": 5,
      "y": 2,
      "z": 0,
      "name": "Rock_Basalt_Brick"
    },
    {
      "x": 5,
      "y": 3,
      "z": 0,
      "name": "Rock_Basalt_Brick"
    },
    {
      "x": 5,
      "y": 4,
      "z": 0,
      "name": "Rock_Basalt_Brick"
    },
    {
      "x": 5,
      "y": 5,
      "z": 0,
      "name": "Rock_Basalt_Brick_Half"
    },
    {
      "x": 5,
      "y": 6,
      "z": 0,
      "name": "Deco_Iron_Bars_Platforms"
    },
    {
      "x": 5,
      "y": 7,
      "z": 0,
      "name": "Deco_Bronze_Railing"
    },
    {
      "x": 5,
      "y": 13,
      "z": 0,
      "name": "Rock_Basalt_Brick"
    },
    {
      "x": 5,
      "y": -1,
      "z": 1,
      "name": "Rock_Ice"
    },
    {
      "x": 5,
      "y": 0,
      "z": 1,
      "name": "Rock_Basalt",
      "rotation": 3
    },
    {
      "x": 5,
      "y": 1,
      "z": 1,
      "name": "Deco_Treasure_Pile_Large"
    },
    {
      "x": 5,
      "y": 5,
      "z": 1,
      "name": "Rock_Basalt_Cobble_Half"
    },
    {
      "x": 5,
      "y": 6,
      "z": 1,
      "name": "Deco_Iron_Bars_Platforms"
    },
    {
      "x": 5,
      "y": 13,
      "z": 1,
      "name": "Rock_Basalt_Brick"
    },
    {
      "x": 5,
      "y": -1,
      "z": 2,
      "name": "Rock_Ice"
    },
    {
      "x": 5,
      "y": 0,
      "z": 2,
      "name": "Rock_Basalt",
      "rotation": 3
    },
    {
      "x": 5,
      "y": 1,
      "z": 2,
      "name": "Block_Spawner_Block",
      "components": {
        "Components": {
          "PlacedByInteraction": {
            "WhoPlacedUuid": {
              "$binary": "B1yBGZcjQ2KREo5yyLGY0g==",
              "$type": "04"
            }
          },
          "BlockSpawner": {
            "BlockSpawnerId": "Zone3_Outlander_Tier3"
          }
        }
      },
      "rotation": 3
    },
    {
      "x": 5,
      "y": 5,
      "z": 2,
      "name": "Rock_Basalt_Cobble_Half"
    },
    {
      "x": 5,
      "y": 6,
      "z": 2,
      "name": "Deco_Iron_Bars_Platforms"
    },
    {
      "x": 5,
      "y": 13,
      "z": 2,
      "name": "Rock_Basalt_Brick"
    },
    {
      "x": 5,
      "y": -1,
      "z": 3,
      "name": "Rock_Ice"
    },
    {
      "x": 5,
      "y": 0,
      "z": 3,
      "name": "Rock_Basalt",
      "rotation": 3
    },
    {
      "x": 5,
      "y": 1,
      "z": 3,
      "name": "Deco_Treasure_Pile_Small",
      "rotation": 3
    },
    {
      "x": 5,
      "y": 2,
      "z": 3,
      "name": "Furniture_Ancient_Shelf",
      "rotation": 3
    },
    {
      "x": 5,
      "y": 5,
      "z": 3,
      "name": "Rock_Basalt_Cobble_Half"
    },
    {
      "x": 5,
      "y": 6,
      "z": 3,
      "name": "Deco_Iron_Bars_Platforms"
    },
    {
      "x": 5,
      "y": 7,
      "z": 3,
      "name": "Deco_Bronze_Railing"
    },
    {
      "x": 5,
      "y": 13,
      "z": 3,
      "name": "Rock_Basalt_Brick"
    },
    {
      "x": 5,
      "y": -1,
      "z": 4,
      "name": "Rock_Ice"
    },
    {
      "x": 5,
      "y": 0,
      "z": 4,
      "name": "Rock_Basalt",
      "rotation": 3
    },
    {
      "x": 5,
      "y": 1,
      "z": 4,
      "name": "Deco_Treasure_Pile_Large",
      "rotation": 3
    },
    {
      "x": 5,
      "y": 2,
      "z": 4,
      "name": "Furniture_Ancient_Shelf",
      "rotation": 3
    },
    {
      "x": 5,
      "y": 5,
      "z": 4,
      "name": "Rock_Basalt_Cobble_Half"
    },
    {
      "x": 5,
      "y": 13,
      "z": 4,
      "name": "Rock_Basalt_Brick"
    },
    {
      "x": 5,
      "y": -1,
      "z": 5,
      "name": "Rock_Ice"
    },
    {
      "x": 5,
      "y": 0,
      "z": 5,
      "name": "Rock_Basalt_Brick"
    },
    {
      "x": 5,
      "y": 1,
      "z": 5,
      "name": "Rock_Basalt_Brick"
    },
    {
      "x": 5,
      "y": 2,
      "z": 5,
      "name": "Rock_Basalt_Brick"
    },
    {
      "x": 5,
      "y": 3,
      "z": 5,
      "name": "Rock_Basalt_Brick"
    },
    {
      "x": 5,
      "y": 4,
      "z": 5,
      "name": "Rock_Basalt_Brick"
    },
    {
      "x": 5,
      "y": 5,
      "z": 5,
      "name": "Rock_Basalt_Brick"
    },
    {
      "x": 5,
      "y": 6,
      "z": 5,
      "name": "Rock_Basalt_Brick"
    },
    {
      "x": 5,
      "y": 7,
      "z": 5,
      "name": "Rock_Basalt_Brick"
    },
    {
      "x": 5,
      "y": 8,
      "z": 5,
      "name": "Rock_Basalt_Brick"
    },
    {
      "x": 5,
      "y": 9,
      "z": 5,
      "name": "Rock_Basalt_Brick"
    },
    {
      "x": 5,
      "y": 10,
      "z": 5,
      "name": "Rock_Basalt_Brick"
    },
    {
      "x": 5,
      "y": 11,
      "z": 5,
      "name": "Rock_Basalt_Brick"
    },
    {
      "x": 5,
      "y": 12,
      "z": 5,
      "name": "Rock_Basalt_Brick"
    },
    {
      "x": 5,
      "y": 13,
      "z": 5,
      "name": "Rock_Basalt_Brick"
    },
    {
      "x": 6,
      "y": -1,
      "z": -3,
      "name": "Rock_Ice"
    },
    {
      "x": 6,
      "y": 0,
      "z": -3,
      "name": "Rock_Basalt_Brick",
      "rotation": 3
    },
    {
      "x": 6,
      "y": 13,
      "z": -3,
      "name": "Rock_Basalt_Brick"
    },
    {
      "x": 6,
      "y": -1,
      "z": -2,
      "name": "Rock_Ice"
    },
    {
      "x": 6,
      "y": 0,
      "z": -2,
      "name": "Rock_Basalt_Brick",
      "rotation": 3
    },
    {
      "x": 6,
      "y": 1,
      "z": -2,
      "name": "Rock_Basalt_Brick_Pillar_Base",
      "rotation": 3
    },
    {
      "x": 6,
      "y": 2,
      "z": -2,
      "name": "Rock_Basalt_Brick_Pillar_Middle",
      "rotation": 3
    },
    {
      "x": 6,
      "y": 3,
      "z": -2,
      "name": "Rock_Basalt_Brick_Pillar_Middle",
      "rotation": 3
    },
    {
      "x": 6,
      "y": 4,
      "z": -2,
      "name": "Rock_Basalt_Brick_Pillar_Middle",
      "rotation": 3
    },
    {
      "x": 6,
      "y": 5,
      "z": -2,
      "name": "Rock_Basalt_Brick_Pillar_Middle",
      "rotation": 3
    },
    {
      "x": 6,
      "y": 6,
      "z": -2,
      "name": "Rock_Basalt_Brick_Pillar_Middle",
      "rotation": 3
    },
    {
      "x": 6,
      "y": 7,
      "z": -2,
      "name": "Rock_Basalt_Brick_Pillar_Middle",
      "rotation": 3
    },
    {
      "x": 6,
      "y": 8,
      "z": -2,
      "name": "Rock_Basalt_Brick_Pillar_Middle",
      "rotation": 3
    },
    {
      "x": 6,
      "y": 9,
      "z": -2,
      "name": "Rock_Basalt_Brick_Pillar_Middle",
      "rotation": 3
    },
    {
      "x": 6,
      "y": 10,
      "z": -2,
      "name": "Rock_Basalt_Brick_Pillar_Middle",
      "rotation": 3
    },
    {
      "x": 6,
      "y": 11,
      "z": -2,
      "name": "Rock_Basalt_Brick_Pillar_Base",
      "rotation": 11
    },
    {
      "x": 6,
      "y": 12,
      "z": -2,
      "name": "Rock_Basalt_Brick",
      "rotation": 3
    },
    {
      "x": 6,
      "y": 13,
      "z": -2,
      "name": "Rock_Basalt_Brick"
    },
    {
      "x": 6,
      "y": -1,
      "z": -1,
      "name": "Rock_Ice"
    },
    {
      "x": 6,
      "y": 0,
      "z": -1,
      "name": "Rock_Basalt_Brick",
      "rotation": 3
    },
    {
      "x": 6,
      "y": 1,
      "z": -1,
      "name": "Furniture_Ancient_Barrel"
    },
    {
      "x": 6,
      "y": 13,
      "z": -1,
      "name": "Rock_Basalt_Brick"
    },
    {
      "x": 6,
      "y": -1,
      "z": 0,
      "name": "Rock_Ice"
    },
    {
      "x": 6,
      "y": 0,
      "z": 0,
      "name": "Rock_Basalt_Brick",
      "rotation": 3
    },
    {
      "x": 6,
      "y": 1,
      "z": 0,
      "name": "Rock_Basalt_Brick"
    },
    {
      "x": 6,
      "y": 2,
      "z": 0,
      "name": "Rock_Basalt_Brick"
    },
    {
      "x": 6,
      "y": 3,
      "z": 0,
      "name": "Rock_Basalt_Brick"
    },
    {
      "x": 6,
      "y": 4,
      "z": 0,
      "name": "Rock_Basalt_Brick"
    },
    {
      "x": 6,
      "y": 5,
      "z": 0,
      "name": "Rock_Basalt_Brick_Half"
    },
    {
      "x": 6,
      "y": 6,
      "z": 0,
      "name": "Deco_Iron_Bars_Platforms"
    },
    {
      "x": 6,
      "y": 7,
      "z": 0,
      "name": "Deco_Bronze_Railing"
    },
    {
      "x": 6,
      "y": 12,
      "z": 0,
      "name": "Rock_Ice_Icicles",
      "rotation": 8
    },
    {
      "x": 6,
      "y": 13,
      "z": 0,
      "name": "Rock_Basalt_Brick"
    },
    {
      "x": 6,
      "y": -1,
      "z": 1,
      "name": "Rock_Ice"
    },
    {
      "x": 6,
      "y": 0,
      "z": 1,
      "name": "Rock_Basalt_Brick",
      "rotation": 3
    },
    {
      "x": 6,
      "y": 1,
      "z": 1,
      "name": "Rock_Basalt_Brick"
    },
    {
      "x": 6,
      "y": 2,
      "z": 1,
      "name": "Rock_Basalt_Brick"
    },
    {
      "x": 6,
      "y": 3,
      "z": 1,
      "name": "Rock_Basalt_Brick"
    },
    {
      "x": 6,
      "y": 4,
      "z": 1,
      "name": "Rock_Basalt_Brick"
    },
    {
      "x": 6,
      "y": 5,
      "z": 1,
      "name": "Rock_Basalt_Brick_Half"
    },
    {
      "x": 6,
      "y": 6,
      "z": 1,
      "name": "Deco_Iron_Bars_Platforms"
    },
    {
      "x": 6,
      "y": 13,
      "z": 1,
      "name": "Rock_Basalt_Brick"
    },
    {
      "x": 6,
      "y": -1,
      "z": 2,
      "name": "Rock_Ice"
    },
    {
      "x": 6,
      "y": 0,
      "z": 2,
      "name": "Rock_Basalt_Brick",
      "rotation": 3
    },
    {
      "x": 6,
      "y": 1,
      "z": 2,
      "name": "Rock_Basalt_Brick"
    },
    {
      "x": 6,
      "y": 2,
      "z": 2,
      "name": "Rock_Basalt_Brick"
    },
    {
      "x": 6,
      "y": 3,
      "z": 2,
      "name": "Rock_Basalt_Brick"
    },
    {
      "x": 6,
      "y": 4,
      "z": 2,
      "name": "Rock_Basalt_Brick"
    },
    {
      "x": 6,
      "y": 5,
      "z": 2,
      "name": "Rock_Basalt_Brick_Half"
    },
    {
      "x": 6,
      "y": 6,
      "z": 2,
      "name": "Deco_Iron_Bars_Platforms"
    },
    {
      "x": 6,
      "y": 13,
      "z": 2,
      "name": "Rock_Basalt_Brick"
    },
    {
      "x": 6,
      "y": -1,
      "z": 3,
      "name": "Rock_Ice"
    },
    {
      "x": 6,
      "y": 0,
      "z": 3,
      "name": "Rock_Basalt_Brick",
      "rotation": 3
    },
    {
      "x": 6,
      "y": 1,
      "z": 3,
      "name": "Rock_Basalt_Brick"
    },
    {
      "x": 6,
      "y": 2,
      "z": 3,
      "name": "Rock_Basalt_Brick"
    },
    {
      "x": 6,
      "y": 3,
      "z": 3,
      "name": "Rock_Basalt_Brick"
    },
    {
      "x": 6,
      "y": 4,
      "z": 3,
      "name": "Rock_Basalt_Brick"
    },
    {
      "x": 6,
      "y": 5,
      "z": 3,
      "name": "Rock_Basalt_Brick_Half"
    },
    {
      "x": 6,
      "y": 6,
      "z": 3,
      "name": "Deco_Iron_Bars_Platforms"
    },
    {
      "x": 6,
      "y": 7,
      "z": 3,
      "name": "Deco_Bronze_Railing"
    },
    {
      "x": 6,
      "y": 13,
      "z": 3,
      "name": "Rock_Basalt_Brick"
    },
    {
      "x": 6,
      "y": -1,
      "z": 4,
      "name": "Rock_Ice"
    },
    {
      "x": 6,
      "y": 0,
      "z": 4,
      "name": "Rock_Basalt_Brick",
      "rotation": 3
    },
    {
      "x": 6,
      "y": 1,
      "z": 4,
      "name": "Rock_Basalt_Brick"
    },
    {
      "x": 6,
      "y": 2,
      "z": 4,
      "name": "Rock_Basalt_Brick"
    },
    {
      "x": 6,
      "y": 3,
      "z": 4,
      "name": "Rock_Basalt_Brick"
    },
    {
      "x": 6,
      "y": 4,
      "z": 4,
      "name": "Rock_Basalt_Brick"
    },
    {
      "x": 6,
      "y": 5,
      "z": 4,
      "name": "Rock_Basalt_Brick_Half"
    },
    {
      "x": 6,
      "y": 13,
      "z": 4,
      "name": "Rock_Basalt_Brick"
    },
    {
      "x": 6,
      "y": -1,
      "z": 5,
      "name": "Rock_Ice"
    },
    {
      "x": 6,
      "y": 0,
      "z": 5,
      "name": "Rock_Basalt_Brick"
    },
    {
      "x": 6,
      "y": 1,
      "z": 5,
      "name": "Rock_Basalt_Brick"
    },
    {
      "x": 6,
      "y": 2,
      "z": 5,
      "name": "Rock_Basalt_Brick"
    },
    {
      "x": 6,
      "y": 3,
      "z": 5,
      "name": "Rock_Basalt_Brick"
    },
    {
      "x": 6,
      "y": 4,
      "z": 5,
      "name": "Rock_Basalt_Brick"
    },
    {
      "x": 6,
      "y": 5,
      "z": 5,
      "name": "Rock_Basalt_Brick"
    },
    {
      "x": 6,
      "y": 6,
      "z": 5,
      "name": "Rock_Basalt_Brick"
    },
    {
      "x": 6,
      "y": 7,
      "z": 5,
      "name": "Rock_Basalt_Brick"
    },
    {
      "x": 6,
      "y": 8,
      "z": 5,
      "name": "Rock_Basalt_Brick"
    },
    {
      "x": 6,
      "y": 9,
      "z": 5,
      "name": "Rock_Basalt_Brick"
    },
    {
      "x": 6,
      "y": 10,
      "z": 5,
      "name": "Rock_Basalt_Brick"
    },
    {
      "x": 6,
      "y": 11,
      "z": 5,
      "name": "Rock_Basalt_Brick"
    },
    {
      "x": 6,
      "y": 12,
      "z": 5,
      "name": "Rock_Basalt_Brick"
    },
    {
      "x": 6,
      "y": 13,
      "z": 5,
      "name": "Rock_Basalt_Brick"
    },
    {
      "x": 7,
      "y": -1,
      "z": -3,
      "name": "Rock_Ice"
    },
    {
      "x": 7,
      "y": 0,
      "z": -3,
      "name": "Rock_Basalt",
      "rotation": 3
    },
    {
      "x": 7,
      "y": 13,
      "z": -3,
      "name": "Rock_Basalt_Brick"
    },
    {
      "x": 7,
      "y": -1,
      "z": -2,
      "name": "Rock_Ice"
    },
    {
      "x": 7,
      "y": 0,
      "z": -2,
      "name": "Rock_Basalt",
      "rotation": 3
    },
    {
      "x": 7,
      "y": 1,
      "z": -2,
      "name": "Rubble_Basalt",
      "support": 15
    },
    {
      "x": 7,
      "y": 12,
      "z": -2,
      "name": "Rock_Basalt_Brick_Stairs",
      "rotation": 11
    },
    {
      "x": 7,
      "y": 13,
      "z": -2,
      "name": "Rock_Basalt_Brick"
    },
    {
      "x": 7,
      "y": -1,
      "z": -1,
      "name": "Rock_Ice"
    },
    {
      "x": 7,
      "y": 0,
      "z": -1,
      "name": "Rock_Basalt",
      "rotation": 3
    },
    {
      "x": 7,
      "y": 1,
      "z": -1,
      "name": "Rubble_Basalt_Medium",
      "support": 15
    },
    {
      "x": 7,
      "y": 11,
      "z": -1,
      "name": "Rock_Ice_Stalactite_Large",
      "filler": 31744,
      "rotation": 8
    },
    {
      "x": 7,
      "y": 12,
      "z": -1,
      "name": "Rock_Ice_Stalactite_Large",
      "rotation": 8
    },
    {
      "x": 7,
      "y": 13,
      "z": -1,
      "name": "Rock_Basalt_Brick"
    },
    {
      "x": 7,
      "y": -1,
      "z": 0,
      "name": "Rock_Ice"
    },
    {
      "x": 7,
      "y": 0,
      "z": 0,
      "name": "Rock_Basalt",
      "rotation": 3
    },
    {
      "x": 7,
      "y": 1,
      "z": 0,
      "name": "Furniture_Ancient_Crate",
      "rotation": 1
    },
    {
      "x": 7,
      "y": 6,
      "z": 0,
      "name": "Deco_Iron_Bars_Platforms"
    },
    {
      "x": 7,
      "y": 7,
      "z": 0,
      "name": "Deco_Bronze_Railing"
    },
    {
      "x": 7,
      "y": 13,
      "z": 0,
      "name": "Rock_Basalt_Brick"
    },
    {
      "x": 7,
      "y": -1,
      "z": 1,
      "name": "Rock_Ice"
    },
    {
      "x": 7,
      "y": 0,
      "z": 1,
      "name": "Rock_Basalt",
      "rotation": 3
    },
    {
      "x": 7,
      "y": 1,
      "z": 1,
      "name": "Furniture_Ancient_Crate",
      "rotation": 1
    },
    {
      "x": 7,
      "y": 2,
      "z": 1,
      "name": "Furniture_Ancient_Crate",
      "rotation": 1
    },
    {
      "x": 7,
      "y": 4,
      "z": 1,
      "name": "Wood_Deadwood_Planks_Half",
      "rotation": 5
    },
    {
      "x": 7,
      "y": 6,
      "z": 1,
      "name": "Deco_Iron_Bars_Platforms"
    },
    {
      "x": 7,
      "y": 13,
      "z": 1,
      "name": "Rock_Basalt_Brick"
    },
    {
      "x": 7,
      "y": -1,
      "z": 2,
      "name": "Rock_Ice"
    },
    {
      "x": 7,
      "y": 0,
      "z": 2,
      "name": "Rock_Basalt",
      "rotation": 3
    },
    {
      "x": 7,
      "y": 1,
      "z": 2,
      "name": "Furniture_Ancient_Crate",
      "rotation": 1
    },
    {
      "x": 7,
      "y": 2,
      "z": 2,
      "name": "Furniture_Ancient_Crate",
      "rotation": 1
    },
    {
      "x": 7,
      "y": 4,
      "z": 2,
      "name": "Wood_Deadwood_Planks_Half",
      "rotation": 5
    },
    {
      "x": 7,
      "y": 6,
      "z": 2,
      "name": "Deco_Iron_Bars_Platforms"
    },
    {
      "x": 7,
      "y": 11,
      "z": 2,
      "name": "Rock_Ice_Stalactite_Large",
      "filler": 31744,
      "rotation": 8
    },
    {
      "x": 7,
      "y": 12,
      "z": 2,
      "name": "Rock_Ice_Stalactite_Large",
      "rotation": 8
    },
    {
      "x": 7,
      "y": 13,
      "z": 2,
      "name": "Rock_Basalt_Brick"
    },
    {
      "x": 7,
      "y": -1,
      "z": 3,
      "name": "Rock_Ice"
    },
    {
      "x": 7,
      "y": 0,
      "z": 3,
      "name": "Rock_Basalt",
      "rotation": 3
    },
    {
      "x": 7,
      "y": 1,
      "z": 3,
      "name": "Furniture_Ancient_Crate",
      "rotation": 1
    },
    {
      "x": 7,
      "y": 2,
      "z": 3,
      "name": "Furniture_Ancient_Crate",
      "rotation": 1
    },
    {
      "x": 7,
      "y": 4,
      "z": 3,
      "name": "Wood_Deadwood_Planks_Half",
      "rotation": 5
    },
    {
      "x": 7,
      "y": 6,
      "z": 3,
      "name": "Deco_Iron_Bars_Platforms"
    },
    {
      "x": 7,
      "y": 7,
      "z": 3,
      "name": "Deco_Bronze_Railing"
    },
    {
      "x": 7,
      "y": 13,
      "z": 3,
      "name": "Rock_Basalt_Brick"
    },
    {
      "x": 7,
      "y": -1,
      "z": 4,
      "name": "Rock_Ice"
    },
    {
      "x": 7,
      "y": 0,
      "z": 4,
      "name": "Rock_Basalt",
      "rotation": 3
    },
    {
      "x": 7,
      "y": 1,
      "z": 4,
      "name": "Furniture_Ancient_Crate",
      "rotation": 1
    },
    {
      "x": 7,
      "y": 4,
      "z": 4,
      "name": "Wood_Deadwood_Planks_Half",
      "rotation": 5
    },
    {
      "x": 7,
      "y": 13,
      "z": 4,
      "name": "Rock_Basalt_Brick"
    },
    {
      "x": 7,
      "y": -1,
      "z": 5,
      "name": "Rock_Ice"
    },
    {
      "x": 7,
      "y": 0,
      "z": 5,
      "name": "Rock_Basalt_Brick"
    },
    {
      "x": 7,
      "y": 1,
      "z": 5,
      "name": "Rock_Basalt_Brick"
    },
    {
      "x": 7,
      "y": 2,
      "z": 5,
      "name": "Rock_Basalt_Brick"
    },
    {
      "x": 7,
      "y": 3,
      "z": 5,
      "name": "Rock_Basalt_Brick"
    },
    {
      "x": 7,
      "y": 4,
      "z": 5,
      "name": "Rock_Basalt_Brick"
    },
    {
      "x": 7,
      "y": 5,
      "z": 5,
      "name": "Rock_Basalt_Brick"
    },
    {
      "x": 7,
      "y": 6,
      "z": 5,
      "name": "Rock_Basalt_Brick"
    },
    {
      "x": 7,
      "y": 7,
      "z": 5,
      "name": "Rock_Basalt_Brick"
    },
    {
      "x": 7,
      "y": 8,
      "z": 5,
      "name": "Rock_Basalt_Brick"
    },
    {
      "x": 7,
      "y": 9,
      "z": 5,
      "name": "Rock_Basalt_Brick"
    },
    {
      "x": 7,
      "y": 10,
      "z": 5,
      "name": "Rock_Basalt_Brick"
    },
    {
      "x": 7,
      "y": 11,
      "z": 5,
      "name": "Rock_Basalt_Brick"
    },
    {
      "x": 7,
      "y": 12,
      "z": 5,
      "name": "Rock_Basalt_Brick"
    },
    {
      "x": 7,
      "y": 13,
      "z": 5,
      "name": "Rock_Basalt_Brick"
    },
    {
      "x": 8,
      "y": -1,
      "z": -3,
      "name": "Rock_Ice"
    },
    {
      "x": 8,
      "y": 0,
      "z": -3,
      "name": "Rock_Basalt",
      "rotation": 3
    },
    {
      "x": 8,
      "y": 1,
      "z": -3,
      "name": "Empty"
    },
    {
      "x": 8,
      "y": 13,
      "z": -3,
      "name": "Rock_Basalt_Brick"
    },
    {
      "x": 8,
      "y": -1,
      "z": -2,
      "name": "Rock_Ice"
    },
    {
      "x": 8,
      "y": 0,
      "z": -2,
      "name": "Rock_Basalt",
      "rotation": 3
    },
    {
      "x": 8,
      "y": 12,
      "z": -2,
      "name": "Rock_Basalt_Brick_Half",
      "rotation": 11
    },
    {
      "x": 8,
      "y": 13,
      "z": -2,
      "name": "Rock_Basalt_Brick"
    },
    {
      "x": 8,
      "y": -1,
      "z": -1,
      "name": "Rock_Ice"
    },
    {
      "x": 8,
      "y": 0,
      "z": -1,
      "name": "Rock_Basalt",
      "rotation": 3
    },
    {
      "x": 8,
      "y": 13,
      "z": -1,
      "name": "Rock_Basalt_Brick"
    },
    {
      "x": 8,
      "y": -1,
      "z": 0,
      "name": "Rock_Ice"
    },
    {
      "x": 8,
      "y": 0,
      "z": 0,
      "name": "Rock_Basalt",
      "rotation": 3
    },
    {
      "x": 8,
      "y": 1,
      "z": 0,
      "name": "Furniture_Ancient_Barrel"
    },
    {
      "x": 8,
      "y": 6,
      "z": 0,
      "name": "Deco_Iron_Bars_Platforms"
    },
    {
      "x": 8,
      "y": 7,
      "z": 0,
      "name": "Deco_Bronze_Railing"
    },
    {
      "x": 8,
      "y": 13,
      "z": 0,
      "name": "Rock_Basalt_Brick"
    },
    {
      "x": 8,
      "y": -1,
      "z": 1,
      "name": "Rock_Ice"
    },
    {
      "x": 8,
      "y": 0,
      "z": 1,
      "name": "Rock_Basalt",
      "rotation": 3
    },
    {
      "x": 8,
      "y": 1,
      "z": 1,
      "name": "Furniture_Ancient_Crate",
      "rotation": 1
    },
    {
      "x": 8,
      "y": 6,
      "z": 1,
      "name": "Deco_Iron_Bars_Platforms"
    },
    {
      "x": 8,
      "y": 13,
      "z": 1,
      "name": "Rock_Basalt_Brick"
    },
    {
      "x": 8,
      "y": -1,
      "z": 2,
      "name": "Rock_Ice"
    },
    {
      "x": 8,
      "y": 0,
      "z": 2,
      "name": "Rock_Basalt",
      "rotation": 3
    },
    {
      "x": 8,
      "y": 1,
      "z": 2,
      "name": "Furniture_Ancient_Crate",
      "rotation": 1
    },
    {
      "x": 8,
      "y": 2,
      "z": 2,
      "name": "Furniture_Ancient_Crate",
      "rotation": 1
    },
    {
      "x": 8,
      "y": 6,
      "z": 2,
      "name": "Deco_Iron_Bars_Platforms"
    },
    {
      "x": 8,
      "y": 13,
      "z": 2,
      "name": "Rock_Basalt_Brick"
    },
    {
      "x": 8,
      "y": -1,
      "z": 3,
      "name": "Rock_Ice"
    },
    {
      "x": 8,
      "y": 0,
      "z": 3,
      "name": "Rock_Basalt",
      "rotation": 3
    },
    {
      "x": 8,
      "y": 1,
      "z": 3,
      "name": "Furniture_Ancient_Crate",
      "rotation": 1
    },
    {
      "x": 8,
      "y": 6,
      "z": 3,
      "name": "Deco_Iron_Bars_Platforms"
    },
    {
      "x": 8,
      "y": 7,
      "z": 3,
      "name": "Deco_Bronze_Railing"
    },
    {
      "x": 8,
      "y": 13,
      "z": 3,
      "name": "Rock_Basalt_Brick"
    },
    {
      "x": 8,
      "y": -1,
      "z": 4,
      "name": "Rock_Ice"
    },
    {
      "x": 8,
      "y": 0,
      "z": 4,
      "name": "Rock_Basalt",
      "rotation": 3
    },
    {
      "x": 8,
      "y": 13,
      "z": 4,
      "name": "Rock_Basalt_Brick"
    },
    {
      "x": 8,
      "y": -1,
      "z": 5,
      "name": "Rock_Ice"
    },
    {
      "x": 8,
      "y": 0,
      "z": 5,
      "name": "Rock_Basalt_Brick"
    },
    {
      "x": 8,
      "y": 1,
      "z": 5,
      "name": "Rock_Basalt_Brick"
    },
    {
      "x": 8,
      "y": 2,
      "z": 5,
      "name": "Rock_Basalt_Brick"
    },
    {
      "x": 8,
      "y": 3,
      "z": 5,
      "name": "Rock_Basalt_Brick"
    },
    {
      "x": 8,
      "y": 4,
      "z": 5,
      "name": "Rock_Basalt_Brick"
    },
    {
      "x": 8,
      "y": 5,
      "z": 5,
      "name": "Rock_Basalt_Brick"
    },
    {
      "x": 8,
      "y": 6,
      "z": 5,
      "name": "Rock_Basalt_Brick"
    },
    {
      "x": 8,
      "y": 7,
      "z": 5,
      "name": "Rock_Basalt_Brick"
    },
    {
      "x": 8,
      "y": 8,
      "z": 5,
      "name": "Rock_Basalt_Brick"
    },
    {
      "x": 8,
      "y": 9,
      "z": 5,
      "name": "Rock_Basalt_Brick"
    },
    {
      "x": 8,
      "y": 10,
      "z": 5,
      "name": "Rock_Basalt_Brick"
    },
    {
      "x": 8,
      "y": 11,
      "z": 5,
      "name": "Rock_Basalt_Brick"
    },
    {
      "x": 8,
      "y": 12,
      "z": 5,
      "name": "Rock_Basalt_Brick"
    },
    {
      "x": 8,
      "y": 13,
      "z": 5,
      "name": "Rock_Basalt_Brick"
    }
  ],
  "entities": [
    {
      "Components": {
        "EffectController": {},
        "DisplayName": {
          "DisplayName": {
