{
  "version": 8,
  "blockIdVersion": 11,
  "anchorX": -6,
  "anchorY": 1,
  "anchorZ": -4,
  "blocks": [
    {
      "x": -6,
      "y": 0,
      "z": -4,
      "name": "Rock_Basalt",
      "rotation": 2
    },
    {
      "x": -6,
      "y": 1,
      "z": -4,
      "name": "Empty",
      "rotation": 2
    },
    {
      "x": -6,
      "y": 0,
      "z": -3,
      "name": "Rock_Basalt",
      "rotation": 2
    },
    {
      "x": -6,
      "y": 1,
      "z": -3,
      "name": "Furniture_Ancient_Barrel"
    },
    {
      "x": -6,
      "y": 7,
      "z": -3,
      "name": "Rock_Basalt_Brick",
      "rotation": 2
    },
    {
      "x": -6,
      "y": 0,
      "z": -2,
      "name": "Rock_Basalt"
    },
    {
      "x": -6,
      "y": 1,
      "z": -2,
      "name": "Rock_Basalt_Brick",
      "rotation": 2
    },
    {
      "x": -6,
      "y": 2,
      "z": -2,
      "name": "Rock_Basalt_Brick",
      "rotation": 2
    },
    {
      "x": -6,
      "y": 3,
      "z": -2,
      "name": "Rock_Basalt_Brick",
      "rotation": 2
    },
    {
      "x": -6,
      "y": 4,
      "z": -2,
      "name": "Rock_Basalt_Brick",
      "rotation": 2
    },
    {
      "x": -6,
      "y": 5,
      "z": -2,
      "name": "Rock_Basalt_Brick",
      "rotation": 2
    },
    {
      "x": -6,
      "y": 6,
      "z": -2,
      "name": "Rock_Basalt_Brick",
      "rotation": 2
    },
    {
      "x": -6,
      "y": 7,
      "z": -2,
      "name": "Rock_Basalt_Brick",
      "rotation": 2
    },
    {
      "x": -6,
      "y": 0,
      "z": -1,
      "name": "Rock_Basalt",
      "rotation": 2
    },
    {
      "x": -6,
      "y": 1,
      "z": -1,
      "name": "Furniture_Ancient_Crate",
      "rotation": 1
    },
    {
      "x": -6,
      "y": 2,
      "z": -1,
      "name": "Furniture_Ancient_Crate",
      "rotation": 1
    },
    {
      "x": -6,
      "y": 4,
      "z": -1,
      "name": "Deco_SpiderWeb_Flat",
      "support": 15,
      "rotation": 5
    },
    {
      "x": -6,
      "y": 5,
      "z": -1,
      "name": "Deco_SpiderWeb_Full",
      "support": 15
    },
    {
      "x": -6,
      "y": 6,
      "z": -1,
      "name": "Wood_Deadwood_Planks_Half",
      "rotation": 5
    },
    {
      "x": -6,
      "y": 7,
      "z": -1,
      "name": "Rock_Basalt_Brick",
      "rotation": 2
    },
    {
      "x": -6,
      "y": 0,
      "z": 0,
      "name": "Rock_Basalt"
    },
    {
      "x": -6,
      "y": 1,
      "z": 0,
      "name": "Furniture_Ancient_Crate",
      "rotation": 1
    },
    {
      "x": -6,
      "y": 5,
      "z": 0,
      "name": "Deco_SpiderWeb_Flat",
      "support": 15,
      "rotation": 5
    },
    {
      "x": -6,
      "y": 6,
      "z": 0,
      "name": "Wood_Deadwood_Planks_Half",
      "rotation": 5
    },
    {
      "x": -6,
      "y": 7,
      "z": 0,
      "name": "Rock_Basalt_Brick",
      "rotation": 2
    },
    {
      "x": -6,
      "y": 0,
      "z": 1,
      "name": "Rock_Basalt",
      "rotation": 2
    },
    {
      "x": -6,
      "y": 1,
      "z": 1,
      "name": "Furniture_Ancient_Barrel"
    },
    {
      "x": -6,
      "y": 6,
      "z": 1,
      "name": "Wood_Deadwood_Planks_Half",
      "rotation": 5
    },
    {
      "x": -6,
      "y": 7,
      "z": 1,
      "name": "Rock_Basalt_Brick",
      "rotation": 2
    },
    {
      "x": -6,
      "y": 0,
      "z": 2,
      "name": "Rock_Basalt",
      "rotation": 2
    },
    {
      "x": -6,
      "y": 1,
      "z": 2,
      "name": "Block_Spawner_Block",
      "components": {
        "Components": {
          "PlacedByInteraction": {
            "WhoPlacedUuid": {
              "$binary": "B1yBGZcjQ2KREo5yyLGY0g==",
              "$type": "04"
            }
          },
          "BlockSpawner": {
            "BlockSpawnerId": "Zone3_Outlander_Tier2"
          }
        }
      },
      "rotation": 1
    },
    {
      "x": -6,
      "y": 2,
      "z": 2,
      "name": "Furniture_Ancient_Platform"
    },
    {
      "x": -6,
      "y": 3,
      "z": 2,
      "name": "Furniture_Ancient_Candle"
    },
    {
      "x": -6,
      "y": 6,
      "z": 2,
      "name": "Wood_Deadwood_Planks_Half",
      "rotation": 5
    },
    {
      "x": -6,
      "y": 7,
      "z": 2,
      "name": "Rock_Basalt_Brick",
      "rotation": 2
    },
    {
      "x": -6,
      "y": 0,
      "z": 3,
      "name": "Rock_Basalt",
      "rotation": 2
    },
    {
      "x": -6,
      "y": 1,
      "z": 3,
      "name": "Rubble_Basalt",
      "support": 15
    },
    {
      "x": -6,
      "y": 2,
      "z": 3,
      "name": "Furniture_Ancient_Platform"
    },
    {
      "x": -6,
      "y": 3,
      "z": 3,
      "name": "Deco_SpiderWeb_Full",
      "support": 15
    },
    {
      "x": -6,
      "y": 6,
      "z": 3,
      "name": "Wood_Deadwood_Planks_Half",
      "rotation": 5
    },
    {
      "x": -6,
      "y": 7,
      "z": 3,
      "name": "Rock_Basalt_Brick",
      "rotation": 2
    },
    {
      "x": -6,
      "y": 0,
      "z": 4,
      "name": "Rock_Basalt",
      "rotation": 2
    },
    {
      "x": -6,
      "y": 1,
      "z": 4,
      "name": "Furniture_Ancient_Barrel"
    },
    {
      "x": -6,
      "y": 2,
      "z": 4,
      "name": "Furniture_Ancient_Platform"
    },
    {
      "x": -6,
      "y": 3,
      "z": 4,
      "name": "Deco_SpiderWeb_Full",
      "support": 15
    },
    {
      "x": -6,
      "y": 4,
      "z": 4,
      "name": "Deco_SpiderWeb_Full",
      "support": 15
    },
    {
      "x": -6,
      "y": 5,
      "z": 4,
      "name": "Deco_SpiderWeb_Flat",
      "support": 15,
      "rotation": 6
    },
    {
      "x": -6,
      "y": 6,
      "z": 4,
      "name": "Wood_Deadwood_Planks_Half",
      "rotation": 5
    },
    {
      "x": -6,
      "y": 7,
      "z": 4,
      "name": "Rock_Basalt_Brick",
      "rotation": 2
    },
    {
      "x": -6,
      "y": 0,
      "z": 5,
      "name": "Rock_Basalt_Brick",
      "rotation": 2
    },
    {
      "x": -6,
      "y": 1,
      "z": 5,
      "name": "Rock_Basalt_Brick",
      "rotation": 2
    },
    {
      "x": -6,
      "y": 2,
      "z": 5,
      "name": "Rock_Basalt_Brick",
      "rotation": 2
    },
    {
      "x": -6,
      "y": 3,
      "z": 5,
      "name": "Rock_Basalt_Brick",
      "rotation": 2
    },
    {
      "x": -6,
      "y": 4,
      "z": 5,
      "name": "Rock_Basalt_Brick",
      "rotation": 2
    },
    {
      "x": -6,
      "y": 5,
      "z": 5,
      "name": "Rock_Basalt_Brick",
      "rotation": 2
    },
    {
      "x": -6,
      "y": 6,
      "z": 5,
      "name": "Rock_Basalt_Brick",
      "rotation": 2
    },
    {
      "x": -6,
      "y": 7,
      "z": 5,
      "name": "Rock_Basalt_Brick",
      "rotation": 2
    },
    {
      "x": -5,
      "y": 0,
      "z": -4,
      "name": "Rock_Basalt",
      "rotation": 2
    },
    {
      "x": -5,
      "y": 0,
      "z": -3,
      "name": "Rock_Basalt",
      "rotation": 2
    },
    {
      "x": -5,
      "y": 7,
      "z": -3,
      "name": "Rock_Basalt_Brick",
      "rotation": 2
    },
    {
      "x": -5,
      "y": 0,
      "z": -2,
      "name": "Rock_Basalt"
    },
    {
      "x": -5,
      "y": 1,
      "z": -2,
      "name": "Rock_Basalt_Brick_Half",
      "rotation": 5
    },
    {
      "x": -5,
      "y": 2,
      "z": -2,
      "name": "Rock_Basalt_Brick_Half",
      "rotation": 5
    },
    {
      "x": -5,
      "y": 3,
      "z": -2,
      "name": "Rock_Basalt_Brick_Half",
      "rotation": 5
    },
    {
      "x": -5,
      "y": 4,
      "z": -2,
      "name": "Rock_Basalt_Brick_Half",
      "rotation": 5
    },
    {
      "x": -5,
      "y": 5,
      "z": -2,
      "name": "Rock_Basalt_Brick"
    },
    {
      "x": -5,
      "y": 6,
      "z": -2,
      "name": "Rock_Basalt_Brick",
      "rotation": 2
    },
    {
      "x": -5,
      "y": 7,
      "z": -2,
      "name": "Rock_Basalt_Brick",
      "rotation": 2
    },
    {
      "x": -5,
      "y": 0,
      "z": -1,
      "name": "Rock_Basalt",
      "rotation": 2
    },
    {
      "x": -5,
      "y": 1,
      "z": -1,
      "name": "Furniture_Ancient_Barrel"
    },
    {
      "x": -5,
      "y": 5,
      "z": -1,
      "name": "Deco_SpiderWeb",
      "support": 15,
      "rotation": 10
    },
    {
      "x": -5,
      "y": 6,
      "z": -1,
      "name": "Deco_SpiderWeb_Full",
      "support": 15
    },
    {
      "x": -5,
      "y": 7,
      "z": -1,
      "name": "Rock_Basalt_Brick",
      "rotation": 2
    },
    {
      "x": -5,
      "y": 0,
      "z": 0,
      "name": "Rock_Basalt",
      "rotation": 2
    },
    {
      "x": -5,
      "y": 1,
      "z": 0,
      "name": "Deco_SpiderWeb_Flat",
      "support": 15
    },
    {
      "x": -5,
      "y": 6,
      "z": 0,
      "name": "Deco_SpiderWeb_Flat",
      "support": 15,
      "rotation": 8
    },
    {
      "x": -5,
      "y": 7,
      "z": 0,
      "name": "Rock_Basalt_Brick",
      "rotation": 2
    },
    {
      "x": -5,
      "y": 0,
      "z": 1,
      "name": "Rock_Basalt",
      "rotation": 2
    },
    {
      "x": -5,
      "y": 7,
      "z": 1,
      "name": "Rock_Basalt_Brick",
      "rotation": 2
    },
    {
      "x": -5,
      "y": 0,
      "z": 2,
      "name": "Rock_Basalt",
      "rotation": 2
    },
    {
      "x": -5,
      "y": 6,
      "z": 2,
      "name": "Rock_Ice_Icicles",
      "rotation": 8
    },
    {
      "x": -5,
      "y": 7,
      "z": 2,
      "name": "Rock_Basalt_Brick",
      "rotation": 2
    },
    {
      "x": -5,
      "y": 0,
      "z": 3,
      "name": "Rock_Basalt",
      "rotation": 2
    },
    {
      "x": -5,
      "y": 7,
      "z": 3,
      "name": "Rock_Basalt_Brick",
      "rotation": 2
    },
    {
      "x": -5,
      "y": 0,
      "z": 4,
      "name": "Rock_Basalt",
      "rotation": 2
    },
    {
      "x": -5,
      "y": 1,
      "z": 4,
      "name": "Deco_SpiderWeb",
      "support": 15,
      "rotation": 2
    },
    {
      "x": -5,
      "y": 3,
      "z": 4,
      "name": "Deco_SpiderWeb",
      "support": 15,
      "rotation": 8
    },
    {
      "x": -5,
      "y": 4,
      "z": 4,
      "name": "Deco_SpiderWeb_Full",
      "support": 15
    },
    {
      "x": -5,
      "y": 5,
      "z": 4,
      "name": "Deco_SpiderWeb",
      "support": 15,
      "rotation": 2
    },
    {
      "x": -5,
      "y": 6,
      "z": 4,
      "name": "Deco_SpiderWeb_Flat",
      "support": 15,
      "rotation": 6
    },
    {
      "x": -5,
      "y": 7,
      "z": 4,
      "name": "Rock_Basalt_Brick",
      "rotation": 2
    },
    {
      "x": -5,
      "y": 0,
      "z": 5,
      "name": "Rock_Basalt_Brick",
      "rotation": 2
    },
    {
      "x": -5,
      "y": 1,
      "z": 5,
      "name": "Rock_Basalt_Brick",
      "rotation": 2
    },
    {
      "x": -5,
      "y": 2,
      "z": 5,
      "name": "Rock_Basalt_Brick",
      "rotation": 2
    },
    {
      "x": -5,
      "y": 3,
      "z": 5,
      "name": "Rock_Basalt_Brick",
      "rotation": 2
    },
    {
      "x": -5,
      "y": 4,
      "z": 5,
      "name": "Rock_Basalt_Brick",
      "rotation": 2
    },
    {
      "x": -5,
      "y": 5,
      "z": 5,
      "name": "Rock_Basalt_Brick",
      "rotation": 2
    },
    {
      "x": -5,
      "y": 6,
      "z": 5,
      "name": "Rock_Basalt_Brick",
      "rotation": 2
    },
    {
      "x": -5,
      "y": 7,
      "z": 5,
      "name": "Rock_Basalt_Brick",
      "rotation": 2
    },
    {
      "x": -4,
      "y": 0,
      "z": -4,
      "name": "Rock_Basalt",
      "rotation": 2
    },
    {
      "x": -4,
      "y": 0,
      "z": -3,
      "name": "Rock_Basalt",
      "rotation": 2
    },
    {
      "x": -4,
      "y": 7,
      "z": -3,
      "name": "Rock_Basalt_Brick",
      "rotation": 2
    },
    {
      "x": -4,
      "y": 0,
      "z": -2,
      "name": "Rock_Basalt"
    },
    {
      "x": -4,
      "y": 5,
      "z": -2,
      "name": "Rock_Basalt_Brick_Half",
      "rotation": 8
    },
    {
      "x": -4,
      "y": 6,
      "z": -2,
      "name": "Rock_Basalt_Brick",
      "rotation": 2
    },
    {
      "x": -4,
      "y": 7,
      "z": -2,
      "name": "Rock_Basalt_Brick",
      "rotation": 2
    },
    {
      "x": -4,
      "y": 0,
      "z": -1,
      "name": "Rock_Basalt",
      "rotation": 2
    },
    {
      "x": -4,
      "y": 6,
      "z": -1,
      "name": "Deco_SpiderWeb_Flat",
      "support": 15,
      "rotation": 8
    },
    {
      "x": -4,
      "y": 7,
      "z": -1,
      "name": "Rock_Basalt_Brick",
      "rotation": 2
    },
    {
      "x": -4,
      "y": 0,
      "z": 0,
      "name": "Rock_Basalt",
      "rotation": 2
    },
    {
      "x": -4,
      "y": 7,
      "z": 0,
      "name": "Rock_Basalt_Brick",
      "rotation": 2
    },
    {
      "x": -4,
      "y": 0,
      "z": 1,
      "name": "Rock_Basalt",
      "rotation": 2
    },
    {
      "x": -4,
      "y": 7,
      "z": 1,
      "name": "Rock_Basalt_Brick",
      "rotation": 2
    },
    {
      "x": -4,
      "y": 0,
      "z": 2,
      "name": "Rock_Basalt",
      "rotation": 2
    },
    {
      "x": -4,
      "y": 7,
      "z": 2,
      "name": "Rock_Basalt_Brick",
      "rotation": 2
    },
    {
      "x": -4,
      "y": 0,
      "z": 3,
      "name": "Rock_Basalt",
      "rotation": 2
    },
    {
      "x": -4,
      "y": 1,
      "z": 3,
      "name": "Furniture_Ancient_Barrel"
    },
    {
      "x": -4,
      "y": 6,
      "z": 3,
      "name": "Rock_Ice_Icicles",
      "rotation": 8
    },
    {
      "x": -4,
      "y": 7,
      "z": 3,
      "name": "Rock_Basalt_Brick",
      "rotation": 2
    },
    {
      "x": -4,
      "y": 0,
      "z": 4,
      "name": "Rock_Basalt",
      "rotation": 2
    },
    {
      "x": -4,
      "y": 1,
      "z": 4,
      "name": "Furniture_Ancient_Crate",
      "rotation": 2
    },
    {
      "x": -4,
      "y": 4,
      "z": 4,
      "name": "Deco_SpiderWeb_Flat",
      "support": 15,
      "rotation": 6
    },
    {
      "x": -4,
      "y": 5,
      "z": 4,
      "name": "Deco_SpiderWeb_Flat",
      "support": 15,
      "rotation": 6
    },
    {
      "x": -4,
      "y": 7,
      "z": 4,
      "name": "Rock_Basalt_Brick",
      "rotation": 2
    },
    {
      "x": -4,
      "y": 0,
      "z": 5,
      "name": "Rock_Basalt_Brick",
      "rotation": 2
    },
    {
      "x": -4,
      "y": 1,
      "z": 5,
      "name": "Rock_Basalt_Brick",
      "rotation": 2
    },
    {
      "x": -4,
      "y": 2,
      "z": 5,
      "name": "Rock_Basalt_Brick",
      "rotation": 2
    },
    {
      "x": -4,
      "y": 3,
      "z": 5,
      "name": "Rock_Basalt_Brick",
      "rotation": 2
    },
    {
      "x": -4,
      "y": 4,
      "z": 5,
      "name": "Rock_Basalt_Brick",
      "rotation": 2
    },
    {
      "x": -4,
      "y": 5,
      "z": 5,
      "name": "Rock_Basalt_Brick",
      "rotation": 2
    },
    {
      "x": -4,
      "y": 6,
      "z": 5,
      "name": "Rock_Basalt_Brick",
      "rotation": 2
    },
    {
      "x": -4,
      "y": 7,
      "z": 5,
      "name": "Rock_Basalt_Brick",
      "rotation": 2
    },
    {
      "x": -3,
      "y": 0,
      "z": -4,
      "name": "Rock_Basalt",
      "rotation": 2
    },
    {
      "x": -3,
      "y": 0,
      "z": -3,
      "name": "Rock_Basalt",
      "rotation": 2
    },
    {
      "x": -3,
      "y": 7,
      "z": -3,
      "name": "Rock_Basalt_Brick",
      "rotation": 2
    },
    {
      "x": -3,
      "y": 0,
      "z": -2,
      "name": "Rock_Basalt"
    },
    {
      "x": -3,
      "y": 6,
      "z": -2,
      "name": "Rock_Basalt_Brick",
      "rotation": 2
    },
    {
      "x": -3,
      "y": 7,
      "z": -2,
      "name": "Rock_Basalt_Brick",
      "rotation": 2
    },
    {
      "x": -3,
      "y": 0,
      "z": -1,
      "name": "Rock_Basalt",
      "rotation": 2
    },
    {
      "x": -3,
      "y": 1,
      "z": -1,
      "name": "Rock_Ice_Icicles"
    },
    {
      "x": -3,
      "y": 7,
      "z": -1,
      "name": "Rock_Basalt_Brick",
      "rotation": 2
    },
    {
      "x": -3,
      "y": 0,
      "z": 0,
      "name": "Rock_Basalt",
      "rotation": 2
    },
    {
      "x": -3,
      "y": 6,
      "z": 0,
      "name": "Rock_Ice_Icicles",
      "rotation": 8
    },
    {
      "x": -3,
      "y": 7,
      "z": 0,
      "name": "Rock_Basalt_Brick",
      "rotation": 2
    },
    {
      "x": -3,
      "y": 0,
      "z": 1,
      "name": "Rock_Basalt",
      "rotation": 2
    },
    {
      "x": -3,
      "y": 1,
      "z": 1,
      "name": "Furniture_Ancient_Barrel"
    },
    {
      "x": -3,
      "y": 6,
      "z": 1,
      "name": "Wood_Deadwood_Planks_Half",
      "rotation": 7
    },
    {
      "x": -3,
      "y": 7,
      "z": 1,
      "name": "Rock_Basalt_Brick",
      "rotation": 2
    },
    {
      "x": -3,
      "y": 0,
      "z": 2,
      "name": "Rock_Basalt",
      "rotation": 2
    },
    {
      "x": -3,
      "y": 1,
      "z": 2,
      "name": "Furniture_Ancient_Crate",
      "rotation": 3
    },
    {
      "x": -3,
      "y": 2,
      "z": 2,
      "name": "Deco_SpiderWeb_Flat",
      "support": 15,
      "rotation": 7
    },
    {
      "x": -3,
      "y": 3,
      "z": 2,
      "name": "Furniture_Ancient_Platform"
    },
    {
      "x": -3,
      "y": 6,
      "z": 2,
      "name": "Wood_Deadwood_Planks_Half",
      "rotation": 7
    },
    {
      "x": -3,
      "y": 7,
      "z": 2,
      "name": "Rock_Basalt_Brick",
      "rotation": 2
    },
    {
      "x": -3,
      "y": 0,
      "z": 3,
      "name": "Rock_Basalt",
      "rotation": 2
    },
    {
      "x": -3,
      "y": 1,
      "z": 3,
      "name": "Furniture_Ancient_Crate",
      "rotation": 3
    },
    {
      "x": -3,
      "y": 2,
      "z": 3,
      "name": "Deco_SpiderWeb",
      "support": 15,
      "rotation": 3
    },
    {
      "x": -3,
      "y": 3,
      "z": 3,
      "name": "Furniture_Ancient_Platform"
    },
    {
      "x": -3,
      "y": 4,
      "z": 3,
      "name": "Rock_Ice_Icicles"
    },
    {
      "x": -3,
      "y": 6,
      "z": 3,
      "name": "Wood_Deadwood_Planks_Half",
      "rotation": 7
    },
    {
      "x": -3,
      "y": 7,
      "z": 3,
      "name": "Rock_Basalt_Brick",
      "rotation": 2
    },
    {
      "x": -3,
      "y": 0,
      "z": 4,
      "name": "Rock_Basalt",
      "rotation": 2
    },
    {
      "x": -3,
      "y": 1,
      "z": 4,
      "name": "Furniture_Ancient_Crate",
      "rotation": 2
    },
    {
      "x": -3,
      "y": 2,
      "z": 4,
      "name": "Furniture_Ancient_Crate",
      "rotation": 2
    },
    {
      "x": -3,
      "y": 3,
      "z": 4,
      "name": "Furniture_Ancient_Platform"
    },
    {
      "x": -3,
      "y": 4,
      "z": 4,
      "name": "Deco_Book_Pile_Small",
      "rotation": 2
    },
    {
      "x": -3,
      "y": 6,
      "z": 4,
      "name": "Wood_Deadwood_Planks_Half",
      "rotation": 7
    },
    {
      "x": -3,
      "y": 7,
      "z": 4,
      "name": "Rock_Basalt_Brick",
      "rotation": 2
    },
    {
      "x": -3,
      "y": 0,
      "z": 5,
      "name": "Rock_Basalt_Brick",
      "rotation": 2
    },
    {
      "x": -3,
      "y": 1,
      "z": 5,
      "name": "Rock_Basalt_Brick",
      "rotation": 2
    },
    {
      "x": -3,
      "y": 2,
      "z": 5,
      "name": "Rock_Basalt_Brick",
      "rotation": 2
    },
    {
      "x": -3,
      "y": 3,
      "z": 5,
      "name": "Rock_Basalt_Brick",
      "rotation": 2
    },
    {
      "x": -3,
      "y": 4,
      "z": 5,
      "name": "Rock_Basalt_Brick",
      "rotation": 2
    },
    {
      "x": -3,
      "y": 5,
      "z": 5,
      "name": "Rock_Basalt_Brick",
      "rotation": 2
    },
    {
      "x": -3,
      "y": 6,
      "z": 5,
      "name": "Rock_Basalt_Brick",
      "rotation": 2
    },
    {
      "x": -3,
      "y": 7,
      "z": 5,
      "name": "Rock_Basalt_Brick",
      "rotation": 2
    },
    {
      "x": -2,
      "y": 0,
      "z": -4,
      "name": "Rock_Basalt",
      "rotation": 2
    },
    {
      "x": -2,
      "y": 0,
      "z": -3,
      "name": "Rock_Basalt",
      "rotation": 2
    },
    {
      "x": -2,
      "y": 7,
      "z": -3,
      "name": "Rock_Basalt_Brick",
      "rotation": 2
    },
    {
      "x": -2,
      "y": 0,
      "z": -2,
      "name": "Rock_Basalt"
    },
    {
      "x": -2,
      "y": 6,
      "z": -2,
      "name": "Rock_Basalt_Brick",
      "rotation": 2
    },
    {
      "x": -2,
      "y": 7,
      "z": -2,
      "name": "Rock_Basalt_Brick",
      "rotation": 2
    },
    {
      "x": -2,
      "y": 0,
      "z": -1,
      "name": "Rock_Basalt",
      "rotation": 2
    },
    {
      "x": -2,
      "y": 7,
      "z": -1,
      "name": "Rock_Basalt_Brick",
      "rotation": 2
    },
    {
      "x": -2,
      "y": 0,
      "z": 0,
      "name": "Rock_Basalt",
      "rotation": 2
    },
    {
      "x": -2,
      "y": 1,
      "z": 0,
      "name": "Rock_Ice_Stalactite_Large"
    },
    {
      "x": -2,
      "y": 2,
      "z": 0,
      "name": "Rock_Ice_Stalactite_Large",
      "filler": 1024
    },
    {
      "x": -2,
      "y": 7,
      "z": 0,
      "name": "Rock_Basalt_Brick",
      "rotation": 2
    },
    {
      "x": -2,
      "y": 0,
      "z": 1,
      "name": "Rock_Basalt",
      "rotation": 2
    },
    {
      "x": -2,
      "y": 1,
      "z": 1,
      "name": "Rock_Basalt_Brick_Half",
      "rotation": 6
    },
    {
      "x": -2,
      "y": 2,
      "z": 1,
      "name": "Rock_Basalt_Brick_Half",
      "rotation": 6
    },
    {
      "x": -2,
      "y": 3,
      "z": 1,
      "name": "Rock_Basalt_Brick_Half",
      "rotation": 6
    },
    {
      "x": -2,
      "y": 4,
      "z": 1,
      "name": "Rock_Basalt_Brick_Half",
      "rotation": 6
    },
    {
      "x": -2,
      "y": 5,
      "z": 1,
      "name": "Rock_Basalt_Brick"
    },
    {
      "x": -2,
      "y": 6,
      "z": 1,
      "name": "Rock_Basalt_Brick"
    },
    {
      "x": -2,
      "y": 7,
      "z": 1,
      "name": "Rock_Basalt_Brick",
      "rotation": 2
    },
    {
      "x": -2,
      "y": 0,
      "z": 2,
      "name": "Rock_Basalt",
      "rotation": 2
    },
    {
      "x": -2,
      "y": 1,
      "z": 2,
      "name": "Rock_Basalt_Brick"
    },
    {
      "x": -2,
      "y": 2,
      "z": 2,
      "name": "Rock_Basalt_Brick"
    },
    {
      "x": -2,
      "y": 3,
      "z": 2,
      "name": "Rock_Basalt_Brick"
    },
    {
      "x": -2,
      "y": 4,
      "z": 2,
      "name": "Rock_Basalt_Brick"
    },
    {
      "x": -2,
      "y": 5,
      "z": 2,
      "name": "Rock_Basalt_Brick"
    },
    {
      "x": -2,
      "y": 6,
      "z": 2,
      "name": "Rock_Basalt_Brick"
    },
    {
      "x": -2,
      "y": 7,
      "z": 2,
      "name": "Rock_Basalt_Brick",
      "rotation": 2
    },
    {
      "x": -2,
      "y": 0,
      "z": 3,
      "name": "Rock_Basalt",
      "rotation": 2
    },
    {
      "x": -2,
      "y": 1,
      "z": 3,
      "name": "Rock_Basalt_Brick"
    },
    {
      "x": -2,
      "y": 2,
      "z": 3,
      "name": "Rock_Basalt_Brick"
    },
    {
      "x": -2,
      "y": 3,
      "z": 3,
      "name": "Rock_Basalt_Brick"
    },
    {
      "x": -2,
      "y": 4,
      "z": 3,
      "name": "Rock_Basalt_Brick"
    },
    {
      "x": -2,
      "y": 5,
      "z": 3,
      "name": "Rock_Basalt_Brick"
    },
    {
      "x": -2,
      "y": 6,
      "z": 3,
      "name": "Rock_Basalt_Brick"
    },
    {
      "x": -2,
      "y": 7,
      "z": 3,
      "name": "Rock_Basalt_Brick",
      "rotation": 2
    },
    {
      "x": -2,
      "y": 0,
      "z": 4,
      "name": "Rock_Basalt",
      "rotation": 2
    },
    {
      "x": -2,
      "y": 1,
      "z": 4,
      "name": "Rock_Basalt_Brick"
    },
    {
      "x": -2,
      "y": 2,
      "z": 4,
      "name": "Rock_Basalt_Brick"
    },
    {
      "x": -2,
      "y": 3,
      "z": 4,
      "name": "Rock_Basalt_Brick"
    },
    {
      "x": -2,
      "y": 4,
      "z": 4,
      "name": "Rock_Basalt_Brick"
    },
    {
      "x": -2,
      "y": 5,
      "z": 4,
      "name": "Rock_Basalt_Brick"
    },
    {
      "x": -2,
      "y": 6,
      "z": 4,
      "name": "Rock_Basalt_Brick"
    },
    {
      "x": -2,
      "y": 7,
      "z": 4,
      "name": "Rock_Basalt_Brick",
      "rotation": 2
    },
    {
      "x": -2,
      "y": 0,
      "z": 5,
      "name": "Rock_Basalt_Brick",
      "rotation": 2
    },
    {
      "x": -2,
      "y": 1,
      "z": 5,
      "name": "Rock_Basalt_Brick",
      "rotation": 2
    },
    {
      "x": -2,
      "y": 2,
      "z": 5,
      "name": "Rock_Basalt_Brick",
      "rotation": 2
    },
    {
      "x": -2,
      "y": 3,
      "z": 5,
      "name": "Rock_Basalt_Brick",
      "rotation": 2
    },
    {
      "x": -2,
      "y": 4,
      "z": 5,
      "name": "Rock_Basalt_Brick",
      "rotation": 2
    },
    {
      "x": -2,
      "y": 5,
      "z": 5,
      "name": "Rock_Basalt_Brick",
      "rotation": 2
    },
    {
      "x": -2,
      "y": 6,
      "z": 5,
      "name": "Rock_Basalt_Brick",
      "rotation": 2
    },
    {
      "x": -2,
      "y": 7,
      "z": 5,
      "name": "Rock_Basalt_Brick",
      "rotation": 2
    },
    {
      "x": -1,
      "y": 0,
      "z": -4,
      "name": "Rock_Basalt",
      "rotation": 2
    },
    {
      "x": -1,
      "y": 1,
      "z": -4,
      "name": "Rubble_Basalt",
      "support": 15
    },
    {
      "x": -1,
      "y": 0,
      "z": -3,
      "name": "Rock_Basalt",
      "rotation": 2
    },
    {
      "x": -1,
      "y": 7,
      "z": -3,
      "name": "Rock_Basalt_Brick",
      "rotation": 2
    },
    {
      "x": -1,
      "y": 0,
      "z": -2,
      "name": "Rock_Basalt"
    },
    {
      "x": -1,
      "y": 1,
      "z": -2,
      "name": "Rock_Ice_Icicles"
    },
    {
      "x": -1,
      "y": 5,
      "z": -2,
      "name": "Rock_Basalt_Brick_Half",
      "rotation": 8
    },
    {
      "x": -1,
      "y": 6,
      "z": -2,
      "name": "Rock_Basalt_Brick",
      "rotation": 2
    },
    {
      "x": -1,
      "y": 7,
      "z": -2,
      "name": "Rock_Basalt_Brick",
      "rotation": 2
    },
    {
      "x": -1,
      "y": 0,
      "z": -1,
      "name": "Rock_Basalt",
      "rotation": 2
    },
    {
      "x": -1,
      "y": 7,
      "z": -1,
      "name": "Rock_Basalt_Brick",
      "rotation": 2
    },
    {
      "x": -1,
      "y": 0,
      "z": 0,
      "name": "Rock_Basalt",
      "rotation": 2
    },
    {
      "x": -1,
      "y": 7,
      "z": 0,
      "name": "Rock_Basalt_Brick",
      "rotation": 2
    },
    {
      "x": -1,
      "y": 0,
      "z": 1,
      "name": "Rock_Basalt",
      "rotation": 2
    },
    {
      "x": -1,
      "y": 6,
      "z": 1,
      "name": "Wood_Deadwood_Planks_Half",
      "rotation": 5
    },
    {
      "x": -1,
      "y": 7,
      "z": 1,
      "name": "Rock_Basalt_Brick",
      "rotation": 2
    },
    {
      "x": -1,
      "y": 0,
      "z": 2,
      "name": "Rock_Basalt",
      "rotation": 2
    },
    {
      "x": -1,
      "y": 1,
      "z": 2,
      "name": "Furniture_Ancient_Wardrobe",
      "rotation": 1
    },
    {
      "x": -1,
      "y": 2,
      "z": 2,
      "name": "Furniture_Ancient_Wardrobe",
      "filler": 1024,
      "rotation": 1
    },
    {
      "x": -1,
      "y": 3,
      "z": 2,
      "name": "Furniture_Ancient_Platform"
    },
    {
      "x": -1,
      "y": 4,
      "z": 2,
      "name": "Rubble_Basalt",
      "support": 15
    },
    {
      "x": -1,
      "y": 5,
      "z": 2,
      "name": "Deco_SpiderWeb_Flat",
      "support": 15,
      "rotation": 5
    },
    {
      "x": -1,
      "y": 6,
      "z": 2,
      "name": "Wood_Deadwood_Planks_Half",
      "rotation": 5
    },
    {
      "x": -1,
      "y": 7,
      "z": 2,
      "name": "Rock_Basalt_Brick",
      "rotation": 2
    },
    {
      "x": -1,
      "y": 0,
      "z": 3,
      "name": "Rock_Basalt",
      "rotation": 2
    },
    {
      "x": -1,
      "y": 1,
      "z": 3,
      "name": "Furniture_Ancient_Wardrobe",
      "filler": 32,
      "rotation": 1
    },
    {
      "x": -1,
      "y": 2,
      "z": 3,
      "name": "Furniture_Ancient_Wardrobe",
      "filler": 1056,
      "rotation": 1
    },
    {
      "x": -1,
      "y": 3,
      "z": 3,
      "name": "Furniture_Ancient_Platform"
    },
    {
      "x": -1,
      "y": 4,
      "z": 3,
      "name": "Rubble_Basalt_Medium",
      "support": 15
    },
    {
      "x": -1,
      "y": 6,
      "z": 3,
      "name": "Wood_Deadwood_Planks_Half",
      "rotation": 5
    },
    {
      "x": -1,
      "y": 7,
      "z": 3,
      "name": "Rock_Basalt_Brick",
      "rotation": 2
    },
    {
      "x": -1,
      "y": 0,
      "z": 4,
      "name": "Rock_Basalt",
      "rotation": 2
    },
    {
      "x": -1,
      "y": 1,
      "z": 4,
      "name": "Furniture_Ancient_Barrel"
    },
    {
      "x": -1,
      "y": 3,
      "z": 4,
      "name": "Furniture_Ancient_Platform"
    },
    {
      "x": -1,
      "y": 4,
      "z": 4,
      "name": "Deco_Book_Pile_Small",
      "rotation": 2
    },
    {
      "x": -1,
      "y": 6,
      "z": 4,
      "name": "Wood_Deadwood_Planks_Half",
      "rotation": 5
    },
    {
      "x": -1,
      "y": 7,
      "z": 4,
      "name": "Rock_Basalt_Brick",
      "rotation": 2
    },
    {
      "x": -1,
      "y": 0,
      "z": 5,
      "name": "Rock_Basalt_Brick",
      "rotation": 2
    },
    {
      "x": -1,
      "y": 1,
      "z": 5,
      "name": "Rock_Basalt_Brick",
      "rotation": 2
    },
    {
      "x": -1,
      "y": 2,
      "z": 5,
      "name": "Rock_Basalt_Brick",
      "rotation": 2
    },
    {
      "x": -1,
      "y": 3,
      "z": 5,
      "name": "Rock_Basalt_Brick",
      "rotation": 2
    },
    {
      "x": -1,
      "y": 4,
      "z": 5,
      "name": "Rock_Basalt_Brick",
      "rotation": 2
    },
    {
      "x": -1,
      "y": 5,
      "z": 5,
      "name": "Rock_Basalt_Brick",
      "rotation": 2
    },
    {
      "x": -1,
      "y": 6,
      "z": 5,
      "name": "Rock_Basalt_Brick",
      "rotation": 2
    },
    {
      "x": -1,
      "y": 7,
      "z": 5,
      "name": "Rock_Basalt_Brick",
      "rotation": 2
    },
    {
      "x": 0,
      "y": 0,
      "z": -4,
      "name": "Rock_Basalt",
      "rotation": 2
    },
    {
      "x": 0,
      "y": 0,
      "z": -3,
      "name": "Rock_Basalt",
      "rotation": 2
    },
    {
      "x": 0,
      "y": 1,
      "z": -3,
      "name": "Furniture_Ancient_Barrel"
    },
    {
      "x": 0,
      "y": 7,
      "z": -3,
      "name": "Rock_Basalt_Brick",
      "rotation": 2
    },
    {
      "x": 0,
      "y": 0,
      "z": -2,
      "name": "Rock_Basalt"
    },
    {
      "x": 0,
      "y": 1,
      "z": -2,
      "name": "Rock_Basalt_Brick_Half",
      "rotation": 7
    },
    {
      "x": 0,
      "y": 2,
      "z": -2,
      "name": "Rock_Basalt_Brick_Half",
      "rotation": 7
    },
    {
      "x": 0,
      "y": 3,
      "z": -2,
      "name": "Rock_Basalt_Brick_Half",
      "rotation": 7
    },
    {
      "x": 0,
      "y": 4,
      "z": -2,
      "name": "Rock_Basalt_Brick_Half",
      "rotation": 7
    },
    {
      "x": 0,
      "y": 5,
      "z": -2,
      "name": "Rock_Basalt_Brick"
    },
    {
      "x": 0,
      "y": 6,
      "z": -2,
      "name": "Rock_Basalt_Brick",
      "rotation": 2
    },
    {
      "x": 0,
      "y": 7,
      "z": -2,
      "name": "Rock_Basalt_Brick",
      "rotation": 2
    },
    {
      "x": 0,
      "y": 0,
      "z": -1,
      "name": "Rock_Basalt",
      "rotation": 2
    },
    {
      "x": 0,
      "y": 7,
      "z": -1,
      "name": "Rock_Basalt_Brick",
      "rotation": 2
    },
    {
      "x": 0,
      "y": 0,
      "z": 0,
      "name": "Rock_Basalt",
      "rotation": 2
    },
    {
      "x": 0,
      "y": 7,
      "z": 0,
      "name": "Rock_Basalt_Brick",
      "rotation": 2
    },
    {
      "x": 0,
      "y": 0,
      "z": 1,
      "name": "Rock_Basalt",
      "rotation": 2
    },
    {
      "x": 0,
      "y": 6,
      "z": 1,
      "name": "Rock_Ice_Icicles",
      "rotation": 8
    },
    {
      "x": 0,
      "y": 7,
      "z": 1,
      "name": "Rock_Basalt_Brick",
      "rotation": 2
    },
    {
      "x": 0,
      "y": 0,
      "z": 2,
      "name": "Rock_Basalt",
      "rotation": 2
    },
    {
      "x": 0,
      "y": 7,
      "z": 2,
      "name": "Rock_Basalt_Brick",
      "rotation": 2
    },
    {
      "x": 0,
      "y": 0,
      "z": 3,
      "name": "Rock_Basalt",
      "rotation": 2
    },
    {
      "x": 0,
      "y": 7,
      "z": 3,
      "name": "Rock_Basalt_Brick",
      "rotation": 2
    },
    {
      "x": 0,
      "y": 0,
      "z": 4,
      "name": "Rock_Basalt",
      "rotation": 2
    },
    {
      "x": 0,
      "y": 1,
      "z": 4,
      "name": "Block_Spawner_Block",
      "components": {
        "Components": {
          "PlacedByInteraction": {
            "WhoPlacedUuid": {
              "$binary": "B1yBGZcjQ2KREo5yyLGY0g==",
              "$type": "04"
            }
          },
          "BlockSpawner": {
            "BlockSpawnerId": "Zone3_Outlander_Tier1"
          }
        }
      },
      "rotation": 2
    },
    {
      "x": 0,
      "y": 5,
      "z": 4,
      "name": "Deco_SpiderWeb_Flat",
      "support": 15,
      "rotation": 6
    },
    {
      "x": 0,
      "y": 6,
      "z": 4,
      "name": "Deco_SpiderWeb_Flat",
      "support": 15,
      "rotation": 8
    },
    {
      "x": 0,
      "y": 7,
      "z": 4,
      "name": "Rock_Basalt_Brick",
      "rotation": 2
    },
    {
      "x": 0,
      "y": 0,
      "z": 5,
      "name": "Rock_Basalt_Brick",
      "rotation": 2
    },
    {
      "x": 0,
      "y": 1,
      "z": 5,
      "name": "Rock_Basalt_Brick",
      "rotation": 2
    },
    {
      "x": 0,
      "y": 2,
      "z": 5,
      "name": "Rock_Basalt_Brick",
      "rotation": 2
    },
    {
      "x": 0,
      "y": 3,
      "z": 5,
      "name": "Rock_Basalt_Brick",
      "rotation": 2
    },
    {
      "x": 0,
      "y": 4,
      "z": 5,
      "name": "Rock_Basalt_Brick",
      "rotation": 2
    },
    {
      "x": 0,
      "y": 5,
      "z": 5,
      "name": "Rock_Basalt_Brick",
      "rotation": 2
    },
    {
      "x": 0,
      "y": 6,
      "z": 5,
      "name": "Rock_Basalt_Brick"
    },
    {
      "x": 0,
      "y": 7,
      "z": 5,
      "name": "Rock_Basalt_Brick",
      "rotation": 2
    },
    {
      "x": 1,
      "y": 0,
      "z": -4,
      "name": "Rock_Basalt",
      "rotation": 2
    },
    {
      "x": 1,
      "y": 0,
      "z": -3,
      "name": "Rock_Basalt",
      "rotation": 2
    },
    {
      "x": 1,
      "y": 1,
      "z": -3,
      "name": "Rock_Ice_Icicles"
    },
    {
      "x": 1,
      "y": 7,
      "z": -3,
      "name": "Rock_Basalt_Brick",
      "rotation": 2
    },
    {
      "x": 1,
      "y": 0,
      "z": -2,
      "name": "Rock_Basalt"
    },
    {
      "x": 1,
      "y": 1,
      "z": -2,
      "name": "Rock_Basalt_Brick_Half",
      "rotation": 5
    },
    {
      "x": 1,
      "y": 2,
      "z": -2,
      "name": "Rock_Basalt_Brick_Half",
      "rotation": 5
    },
    {
      "x": 1,
      "y": 3,
      "z": -2,
      "name": "Rock_Basalt_Brick_Half",
      "rotation": 5
    },
    {
      "x": 1,
      "y": 4,
      "z": -2,
      "name": "Rock_Basalt_Brick_Half",
      "rotation": 5
    },
    {
      "x": 1,
      "y": 5,
      "z": -2,
      "name": "Rock_Basalt_Brick"
    },
    {
      "x": 1,
      "y": 6,
      "z": -2,
      "name": "Rock_Basalt_Brick",
      "rotation": 2
    },
    {
      "x": 1,
      "y": 7,
      "z": -2,
      "name": "Rock_Basalt_Brick",
      "rotation": 2
    },
    {
      "x": 1,
      "y": 0,
      "z": -1,
      "name": "Rock_Basalt",
      "rotation": 2
    },
    {
      "x": 1,
      "y": 7,
      "z": -1,
      "name": "Rock_Basalt_Brick",
      "rotation": 2
    },
    {
      "x": 1,
      "y": 0,
      "z": 0,
      "name": "Rock_Basalt",
      "rotation": 2
    },
    {
      "x": 1,
      "y": 1,
      "z": 0,
      "name": "Rubble_Basalt",
      "support": 15
    },
    {
      "x": 1,
      "y": 7,
      "z": 0,
      "name": "Rock_Basalt_Brick",
      "rotation": 2
    },
    {
      "x": 1,
      "y": 0,
      "z": 1,
      "name": "Rock_Basalt",
      "rotation": 2
    },
    {
      "x": 1,
      "y": 7,
      "z": 1,
      "name": "Rock_Basalt_Brick",
      "rotation": 2
    },
    {
      "x": 1,
      "y": 0,
      "z": 2,
      "name": "Rock_Basalt",
      "rotation": 2
    },
    {
      "x": 1,
      "y": 7,
      "z": 2,
      "name": "Rock_Basalt_Brick",
      "rotation": 2
    },
    {
      "x": 1,
      "y": 0,
      "z": 3,
      "name": "Rock_Basalt",
      "rotation": 2
    },
    {
      "x": 1,
      "y": 1,
      "z": 3,
      "name": "Deco_SpiderWeb",
      "support": 15,
      "rotation": 3
    },
    {
      "x": 1,
      "y": 6,
      "z": 3,
      "name": "Deco_SpiderWeb_Flat",
      "support": 15,
      "rotation": 8
    },
    {
      "x": 1,
      "y": 7,
      "z": 3,
      "name": "Rock_Basalt_Brick",
      "rotation": 2
    },
    {
      "x": 1,
      "y": 0,
      "z": 4,
      "name": "Rock_Basalt",
      "rotation": 2
    },
    {
      "x": 1,
      "y": 1,
      "z": 4,
      "name": "Furniture_Ancient_Barrel"
    },
    {
      "x": 1,
      "y": 4,
      "z": 4,
      "name": "Deco_SpiderWeb_Flat",
      "support": 15,
      "rotation": 6
    },
    {
      "x": 1,
      "y": 5,
      "z": 4,
      "name": "Deco_SpiderWeb",
      "support": 15,
      "rotation": 8
    },
    {
      "x": 1,
      "y": 6,
      "z": 4,
      "name": "Deco_SpiderWeb_Full",
      "support": 15
    },
    {
      "x": 1,
      "y": 7,
      "z": 4,
      "name": "Rock_Basalt_Brick",
      "rotation": 2
    },
    {
      "x": 1,
      "y": 0,
      "z": 5,
      "name": "Rock_Basalt_Brick",
      "rotation": 2
    },
    {
      "x": 1,
      "y": 1,
      "z": 5,
      "name": "Rock_Basalt_Brick",
      "rotation": 2
    },
    {
      "x": 1,
      "y": 2,
      "z": 5,
      "name": "Rock_Basalt_Brick"
    },
    {
      "x": 1,
      "y": 3,
      "z": 5,
      "name": "Rock_Basalt_Brick",
      "rotation": 2
    },
    {
      "x": 1,
      "y": 4,
      "z": 5,
      "name": "Rock_Basalt_Brick",
      "rotation": 2
    },
    {
      "x": 1,
      "y": 5,
      "z": 5,
      "name": "Rock_Basalt_Brick",
      "rotation": 2
    },
    {
      "x": 1,
      "y": 6,
      "z": 5,
      "name": "Rock_Basalt_Brick",
      "rotation": 2
    },
    {
      "x": 1,
      "y": 7,
      "z": 5,
      "name": "Rock_Basalt_Brick",
      "rotation": 2
    },
    {
      "x": 2,
      "y": 0,
      "z": -4,
      "name": "Rock_Basalt",
      "rotation": 2
    },
    {
      "x": 2,
      "y": 0,
      "z": -3,
      "name": "Rock_Basalt",
      "rotation": 2
    },
    {
      "x": 2,
      "y": 7,
      "z": -3,
      "name": "Rock_Basalt_Brick",
      "rotation": 2
    },
    {
      "x": 2,
      "y": 0,
      "z": -2,
      "name": "Rock_Basalt"
    },
    {
      "x": 2,
      "y": 5,
      "z": -2,
      "name": "Rock_Basalt_Brick_Half",
      "rotation": 8
    },
    {
      "x": 2,
      "y": 6,
      "z": -2,
      "name": "Rock_Basalt_Brick",
      "rotation": 2
    },
    {
      "x": 2,
      "y": 7,
      "z": -2,
      "name": "Rock_Basalt_Brick",
      "rotation": 2
    },
    {
      "x": 2,
      "y": 0,
      "z": -1,
      "name": "Rock_Basalt",
      "rotation": 2
    },
    {
      "x": 2,
      "y": 7,
      "z": -1,
      "name": "Rock_Basalt_Brick",
      "rotation": 2
    },
    {
      "x": 2,
      "y": 0,
      "z": 0,
      "name": "Rock_Basalt",
      "rotation": 2
    },
    {
      "x": 2,
      "y": 1,
      "z": 0,
      "name": "Rock_Ice_Icicles"
    },
    {
      "x": 2,
      "y": 7,
      "z": 0,
      "name": "Rock_Basalt_Brick",
      "rotation": 2
    },
    {
      "x": 2,
      "y": 0,
      "z": 1,
      "name": "Rock_Basalt",
      "rotation": 2
    },
    {
      "x": 2,
      "y": 6,
      "z": 1,
      "name": "Wood_Deadwood_Planks_Half",
      "rotation": 7
    },
    {
      "x": 2,
      "y": 7,
      "z": 1,
      "name": "Rock_Basalt_Brick",
      "rotation": 2
    },
    {
      "x": 2,
      "y": 0,
      "z": 2,
      "name": "Rock_Basalt",
      "rotation": 2
    },
    {
      "x": 2,
      "y": 1,
      "z": 2,
      "name": "Furniture_Ancient_Barrel"
    },
    {
      "x": 2,
      "y": 2,
      "z": 2,
      "name": "Furniture_Ancient_Platform"
    },
    {
      "x": 2,
      "y": 6,
      "z": 2,
      "name": "Wood_Deadwood_Planks_Half",
      "rotation": 7
    },
    {
      "x": 2,
      "y": 7,
      "z": 2,
      "name": "Rock_Basalt_Brick",
      "rotation": 2
    },
    {
      "x": 2,
      "y": 0,
      "z": 3,
      "name": "Rock_Basalt"
    },
    {
      "x": 2,
      "y": 1,
      "z": 3,
      "name": "Furniture_Ancient_Crate",
      "rotation": 3
    },
    {
      "x": 2,
      "y": 2,
      "z": 3,
      "name": "Furniture_Ancient_Platform"
    },
    {
      "x": 2,
      "y": 3,
      "z": 3,
      "name": "Deco_Book_Pile_Small",
      "rotation": 2
    },
    {
      "x": 2,
      "y": 6,
      "z": 3,
      "name": "Wood_Deadwood_Planks_Half",
      "rotation": 7
    },
    {
      "x": 2,
      "y": 7,
      "z": 3,
      "name": "Rock_Basalt_Brick",
      "rotation": 2
    },
    {
      "x": 2,
      "y": 0,
      "z": 4,
      "name": "Rock_Basalt",
      "rotation": 2
    },
    {
      "x": 2,
      "y": 1,
      "z": 4,
      "name": "Furniture_Ancient_Crate",
      "rotation": 2
    },
    {
      "x": 2,
      "y": 2,
      "z": 4,
      "name": "Furniture_Ancient_Platform"
    },
    {
      "x": 2,
      "y": 3,
      "z": 4,
      "name": "Furniture_Ancient_Barrel"
    },
    {
      "x": 2,
      "y": 5,
      "z": 4,
      "name": "Deco_SpiderWeb_Full",
      "support": 15
    },
    {
      "x": 2,
      "y": 6,
      "z": 4,
      "name": "Wood_Deadwood_Planks_Half",
      "rotation": 7
    },
    {
      "x": 2,
      "y": 7,
      "z": 4,
      "name": "Rock_Basalt_Brick",
      "rotation": 2
    },
    {
      "x": 2,
      "y": 0,
      "z": 5,
      "name": "Rock_Basalt_Brick",
      "rotation": 2
    },
    {
      "x": 2,
      "y": 1,
      "z": 5,
      "name": "Rock_Basalt_Brick",
      "rotation": 2
    },
    {
      "x": 2,
      "y": 2,
      "z": 5,
      "name": "Rock_Basalt_Brick",
      "rotation": 2
    },
    {
      "x": 2,
      "y": 3,
      "z": 5,
      "name": "Rock_Basalt_Brick",
      "rotation": 2
    },
    {
      "x": 2,
      "y": 4,
      "z": 5,
      "name": "Rock_Basalt_Brick",
      "rotation": 2
    },
    {
      "x": 2,
      "y": 5,
      "z": 5,
      "name": "Rock_Basalt_Brick",
      "rotation": 2
    },
    {
      "x": 2,
      "y": 6,
      "z": 5,
      "name": "Rock_Basalt_Brick",
      "rotation": 2
    },
    {
      "x": 2,
      "y": 7,
      "z": 5,
      "name": "Rock_Basalt_Brick",
      "rotation": 2
    },
    {
      "x": 3,
      "y": 0,
      "z": -4,
      "name": "Rock_Basalt",
      "rotation": 2
    },
    {
      "x": 3,
      "y": 0,
      "z": -3,
      "name": "Rock_Basalt",
      "rotation": 2
    },
    {
      "x": 3,
      "y": 7,
      "z": -3,
      "name": "Rock_Basalt_Brick",
      "rotation": 2
    },
    {
      "x": 3,
      "y": 0,
      "z": -2,
      "name": "Rock_Basalt"
    },
    {
      "x": 3,
      "y": 6,
      "z": -2,
      "name": "Rock_Basalt_Brick",
      "rotation": 2
    },
    {
      "x": 3,
      "y": 7,
      "z": -2,
      "name": "Rock_Basalt_Brick",
      "rotation": 2
    },
    {
      "x": 3,
      "y": 0,
      "z": -1,
      "name": "Rock_Basalt",
      "rotation": 2
    },
    {
      "x": 3,
      "y": 7,
      "z": -1,
      "name": "Rock_Basalt_Brick",
      "rotation": 2
    },
    {
      "x": 3,
      "y": 0,
      "z": 0,
      "name": "Rock_Basalt",
      "rotation": 2
    },
    {
      "x": 3,
      "y": 7,
      "z": 0,
      "name": "Rock_Basalt_Brick",
      "rotation": 2
    },
    {
      "x": 3,
      "y": 0,
      "z": 1,
      "name": "Rock_Basalt",
      "rotation": 2
    },
    {
      "x": 3,
      "y": 1,
      "z": 1,
      "name": "Rock_Basalt_Brick_Half",
      "rotation": 6
    },
    {
      "x": 3,
      "y": 2,
      "z": 1,
      "name": "Rock_Basalt_Brick_Half",
      "rotation": 6
    },
    {
      "x": 3,
      "y": 3,
      "z": 1,
      "name": "Rock_Basalt_Brick_Half",
      "rotation": 6
    },
    {
      "x": 3,
      "y": 4,
      "z": 1,
      "name": "Rock_Basalt_Brick_Half",
      "rotation": 6
    },
    {
      "x": 3,
      "y": 5,
      "z": 1,
      "name": "Rock_Basalt_Brick"
    },
    {
      "x": 3,
      "y": 6,
      "z": 1,
      "name": "Rock_Basalt_Brick"
    },
    {
      "x": 3,
      "y": 7,
      "z": 1,
      "name": "Rock_Basalt_Brick",
      "rotation": 2
    },
    {
      "x": 3,
      "y": 0,
      "z": 2,
      "name": "Rock_Basalt",
      "rotation": 2
    },
    {
      "x": 3,
      "y": 1,
      "z": 2,
      "name": "Rock_Basalt_Brick"
    },
    {
      "x": 3,
      "y": 2,
      "z": 2,
      "name": "Rock_Basalt_Brick"
    },
    {
      "x": 3,
      "y": 3,
      "z": 2,
      "name": "Rock_Basalt_Brick"
    },
    {
      "x": 3,
      "y": 4,
      "z": 2,
      "name": "Rock_Basalt_Brick"
    },
    {
      "x": 3,
      "y": 5,
      "z": 2,
      "name": "Rock_Basalt_Brick"
    },
    {
      "x": 3,
      "y": 6,
      "z": 2,
      "name": "Rock_Basalt_Brick"
    },
    {
      "x": 3,
      "y": 7,
      "z": 2,
      "name": "Rock_Basalt_Brick",
      "rotation": 2
    },
    {
      "x": 3,
      "y": 0,
      "z": 3,
      "name": "Rock_Basalt",
      "rotation": 2
    },
    {
      "x": 3,
      "y": 1,
      "z": 3,
      "name": "Rock_Basalt_Brick"
    },
    {
      "x": 3,
      "y": 2,
      "z": 3,
      "name": "Rock_Basalt_Brick"
    },
    {
      "x": 3,
      "y": 3,
      "z": 3,
      "name": "Rock_Basalt_Brick"
    },
    {
      "x": 3,
      "y": 4,
      "z": 3,
      "name": "Rock_Basalt_Brick"
    },
    {
      "x": 3,
      "y": 5,
      "z": 3,
      "name": "Rock_Basalt_Brick"
    },
    {
      "x": 3,
      "y": 6,
      "z": 3,
      "name": "Rock_Basalt_Brick"
    },
    {
      "x": 3,
      "y": 7,
      "z": 3,
      "name": "Rock_Basalt_Brick",
      "rotation": 2
    },
    {
      "x": 3,
      "y": 0,
      "z": 4,
      "name": "Rock_Basalt",
      "rotation": 2
    },
    {
      "x": 3,
      "y": 1,
      "z": 4,
      "name": "Rock_Basalt_Brick"
    },
    {
      "x": 3,
      "y": 2,
      "z": 4,
      "name": "Rock_Basalt_Brick"
    },
    {
      "x": 3,
      "y": 3,
      "z": 4,
      "name": "Rock_Basalt_Brick"
    },
    {
      "x": 3,
      "y": 4,
      "z": 4,
      "name": "Rock_Basalt_Brick"
    },
    {
      "x": 3,
      "y": 5,
      "z": 4,
      "name": "Rock_Basalt_Brick"
    },
    {
      "x": 3,
      "y": 6,
      "z": 4,
      "name": "Rock_Basalt_Brick"
    },
    {
      "x": 3,
      "y": 7,
      "z": 4,
      "name": "Rock_Basalt_Brick",
      "rotation": 2
    },
    {
      "x": 3,
      "y": 0,
      "z": 5,
      "name": "Rock_Basalt_Brick",
      "rotation": 2
    },
    {
      "x": 3,
      "y": 1,
      "z": 5,
      "name": "Rock_Basalt_Brick",
      "rotation": 2
    },
    {
      "x": 3,
      "y": 2,
      "z": 5,
      "name": "Rock_Basalt_Brick",
      "rotation": 2
    },
    {
      "x": 3,
      "y": 3,
      "z": 5,
      "name": "Rock_Basalt_Brick",
      "rotation": 2
    },
    {
      "x": 3,
      "y": 4,
      "z": 5,
      "name": "Rock_Basalt_Brick",
      "rotation": 2
    },
    {
      "x": 3,
      "y": 5,
      "z": 5,
      "name": "Rock_Basalt_Brick",
      "rotation": 2
    },
    {
      "x": 3,
      "y": 6,
      "z": 5,
      "name": "Rock_Basalt_Brick",
      "rotation": 2
    },
    {
      "x": 3,
      "y": 7,
      "z": 5,
      "name": "Rock_Basalt_Brick",
      "rotation": 2
    },
    {
      "x": 4,
      "y": 0,
      "z": -4,
      "name": "Rock_Basalt",
      "rotation": 2
    },
    {
      "x": 4,
      "y": 0,
      "z": -3,
      "name": "Rock_Basalt",
      "rotation": 2
    },
    {
      "x": 4,
      "y": 7,
      "z": -3,
      "name": "Rock_Basalt_Brick",
      "rotation": 2
    },
    {
      "x": 4,
      "y": 0,
      "z": -2,
      "name": "Rock_Basalt"
    },
    {
      "x": 4,
      "y": 6,
      "z": -2,
      "name": "Rock_Basalt_Brick",
      "rotation": 2
    },
    {
      "x": 4,
      "y": 7,
      "z": -2,
      "name": "Rock_Basalt_Brick",
      "rotation": 2
    },
    {
      "x": 4,
      "y": 0,
      "z": -1,
      "name": "Rock_Basalt",
      "rotation": 2
    },
    {
      "x": 4,
      "y": 7,
      "z": -1,
      "name": "Rock_Basalt_Brick",
      "rotation": 2
    },
    {
      "x": 4,
      "y": 0,
      "z": 0,
      "name": "Rock_Basalt",
      "rotation": 2
    },
    {
      "x": 4,
      "y": 7,
      "z": 0,
      "name": "Rock_Basalt_Brick",
      "rotation": 2
    },
    {
      "x": 4,
      "y": 0,
      "z": 1,
      "name": "Rock_Basalt",
      "rotation": 2
    },
    {
      "x": 4,
      "y": 6,
      "z": 1,
      "name": "Wood_Deadwood_Planks_Half",
      "rotation": 5
    },
    {
      "x": 4,
      "y": 7,
      "z": 1,
      "name": "Rock_Basalt_Brick",
      "rotation": 2
    },
    {
      "x": 4,
      "y": 0,
      "z": 2,
      "name": "Rock_Basalt",
      "rotation": 2
    },
    {
      "x": 4,
      "y": 1,
      "z": 2,
      "name": "Furniture_Ancient_Barrel"
    },
    {
      "x": 4,
      "y": 2,
      "z": 2,
      "name": "Furniture_Ancient_Platform"
    },
    {
      "x": 4,
      "y": 6,
      "z": 2,
      "name": "Wood_Deadwood_Planks_Half",
      "rotation": 5
    },
    {
      "x": 4,
      "y": 7,
      "z": 2,
      "name": "Rock_Basalt_Brick",
      "rotation": 2
    },
    {
      "x": 4,
      "y": 0,
      "z": 3,
      "name": "Rock_Basalt",
      "rotation": 2
    },
    {
      "x": 4,
      "y": 1,
      "z": 3,
      "name": "Furniture_Ancient_Crate",
      "rotation": 2
    },
    {
      "x": 4,
      "y": 2,
      "z": 3,
      "name": "Furniture_Ancient_Platform"
    },
    {
      "x": 4,
      "y": 3,
      "z": 3,
      "name": "Deco_Book_Pile_Small",
      "rotation": 1
    },
    {
      "x": 4,
      "y": 5,
      "z": 3,
      "name": "Deco_SpiderWeb",
      "support": 15,
      "rotation": 11
    },
    {
      "x": 4,
      "y": 6,
      "z": 3,
      "name": "Wood_Deadwood_Planks_Half",
      "rotation": 5
    },
    {
      "x": 4,
      "y": 7,
      "z": 3,
      "name": "Rock_Basalt_Brick",
      "rotation": 2
    },
    {
      "x": 4,
      "y": 0,
      "z": 4,
      "name": "Rock_Basalt",
      "rotation": 2
    },
    {
      "x": 4,
      "y": 1,
      "z": 4,
      "name": "Furniture_Ancient_Crate",
      "rotation": 2
    },
    {
      "x": 4,
      "y": 2,
      "z": 4,
      "name": "Furniture_Ancient_Platform"
    },
    {
      "x": 4,
      "y": 3,
      "z": 4,
      "name": "Furniture_Ancient_Pot",
      "rotation": 2
    },
    {
      "x": 4,
      "y": 5,
      "z": 4,
      "name": "Deco_SpiderWeb_Full",
      "support": 15
    },
    {
      "x": 4,
      "y": 6,
      "z": 4,
      "name": "Wood_Deadwood_Planks_Half",
      "rotation": 5
    },
    {
      "x": 4,
      "y": 7,
      "z": 4,
      "name": "Rock_Basalt_Brick",
      "rotation": 2
    },
    {
      "x": 4,
      "y": 0,
      "z": 5,
      "name": "Rock_Basalt_Brick",
      "rotation": 2
    },
    {
      "x": 4,
      "y": 1,
      "z": 5,
      "name": "Rock_Basalt_Brick",
      "rotation": 2
    },
    {
      "x": 4,
      "y": 2,
      "z": 5,
      "name": "Rock_Basalt_Brick",
      "rotation": 2
    },
    {
      "x": 4,
      "y": 3,
      "z": 5,
      "name": "Rock_Basalt_Brick",
      "rotation": 2
    },
    {
      "x": 4,
      "y": 4,
      "z": 5,
      "name": "Rock_Basalt_Brick",
      "rotation": 2
    },
    {
      "x": 4,
      "y": 5,
      "z": 5,
      "name": "Rock_Basalt_Brick",
      "rotation": 2
    },
    {
      "x": 4,
      "y": 6,
      "z": 5,
      "name": "Rock_Basalt_Brick",
      "rotation": 2
    },
    {
      "x": 4,
      "y": 7,
      "z": 5,
      "name": "Rock_Basalt_Brick",
      "rotation": 2
    },
    {
      "x": 5,
      "y": 0,
      "z": -4,
      "name": "Rock_Basalt",
      "rotation": 2
    },
    {
      "x": 5,
      "y": 0,
      "z": -3,
      "name": "Rock_Basalt",
      "rotation": 2
    },
    {
      "x": 5,
      "y": 7,
      "z": -3,
      "name": "Rock_Basalt_Brick",
      "rotation": 2
    },
    {
      "x": 5,
      "y": 0,
      "z": -2,
      "name": "Rock_Basalt"
    },
    {
      "x": 5,
      "y": 1,
      "z": -2,
      "name": "Rock_Ice_Icicles"
    },
    {
      "x": 5,
      "y": 5,
      "z": -2,
      "name": "Rock_Basalt_Brick_Half",
      "rotation": 8
    },
    {
      "x": 5,
      "y": 6,
      "z": -2,
      "name": "Rock_Basalt_Brick",
      "rotation": 2
    },
    {
      "x": 5,
      "y": 7,
      "z": -2,
      "name": "Rock_Basalt_Brick",
      "rotation": 2
    },
    {
      "x": 5,
      "y": 0,
      "z": -1,
      "name": "Rock_Basalt",
      "rotation": 2
    },
    {
      "x": 5,
      "y": 1,
      "z": -1,
      "name": "Deco_SpiderWeb_Flat",
      "support": 15
    },
    {
      "x": 5,
      "y": 7,
      "z": -1,
      "name": "Rock_Basalt_Brick",
      "rotation": 2
    },
    {
      "x": 5,
      "y": 0,
      "z": 0,
      "name": "Rock_Basalt",
      "rotation": 2
    },
    {
      "x": 5,
      "y": 6,
      "z": 0,
      "name": "Rock_Ice_Icicles",
      "rotation": 8
    },
    {
      "x": 5,
      "y": 7,
      "z": 0,
      "name": "Rock_Basalt_Brick",
      "rotation": 2
    },
    {
      "x": 5,
      "y": 0,
      "z": 1,
      "name": "Rock_Basalt",
      "rotation": 2
    },
    {
      "x": 5,
      "y": 7,
      "z": 1,
      "name": "Rock_Basalt_Brick",
      "rotation": 2
    },
    {
      "x": 5,
      "y": 0,
      "z": 2,
      "name": "Rock_Basalt",
      "rotation": 2
    },
    {
      "x": 5,
      "y": 6,
      "z": 2,
      "name": "Rock_Ice_Icicles",
      "rotation": 8
    },
    {
      "x": 5,
      "y": 7,
      "z": 2,
      "name": "Rock_Basalt_Brick",
      "rotation": 2
    },
    {
      "x": 5,
      "y": 0,
      "z": 3,
      "name": "Rock_Basalt",
      "rotation": 2
    },
    {
      "x": 5,
      "y": 1,
      "z": 3,
      "name": "*Furniture_Ancient_Candle_State_Definitions_Off"
    },
    {
      "x": 5,
      "y": 7,
      "z": 3,
      "name": "Rock_Basalt_Brick",
      "rotation": 2
    },
    {
      "x": 5,
      "y": 0,
      "z": 4,
      "name": "Rock_Basalt",
      "rotation": 2
    },
    {
      "x": 5,
      "y": 1,
      "z": 4,
      "name": "Furniture_Ancient_Barrel"
    },
    {
      "x": 5,
      "y": 5,
      "z": 4,
      "name": "Deco_SpiderWeb_Flat",
      "support": 15,
      "rotation": 6
    },
    {
      "x": 5,
      "y": 6,
      "z": 4,
      "name": "Deco_SpiderWeb_Full",
      "support": 15
    },
    {
      "x": 5,
      "y": 7,
      "z": 4,
      "name": "Rock_Basalt_Brick",
      "rotation": 2
    },
    {
      "x": 5,
      "y": 0,
      "z": 5,
      "name": "Rock_Basalt_Brick",
      "rotation": 2
    },
    {
      "x": 5,
      "y": 1,
      "z": 5,
      "name": "Rock_Basalt_Brick",
      "rotation": 2
    },
    {
      "x": 5,
      "y": 2,
      "z": 5,
      "name": "Rock_Basalt_Brick",
      "rotation": 2
    },
    {
      "x": 5,
      "y": 3,
      "z": 5,
      "name": "Rock_Basalt_Brick",
      "rotation": 2
    },
    {
      "x": 5,
      "y": 4,
      "z": 5,
      "name": "Rock_Basalt_Brick",
      "rotation": 2
    },
    {
      "x": 5,
      "y": 5,
      "z": 5,
      "name": "Rock_Basalt_Brick",
      "rotation": 2
    },
    {
      "x": 5,
      "y": 6,
      "z": 5,
      "name": "Rock_Basalt_Brick",
      "rotation": 2
    },
    {
      "x": 5,
      "y": 7,
      "z": 5,
      "name": "Rock_Basalt_Brick",
      "rotation": 2
    },
    {
      "x": 6,
      "y": 0,
      "z": -4,
      "name": "Rock_Basalt",
      "rotation": 2
    },
    {
      "x": 6,
      "y": 0,
      "z": -3,
      "name": "Rock_Basalt",
      "rotation": 2
    },
    {
      "x": 6,
      "y": 1,
      "z": -3,
      "name": "Furniture_Ancient_Barrel"
    },
    {
      "x": 6,
      "y": 7,
      "z": -3,
      "name": "Rock_Basalt_Brick",
      "rotation": 2
    },
    {
      "x": 6,
      "y": 0,
      "z": -2,
      "name": "Rock_Basalt"
    },
    {
      "x": 6,
      "y": 1,
      "z": -2,
      "name": "Rock_Basalt_Brick_Half",
      "rotation": 7
    },
    {
      "x": 6,
      "y": 2,
      "z": -2,
      "name": "Rock_Basalt_Brick_Half",
      "rotation": 7
    },
    {
      "x": 6,
      "y": 3,
      "z": -2,
      "name": "Rock_Basalt_Brick_Half",
      "rotation": 7
    },
    {
      "x": 6,
      "y": 4,
      "z": -2,
      "name": "Rock_Basalt_Brick_Half",
      "rotation": 7
    },
    {
      "x": 6,
      "y": 5,
      "z": -2,
      "name": "Rock_Basalt_Brick"
    },
    {
      "x": 6,
      "y": 6,
      "z": -2,
      "name": "Rock_Basalt_Brick",
      "rotation": 2
    },
    {
      "x": 6,
      "y": 7,
      "z": -2,
      "name": "Rock_Basalt_Brick",
      "rotation": 2
    },
    {
      "x": 6,
      "y": 0,
      "z": -1,
      "name": "Rock_Basalt",
      "rotation": 2
    },
    {
      "x": 6,
      "y": 1,
      "z": -1,
      "name": "Furniture_Ancient_Barrel"
    },
    {
      "x": 6,
      "y": 7,
      "z": -1,
      "name": "Rock_Basalt_Brick",
      "rotation": 2
    },
    {
      "x": 6,
      "y": 0,
      "z": 0,
      "name": "Rock_Basalt",
      "rotation": 2
    },
    {
      "x": 6,
      "y": 1,
      "z": 0,
      "name": "Furniture_Ancient_Crate",
      "rotation": 3
    },
    {
      "x": 6,
      "y": 7,
      "z": 0,
      "name": "Rock_Basalt_Brick",
      "rotation": 2
    },
    {
      "x": 6,
      "y": 0,
      "z": 1,
      "name": "Rock_Basalt",
      "rotation": 2
    },
    {
      "x": 6,
      "y": 1,
      "z": 1,
      "name": "Deco_SpiderWeb",
      "support": 15,
      "rotation": 3
    },
    {
      "x": 6,
      "y": 5,
      "z": 1,
      "name": "Rock_Ice_Stalactite_Large",
      "filler": 31744,
      "rotation": 8
    },
    {
      "x": 6,
      "y": 6,
      "z": 1,
      "name": "Rock_Ice_Stalactite_Large",
      "rotation": 8
    },
    {
      "x": 6,
      "y": 7,
      "z": 1,
      "name": "Rock_Basalt_Brick",
      "rotation": 2
    },
    {
      "x": 6,
      "y": 0,
      "z": 2,
      "name": "Rock_Basalt",
      "rotation": 2
    },
    {
      "x": 6,
      "y": 7,
      "z": 2,
      "name": "Rock_Basalt_Brick",
      "rotation": 2
    },
    {
      "x": 6,
      "y": 0,
      "z": 3,
      "name": "Rock_Basalt",
      "rotation": 2
    },
    {
      "x": 6,
      "y": 1,
      "z": 3,
      "name": "Rubble_Basalt",
      "support": 15
    },
    {
      "x": 6,
      "y": 7,
      "z": 3,
      "name": "Rock_Basalt_Brick",
      "rotation": 2
    },
    {
      "x": 6,
      "y": 0,
      "z": 4,
      "name": "Rock_Basalt",
      "rotation": 2
    },
    {
      "x": 6,
      "y": 1,
      "z": 4,
      "name": "Furniture_Ancient_Wardrobe",
      "rotation": 2
    },
    {
      "x": 6,
      "y": 2,
      "z": 4,
      "name": "Furniture_Ancient_Wardrobe",
      "filler": 1024,
      "rotation": 2
    },
    {
      "x": 6,
      "y": 6,
      "z": 4,
      "name": "Deco_SpiderWeb_Flat",
      "support": 15,
      "rotation": 6
    },
    {
      "x": 6,
      "y": 7,
      "z": 4,
      "name": "Rock_Basalt_Brick",
      "rotation": 2
    },
    {
      "x": 6,
      "y": 0,
      "z": 5,
      "name": "Rock_Basalt_Brick",
      "rotation": 2
    },
    {
      "x": 6,
      "y": 1,
      "z": 5,
      "name": "Rock_Basalt_Brick",
      "rotation": 2
    },
    {
      "x": 6,
      "y": 2,
      "z": 5,
      "name": "Rock_Basalt_Brick",
      "rotation": 2
    },
    {
      "x": 6,
      "y": 3,
      "z": 5,
      "name": "Rock_Basalt_Brick",
      "rotation": 2
    },
    {
      "x": 6,
      "y": 4,
      "z": 5,
      "name": "Rock_Basalt_Brick",
      "rotation": 2
    },
    {
      "x": 6,
      "y": 5,
      "z": 5,
      "name": "Rock_Basalt_Brick",
      "rotation": 2
    },
    {
      "x": 6,
      "y": 6,
      "z": 5,
      "name": "Rock_Basalt_Brick",
      "rotation": 2
    },
    {
      "x": 6,
      "y": 7,
      "z": 5,
      "name": "Rock_Basalt_Brick",
      "rotation": 2
    },
    {
      "x": 7,
      "y": 0,
      "z": -4,
      "name": "Rock_Basalt",
      "rotation": 2
    },
    {
      "x": 7,
      "y": 1,
      "z": -4,
      "name": "Rubble_Basalt",
      "support": 15
    },
    {
      "x": 7,
      "y": 0,
      "z": -3,
      "name": "Rock_Basalt",
      "rotation": 2
    },
    {
      "x": 7,
      "y": 1,
      "z": -3,
      "name": "Furniture_Ancient_Crate",
      "rotation": 3
    },
    {
      "x": 7,
      "y": 7,
      "z": -3,
      "name": "Rock_Basalt_Brick",
      "rotation": 2
    },
    {
      "x": 7,
      "y": 0,
      "z": -2,
      "name": "Rock_Basalt"
    },
    {
      "x": 7,
      "y": 1,
      "z": -2,
      "name": "Rock_Basalt_Brick"
    },
    {
      "x": 7,
      "y": 2,
      "z": -2,
      "name": "Rock_Basalt_Brick"
    },
    {
      "x": 7,
      "y": 3,
      "z": -2,
      "name": "Rock_Basalt_Brick",
      "rotation": 2
    },
    {
      "x": 7,
      "y": 4,
      "z": -2,
      "name": "Rock_Basalt_Brick",
      "rotation": 2
    },
    {
      "x": 7,
      "y": 5,
      "z": -2,
      "name": "Rock_Basalt_Brick",
      "rotation": 2
    },
    {
      "x": 7,
      "y": 6,
      "z": -2,
      "name": "Rock_Basalt_Brick",
      "rotation": 2
    },
    {
      "x": 7,
      "y": 7,
      "z": -2,
      "name": "Rock_Basalt_Brick",
      "rotation": 2
    },
    {
      "x": 7,
      "y": 0,
      "z": -1,
      "name": "Rock_Basalt",
      "rotation": 2
    },
    {
      "x": 7,
      "y": 1,
      "z": -1,
      "name": "Furniture_Ancient_Crate",
      "rotation": 3
    },
    {
      "x": 7,
      "y": 2,
      "z": -1,
      "name": "Furniture_Ancient_Crate",
      "rotation": 3
    },
    {
      "x": 7,
      "y": 4,
      "z": -1,
      "name": "Deco_SpiderWeb_Flat",
      "support": 15,
      "rotation": 7
    },
    {
      "x": 7,
      "y": 5,
      "z": -1,
      "name": "Deco_SpiderWeb",
      "support": 15,
      "rotation": 9
    },
    {
      "x": 7,
      "y": 6,
      "z": -1,
      "name": "Wood_Deadwood_Planks_Half",
      "rotation": 7
    },
    {
      "x": 7,
      "y": 7,
      "z": -1,
      "name": "Rock_Basalt_Brick",
      "rotation": 2
    },
    {
      "x": 7,
      "y": 0,
      "z": 0,
      "name": "Rock_Basalt",
      "rotation": 2
    },
    {
      "x": 7,
      "y": 1,
      "z": 0,
      "name": "Furniture_Ancient_Crate",
      "rotation": 3
    },
    {
      "x": 7,
      "y": 2,
      "z": 0,
      "name": "Furniture_Ancient_Crate",
      "rotation": 3
    },
    {
      "x": 7,
      "y": 5,
      "z": 0,
      "name": "Deco_SpiderWeb_Flat",
      "support": 15,
      "rotation": 7
    },
    {
      "x": 7,
      "y": 6,
      "z": 0,
      "name": "Wood_Deadwood_Planks_Half",
      "rotation": 7
    },
    {
      "x": 7,
      "y": 7,
      "z": 0,
      "name": "Rock_Basalt_Brick",
      "rotation": 2
    },
    {
      "x": 7,
      "y": 0,
      "z": 1,
      "name": "Rock_Basalt",
      "rotation": 2
    },
    {
      "x": 7,
      "y": 1,
      "z": 1,
      "name": "Furniture_Ancient_Crate",
      "rotation": 3
    },
    {
      "x": 7,
      "y": 6,
      "z": 1,
      "name": "Wood_Deadwood_Planks_Half",
      "rotation": 7
    },
    {
      "x": 7,
      "y": 7,
      "z": 1,
      "name": "Rock_Basalt_Brick",
      "rotation": 2
    },
    {
      "x": 7,
      "y": 0,
      "z": 2,
      "name": "Rock_Basalt",
      "rotation": 2
    },
    {
      "x": 7,
      "y": 1,
      "z": 2,
      "name": "Block_Spawner_Block",
      "components": {
        "Components": {
          "PlacedByInteraction": {
            "WhoPlacedUuid": {
              "$binary": "B1yBGZcjQ2KREo5yyLGY0g==",
              "$type": "04"
            }
          },
          "BlockSpawner": {
            "BlockSpawnerId": "Zone3_Outlander_Tier2"
          }
        }
      },
      "rotation": 3
    },
    {
      "x": 7,
      "y": 3,
      "z": 2,
      "name": "Furniture_Ancient_Platform"
    },
    {
      "x": 7,
      "y": 6,
      "z": 2,
      "name": "Wood_Deadwood_Planks_Half",
      "rotation": 7
    },
    {
      "x": 7,
      "y": 7,
      "z": 2,
      "name": "Rock_Basalt_Brick",
      "rotation": 2
    },
    {
      "x": 7,
      "y": 0,
      "z": 3,
      "name": "Rock_Basalt",
      "rotation": 2
    },
    {
      "x": 7,
      "y": 1,
      "z": 3,
      "name": "Deco_SpiderWeb_Flat",
      "support": 15
    },
    {
      "x": 7,
      "y": 3,
      "z": 3,
      "name": "Furniture_Ancient_Platform"
    },
    {
      "x": 7,
      "y": 4,
      "z": 3,
      "name": "Deco_Book_Pile_Small",
      "rotation": 3
    },
    {
      "x": 7,
      "y": 6,
      "z": 3,
      "name": "Wood_Deadwood_Planks_Half",
      "rotation": 7
    },
    {
      "x": 7,
      "y": 7,
      "z": 3,
      "name": "Rock_Basalt_Brick",
      "rotation": 2
    },
    {
      "x": 7,
      "y": 0,
      "z": 4,
      "name": "Rock_Basalt",
      "rotation": 2
    },
    {
      "x": 7,
      "y": 1,
      "z": 4,
      "name": "Furniture_Ancient_Wardrobe",
      "filler": 1,
      "rotation": 2
    },
    {
      "x": 7,
      "y": 2,
      "z": 4,
      "name": "Furniture_Ancient_Wardrobe",
      "filler": 1025,
      "rotation": 2
    },
    {
      "x": 7,
      "y": 3,
      "z": 4,
      "name": "Furniture_Ancient_Platform"
    },
    {
      "x": 7,
      "y": 4,
      "z": 4,
      "name": "Furniture_Ancient_Barrel"
    },
    {
      "x": 7,
      "y": 6,
      "z": 4,
      "name": "Wood_Deadwood_Planks_Half",
      "rotation": 7
    },
    {
      "x": 7,
      "y": 7,
      "z": 4,
      "name": "Rock_Basalt_Brick",
      "rotation": 2
    },
    {
      "x": 7,
      "y": 0,
      "z": 5,
      "name": "Rock_Basalt_Brick",
      "rotation": 2
    },
    {
      "x": 7,
      "y": 1,
      "z": 5,
      "name": "Rock_Basalt_Brick",
      "rotation": 2
    },
    {
      "x": 7,
      "y": 2,
      "z": 5,
      "name": "Rock_Basalt_Brick",
      "rotation": 2
    },
    {
      "x": 7,
      "y": 3,
      "z": 5,
      "name": "Rock_Basalt_Brick",
      "rotation": 2
    },
    {
      "x": 7,
      "y": 4,
      "z": 5,
      "name": "Rock_Basalt_Brick",
      "rotation": 2
    },
    {
      "x": 7,
      "y": 5,
      "z": 5,
      "name": "Rock_Basalt_Brick",
      "rotation": 2
    },
    {
      "x": 7,
      "y": 6,
      "z": 5,
      "name": "Rock_Basalt_Brick",
      "rotation": 2
    },
    {
      "x": 7,
      "y": 7,
      "z": 5,
      "name": "Rock_Basalt_Brick",
      "rotation": 2
    }
  ],
  "entities": [
    {
      "Components": {
        "EffectController": {},
        "DisplayName": {
          "DisplayName": {
            "MessageId": "server.npcRoles.Skeleton_Frost_Fighter.name",
            "Bold": null,
            "Italic": null,
            "Monospace": null,
            "Underline": null
          }
        },
        "UIComponentList": {},
        "Transform": {
          "Position": {
            "X": -3.9706529084600106,
            "Y": 1.0,
            "Z": 1.7032827628721847
          },
          "Rotation": {
            "Pitch": 0.0,
            "Yaw": -0.45482510328292847,
            "Roll": 0.0
          }
        },
        "Velocity": {
          "Velocity": {
            "X": 0.0,
            "Y": 0.0,
            "Z": 0.0
          }
        },
        "PrefabCopyable": {},
        "Interactions": {
          "Interactions": {
            "Use": "*UseNPC"
          }
        },
        "Model": {
          "Model": {
            "Id": "Skeleton_Frost_Fighter",
            "Scale": 1.0,
            "Static": false
          }
        },
        "UUID": {
          "UUID": {
            "$binary": "vVUyA8zAOj6Jp7P4q2hNhQ==",
            "$type": "04"
          }
        },
        "EntityStats": {
          "Version": 5,
          "Stats": {
            "Oxygen": {
              "Id": "Oxygen",
              "Value": 100.0
            },
            "Mana": {
              "Id": "Mana",
              "Value": 0.0
            },
            "Health": {
              "Id": "Health",
              "Value": 74.0
            },
            "GlidingActive": {
              "Id": "GlidingActive",
              "Value": 0.0
            },
            "Immunity": {
              "Id": "Immunity",
              "Value": 0.0
            },
            "Stamina": {
              "Id": "Stamina",
              "Value": 10.0
            },
            "SignatureCharges": {
              "Id": "SignatureCharges",
              "Value": 0.0
            },
            "Ammo": {
              "Id": "Ammo",
              "Value": 0.0
            },
            "Unknown": {
              "Id": "Unknown",
              "Value": 0.0
            },
            "SignatureEnergy": {
              "Id": "SignatureEnergy",
              "Value": 0.0
            },
            "DeployablePreview": {
              "Id": "DeployablePreview",
              "Value": 0.0
            },
            "StaminaRegenDelay": {
              "Id": "StaminaRegenDelay",
              "Value": 0.0
            },
            "MagicCharges": {
              "Id": "MagicCharges",
              "Value": 0.0
            }
          }
        },
        "NPC": {
          "Version": 5,
          "UUID": {
            "$binary": "oq210xF8OtWPXEZ7F19hJQ==",
            "$type": "04"
          },
          "Inventory": {
            "Version": 4,
            "Storage": {
              "Id": "Empty"
            },
            "Armor": {
              "Id": "Simple",
              "Capacity": 4,
              "Items": {}
            },
            "HotBar": {
              "Id": "Simple",
              "Capacity": 3,
              "Items": {
                "0": {
                  "Id": "Weapon_Club_Iron_Rusty",
                  "Quantity": 1,
                  "Durability": 81.0,
                  "MaxDurability": 81.0,
                  "OverrideDroppedItemAnimation": false
                }
              }
            },
            "Utility": {
              "Id": "Simple",
              "Capacity": 2,
              "Items": {
                "0": {
                  "Id": "Furniture_Crude_Torch",
                  "Quantity": 1,
                  "Durability": 0.0,
                  "MaxDurability": 0.0,
                  "OverrideDroppedItemAnimation": false
                }
              }
            },
            "Backpack": {
              "Id": "Empty"
            },
            "ActiveHotbarSlot": 0,
            "Tool": {
              "Id": "Empty"
            },
            "ActiveToolsSlot": -1,
            "ActiveUtilitySlot": -1,
            "SortType": "Name"
          },
          "HvrPhs": 0.0,
          "HvrHght": 0.0,
          "MdlScl": 1.0,
          "SpawnInstant": "0001-01-01T12:00:00Z",
          "WorldgenId": 0,
          "PathManager": {},
          "LeashPos": {
            "X": 118.02934709153999,
            "Y": 56.0,
            "Z": 5.703282762872185
          },
          "LeashHdg": -0.45482510328292847,
          "LeashPtch": 0.0,
          "RoleName": "Skeleton_Frost_Fighter"
        },
        "HeadRotation": {
          "Rotation": {
            "Pitch": 0.0,
            "Yaw": -0.45482510328292847,
            "Roll": 0.0
          }
        }
      }
    },
    {
      "Components": {
        "EffectController": {},
        "DisplayName": {
          "DisplayName": {
            "MessageId": "server.npcRoles.Skeleton_Frost_Fighter.name",
            "Bold": null,
            "Italic": null,
            "Monospace": null,
            "Underline": null
          }
        },
        "UIComponentList": {},
        "Transform": {
          "Position": {
            "X": 0.7733091163845955,
            "Y": 1.0,
            "Z": 1.905128883941063
          },
          "Rotation": {
            "Pitch": 0.0,
            "Yaw": -0.4089093506336212,
            "Roll": 0.0
          }
        },
        "Velocity": {
          "Velocity": {
            "X": 0.0,
            "Y": 0.0,
            "Z": 0.0
          }
        },
        "PrefabCopyable": {},
        "Interactions": {
          "Interactions": {
            "Use": "*UseNPC"
          }
        },
        "Model": {
          "Model": {
            "Id": "Skeleton_Frost_Fighter",
            "Scale": 1.0,
            "Static": false
          }
        },
        "UUID": {
          "UUID": {
            "$binary": "zNa6Rwd2N6yFd+1z0nrMkw==",
            "$type": "04"
          }
        },
        "EntityStats": {
          "Version": 5,
          "Stats": {
            "Oxygen": {
              "Id": "Oxygen",
              "Value": 100.0
            },
            "Mana": {
              "Id": "Mana",
              "Value": 0.0
            },
            "Health": {
              "Id": "Health",
              "Value": 74.0
            },
            "GlidingActive": {
              "Id": "GlidingActive",
              "Value": 0.0
            },
            "Immunity": {
              "Id": "Immunity",
              "Value": 0.0
            },
            "Stamina": {
              "Id": "Stamina",
              "Value": 10.0
            },
            "SignatureCharges": {
              "Id": "SignatureCharges",
              "Value": 0.0
            },
            "Ammo": {
              "Id": "Ammo",
              "Value": 0.0
            },
            "Unknown": {
              "Id": "Unknown",
              "Value": 0.0
            },
            "SignatureEnergy": {
              "Id": "SignatureEnergy",
              "Value": 0.0
            },
            "DeployablePreview": {
              "Id": "DeployablePreview",
              "Value": 0.0
            },
            "StaminaRegenDelay": {
              "Id": "StaminaRegenDelay",
              "Value": 0.0
            },
            "MagicCharges": {
              "Id": "MagicCharges",
              "Value": 0.0
            }
          }
        },
        "NPC": {
          "Version": 5,
          "UUID": {
            "$binary": "YEsrvjduOxiqK0Aszn+AcQ==",
            "$type": "04"
          },
          "Inventory": {
            "Version": 4,
            "Storage": {
              "Id": "Empty"
            },
            "Armor": {
              "Id": "Simple",
              "Capacity": 4,
              "Items": {}
            },
            "HotBar": {
              "Id": "Simple",
              "Capacity": 3,
              "Items": {
                "0": {
                  "Id": "Weapon_Club_Iron_Rusty",
                  "Quantity": 1,
                  "Durability": 81.0,
                  "MaxDurability": 81.0,
                  "OverrideDroppedItemAnimation": false
                }
              }
            },
            "Utility": {
              "Id": "Simple",
              "Capacity": 2,
              "Items": {
                "0": {
                  "Id": "Furniture_Crude_Torch",
                  "Quantity": 1,
                  "Durability": 0.0,
                  "MaxDurability": 0.0,
                  "OverrideDroppedItemAnimation": false
                }
              }
            },
            "Backpack": {
              "Id": "Empty"
            },
            "ActiveHotbarSlot": 0,
            "Tool": {
              "Id": "Empty"
            },
            "ActiveToolsSlot": -1,
            "ActiveUtilitySlot": -1,
            "SortType": "Name"
          },
          "HvrPhs": 0.0,
          "HvrHght": 0.0,
          "MdlScl": 1.0,
          "SpawnInstant": "0001-01-01T12:00:00Z",
          "WorldgenId": 0,
          "PathManager": {},
          "LeashPos": {
            "X": 122.7733091163846,
            "Y": 56.0,
            "Z": 5.905128883941063
          },
          "LeashHdg": -0.4089093506336212,
          "LeashPtch": 0.0,
          "RoleName": "Skeleton_Frost_Fighter"
        },
        "HeadRotation": {
          "Rotation": {
            "Pitch": 0.0,
            "Yaw": -0.4089093506336212,
            "Roll": 0.0
          }
        }
      }
    },
    {
      "Components": {
        "EffectController": {},
        "DisplayName": {
          "DisplayName": {
            "MessageId": "server.npcRoles.Skeleton_Frost_Archer.name",
            "Bold": null,
            "Italic": null,
            "Monospace": null,
            "Underline": null
          }
        },
        "UIComponentList": {},
        "Transform": {
          "Position": {
            "X": 5.321902961244916,
            "Y": 1.0,
            "Z": 1.266772125394878
          },
          "Rotation": {
            "Pitch": 0.0,
            "Yaw": 0.4011335074901581,
            "Roll": 0.0
          }
        },
        "Velocity": {
          "Velocity": {
            "X": 0.0,
            "Y": 0.0,
            "Z": 0.0
          }
        },
        "PrefabCopyable": {},
        "Interactions": {
          "Interactions": {
            "Use": "*UseNPC"
          }
        },
        "Model": {
          "Model": {
            "Id": "Skeleton_Frost_Archer",
            "Scale": 1.0,
            "Static": false
          }
        },
        "UUID": {
          "UUID": {
            "$binary": "kgCMYm57MIe5l4J5LgW62g==",
            "$type": "04"
          }
        },
        "EntityStats": {
          "Version": 5,
          "Stats": {
            "Oxygen": {
              "Id": "Oxygen",
              "Value": 100.0
            },
            "Mana": {
              "Id": "Mana",
              "Value": 0.0
            },
            "Health": {
              "Id": "Health",
              "Value": 61.0
            },
            "GlidingActive": {
              "Id": "GlidingActive",
              "Value": 0.0
            },
            "Immunity": {
              "Id": "Immunity",
              "Value": 0.0
            },
            "Stamina": {
              "Id": "Stamina",
              "Value": 10.0
            },
            "SignatureCharges": {
              "Id": "SignatureCharges",
              "Value": 0.0
            },
            "Ammo": {
              "Id": "Ammo",
              "Value": 0.0
            },
            "Unknown": {
              "Id": "Unknown",
              "Value": 0.0
            },
            "SignatureEnergy": {
              "Id": "SignatureEnergy",
              "Value": 0.0
            },
            "DeployablePreview": {
              "Id": "DeployablePreview",
              "Value": 0.0
            },
            "StaminaRegenDelay": {
              "Id": "StaminaRegenDelay",
              "Value": 0.0
            },
            "MagicCharges": {
              "Id": "MagicCharges",
              "Value": 0.0
            }
          }
        },
        "NPC": {
          "Version": 5,
          "UUID": {
            "$binary": "wfCt2vz5PIerRMrpcJPsyw==",
            "$type": "04"
          },
          "Inventory": {
            "Version": 4,
            "Storage": {
              "Id": "Empty"
            },
            "Armor": {
              "Id": "Simple",
              "Capacity": 4,
              "Items": {}
            },
            "HotBar": {
              "Id": "Simple",
              "Capacity": 3,
              "Items": {
                "0": {
                  "Id": "Weapon_Shortbow_Frost",
                  "Quantity": 1,
                  "Durability": 80.0,
                  "MaxDurability": 80.0,
                  "OverrideDroppedItemAnimation": false
                }
              }
            },
            "Utility": {
              "Id": "Simple",
              "Capacity": 2,
              "Items": {
                "0": {
                  "Id": "Furniture_Crude_Torch",
                  "Quantity": 1,
                  "Durability": 0.0,
                  "MaxDurability": 0.0,
                  "OverrideDroppedItemAnimation": false
                }
              }
            },
            "Backpack": {
              "Id": "Empty"
            },
            "ActiveHotbarSlot": 0,
            "Tool": {
              "Id": "Empty"
            },
            "ActiveToolsSlot": -1,
            "ActiveUtilitySlot": -1,
            "SortType": "Name"
          },
          "HvrPhs": 0.0,
          "HvrHght": 0.0,
          "MdlScl": 1.0,
          "SpawnInstant": "0001-01-01T12:00:00Z",
          "WorldgenId": 0,
          "PathManager": {},
          "LeashPos": {
            "X": 127.32190296124492,
            "Y": 56.0,
            "Z": 5.266772125394878
          },
          "LeashHdg": 0.4011335074901581,
          "LeashPtch": 0.0,
          "RoleName": "Skeleton_Frost_Archer"
        },
        "HeadRotation": {
          "Rotation": {
            "Pitch": 0.0,
            "Yaw": 0.4011335074901581,
            "Roll": 0.0
          }
        }
      }
    }
  ]
}