{
  "version": 8,
  "blockIdVersion": 11,
  "anchorX": -6,
  "anchorY": 1,
  "anchorZ": -4,
  "blocks": [
    {
      "x": -6,
      "y": 0,
      "z": -4,
      "name": "Rock_Basalt",
      "rotation": 2
    },
    {
      "x": -6,
      "y": 1,
      "z": -4,
      "name": "Empty",
      "rotation": 2
    },
    {
      "x": -6,
      "y": 0,
      "z": -3,
      "name": "Rock_Basalt",
      "rotation": 2
    },
    {
      "x": -6,
      "y": 1,
      "z": -3,
      "name": "Rubble_Basalt",
      "support": 15
    },
    {
      "x": -6,
      "y": 7,
      "z": -3,
      "name": "Rock_Basalt_Brick",
      "rotation": 2
    },
    {
      "x": -6,
      "y": 0,
      "z": -2,
      "name": "Rock_Basalt"
    },
    {
      "x": -6,
      "y": 1,
      "z": -2,
      "name": "Rock_Basalt_Brick",
      "rotation": 2
    },
    {
      "x": -6,
      "y": 2,
      "z": -2,
      "name": "Rock_Basalt_Brick",
      "rotation": 2
    },
    {
      "x": -6,
      "y": 3,
      "z": -2,
      "name": "Rock_Basalt_Brick",
      "rotation": 2
    },
    {
      "x": -6,
      "y": 4,
      "z": -2,
      "name": "Rock_Basalt_Brick",
      "rotation": 2
    },
    {
      "x": -6,
      "y": 5,
      "z": -2,
      "name": "Rock_Basalt_Brick",
      "rotation": 2
    },
    {
      "x": -6,
      "y": 6,
      "z": -2,
      "name": "Rock_Basalt_Brick",
      "rotation": 2
    },
    {
      "x": -6,
      "y": 7,
      "z": -2,
      "name": "Rock_Basalt_Brick",
      "rotation": 2
    },
    {
      "x": -6,
      "y": 0,
      "z": -1,
      "name": "Rock_Basalt",
      "rotation": 2
    },
    {
      "x": -6,
      "y": 1,
      "z": -1,
      "name": "Furniture_Ancient_Crate",
      "rotation": 1
    },
    {
      "x": -6,
      "y": 2,
      "z": -1,
      "name": "Furniture_Ancient_Crate",
      "rotation": 1
    },
    {
      "x": -6,
      "y": 3,
      "z": -1,
      "name": "Furniture_Ancient_Shelf",
      "rotation": 1
    },
    {
      "x": -6,
      "y": 6,
      "z": -1,
      "name": "Wood_Deadwood_Planks_Half",
      "rotation": 5
    },
    {
      "x": -6,
      "y": 7,
      "z": -1,
      "name": "Rock_Basalt_Brick",
      "rotation": 2
    },
    {
      "x": -6,
      "y": 0,
      "z": 0,
      "name": "Rock_Basalt",
      "rotation": 2
    },
    {
      "x": -6,
      "y": 1,
      "z": 0,
      "name": "Furniture_Ancient_Crate",
      "rotation": 1
    },
    {
      "x": -6,
      "y": 3,
      "z": 0,
      "name": "Furniture_Ancient_Shelf",
      "rotation": 1
    },
    {
      "x": -6,
      "y": 6,
      "z": 0,
      "name": "Wood_Deadwood_Planks_Half",
      "rotation": 5
    },
    {
      "x": -6,
      "y": 7,
      "z": 0,
      "name": "Rock_Basalt_Brick",
      "rotation": 2
    },
    {
      "x": -6,
      "y": 0,
      "z": 1,
      "name": "Rock_Basalt",
      "rotation": 2
    },
    {
      "x": -6,
      "y": 1,
      "z": 1,
      "name": "Rock_Ice_Icicles"
    },
    {
      "x": -6,
      "y": 6,
      "z": 1,
      "name": "Wood_Deadwood_Planks_Half",
      "rotation": 5
    },
    {
      "x": -6,
      "y": 7,
      "z": 1,
      "name": "Rock_Basalt_Brick",
      "rotation": 2
    },
    {
      "x": -6,
      "y": 0,
      "z": 2,
      "name": "Rock_Basalt",
      "rotation": 2
    },
    {
      "x": -6,
      "y": 1,
      "z": 2,
      "name": "Rubble_Basalt_Medium",
      "support": 15
    },
    {
      "x": -6,
      "y": 2,
      "z": 2,
      "name": "Furniture_Ancient_Shelf",
      "rotation": 1
    },
    {
      "x": -6,
      "y": 6,
      "z": 2,
      "name": "Wood_Deadwood_Planks_Half",
      "rotation": 5
    },
    {
      "x": -6,
      "y": 7,
      "z": 2,
      "name": "Rock_Basalt_Brick",
      "rotation": 2
    },
    {
      "x": -6,
      "y": 0,
      "z": 3,
      "name": "Rock_Basalt",
      "rotation": 2
    },
    {
      "x": -6,
      "y": 1,
      "z": 3,
      "name": "Deco_Iron_Stack",
      "support": 15,
      "rotation": 1
    },
    {
      "x": -6,
      "y": 2,
      "z": 3,
      "name": "Furniture_Ancient_Shelf",
      "rotation": 1
    },
    {
      "x": -6,
      "y": 6,
      "z": 3,
      "name": "Wood_Deadwood_Planks_Half",
      "rotation": 5
    },
    {
      "x": -6,
      "y": 7,
      "z": 3,
      "name": "Rock_Basalt_Brick",
      "rotation": 2
    },
    {
      "x": -6,
      "y": 0,
      "z": 4,
      "name": "Rock_Basalt",
      "rotation": 2
    },
    {
      "x": -6,
      "y": 1,
      "z": 4,
      "name": "Deco_Iron_Stack",
      "support": 15,
      "rotation": 1
    },
    {
      "x": -6,
      "y": 2,
      "z": 4,
      "name": "Deco_Iron_Stack",
      "support": 15
    },
    {
      "x": -6,
      "y": 6,
      "z": 4,
      "name": "Wood_Deadwood_Planks_Half",
      "rotation": 5
    },
    {
      "x": -6,
      "y": 7,
      "z": 4,
      "name": "Rock_Basalt_Brick",
      "rotation": 2
    },
    {
      "x": -6,
      "y": 0,
      "z": 5,
      "name": "Rock_Basalt_Brick",
      "rotation": 2
    },
    {
      "x": -6,
      "y": 1,
      "z": 5,
      "name": "Rock_Basalt_Brick",
      "rotation": 2
    },
    {
      "x": -6,
      "y": 2,
      "z": 5,
      "name": "Rock_Basalt_Brick",
      "rotation": 2
    },
    {
      "x": -6,
      "y": 3,
      "z": 5,
      "name": "Rock_Basalt_Brick",
      "rotation": 2
    },
    {
      "x": -6,
      "y": 4,
      "z": 5,
      "name": "Rock_Basalt_Brick",
      "rotation": 2
    },
    {
      "x": -6,
      "y": 5,
      "z": 5,
      "name": "Rock_Basalt_Brick",
      "rotation": 2
    },
    {
      "x": -6,
      "y": 6,
      "z": 5,
      "name": "Rock_Basalt_Brick",
      "rotation": 2
    },
    {
      "x": -6,
      "y": 7,
      "z": 5,
      "name": "Rock_Basalt_Brick",
      "rotation": 2
    },
    {
      "x": -5,
      "y": 0,
      "z": -4,
      "name": "Rock_Basalt",
      "rotation": 2
    },
    {
      "x": -5,
      "y": 0,
      "z": -3,
      "name": "Rock_Basalt",
      "rotation": 2
    },
    {
      "x": -5,
      "y": 1,
      "z": -3,
      "name": "Rubble_Basalt_Medium",
      "support": 15
    },
    {
      "x": -5,
      "y": 7,
      "z": -3,
      "name": "Rock_Basalt_Brick",
      "rotation": 2
    },
    {
      "x": -5,
      "y": 0,
      "z": -2,
      "name": "Rock_Basalt"
    },
    {
      "x": -5,
      "y": 1,
      "z": -2,
      "name": "Rock_Basalt_Brick_Half",
      "rotation": 5
    },
    {
      "x": -5,
      "y": 2,
      "z": -2,
      "name": "Rock_Basalt_Brick_Half",
      "rotation": 5
    },
    {
      "x": -5,
      "y": 3,
      "z": -2,
      "name": "Rock_Basalt_Brick_Half",
      "rotation": 5
    },
    {
      "x": -5,
      "y": 4,
      "z": -2,
      "name": "Rock_Basalt_Brick_Half",
      "rotation": 5
    },
    {
      "x": -5,
      "y": 5,
      "z": -2,
      "name": "Rock_Basalt_Brick"
    },
    {
      "x": -5,
      "y": 6,
      "z": -2,
      "name": "Rock_Basalt_Brick",
      "rotation": 2
    },
    {
      "x": -5,
      "y": 7,
      "z": -2,
      "name": "Rock_Basalt_Brick",
      "rotation": 2
    },
    {
      "x": -5,
      "y": 0,
      "z": -1,
      "name": "Rock_Basalt",
      "rotation": 2
    },
    {
      "x": -5,
      "y": 1,
      "z": -1,
      "name": "Furniture_Ancient_Barrel"
    },
    {
      "x": -5,
      "y": 7,
      "z": -1,
      "name": "Rock_Basalt_Brick",
      "rotation": 2
    },
    {
      "x": -5,
      "y": 0,
      "z": 0,
      "name": "Rock_Basalt",
      "rotation": 2
    },
    {
      "x": -5,
      "y": 7,
      "z": 0,
      "name": "Rock_Basalt_Brick",
      "rotation": 2
    },
    {
      "x": -5,
      "y": 0,
      "z": 1,
      "name": "Rock_Basalt",
      "rotation": 2
    },
    {
      "x": -5,
      "y": 7,
      "z": 1,
      "name": "Rock_Basalt_Brick",
      "rotation": 2
    },
    {
      "x": -5,
      "y": 0,
      "z": 2,
      "name": "Rock_Basalt",
      "rotation": 2
    },
    {
      "x": -5,
      "y": 1,
      "z": 2,
      "name": "Furniture_Ancient_Table",
      "filler": 1023,
      "rotation": 2
    },
    {
      "x": -5,
      "y": 5,
      "z": 2,
      "name": "Rock_Ice_Stalactite_Large",
      "filler": 31744,
      "rotation": 8
    },
    {
      "x": -5,
      "y": 6,
      "z": 2,
      "name": "Rock_Ice_Stalactite_Large",
      "rotation": 8
    },
    {
      "x": -5,
      "y": 7,
      "z": 2,
      "name": "Rock_Basalt_Brick",
      "rotation": 2
    },
    {
      "x": -5,
      "y": 0,
      "z": 3,
      "name": "Rock_Basalt",
      "rotation": 2
    },
    {
      "x": -5,
      "y": 1,
      "z": 3,
      "name": "Furniture_Ancient_Table",
      "filler": 31,
      "rotation": 2
    },
    {
      "x": -5,
      "y": 2,
      "z": 3,
      "name": "Block_Spawner_Block",
      "components": {
        "Components": {
          "PlacedByInteraction": {
            "WhoPlacedUuid": {
              "$binary": "B1yBGZcjQ2KREo5yyLGY0g==",
              "$type": "04"
            }
          },
          "BlockSpawner": {
            "BlockSpawnerId": "Zone3_Outlander_Tier2"
          }
        }
      }
    },
    {
      "x": -5,
      "y": 7,
      "z": 3,
      "name": "Rock_Basalt_Brick",
      "rotation": 2
    },
    {
      "x": -5,
      "y": 0,
      "z": 4,
      "name": "Rock_Basalt",
      "rotation": 2
    },
    {
      "x": -5,
      "y": 1,
      "z": 4,
      "name": "Deco_Iron_Stack",
      "support": 15,
      "rotation": 1
    },
    {
      "x": -5,
      "y": 2,
      "z": 4,
      "name": "Deco_Iron_Stack",
      "support": 15
    },
    {
      "x": -5,
      "y": 7,
      "z": 4,
      "name": "Rock_Basalt_Brick",
      "rotation": 2
    },
    {
      "x": -5,
      "y": 0,
      "z": 5,
      "name": "Rock_Basalt_Brick",
      "rotation": 2
    },
    {
      "x": -5,
      "y": 1,
      "z": 5,
      "name": "Rock_Basalt_Brick",
      "rotation": 2
    },
    {
      "x": -5,
      "y": 2,
      "z": 5,
      "name": "Rock_Basalt_Brick",
      "rotation": 2
    },
    {
      "x": -5,
      "y": 3,
      "z": 5,
      "name": "Rock_Basalt_Brick",
      "rotation": 2
    },
    {
      "x": -5,
      "y": 4,
      "z": 5,
      "name": "Rock_Basalt_Brick",
      "rotation": 2
    },
    {
      "x": -5,
      "y": 5,
      "z": 5,
      "name": "Rock_Basalt_Brick",
      "rotation": 2
    },
    {
      "x": -5,
      "y": 6,
      "z": 5,
      "name": "Rock_Basalt_Brick",
      "rotation": 2
    },
    {
      "x": -5,
      "y": 7,
      "z": 5,
      "name": "Rock_Basalt_Brick",
      "rotation": 2
    },
    {
      "x": -4,
      "y": 0,
      "z": -4,
      "name": "Rock_Basalt",
      "rotation": 2
    },
    {
      "x": -4,
      "y": 1,
      "z": -4,
      "name": "Rubble_Basalt",
      "support": 15
    },
    {
      "x": -4,
      "y": 0,
      "z": -3,
      "name": "Rock_Basalt",
      "rotation": 2
    },
    {
      "x": -4,
      "y": 7,
      "z": -3,
      "name": "Rock_Basalt_Brick",
      "rotation": 2
    },
    {
      "x": -4,
      "y": 0,
      "z": -2,
      "name": "Rock_Basalt"
    },
    {
      "x": -4,
      "y": 5,
      "z": -2,
      "name": "Rock_Basalt_Brick_Half",
      "rotation": 8
    },
    {
      "x": -4,
      "y": 6,
      "z": -2,
      "name": "Rock_Basalt_Brick",
      "rotation": 2
    },
    {
      "x": -4,
      "y": 7,
      "z": -2,
      "name": "Rock_Basalt_Brick",
      "rotation": 2
    },
    {
      "x": -4,
      "y": 0,
      "z": -1,
      "name": "Rock_Basalt",
      "rotation": 2
    },
    {
      "x": -4,
      "y": 7,
      "z": -1,
      "name": "Rock_Basalt_Brick",
      "rotation": 2
    },
    {
      "x": -4,
      "y": 0,
      "z": 0,
      "name": "Rock_Basalt",
      "rotation": 2
    },
    {
      "x": -4,
      "y": 7,
      "z": 0,
      "name": "Rock_Basalt_Brick",
      "rotation": 2
    },
    {
      "x": -4,
      "y": 0,
      "z": 1,
      "name": "Rock_Basalt",
      "rotation": 2
    },
    {
      "x": -4,
      "y": 1,
      "z": 1,
      "name": "Deco_Iron_Stack",
      "support": 15,
      "rotation": 1
    },
    {
      "x": -4,
      "y": 6,
      "z": 1,
      "name": "Rock_Ice_Icicles",
      "rotation": 8
    },
    {
      "x": -4,
      "y": 7,
      "z": 1,
      "name": "Rock_Basalt_Brick",
      "rotation": 2
    },
    {
      "x": -4,
      "y": 0,
      "z": 2,
      "name": "Rock_Basalt",
      "rotation": 2
    },
    {
      "x": -4,
      "y": 1,
      "z": 2,
      "name": "Furniture_Ancient_Table",
      "filler": 992,
      "rotation": 2
    },
    {
      "x": -4,
      "y": 2,
      "z": 2,
      "name": "Deco_Iron_Stack",
      "support": 15
    },
    {
      "x": -4,
      "y": 7,
      "z": 2,
      "name": "Rock_Basalt_Brick",
      "rotation": 2
    },
    {
      "x": -4,
      "y": 0,
      "z": 3,
      "name": "Rock_Basalt",
      "rotation": 2
    },
    {
      "x": -4,
      "y": 1,
      "z": 3,
      "name": "Furniture_Ancient_Table",
      "rotation": 2
    },
    {
      "x": -4,
      "y": 2,
      "z": 3,
      "name": "Rock_Bronze_Smooth"
    },
    {
      "x": -4,
      "y": 3,
      "z": 3,
      "name": "Bronze_Pipe_Large"
    },
    {
      "x": -4,
      "y": 4,
      "z": 3,
      "name": "Bronze_Pipe_Large"
    },
    {
      "x": -4,
      "y": 5,
      "z": 3,
      "name": "Rock_Bronze_Smooth"
    },
    {
      "x": -4,
      "y": 7,
      "z": 3,
      "name": "Rock_Basalt_Brick",
      "rotation": 2
    },
    {
      "x": -4,
      "y": 0,
      "z": 4,
      "name": "Rock_Basalt",
      "rotation": 2
    },
    {
      "x": -4,
      "y": 1,
      "z": 4,
      "name": "Deco_Iron_Stack",
      "support": 15,
      "rotation": 1
    },
    {
      "x": -4,
      "y": 2,
      "z": 4,
      "name": "Deco_Iron_Stack",
      "support": 15
    },
    {
      "x": -4,
      "y": 3,
      "z": 4,
      "name": "Deco_Iron_Stack",
      "support": 15,
      "rotation": 1
    },
    {
      "x": -4,
      "y": 7,
      "z": 4,
      "name": "Rock_Basalt_Brick",
      "rotation": 2
    },
    {
      "x": -4,
      "y": 0,
      "z": 5,
      "name": "Rock_Basalt_Brick",
      "rotation": 2
    },
    {
      "x": -4,
      "y": 1,
      "z": 5,
      "name": "Rock_Basalt_Brick",
      "rotation": 2
    },
    {
      "x": -4,
      "y": 2,
      "z": 5,
      "name": "Rock_Basalt_Brick",
      "rotation": 2
    },
    {
      "x": -4,
      "y": 3,
      "z": 5,
      "name": "Rock_Basalt_Brick",
      "rotation": 2
    },
    {
      "x": -4,
      "y": 4,
      "z": 5,
      "name": "Rock_Basalt_Brick",
      "rotation": 2
    },
    {
      "x": -4,
      "y": 5,
      "z": 5,
      "name": "Rock_Basalt_Brick",
      "rotation": 2
    },
    {
      "x": -4,
      "y": 6,
      "z": 5,
      "name": "Rock_Basalt_Brick",
      "rotation": 2
    },
    {
      "x": -4,
      "y": 7,
      "z": 5,
      "name": "Rock_Basalt_Brick",
      "rotation": 2
    },
    {
      "x": -3,
      "y": 0,
      "z": -4,
      "name": "Rock_Basalt",
      "rotation": 2
    },
    {
      "x": -3,
      "y": 0,
      "z": -3,
      "name": "Rock_Basalt",
      "rotation": 2
    },
    {
      "x": -3,
      "y": 7,
      "z": -3,
      "name": "Rock_Basalt_Brick",
      "rotation": 2
    },
    {
      "x": -3,
      "y": 0,
      "z": -2,
      "name": "Rock_Basalt"
    },
    {
      "x": -3,
      "y": 6,
      "z": -2,
      "name": "Rock_Basalt_Brick",
      "rotation": 2
    },
    {
      "x": -3,
      "y": 7,
      "z": -2,
      "name": "Rock_Basalt_Brick",
      "rotation": 2
    },
    {
      "x": -3,
      "y": 0,
      "z": -1,
      "name": "Rock_Basalt",
      "rotation": 2
    },
    {
      "x": -3,
      "y": 1,
      "z": -1,
      "name": "Furniture_Basalt_Trough",
      "rotation": 2
    },
    {
      "x": -3,
      "y": 7,
      "z": -1,
      "name": "Rock_Basalt_Brick",
      "rotation": 2
    },
    {
      "x": -3,
      "y": 0,
      "z": 0,
      "name": "Rock_Basalt",
      "rotation": 2
    },
    {
      "x": -3,
      "y": 1,
      "z": 0,
      "name": "Furniture_Basalt_Trough",
      "filler": 32,
      "rotation": 2
    },
    {
      "x": -3,
      "y": 5,
      "z": 0,
      "name": "Rock_Ice_Stalactite_Large",
      "filler": 31744,
      "rotation": 8
    },
    {
      "x": -3,
      "y": 6,
      "z": 0,
      "name": "Rock_Ice_Stalactite_Large",
      "rotation": 8
    },
    {
      "x": -3,
      "y": 7,
      "z": 0,
      "name": "Rock_Basalt_Brick",
      "rotation": 2
    },
    {
      "x": -3,
      "y": 0,
      "z": 1,
      "name": "Rock_Basalt",
      "rotation": 2
    },
    {
      "x": -3,
      "y": 1,
      "z": 1,
      "name": "Deco_Mystery_Machine_Large",
      "filler": 31
    },
    {
      "x": -3,
      "y": 2,
      "z": 1,
      "name": "Deco_Mystery_Machine_Large",
      "filler": 1055
    },
    {
      "x": -3,
      "y": 3,
      "z": 1,
      "name": "Deco_Mystery_Machine_Large",
      "filler": 2079
    },
    {
      "x": -3,
      "y": 4,
      "z": 1,
      "name": "Deco_Mystery_Machine_Large",
      "filler": 3103
    },
    {
      "x": -3,
      "y": 7,
      "z": 1,
      "name": "Rock_Basalt_Brick",
      "rotation": 2
    },
    {
      "x": -3,
      "y": 0,
      "z": 2,
      "name": "Rock_Basalt",
      "rotation": 2
    },
    {
      "x": -3,
      "y": 1,
      "z": 2,
      "name": "Deco_Mystery_Machine_Large",
      "filler": 63
    },
    {
      "x": -3,
      "y": 2,
      "z": 2,
      "name": "Deco_Mystery_Machine_Large",
      "filler": 1087
    },
    {
      "x": -3,
      "y": 3,
      "z": 2,
      "name": "Deco_Mystery_Machine_Large",
      "filler": 2111
    },
    {
      "x": -3,
      "y": 4,
      "z": 2,
      "name": "Deco_Mystery_Machine_Large",
      "filler": 3135
    },
    {
      "x": -3,
      "y": 7,
      "z": 2,
      "name": "Rock_Basalt_Brick",
      "rotation": 2
    },
    {
      "x": -3,
      "y": 0,
      "z": 3,
      "name": "Rock_Basalt",
      "rotation": 2
    },
    {
      "x": -3,
      "y": 1,
      "z": 3,
      "name": "Deco_Mystery_Machine_Large",
      "filler": 95
    },
    {
      "x": -3,
      "y": 2,
      "z": 3,
      "name": "Deco_Mystery_Machine_Large",
      "filler": 1119
    },
    {
      "x": -3,
      "y": 3,
      "z": 3,
      "name": "Deco_Mystery_Machine_Large",
      "filler": 2143
    },
    {
      "x": -3,
      "y": 4,
      "z": 3,
      "name": "Deco_Mystery_Machine_Large",
      "filler": 3167
    },
    {
      "x": -3,
      "y": 5,
      "z": 3,
      "name": "Bronze_Pipe_Large",
      "rotation": 5
    },
    {
      "x": -3,
      "y": 7,
      "z": 3,
      "name": "Rock_Basalt_Brick",
      "rotation": 2
    },
    {
      "x": -3,
      "y": 0,
      "z": 4,
      "name": "Rock_Basalt",
      "rotation": 2
    },
    {
      "x": -3,
      "y": 1,
      "z": 4,
      "name": "Deco_Mystery_Machine_Large",
      "filler": 127
    },
    {
      "x": -3,
      "y": 2,
      "z": 4,
      "name": "Deco_Mystery_Machine_Large",
      "filler": 1151
    },
    {
      "x": -3,
      "y": 3,
      "z": 4,
      "name": "Deco_Mystery_Machine_Large",
      "filler": 2175
    },
    {
      "x": -3,
      "y": 4,
      "z": 4,
      "name": "Deco_Mystery_Machine_Large",
      "filler": 3199
    },
    {
      "x": -3,
      "y": 7,
      "z": 4,
      "name": "Rock_Basalt_Brick",
      "rotation": 2
    },
    {
      "x": -3,
      "y": 0,
      "z": 5,
      "name": "Rock_Basalt_Brick",
      "rotation": 2
    },
    {
      "x": -3,
      "y": 1,
      "z": 5,
      "name": "Rock_Basalt_Brick",
      "rotation": 2
    },
    {
      "x": -3,
      "y": 2,
      "z": 5,
      "name": "Rock_Basalt_Brick",
      "rotation": 2
    },
    {
      "x": -3,
      "y": 3,
      "z": 5,
      "name": "Rock_Basalt_Brick",
      "rotation": 2
    },
    {
      "x": -3,
      "y": 4,
      "z": 5,
      "name": "Rock_Basalt_Brick",
      "rotation": 2
    },
    {
      "x": -3,
      "y": 5,
      "z": 5,
      "name": "Rock_Basalt_Brick",
      "rotation": 2
    },
    {
      "x": -3,
      "y": 6,
      "z": 5,
      "name": "Rock_Basalt_Brick",
      "rotation": 2
    },
    {
      "x": -3,
      "y": 7,
      "z": 5,
      "name": "Rock_Basalt_Brick",
      "rotation": 2
    },
    {
      "x": -2,
      "y": 0,
      "z": -4,
      "name": "Rock_Basalt",
      "rotation": 2
    },
    {
      "x": -2,
      "y": 0,
      "z": -3,
      "name": "Rock_Basalt",
      "rotation": 2
    },
    {
      "x": -2,
      "y": 7,
      "z": -3,
      "name": "Rock_Basalt_Brick",
      "rotation": 2
    },
    {
      "x": -2,
      "y": 0,
      "z": -2,
      "name": "Rock_Basalt"
    },
    {
      "x": -2,
      "y": 1,
      "z": -2,
      "name": "Rubble_Basalt",
      "support": 15
    },
    {
      "x": -2,
      "y": 6,
      "z": -2,
      "name": "Rock_Basalt_Brick",
      "rotation": 2
    },
    {
      "x": -2,
      "y": 7,
      "z": -2,
      "name": "Rock_Basalt_Brick",
      "rotation": 2
    },
    {
      "x": -2,
      "y": 0,
      "z": -1,
      "name": "Rock_Basalt",
      "rotation": 2
    },
    {
      "x": -2,
      "y": 1,
      "z": -1,
      "name": "Furniture_Basalt_Trough",
      "filler": 1,
      "rotation": 2
    },
    {
      "x": -2,
      "y": 7,
      "z": -1,
      "name": "Rock_Basalt_Brick",
      "rotation": 2
    },
    {
      "x": -2,
      "y": 0,
      "z": 0,
      "name": "Rock_Basalt",
      "rotation": 2
    },
    {
      "x": -2,
      "y": 1,
      "z": 0,
      "name": "Furniture_Basalt_Trough",
      "filler": 33,
      "rotation": 2
    },
    {
      "x": -2,
      "y": 7,
      "z": 0,
      "name": "Rock_Basalt_Brick",
      "rotation": 2
    },
    {
      "x": -2,
      "y": 0,
      "z": 1,
      "name": "Rock_Basalt",
      "rotation": 2
    },
    {
      "x": -2,
      "y": 1,
      "z": 1,
      "name": "Deco_Mystery_Machine_Large"
    },
    {
      "x": -2,
      "y": 2,
      "z": 1,
      "name": "Deco_Mystery_Machine_Large",
      "filler": 1024
    },
    {
      "x": -2,
      "y": 3,
      "z": 1,
      "name": "Deco_Mystery_Machine_Large",
      "filler": 2048
    },
    {
      "x": -2,
      "y": 4,
      "z": 1,
      "name": "Deco_Mystery_Machine_Large",
      "filler": 3072
    },
    {
      "x": -2,
      "y": 7,
      "z": 1,
      "name": "Rock_Basalt_Brick",
      "rotation": 2
    },
    {
      "x": -2,
      "y": 0,
      "z": 2,
      "name": "Rock_Basalt",
      "rotation": 2
    },
    {
      "x": -2,
      "y": 1,
      "z": 2,
      "name": "Deco_Mystery_Machine_Large",
      "filler": 32
    },
    {
      "x": -2,
      "y": 2,
      "z": 2,
      "name": "Deco_Mystery_Machine_Large",
      "filler": 1056
    },
    {
      "x": -2,
      "y": 3,
      "z": 2,
      "name": "Deco_Mystery_Machine_Large",
      "filler": 2080
    },
    {
      "x": -2,
      "y": 4,
      "z": 2,
      "name": "Deco_Mystery_Machine_Large",
      "filler": 3104
    },
    {
      "x": -2,
      "y": 5,
      "z": 2,
      "name": "Rock_Ice_Stalactite_Large",
      "filler": 31744,
      "rotation": 8
    },
    {
      "x": -2,
      "y": 6,
      "z": 2,
      "name": "Rock_Ice_Stalactite_Large",
      "rotation": 8
    },
    {
      "x": -2,
      "y": 7,
      "z": 2,
      "name": "Rock_Basalt_Brick",
      "rotation": 2
    },
    {
      "x": -2,
      "y": 0,
      "z": 3,
      "name": "Rock_Basalt",
      "rotation": 2
    },
    {
      "x": -2,
      "y": 1,
      "z": 3,
      "name": "Deco_Mystery_Machine_Large",
      "filler": 64
    },
    {
      "x": -2,
      "y": 2,
      "z": 3,
      "name": "Deco_Mystery_Machine_Large",
      "filler": 1088
    },
    {
      "x": -2,
      "y": 3,
      "z": 3,
      "name": "Deco_Mystery_Machine_Large",
      "filler": 2112
    },
    {
      "x": -2,
      "y": 4,
      "z": 3,
      "name": "Deco_Mystery_Machine_Large",
      "filler": 3136
    },
    {
      "x": -2,
      "y": 5,
      "z": 3,
      "name": "Bronze_Pipe_Large",
      "rotation": 5
    },
    {
      "x": -2,
      "y": 7,
      "z": 3,
      "name": "Rock_Basalt_Brick",
      "rotation": 2
    },
    {
      "x": -2,
      "y": 0,
      "z": 4,
      "name": "Rock_Basalt",
      "rotation": 2
    },
    {
      "x": -2,
      "y": 1,
      "z": 4,
      "name": "Deco_Mystery_Machine_Large",
      "filler": 96
    },
    {
      "x": -2,
      "y": 2,
      "z": 4,
      "name": "Deco_Mystery_Machine_Large",
      "filler": 1120
    },
    {
      "x": -2,
      "y": 3,
      "z": 4,
      "name": "Deco_Mystery_Machine_Large",
      "filler": 2144
    },
    {
      "x": -2,
      "y": 4,
      "z": 4,
      "name": "Deco_Mystery_Machine_Large",
      "filler": 3168
    },
    {
      "x": -2,
      "y": 7,
      "z": 4,
      "name": "Rock_Basalt_Brick",
      "rotation": 2
    },
    {
      "x": -2,
      "y": 0,
      "z": 5,
      "name": "Rock_Basalt_Brick",
      "rotation": 2
    },
    {
      "x": -2,
      "y": 1,
      "z": 5,
      "name": "Rock_Basalt_Brick",
      "rotation": 2
    },
    {
      "x": -2,
      "y": 2,
      "z": 5,
      "name": "Rock_Basalt_Brick",
      "rotation": 2
    },
    {
      "x": -2,
      "y": 3,
      "z": 5,
      "name": "Rock_Basalt_Brick",
      "rotation": 2
    },
    {
      "x": -2,
      "y": 4,
      "z": 5,
      "name": "Rock_Basalt_Brick",
      "rotation": 2
    },
    {
      "x": -2,
      "y": 5,
      "z": 5,
      "name": "Rock_Basalt_Brick",
      "rotation": 2
    },
    {
      "x": -2,
      "y": 6,
      "z": 5,
      "name": "Rock_Basalt_Brick",
      "rotation": 2
    },
    {
      "x": -2,
      "y": 7,
      "z": 5,
      "name": "Rock_Basalt_Brick",
      "rotation": 2
    },
    {
      "x": -1,
      "y": 0,
      "z": -4,
      "name": "Rock_Basalt",
      "rotation": 2
    },
    {
      "x": -1,
      "y": 0,
      "z": -3,
      "name": "Rock_Basalt",
      "rotation": 2
    },
    {
      "x": -1,
      "y": 7,
      "z": -3,
      "name": "Rock_Basalt_Brick",
      "rotation": 2
    },
    {
      "x": -1,
      "y": 0,
      "z": -2,
      "name": "Rock_Basalt"
    },
    {
      "x": -1,
      "y": 5,
      "z": -2,
      "name": "Rock_Basalt_Brick_Half",
      "rotation": 8
    },
    {
      "x": -1,
      "y": 6,
      "z": -2,
      "name": "Rock_Basalt_Brick",
      "rotation": 2
    },
    {
      "x": -1,
      "y": 7,
      "z": -2,
      "name": "Rock_Basalt_Brick",
      "rotation": 2
    },
    {
      "x": -1,
      "y": 0,
      "z": -1,
      "name": "Rock_Basalt",
      "rotation": 2
    },
    {
      "x": -1,
      "y": 7,
      "z": -1,
      "name": "Rock_Basalt_Brick",
      "rotation": 2
    },
    {
      "x": -1,
      "y": 0,
      "z": 0,
      "name": "Rock_Basalt",
      "rotation": 2
    },
    {
      "x": -1,
      "y": 1,
      "z": 0,
      "name": "Deco_Iron_Stack",
      "support": 15
    },
    {
      "x": -1,
      "y": 7,
      "z": 0,
      "name": "Rock_Basalt_Brick",
      "rotation": 2
    },
    {
      "x": -1,
      "y": 0,
      "z": 1,
      "name": "Rock_Basalt",
      "rotation": 2
    },
    {
      "x": -1,
      "y": 1,
      "z": 1,
      "name": "Deco_Mystery_Machine_Large",
      "filler": 1
    },
    {
      "x": -1,
      "y": 2,
      "z": 1,
      "name": "Deco_Mystery_Machine_Large",
      "filler": 1025
    },
    {
      "x": -1,
      "y": 3,
      "z": 1,
      "name": "Deco_Mystery_Machine_Large",
      "filler": 2049
    },
    {
      "x": -1,
      "y": 4,
      "z": 1,
      "name": "Deco_Mystery_Machine_Large",
      "filler": 3073
    },
    {
      "x": -1,
      "y": 6,
      "z": 1,
      "name": "Rock_Ice_Icicles",
      "rotation": 8
    },
    {
      "x": -1,
      "y": 7,
      "z": 1,
      "name": "Rock_Basalt_Brick",
      "rotation": 2
    },
    {
      "x": -1,
      "y": 0,
      "z": 2,
      "name": "Rock_Basalt",
      "rotation": 2
    },
    {
      "x": -1,
      "y": 1,
      "z": 2,
      "name": "Deco_Mystery_Machine_Large",
      "filler": 33
    },
    {
      "x": -1,
      "y": 2,
      "z": 2,
      "name": "Deco_Mystery_Machine_Large",
      "filler": 1057
    },
    {
      "x": -1,
      "y": 3,
      "z": 2,
      "name": "Deco_Mystery_Machine_Large",
      "filler": 2081
    },
    {
      "x": -1,
      "y": 4,
      "z": 2,
      "name": "Deco_Mystery_Machine_Large",
      "filler": 3105
    },
    {
      "x": -1,
      "y": 7,
      "z": 2,
      "name": "Rock_Basalt_Brick",
      "rotation": 2
    },
    {
      "x": -1,
      "y": 0,
      "z": 3,
      "name": "Rock_Basalt",
      "rotation": 2
    },
    {
      "x": -1,
      "y": 1,
      "z": 3,
      "name": "Deco_Mystery_Machine_Large",
      "filler": 65
    },
    {
      "x": -1,
      "y": 2,
      "z": 3,
      "name": "Deco_Mystery_Machine_Large",
      "filler": 1089
    },
    {
      "x": -1,
      "y": 3,
      "z": 3,
      "name": "Deco_Mystery_Machine_Large",
      "filler": 2113
    },
    {
      "x": -1,
      "y": 4,
      "z": 3,
      "name": "Deco_Mystery_Machine_Large",
      "filler": 3137
    },
    {
      "x": -1,
      "y": 5,
      "z": 3,
      "name": "Bronze_Pipe_Large",
      "rotation": 5
    },
    {
      "x": -1,
      "y": 6,
      "z": 3,
      "name": "Rock_Ice_Icicles",
      "rotation": 8
    },
    {
      "x": -1,
      "y": 7,
      "z": 3,
      "name": "Rock_Basalt_Brick",
      "rotation": 2
    },
    {
      "x": -1,
      "y": 0,
      "z": 4,
      "name": "Rock_Basalt",
      "rotation": 2
    },
    {
      "x": -1,
      "y": 1,
      "z": 4,
      "name": "Deco_Mystery_Machine_Large",
      "filler": 97
    },
    {
      "x": -1,
      "y": 2,
      "z": 4,
      "name": "Deco_Mystery_Machine_Large",
      "filler": 1121
    },
    {
      "x": -1,
      "y": 3,
      "z": 4,
      "name": "Deco_Mystery_Machine_Large",
      "filler": 2145
    },
    {
      "x": -1,
      "y": 4,
      "z": 4,
      "name": "Deco_Mystery_Machine_Large",
      "filler": 3169
    },
    {
      "x": -1,
      "y": 5,
      "z": 4,
      "name": "Rock_Ice_Stalactite_Large",
      "filler": 31744,
      "rotation": 8
    },
    {
      "x": -1,
      "y": 6,
      "z": 4,
      "name": "Rock_Ice_Stalactite_Large",
      "rotation": 8
    },
    {
      "x": -1,
      "y": 7,
      "z": 4,
      "name": "Rock_Basalt_Brick",
      "rotation": 2
    },
    {
      "x": -1,
      "y": 0,
      "z": 5,
      "name": "Rock_Basalt_Brick",
      "rotation": 2
    },
    {
      "x": -1,
      "y": 1,
      "z": 5,
      "name": "Rock_Basalt_Brick",
      "rotation": 2
    },
    {
      "x": -1,
      "y": 2,
      "z": 5,
      "name": "Rock_Basalt_Brick",
      "rotation": 2
    },
    {
      "x": -1,
      "y": 3,
      "z": 5,
      "name": "Rock_Basalt_Brick",
      "rotation": 2
    },
    {
      "x": -1,
      "y": 4,
      "z": 5,
      "name": "Rock_Basalt_Brick",
      "rotation": 2
    },
    {
      "x": -1,
      "y": 5,
      "z": 5,
      "name": "Rock_Basalt_Brick",
      "rotation": 2
    },
    {
      "x": -1,
      "y": 6,
      "z": 5,
      "name": "Rock_Basalt_Brick",
      "rotation": 2
    },
    {
      "x": -1,
      "y": 7,
      "z": 5,
      "name": "Rock_Basalt_Brick",
      "rotation": 2
    },
    {
      "x": 0,
      "y": 0,
      "z": -4,
      "name": "Rock_Basalt",
      "rotation": 2
    },
    {
      "x": 0,
      "y": 0,
      "z": -3,
      "name": "Rock_Basalt",
      "rotation": 2
    },
    {
      "x": 0,
      "y": 1,
      "z": -3,
      "name": "Rock_Ice_Icicles"
    },
    {
      "x": 0,
      "y": 7,
      "z": -3,
      "name": "Rock_Basalt_Brick",
      "rotation": 2
    },
    {
      "x": 0,
      "y": 0,
      "z": -2,
      "name": "Rock_Basalt"
    },
    {
      "x": 0,
      "y": 1,
      "z": -2,
      "name": "Rock_Basalt_Brick_Half",
      "rotation": 7
    },
    {
      "x": 0,
      "y": 2,
      "z": -2,
      "name": "Rock_Basalt_Brick_Half",
      "rotation": 7
    },
    {
      "x": 0,
      "y": 3,
      "z": -2,
      "name": "Rock_Basalt_Brick_Half",
      "rotation": 7
    },
    {
      "x": 0,
      "y": 4,
      "z": -2,
      "name": "Rock_Basalt_Brick_Half",
      "rotation": 7
    },
    {
      "x": 0,
      "y": 5,
      "z": -2,
      "name": "Rock_Basalt_Brick"
    },
    {
      "x": 0,
      "y": 6,
      "z": -2,
      "name": "Rock_Basalt_Brick",
      "rotation": 2
    },
    {
      "x": 0,
      "y": 7,
      "z": -2,
      "name": "Rock_Basalt_Brick",
      "rotation": 2
    },
    {
      "x": 0,
      "y": 0,
      "z": -1,
      "name": "Rock_Basalt",
      "rotation": 2
    },
    {
      "x": 0,
      "y": 7,
      "z": -1,
      "name": "Rock_Basalt_Brick",
      "rotation": 2
    },
    {
      "x": 0,
      "y": 0,
      "z": 0,
      "name": "Rock_Basalt",
      "rotation": 2
    },
    {
      "x": 0,
      "y": 4,
      "z": 0,
      "name": "Rock_Ice_Icicles",
      "rotation": 8
    },
    {
      "x": 0,
      "y": 5,
      "z": 0,
      "name": "Rock_Bronze_Smooth"
    },
    {
      "x": 0,
      "y": 6,
      "z": 0,
      "name": "Bronze_Pipe_Large"
    },
    {
      "x": 0,
      "y": 7,
      "z": 0,
      "name": "Rock_Basalt_Brick",
      "rotation": 2
    },
    {
      "x": 0,
      "y": 0,
      "z": 1,
      "name": "Rock_Basalt",
      "rotation": 2
    },
    {
      "x": 0,
      "y": 5,
      "z": 1,
      "name": "Bronze_Pipe_Large",
      "rotation": 4
    },
    {
      "x": 0,
      "y": 7,
      "z": 1,
      "name": "Rock_Basalt_Brick",
      "rotation": 2
    },
    {
      "x": 0,
      "y": 0,
      "z": 2,
      "name": "Rock_Basalt",
      "rotation": 2
    },
    {
      "x": 0,
      "y": 1,
      "z": 2,
      "name": "Rubble_Basalt",
      "support": 15
    },
    {
      "x": 0,
      "y": 5,
      "z": 2,
      "name": "Bronze_Pipe_Large",
      "rotation": 4
    },
    {
      "x": 0,
      "y": 7,
      "z": 2,
      "name": "Rock_Basalt_Brick",
      "rotation": 2
    },
    {
      "x": 0,
      "y": 0,
      "z": 3,
      "name": "Rock_Basalt",
      "rotation": 2
    },
    {
      "x": 0,
      "y": 1,
      "z": 3,
      "name": "Furniture_Ancient_Barrel"
    },
    {
      "x": 0,
      "y": 5,
      "z": 3,
      "name": "Rock_Bronze_Smooth"
    },
    {
      "x": 0,
      "y": 7,
      "z": 3,
      "name": "Rock_Basalt_Brick",
      "rotation": 2
    },
    {
      "x": 0,
      "y": 0,
      "z": 4,
      "name": "Rock_Basalt",
      "rotation": 2
    },
    {
      "x": 0,
      "y": 1,
      "z": 4,
      "name": "Furniture_Ancient_Pot",
      "rotation": 2
    },
    {
      "x": 0,
      "y": 3,
      "z": 4,
      "name": "Furniture_Ancient_Shelf",
      "rotation": 2
    },
    {
      "x": 0,
      "y": 6,
      "z": 4,
      "name": "Rock_Ice_Icicles",
      "rotation": 8
    },
    {
      "x": 0,
      "y": 7,
      "z": 4,
      "name": "Rock_Basalt_Brick",
      "rotation": 2
    },
    {
      "x": 0,
      "y": 0,
      "z": 5,
      "name": "Rock_Basalt_Brick",
      "rotation": 2
    },
    {
      "x": 0,
      "y": 1,
      "z": 5,
      "name": "Rock_Basalt_Brick",
      "rotation": 2
    },
    {
      "x": 0,
      "y": 2,
      "z": 5,
      "name": "Rock_Basalt_Brick",
      "rotation": 2
    },
    {
      "x": 0,
      "y": 3,
      "z": 5,
      "name": "Rock_Basalt_Brick",
      "rotation": 2
    },
    {
      "x": 0,
      "y": 4,
      "z": 5,
      "name": "Rock_Basalt_Brick",
      "rotation": 2
    },
    {
      "x": 0,
      "y": 5,
      "z": 5,
      "name": "Rock_Basalt_Brick",
      "rotation": 2
    },
    {
      "x": 0,
      "y": 6,
      "z": 5,
      "name": "Rock_Basalt_Brick",
      "rotation": 2
    },
    {
      "x": 0,
      "y": 7,
      "z": 5,
      "name": "Rock_Basalt_Brick",
      "rotation": 2
    },
    {
      "x": 1,
      "y": 0,
      "z": -4,
      "name": "Rock_Basalt",
      "rotation": 2
    },
    {
      "x": 1,
      "y": 0,
      "z": -3,
      "name": "Rock_Basalt",
      "rotation": 2
    },
    {
      "x": 1,
      "y": 1,
      "z": -3,
      "name": "Rubble_Basalt",
      "support": 15
    },
    {
      "x": 1,
      "y": 7,
      "z": -3,
      "name": "Rock_Basalt_Brick",
      "rotation": 2
    },
    {
      "x": 1,
      "y": 0,
      "z": -2,
      "name": "Rock_Basalt"
    },
    {
      "x": 1,
      "y": 1,
      "z": -2,
      "name": "Rock_Basalt_Brick_Half",
      "rotation": 5
    },
    {
      "x": 1,
      "y": 2,
      "z": -2,
      "name": "Rock_Basalt_Brick_Half",
      "rotation": 5
    },
    {
      "x": 1,
      "y": 3,
      "z": -2,
      "name": "Rock_Basalt_Brick_Half",
      "rotation": 5
    },
    {
      "x": 1,
      "y": 4,
      "z": -2,
      "name": "Rock_Basalt_Brick_Half",
      "rotation": 5
    },
    {
      "x": 1,
      "y": 5,
      "z": -2,
      "name": "Rock_Basalt_Brick"
    },
    {
      "x": 1,
      "y": 6,
      "z": -2,
      "name": "Rock_Basalt_Brick",
      "rotation": 2
    },
    {
      "x": 1,
      "y": 7,
      "z": -2,
      "name": "Rock_Basalt_Brick",
      "rotation": 2
    },
    {
      "x": 1,
      "y": 0,
      "z": -1,
      "name": "Rock_Basalt",
      "rotation": 2
    },
    {
      "x": 1,
      "y": 6,
      "z": -1,
      "name": "Rock_Ice_Icicles",
      "rotation": 8
    },
    {
      "x": 1,
      "y": 7,
      "z": -1,
      "name": "Rock_Basalt_Brick",
      "rotation": 2
    },
    {
      "x": 1,
      "y": 0,
      "z": 0,
      "name": "Rock_Basalt",
      "rotation": 2
    },
    {
      "x": 1,
      "y": 7,
      "z": 0,
      "name": "Rock_Basalt_Brick",
      "rotation": 2
    },
    {
      "x": 1,
      "y": 0,
      "z": 1,
      "name": "Rock_Basalt",
      "rotation": 2
    },
    {
      "x": 1,
      "y": 7,
      "z": 1,
      "name": "Rock_Basalt_Brick",
      "rotation": 2
    },
    {
      "x": 1,
      "y": 0,
      "z": 2,
      "name": "Rock_Basalt",
      "rotation": 2
    },
    {
      "x": 1,
      "y": 1,
      "z": 2,
      "name": "Furniture_Ancient_Table",
      "filler": 1023,
      "rotation": 2
    },
    {
      "x": 1,
      "y": 2,
      "z": 2,
      "name": "Deco_Tankard"
    },
    {
      "x": 1,
      "y": 5,
      "z": 2,
      "name": "Rock_Ice_Stalactite_Large",
      "filler": 31744,
      "rotation": 8
    },
    {
      "x": 1,
      "y": 6,
      "z": 2,
      "name": "Rock_Ice_Stalactite_Large",
      "rotation": 8
    },
    {
      "x": 1,
      "y": 7,
      "z": 2,
      "name": "Rock_Basalt_Brick",
      "rotation": 2
    },
    {
      "x": 1,
      "y": 0,
      "z": 3,
      "name": "Rock_Basalt",
      "rotation": 2
    },
    {
      "x": 1,
      "y": 1,
      "z": 3,
      "name": "Furniture_Ancient_Table",
      "filler": 31,
      "rotation": 2
    },
    {
      "x": 1,
      "y": 2,
      "z": 3,
      "name": "Furniture_Ancient_Barrel"
    },
    {
      "x": 1,
      "y": 5,
      "z": 3,
      "name": "Bronze_Pipe_Large",
      "rotation": 5
    },
    {
      "x": 1,
      "y": 7,
      "z": 3,
      "name": "Rock_Basalt_Brick",
      "rotation": 2
    },
    {
      "x": 1,
      "y": 0,
      "z": 4,
      "name": "Rock_Basalt",
      "rotation": 2
    },
    {
      "x": 1,
      "y": 1,
      "z": 4,
      "name": "Furniture_Ancient_Crate",
      "rotation": 3
    },
    {
      "x": 1,
      "y": 2,
      "z": 4,
      "name": "Furniture_Ancient_Crate",
      "rotation": 2
    },
    {
      "x": 1,
      "y": 7,
      "z": 4,
      "name": "Rock_Basalt_Brick",
      "rotation": 2
    },
    {
      "x": 1,
      "y": 0,
      "z": 5,
      "name": "Rock_Basalt_Brick",
      "rotation": 2
    },
    {
      "x": 1,
      "y": 1,
      "z": 5,
      "name": "Rock_Basalt_Brick",
      "rotation": 2
    },
    {
      "x": 1,
      "y": 2,
      "z": 5,
      "name": "Rock_Basalt_Brick",
      "rotation": 2
    },
    {
      "x": 1,
      "y": 3,
      "z": 5,
      "name": "Rock_Basalt_Brick",
      "rotation": 2
    },
    {
      "x": 1,
      "y": 4,
      "z": 5,
      "name": "Rock_Basalt_Brick",
      "rotation": 2
    },
    {
      "x": 1,
      "y": 5,
      "z": 5,
      "name": "Rock_Basalt_Brick",
      "rotation": 2
    },
    {
      "x": 1,
      "y": 6,
      "z": 5,
      "name": "Rock_Basalt_Brick",
      "rotation": 2
    },
    {
      "x": 1,
      "y": 7,
      "z": 5,
      "name": "Rock_Basalt_Brick",
      "rotation": 2
    },
    {
      "x": 2,
      "y": 0,
      "z": -4,
      "name": "Rock_Basalt",
      "rotation": 2
    },
    {
      "x": 2,
      "y": 0,
      "z": -3,
      "name": "Rock_Basalt",
      "rotation": 2
    },
    {
      "x": 2,
      "y": 7,
      "z": -3,
      "name": "Rock_Basalt_Brick",
      "rotation": 2
    },
    {
      "x": 2,
      "y": 0,
      "z": -2,
      "name": "Rock_Basalt"
    },
    {
      "x": 2,
      "y": 5,
      "z": -2,
      "name": "Rock_Basalt_Brick_Half",
      "rotation": 8
    },
    {
      "x": 2,
      "y": 6,
      "z": -2,
      "name": "Rock_Basalt_Brick",
      "rotation": 2
    },
    {
      "x": 2,
      "y": 7,
      "z": -2,
      "name": "Rock_Basalt_Brick",
      "rotation": 2
    },
    {
      "x": 2,
      "y": 0,
      "z": -1,
      "name": "Rock_Basalt",
      "rotation": 2
    },
    {
      "x": 2,
      "y": 7,
      "z": -1,
      "name": "Rock_Basalt_Brick",
      "rotation": 2
    },
    {
      "x": 2,
      "y": 0,
      "z": 0,
      "name": "Rock_Basalt",
      "rotation": 2
    },
    {
      "x": 2,
      "y": 5,
      "z": 0,
      "name": "Rock_Ice_Stalactite_Large",
      "filler": 31744,
      "rotation": 8
    },
    {
      "x": 2,
      "y": 6,
      "z": 0,
      "name": "Rock_Ice_Stalactite_Large",
      "rotation": 8
    },
    {
      "x": 2,
      "y": 7,
      "z": 0,
      "name": "Rock_Basalt_Brick",
      "rotation": 2
    },
    {
      "x": 2,
      "y": 0,
      "z": 1,
      "name": "Rock_Basalt",
      "rotation": 2
    },
    {
      "x": 2,
      "y": 1,
      "z": 1,
      "name": "Deco_Iron_Stack",
      "support": 15,
      "rotation": 1
    },
    {
      "x": 2,
      "y": 7,
      "z": 1,
      "name": "Rock_Basalt_Brick",
      "rotation": 2
    },
    {
      "x": 2,
      "y": 0,
      "z": 2,
      "name": "Rock_Basalt",
      "rotation": 2
    },
    {
      "x": 2,
      "y": 1,
      "z": 2,
      "name": "Furniture_Ancient_Table",
      "filler": 992,
      "rotation": 2
    },
    {
      "x": 2,
      "y": 2,
      "z": 2,
      "name": "Rock_Ice_Icicles"
    },
    {
      "x": 2,
      "y": 6,
      "z": 2,
      "name": "Rock_Ice_Icicles",
      "rotation": 8
    },
    {
      "x": 2,
      "y": 7,
      "z": 2,
      "name": "Rock_Basalt_Brick",
      "rotation": 2
    },
    {
      "x": 2,
      "y": 0,
      "z": 3,
      "name": "Rock_Basalt",
      "rotation": 2
    },
    {
      "x": 2,
      "y": 1,
      "z": 3,
      "name": "Furniture_Ancient_Table",
      "rotation": 2
    },
    {
      "x": 2,
      "y": 2,
      "z": 3,
      "name": "Rock_Bronze_Smooth"
    },
    {
      "x": 2,
      "y": 3,
      "z": 3,
      "name": "Bronze_Pipe_Large"
    },
    {
      "x": 2,
      "y": 4,
      "z": 3,
      "name": "Bronze_Pipe_Large"
    },
    {
      "x": 2,
      "y": 5,
      "z": 3,
      "name": "Rock_Bronze_Smooth"
    },
    {
      "x": 2,
      "y": 7,
      "z": 3,
      "name": "Rock_Basalt_Brick",
      "rotation": 2
    },
    {
      "x": 2,
      "y": 0,
      "z": 4,
      "name": "Rock_Basalt",
      "rotation": 2
    },
    {
      "x": 2,
      "y": 1,
      "z": 4,
      "name": "Furniture_Ancient_Crate",
      "rotation": 3
    },
    {
      "x": 2,
      "y": 2,
      "z": 4,
      "name": "Furniture_Ancient_Crate",
      "rotation": 3
    },
    {
      "x": 2,
      "y": 3,
      "z": 4,
      "name": "Furniture_Ancient_Crate",
      "rotation": 2
    },
    {
      "x": 2,
      "y": 7,
      "z": 4,
      "name": "Rock_Basalt_Brick",
      "rotation": 2
    },
    {
      "x": 2,
      "y": 0,
      "z": 5,
      "name": "Rock_Basalt_Brick",
      "rotation": 2
    },
    {
      "x": 2,
      "y": 1,
      "z": 5,
      "name": "Rock_Basalt_Brick",
      "rotation": 2
    },
    {
      "x": 2,
      "y": 2,
      "z": 5,
      "name": "Rock_Basalt_Brick",
      "rotation": 2
    },
    {
      "x": 2,
      "y": 3,
      "z": 5,
      "name": "Rock_Basalt_Brick",
      "rotation": 2
    },
    {
      "x": 2,
      "y": 4,
      "z": 5,
      "name": "Rock_Basalt_Brick",
      "rotation": 2
    },
    {
      "x": 2,
      "y": 5,
      "z": 5,
      "name": "Rock_Basalt_Brick",
      "rotation": 2
    },
    {
      "x": 2,
      "y": 6,
      "z": 5,
      "name": "Rock_Basalt_Brick",
      "rotation": 2
    },
    {
      "x": 2,
      "y": 7,
      "z": 5,
      "name": "Rock_Basalt_Brick",
      "rotation": 2
    },
    {
      "x": 3,
      "y": 0,
      "z": -4,
      "name": "Rock_Basalt",
      "rotation": 2
    },
    {
      "x": 3,
      "y": 0,
      "z": -3,
      "name": "Rock_Basalt",
      "rotation": 2
    },
    {
      "x": 3,
      "y": 7,
      "z": -3,
      "name": "Rock_Basalt_Brick",
      "rotation": 2
    },
    {
      "x": 3,
      "y": 0,
      "z": -2,
      "name": "Rock_Basalt"
    },
    {
      "x": 3,
      "y": 6,
      "z": -2,
      "name": "Rock_Basalt_Brick",
      "rotation": 2
    },
    {
      "x": 3,
      "y": 7,
      "z": -2,
      "name": "Rock_Basalt_Brick",
      "rotation": 2
    },
    {
      "x": 3,
      "y": 0,
      "z": -1,
      "name": "Rock_Basalt",
      "rotation": 2
    },
    {
      "x": 3,
      "y": 1,
      "z": -1,
      "name": "Furniture_Basalt_Trough",
      "rotation": 2
    },
    {
      "x": 3,
      "y": 7,
      "z": -1,
      "name": "Rock_Basalt_Brick",
      "rotation": 2
    },
    {
      "x": 3,
      "y": 0,
      "z": 0,
      "name": "Rock_Basalt",
      "rotation": 2
    },
    {
      "x": 3,
      "y": 1,
      "z": 0,
      "name": "Furniture_Basalt_Trough",
      "filler": 32,
      "rotation": 2
    },
    {
      "x": 3,
      "y": 7,
      "z": 0,
      "name": "Rock_Basalt_Brick",
      "rotation": 2
    },
    {
      "x": 3,
      "y": 0,
      "z": 1,
      "name": "Rock_Basalt",
      "rotation": 2
    },
    {
      "x": 3,
      "y": 1,
      "z": 1,
      "name": "Deco_Mystery_Machine_Large",
      "filler": 31
    },
    {
      "x": 3,
      "y": 2,
      "z": 1,
      "name": "Deco_Mystery_Machine_Large",
      "filler": 1055
    },
    {
      "x": 3,
      "y": 3,
      "z": 1,
      "name": "Deco_Mystery_Machine_Large",
      "filler": 2079
    },
    {
      "x": 3,
      "y": 4,
      "z": 1,
      "name": "Deco_Mystery_Machine_Large",
      "filler": 3103
    },
    {
      "x": 3,
      "y": 7,
      "z": 1,
      "name": "Rock_Basalt_Brick",
      "rotation": 2
    },
    {
      "x": 3,
      "y": 0,
      "z": 2,
      "name": "Rock_Basalt",
      "rotation": 2
    },
    {
      "x": 3,
      "y": 1,
      "z": 2,
      "name": "Deco_Mystery_Machine_Large",
      "filler": 63
    },
    {
      "x": 3,
      "y": 2,
      "z": 2,
      "name": "Deco_Mystery_Machine_Large",
      "filler": 1087
    },
    {
      "x": 3,
      "y": 3,
      "z": 2,
      "name": "Deco_Mystery_Machine_Large",
      "filler": 2111
    },
    {
      "x": 3,
      "y": 4,
      "z": 2,
      "name": "Deco_Mystery_Machine_Large",
      "filler": 3135
    },
    {
      "x": 3,
      "y": 7,
      "z": 2,
      "name": "Rock_Basalt_Brick",
      "rotation": 2
    },
    {
      "x": 3,
      "y": 0,
      "z": 3,
      "name": "Rock_Basalt",
      "rotation": 2
    },
    {
      "x": 3,
      "y": 1,
      "z": 3,
      "name": "Deco_Mystery_Machine_Large",
      "filler": 95
    },
    {
      "x": 3,
      "y": 2,
      "z": 3,
      "name": "Deco_Mystery_Machine_Large",
      "filler": 1119
    },
    {
      "x": 3,
      "y": 3,
      "z": 3,
      "name": "Deco_Mystery_Machine_Large",
      "filler": 2143
    },
    {
      "x": 3,
      "y": 4,
      "z": 3,
      "name": "Deco_Mystery_Machine_Large",
      "filler": 3167
    },
    {
      "x": 3,
      "y": 7,
      "z": 3,
      "name": "Rock_Basalt_Brick",
      "rotation": 2
    },
    {
      "x": 3,
      "y": 0,
      "z": 4,
      "name": "Rock_Basalt",
      "rotation": 2
    },
    {
      "x": 3,
      "y": 1,
      "z": 4,
      "name": "Deco_Mystery_Machine_Large",
      "filler": 127
    },
    {
      "x": 3,
      "y": 2,
      "z": 4,
      "name": "Deco_Mystery_Machine_Large",
      "filler": 1151
    },
    {
      "x": 3,
      "y": 3,
      "z": 4,
      "name": "Deco_Mystery_Machine_Large",
      "filler": 2175
    },
    {
      "x": 3,
      "y": 4,
      "z": 4,
      "name": "Deco_Mystery_Machine_Large",
      "filler": 3199
    },
    {
      "x": 3,
      "y": 7,
      "z": 4,
      "name": "Rock_Basalt_Brick",
      "rotation": 2
    },
    {
      "x": 3,
      "y": 0,
      "z": 5,
      "name": "Rock_Basalt_Brick",
      "rotation": 2
    },
    {
      "x": 3,
      "y": 1,
      "z": 5,
      "name": "Rock_Basalt_Brick",
      "rotation": 2
    },
    {
      "x": 3,
      "y": 2,
      "z": 5,
      "name": "Rock_Basalt_Brick",
      "rotation": 2
    },
    {
      "x": 3,
      "y": 3,
      "z": 5,
      "name": "Rock_Basalt_Brick",
      "rotation": 2
    },
    {
      "x": 3,
      "y": 4,
      "z": 5,
      "name": "Rock_Basalt_Brick",
      "rotation": 2
    },
    {
      "x": 3,
      "y": 5,
      "z": 5,
      "name": "Rock_Basalt_Brick",
      "rotation": 2
    },
    {
      "x": 3,
      "y": 6,
      "z": 5,
      "name": "Rock_Basalt_Brick",
      "rotation": 2
    },
    {
      "x": 3,
      "y": 7,
      "z": 5,
      "name": "Rock_Basalt_Brick",
      "rotation": 2
    },
    {
      "x": 4,
      "y": 0,
      "z": -4,
      "name": "Rock_Basalt",
      "rotation": 2
    },
    {
      "x": 4,
      "y": 0,
      "z": -3,
      "name": "Rock_Basalt",
      "rotation": 2
    },
    {
      "x": 4,
      "y": 7,
      "z": -3,
      "name": "Rock_Basalt_Brick",
      "rotation": 2
    },
    {
      "x": 4,
      "y": 0,
      "z": -2,
      "name": "Rock_Basalt"
    },
    {
      "x": 4,
      "y": 6,
      "z": -2,
      "name": "Rock_Basalt_Brick",
      "rotation": 2
    },
    {
      "x": 4,
      "y": 7,
      "z": -2,
      "name": "Rock_Basalt_Brick",
      "rotation": 2
    },
    {
      "x": 4,
      "y": 0,
      "z": -1,
      "name": "Rock_Basalt",
      "rotation": 2
    },
    {
      "x": 4,
      "y": 1,
      "z": -1,
      "name": "Furniture_Basalt_Trough",
      "filler": 1,
      "rotation": 2
    },
    {
      "x": 4,
      "y": 7,
      "z": -1,
      "name": "Rock_Basalt_Brick",
      "rotation": 2
    },
    {
      "x": 4,
      "y": 0,
      "z": 0,
      "name": "Rock_Basalt",
      "rotation": 2
    },
    {
      "x": 4,
      "y": 1,
      "z": 0,
      "name": "Furniture_Basalt_Trough",
      "filler": 33,
      "rotation": 2
    },
    {
      "x": 4,
      "y": 7,
      "z": 0,
      "name": "Rock_Basalt_Brick",
      "rotation": 2
    },
    {
      "x": 4,
      "y": 0,
      "z": 1,
      "name": "Rock_Basalt",
      "rotation": 2
    },
    {
      "x": 4,
      "y": 1,
      "z": 1,
      "name": "Deco_Mystery_Machine_Large"
    },
    {
      "x": 4,
      "y": 2,
      "z": 1,
      "name": "Deco_Mystery_Machine_Large",
      "filler": 1024
    },
    {
      "x": 4,
      "y": 3,
      "z": 1,
      "name": "Deco_Mystery_Machine_Large",
      "filler": 2048
    },
    {
      "x": 4,
      "y": 4,
      "z": 1,
      "name": "Deco_Mystery_Machine_Large",
      "filler": 3072
    },
    {
      "x": 4,
      "y": 6,
      "z": 1,
      "name": "Rock_Ice_Icicles",
      "rotation": 8
    },
    {
      "x": 4,
      "y": 7,
      "z": 1,
      "name": "Rock_Basalt_Brick",
      "rotation": 2
    },
    {
      "x": 4,
      "y": 0,
      "z": 2,
      "name": "Rock_Basalt",
      "rotation": 2
    },
    {
      "x": 4,
      "y": 1,
      "z": 2,
      "name": "Deco_Mystery_Machine_Large",
      "filler": 32
    },
    {
      "x": 4,
      "y": 2,
      "z": 2,
      "name": "Deco_Mystery_Machine_Large",
      "filler": 1056
    },
    {
      "x": 4,
      "y": 3,
      "z": 2,
      "name": "Deco_Mystery_Machine_Large",
      "filler": 2080
    },
    {
      "x": 4,
      "y": 4,
      "z": 2,
      "name": "Deco_Mystery_Machine_Large",
      "filler": 3104
    },
    {
      "x": 4,
      "y": 7,
      "z": 2,
      "name": "Rock_Basalt_Brick",
      "rotation": 2
    },
    {
      "x": 4,
      "y": 0,
      "z": 3,
      "name": "Rock_Basalt",
      "rotation": 2
    },
    {
      "x": 4,
      "y": 1,
      "z": 3,
      "name": "Deco_Mystery_Machine_Large",
      "filler": 64
    },
    {
      "x": 4,
      "y": 2,
      "z": 3,
      "name": "Deco_Mystery_Machine_Large",
      "filler": 1088
    },
    {
      "x": 4,
      "y": 3,
      "z": 3,
      "name": "Deco_Mystery_Machine_Large",
      "filler": 2112
    },
    {
      "x": 4,
      "y": 4,
      "z": 3,
      "name": "Deco_Mystery_Machine_Large",
      "filler": 3136
    },
    {
      "x": 4,
      "y": 7,
      "z": 3,
      "name": "Rock_Basalt_Brick",
      "rotation": 2
    },
    {
      "x": 4,
      "y": 0,
      "z": 4,
      "name": "Rock_Basalt",
      "rotation": 2
    },
    {
      "x": 4,
      "y": 1,
      "z": 4,
      "name": "Deco_Mystery_Machine_Large",
      "filler": 96
    },
    {
      "x": 4,
      "y": 2,
      "z": 4,
      "name": "Deco_Mystery_Machine_Large",
      "filler": 1120
    },
    {
      "x": 4,
      "y": 3,
      "z": 4,
      "name": "Deco_Mystery_Machine_Large",
      "filler": 2144
    },
    {
      "x": 4,
      "y": 4,
      "z": 4,
      "name": "Deco_Mystery_Machine_Large",
      "filler": 3168
    },
    {
      "x": 4,
      "y": 7,
      "z": 4,
      "name": "Rock_Basalt_Brick",
      "rotation": 2
    },
    {
      "x": 4,
      "y": 0,
      "z": 5,
      "name": "Rock_Basalt_Brick",
      "rotation": 2
    },
    {
      "x": 4,
      "y": 1,
      "z": 5,
      "name": "Rock_Basalt_Brick",
      "rotation": 2
    },
    {
      "x": 4,
      "y": 2,
      "z": 5,
      "name": "Rock_Basalt_Brick",
      "rotation": 2
    },
    {
      "x": 4,
      "y": 3,
      "z": 5,
      "name": "Rock_Basalt_Brick",
      "rotation": 2
    },
    {
      "x": 4,
      "y": 4,
      "z": 5,
      "name": "Rock_Basalt_Brick",
      "rotation": 2
    },
    {
      "x": 4,
      "y": 5,
      "z": 5,
      "name": "Rock_Basalt_Brick",
      "rotation": 2
    },
    {
      "x": 4,
      "y": 6,
      "z": 5,
      "name": "Rock_Basalt_Brick",
      "rotation": 2
    },
    {
      "x": 4,
      "y": 7,
      "z": 5,
      "name": "Rock_Basalt_Brick",
      "rotation": 2
    },
    {
      "x": 5,
      "y": 0,
      "z": -4,
      "name": "Rock_Basalt",
      "rotation": 2
    },
    {
      "x": 5,
      "y": 0,
      "z": -3,
      "name": "Rock_Basalt",
      "rotation": 2
    },
    {
      "x": 5,
      "y": 7,
      "z": -3,
      "name": "Rock_Basalt_Brick",
      "rotation": 2
    },
    {
      "x": 5,
      "y": 0,
      "z": -2,
      "name": "Rock_Basalt"
    },
    {
      "x": 5,
      "y": 5,
      "z": -2,
      "name": "Rock_Basalt_Brick_Half",
      "rotation": 8
    },
    {
      "x": 5,
      "y": 6,
      "z": -2,
      "name": "Rock_Basalt_Brick",
      "rotation": 2
    },
    {
      "x": 5,
      "y": 7,
      "z": -2,
      "name": "Rock_Basalt_Brick",
      "rotation": 2
    },
    {
      "x": 5,
      "y": 0,
      "z": -1,
      "name": "Rock_Basalt",
      "rotation": 2
    },
    {
      "x": 5,
      "y": 7,
      "z": -1,
      "name": "Rock_Basalt_Brick",
      "rotation": 2
    },
    {
      "x": 5,
      "y": 0,
      "z": 0,
      "name": "Rock_Basalt",
      "rotation": 2
    },
    {
      "x": 5,
      "y": 1,
      "z": 0,
      "name": "Furniture_Ancient_Pot",
      "rotation": 2
    },
    {
      "x": 5,
      "y": 5,
      "z": 0,
      "name": "Rock_Ice_Stalactite_Large",
      "filler": 31744,
      "rotation": 8
    },
    {
      "x": 5,
      "y": 6,
      "z": 0,
      "name": "Rock_Ice_Stalactite_Large",
      "rotation": 8
    },
    {
      "x": 5,
      "y": 7,
      "z": 0,
      "name": "Rock_Basalt_Brick",
      "rotation": 2
    },
    {
      "x": 5,
      "y": 0,
      "z": 1,
      "name": "Rock_Basalt",
      "rotation": 2
    },
    {
      "x": 5,
      "y": 1,
      "z": 1,
      "name": "Deco_Mystery_Machine_Large",
      "filler": 1
    },
    {
      "x": 5,
      "y": 2,
      "z": 1,
      "name": "Deco_Mystery_Machine_Large",
      "filler": 1025
    },
    {
      "x": 5,
      "y": 3,
      "z": 1,
      "name": "Deco_Mystery_Machine_Large",
      "filler": 2049
    },
    {
      "x": 5,
      "y": 4,
      "z": 1,
      "name": "Deco_Mystery_Machine_Large",
      "filler": 3073
    },
    {
      "x": 5,
      "y": 7,
      "z": 1,
      "name": "Rock_Basalt_Brick",
      "rotation": 2
    },
    {
      "x": 5,
      "y": 0,
      "z": 2,
      "name": "Rock_Basalt",
      "rotation": 2
    },
    {
      "x": 5,
      "y": 1,
      "z": 2,
      "name": "Deco_Mystery_Machine_Large",
      "filler": 33
    },
    {
      "x": 5,
      "y": 2,
      "z": 2,
      "name": "Deco_Mystery_Machine_Large",
      "filler": 1057
    },
    {
      "x": 5,
      "y": 3,
      "z": 2,
      "name": "Deco_Mystery_Machine_Large",
      "filler": 2081
    },
    {
      "x": 5,
      "y": 4,
      "z": 2,
      "name": "Deco_Mystery_Machine_Large",
      "filler": 3105
    },
    {
      "x": 5,
      "y": 7,
      "z": 2,
      "name": "Rock_Basalt_Brick",
      "rotation": 2
    },
    {
      "x": 5,
      "y": 0,
      "z": 3,
      "name": "Rock_Basalt",
      "rotation": 2
    },
    {
      "x": 5,
      "y": 1,
      "z": 3,
      "name": "Deco_Mystery_Machine_Large",
      "filler": 65
    },
    {
      "x": 5,
      "y": 2,
      "z": 3,
      "name": "Deco_Mystery_Machine_Large",
      "filler": 1089
    },
    {
      "x": 5,
      "y": 3,
      "z": 3,
      "name": "Deco_Mystery_Machine_Large",
      "filler": 2113
    },
    {
      "x": 5,
      "y": 4,
      "z": 3,
      "name": "Deco_Mystery_Machine_Large",
      "filler": 3137
    },
    {
      "x": 5,
      "y": 7,
      "z": 3,
      "name": "Rock_Basalt_Brick",
      "rotation": 2
    },
    {
      "x": 5,
      "y": 0,
      "z": 4,
      "name": "Rock_Basalt",
      "rotation": 2
    },
    {
      "x": 5,
      "y": 1,
      "z": 4,
      "name": "Deco_Mystery_Machine_Large",
      "filler": 97
    },
    {
      "x": 5,
      "y": 2,
      "z": 4,
      "name": "Deco_Mystery_Machine_Large",
      "filler": 1121
    },
    {
      "x": 5,
      "y": 3,
      "z": 4,
      "name": "Deco_Mystery_Machine_Large",
      "filler": 2145
    },
    {
      "x": 5,
      "y": 4,
      "z": 4,
      "name": "Deco_Mystery_Machine_Large",
      "filler": 3169
    },
    {
      "x": 5,
      "y": 7,
      "z": 4,
      "name": "Rock_Basalt_Brick",
      "rotation": 2
    },
    {
      "x": 5,
      "y": 0,
      "z": 5,
      "name": "Rock_Basalt_Brick",
      "rotation": 2
    },
    {
      "x": 5,
      "y": 1,
      "z": 5,
      "name": "Rock_Basalt_Brick",
      "rotation": 2
    },
    {
      "x": 5,
      "y": 2,
      "z": 5,
      "name": "Rock_Basalt_Brick",
      "rotation": 2
    },
    {
      "x": 5,
      "y": 3,
      "z": 5,
      "name": "Rock_Basalt_Brick",
      "rotation": 2
    },
    {
      "x": 5,
      "y": 4,
      "z": 5,
      "name": "Rock_Basalt_Brick",
      "rotation": 2
    },
    {
      "x": 5,
      "y": 5,
      "z": 5,
      "name": "Rock_Basalt_Brick",
      "rotation": 2
    },
    {
      "x": 5,
      "y": 6,
      "z": 5,
      "name": "Rock_Basalt_Brick",
      "rotation": 2
    },
    {
      "x": 5,
      "y": 7,
      "z": 5,
      "name": "Rock_Basalt_Brick",
      "rotation": 2
    },
    {
      "x": 6,
      "y": 0,
      "z": -4,
      "name": "Rock_Basalt",
      "rotation": 2
    },
    {
      "x": 6,
      "y": 0,
      "z": -3,
      "name": "Rock_Basalt",
      "rotation": 2
    },
    {
      "x": 6,
      "y": 1,
      "z": -3,
      "name": "Rubble_Basalt_Medium",
      "support": 15
    },
    {
      "x": 6,
      "y": 7,
      "z": -3,
      "name": "Rock_Basalt_Brick",
      "rotation": 2
    },
    {
      "x": 6,
      "y": 0,
      "z": -2,
      "name": "Rock_Basalt"
    },
    {
      "x": 6,
      "y": 1,
      "z": -2,
      "name": "Rock_Basalt_Brick_Half",
      "rotation": 7
    },
    {
      "x": 6,
      "y": 2,
      "z": -2,
      "name": "Rock_Basalt_Brick_Half",
      "rotation": 7
    },
    {
      "x": 6,
      "y": 3,
      "z": -2,
      "name": "Rock_Basalt_Brick_Half",
      "rotation": 7
    },
    {
      "x": 6,
      "y": 4,
      "z": -2,
      "name": "Rock_Basalt_Brick_Half",
      "rotation": 7
    },
    {
      "x": 6,
      "y": 5,
      "z": -2,
      "name": "Rock_Basalt_Brick"
    },
    {
      "x": 6,
      "y": 6,
      "z": -2,
      "name": "Rock_Basalt_Brick",
      "rotation": 2
    },
    {
      "x": 6,
      "y": 7,
      "z": -2,
      "name": "Rock_Basalt_Brick",
      "rotation": 2
    },
    {
      "x": 6,
      "y": 0,
      "z": -1,
      "name": "Rock_Basalt",
      "rotation": 2
    },
    {
      "x": 6,
      "y": 1,
      "z": -1,
      "name": "Rubble_Basalt",
      "support": 15
    },
    {
      "x": 6,
      "y": 6,
      "z": -1,
      "name": "Rock_Ice_Icicles",
      "rotation": 8
    },
    {
      "x": 6,
      "y": 7,
      "z": -1,
      "name": "Rock_Basalt_Brick",
      "rotation": 2
    },
    {
      "x": 6,
      "y": 0,
      "z": 0,
      "name": "Rock_Basalt",
      "rotation": 2
    },
    {
      "x": 6,
      "y": 7,
      "z": 0,
      "name": "Rock_Basalt_Brick",
      "rotation": 2
    },
    {
      "x": 6,
      "y": 0,
      "z": 1,
      "name": "Rock_Basalt",
      "rotation": 2
    },
    {
      "x": 6,
      "y": 7,
      "z": 1,
      "name": "Rock_Basalt_Brick",
      "rotation": 2
    },
    {
      "x": 6,
      "y": 0,
      "z": 2,
      "name": "Rock_Basalt",
      "rotation": 2
    },
    {
      "x": 6,
      "y": 7,
      "z": 2,
      "name": "Rock_Basalt_Brick",
      "rotation": 2
    },
    {
      "x": 6,
      "y": 0,
      "z": 3,
      "name": "Rock_Basalt",
      "rotation": 2
    },
    {
      "x": 6,
      "y": 1,
      "z": 3,
      "name": "Rock_Ice_Icicles"
    },
    {
      "x": 6,
      "y": 6,
      "z": 3,
      "name": "Rock_Ice_Icicles",
      "rotation": 8
    },
    {
      "x": 6,
      "y": 7,
      "z": 3,
      "name": "Rock_Basalt_Brick",
      "rotation": 2
    },
    {
      "x": 6,
      "y": 0,
      "z": 4,
      "name": "Rock_Basalt",
      "rotation": 2
    },
    {
      "x": 6,
      "y": 1,
      "z": 4,
      "name": "Furniture_Ancient_Barrel"
    },
    {
      "x": 6,
      "y": 7,
      "z": 4,
      "name": "Rock_Basalt_Brick",
      "rotation": 2
    },
    {
      "x": 6,
      "y": 0,
      "z": 5,
      "name": "Rock_Basalt_Brick",
      "rotation": 2
    },
    {
      "x": 6,
      "y": 1,
      "z": 5,
      "name": "Rock_Basalt_Brick",
      "rotation": 2
    },
    {
      "x": 6,
      "y": 2,
      "z": 5,
      "name": "Rock_Basalt_Brick",
      "rotation": 2
    },
    {
      "x": 6,
      "y": 3,
      "z": 5,
      "name": "Rock_Basalt_Brick",
      "rotation": 2
    },
    {
      "x": 6,
      "y": 4,
      "z": 5,
      "name": "Rock_Basalt_Brick",
      "rotation": 2
    },
    {
      "x": 6,
      "y": 5,
      "z": 5,
      "name": "Rock_Basalt_Brick",
      "rotation": 2
    },
    {
      "x": 6,
      "y": 6,
      "z": 5,
      "name": "Rock_Basalt_Brick",
      "rotation": 2
    },
    {
      "x": 6,
      "y": 7,
      "z": 5,
      "name": "Rock_Basalt_Brick",
      "rotation": 2
    },
    {
      "x": 7,
      "y": 0,
      "z": -4,
      "name": "Rock_Basalt",
      "rotation": 2
    },
    {
      "x": 7,
      "y": 0,
      "z": -3,
      "name": "Rock_Basalt",
      "rotation": 2
    },
    {
      "x": 7,
      "y": 1,
      "z": -3,
      "name": "Rock_Ice_Stalactite_Large"
    },
    {
      "x": 7,
      "y": 2,
      "z": -3,
      "name": "Rock_Ice_Stalactite_Large",
      "filler": 1024
    },
    {
      "x": 7,
      "y": 7,
      "z": -3,
      "name": "Rock_Basalt_Brick",
      "rotation": 2
    },
    {
      "x": 7,
      "y": 0,
      "z": -2,
      "name": "Rock_Basalt"
    },
    {
      "x": 7,
      "y": 1,
      "z": -2,
      "name": "Rock_Basalt_Brick"
    },
    {
      "x": 7,
      "y": 2,
      "z": -2,
      "name": "Rock_Basalt_Brick"
    },
    {
      "x": 7,
      "y": 3,
      "z": -2,
      "name": "Rock_Basalt_Brick",
      "rotation": 2
    },
    {
      "x": 7,
      "y": 4,
      "z": -2,
      "name": "Rock_Basalt_Brick",
      "rotation": 2
    },
    {
      "x": 7,
      "y": 5,
      "z": -2,
      "name": "Rock_Basalt_Brick",
      "rotation": 2
    },
    {
      "x": 7,
      "y": 6,
      "z": -2,
      "name": "Rock_Basalt_Brick",
      "rotation": 2
    },
    {
      "x": 7,
      "y": 7,
      "z": -2,
      "name": "Rock_Basalt_Brick",
      "rotation": 2
    },
    {
      "x": 7,
      "y": 0,
      "z": -1,
      "name": "Rock_Basalt",
      "rotation": 2
    },
    {
      "x": 7,
      "y": 1,
      "z": -1,
      "name": "Furniture_Ancient_Barrel"
    },
    {
      "x": 7,
      "y": 6,
      "z": -1,
      "name": "Wood_Deadwood_Planks_Half",
      "rotation": 7
    },
    {
      "x": 7,
      "y": 7,
      "z": -1,
      "name": "Rock_Basalt_Brick",
      "rotation": 2
    },
    {
      "x": 7,
      "y": 0,
      "z": 0,
      "name": "Rock_Basalt",
      "rotation": 2
    },
    {
      "x": 7,
      "y": 1,
      "z": 0,
      "name": "Deco_Iron_Stack",
      "support": 15,
      "rotation": 1
    },
    {
      "x": 7,
      "y": 3,
      "z": 0,
      "name": "Furniture_Ancient_Shelf",
      "rotation": 3
    },
    {
      "x": 7,
      "y": 6,
      "z": 0,
      "name": "Wood_Deadwood_Planks_Half",
      "rotation": 7
    },
    {
      "x": 7,
      "y": 7,
      "z": 0,
      "name": "Rock_Basalt_Brick",
      "rotation": 2
    },
    {
      "x": 7,
      "y": 0,
      "z": 1,
      "name": "Rock_Basalt",
      "rotation": 2
    },
    {
      "x": 7,
      "y": 1,
      "z": 1,
      "name": "Deco_Iron_Stack",
      "support": 15
    },
    {
      "x": 7,
      "y": 2,
      "z": 1,
      "name": "Deco_Iron_Stack",
      "support": 15,
      "rotation": 1
    },
    {
      "x": 7,
      "y": 3,
      "z": 1,
      "name": "Furniture_Ancient_Shelf",
      "rotation": 3
    },
    {
      "x": 7,
      "y": 6,
      "z": 1,
      "name": "Wood_Deadwood_Planks_Half",
      "rotation": 7
    },
    {
      "x": 7,
      "y": 7,
      "z": 1,
      "name": "Rock_Basalt_Brick",
      "rotation": 2
    },
    {
      "x": 7,
      "y": 0,
      "z": 2,
      "name": "Rock_Basalt",
      "rotation": 2
    },
    {
      "x": 7,
      "y": 1,
      "z": 2,
      "name": "Block_Spawner_Block",
      "components": {
        "Components": {
          "PlacedByInteraction": {
            "WhoPlacedUuid": {
              "$binary": "B1yBGZcjQ2KREo5yyLGY0g==",
              "$type": "04"
            }
          },
          "BlockSpawner": {
            "BlockSpawnerId": "Zone3_Outlander_Tier2"
          }
        }
      },
      "rotation": 3
    },
    {
      "x": 7,
      "y": 2,
      "z": 2,
      "name": "Furniture_Ancient_Shelf",
      "rotation": 3
    },
    {
      "x": 7,
      "y": 6,
      "z": 2,
      "name": "Wood_Deadwood_Planks_Half",
      "rotation": 7
    },
    {
      "x": 7,
      "y": 7,
      "z": 2,
      "name": "Rock_Basalt_Brick",
      "rotation": 2
    },
    {
      "x": 7,
      "y": 0,
      "z": 3,
      "name": "Rock_Basalt",
      "rotation": 2
    },
    {
      "x": 7,
      "y": 1,
      "z": 3,
      "name": "Furniture_Ancient_Crate",
      "rotation": 3
    },
    {
      "x": 7,
      "y": 2,
      "z": 3,
      "name": "Furniture_Ancient_Shelf",
      "rotation": 3
    },
    {
      "x": 7,
      "y": 4,
      "z": 3,
      "name": "Furniture_Ancient_Shelf",
      "rotation": 3
    },
    {
      "x": 7,
      "y": 6,
      "z": 3,
      "name": "Wood_Deadwood_Planks_Half",
      "rotation": 7
    },
    {
      "x": 7,
      "y": 7,
      "z": 3,
      "name": "Rock_Basalt_Brick",
      "rotation": 2
    },
    {
      "x": 7,
      "y": 0,
      "z": 4,
      "name": "Rock_Basalt",
      "rotation": 2
    },
    {
      "x": 7,
      "y": 1,
      "z": 4,
      "name": "Furniture_Ancient_Crate",
      "rotation": 2
    },
    {
      "x": 7,
      "y": 2,
      "z": 4,
      "name": "Furniture_Ancient_Crate",
      "rotation": 2
    },
    {
      "x": 7,
      "y": 4,
      "z": 4,
      "name": "Furniture_Ancient_Shelf",
      "rotation": 3
    },
    {
      "x": 7,
      "y": 6,
      "z": 4,
      "name": "Wood_Deadwood_Planks_Half",
      "rotation": 7
    },
    {
      "x": 7,
      "y": 7,
      "z": 4,
      "name": "Rock_Basalt_Brick",
      "rotation": 2
    },
    {
      "x": 7,
      "y": 0,
      "z": 5,
      "name": "Rock_Basalt_Brick",
      "rotation": 2
    },
    {
      "x": 7,
      "y": 1,
      "z": 5,
      "name": "Rock_Basalt_Brick",
      "rotation": 2
    },
    {
      "x": 7,
      "y": 2,
      "z": 5,
      "name": "Rock_Basalt_Brick",
      "rotation": 2
    },
    {
      "x": 7,
      "y": 3,
      "z": 5,
      "name": "Rock_Basalt_Brick",
      "rotation": 2
    },
    {
      "x": 7,
      "y": 4,
      "z": 5,
      "name": "Rock_Basalt_Brick",
      "rotation": 2
    },
    {
      "x": 7,
      "y": 5,
      "z": 5,
      "name": "Rock_Basalt_Brick",
      "rotation": 2
    },
    {
      "x": 7,
      "y": 6,
      "z": 5,
      "name": "Rock_Basalt_Brick",
      "rotation": 2
    },
    {
      "x": 7,
      "y": 7,
      "z": 5,
      "name": "Rock_Basalt_Brick",
      "rotation": 2
    }
  ],
  "entities": [
    {
      "Components": {
        "EffectController": {},
        "DisplayName": {
          "DisplayName": {
            "MessageId": "server.npcRoles.Skeleton_Frost_Archmage.name",
            "Bold": null,
            "Italic": null,
            "Monospace": null,
            "Underline": null
          }
        },
        "UIComponentList": {},
        "Transform": {
          "Position": {
            "X": 1.179764745728619,
            "Y": 1.0,
            "Z": 0.7981342958255926
          },
          "Rotation": {
            "Pitch": 0.0,
            "Yaw": 0.5775412917137146,
            "Roll": 0.0
          }
        },
        "Velocity": {
          "Velocity": {
            "X": 0.0,
            "Y": 0.0,
            "Z": 0.0
          }
        },
        "PrefabCopyable": {},
        "Interactions": {
          "Interactions": {
            "Use": "*UseNPC"
          }
        },
        "Model": {
          "Model": {
            "Id": "Skeleton_Frost_Archmage",
            "Scale": 1.0,
            "Static": false
          }
        },
        "UUID": {
          "UUID": {
            "$binary": "IOT8UiVLNMidAVa6gMvYZw==",
            "$type": "04"
          }
        },
        "EntityStats": {
          "Version": 5,
          "Stats": {
            "Oxygen": {
              "Id": "Oxygen",
              "Value": 100.0
            },
            "Mana": {
              "Id": "Mana",
              "Value": 0.0
            },
            "Health": {
              "Id": "Health",
              "Value": 61.0
            },
            "GlidingActive": {
              "Id": "GlidingActive",
              "Value": 0.0
            },
            "Immunity": {
              "Id": "Immunity",
              "Value": 0.0
            },
            "Stamina": {
              "Id": "Stamina",
              "Value": 10.0
            },
            "SignatureCharges": {
              "Id": "SignatureCharges",
              "Value": 0.0
            },
            "Ammo": {
              "Id": "Ammo",
              "Value": 0.0
            },
            "Unknown": {
              "Id": "Unknown",
              "Value": 0.0
            },
            "SignatureEnergy": {
              "Id": "SignatureEnergy",
              "Value": 0.0
            },
            "DeployablePreview": {
              "Id": "DeployablePreview",
              "Value": 0.0
            },
            "StaminaRegenDelay": {
              "Id": "StaminaRegenDelay",
              "Value": 0.0
            },
            "MagicCharges": {
              "Id": "MagicCharges",
              "Value": 0.0
            }
          }
        },
        "NPC": {
          "Version": 5,
          "UUID": {
            "$binary": "QAAC9qPlNZaIKn/wmbNtVA==",
            "$type": "04"
          },
          "Inventory": {
            "Version": 4,
            "Storage": {
              "Id": "Empty"
            },
            "Armor": {
              "Id": "Simple",
              "Capacity": 4,
              "Items": {}
            },
            "HotBar": {
              "Id": "Simple",
              "Capacity": 3,
              "Items": {
                "0": {
                  "Id": "Weapon_Staff_Frost",
                  "Quantity": 1,
                  "Durability": 0.0,
                  "MaxDurability": 0.0,
                  "OverrideDroppedItemAnimation": false
                }
              }
            },
            "Utility": {
              "Id": "Simple",
              "Capacity": 2,
              "Items": {
                "0": {
                  "Id": "Furniture_Crude_Torch",
                  "Quantity": 1,
                  "Durability": 0.0,
                  "MaxDurability": 0.0,
                  "OverrideDroppedItemAnimation": false
                }
              }
            },
            "Backpack": {
              "Id": "Empty"
            },
            "ActiveHotbarSlot": 0,
            "Tool": {
              "Id": "Empty"
            },
            "ActiveToolsSlot": -1,
            "ActiveUtilitySlot": -1,
            "SortType": "Name"
          },
          "HvrPhs": 0.0,
          "HvrHght": 0.0,
          "MdlScl": 1.0,
          "SpawnInstant": "0001-01-01T12:00:00Z",
          "WorldgenId": 0,
          "PathManager": {},
          "LeashPos": {
            "X": 152.17976474572862,
            "Y": 56.0,
            "Z": 4.798134295825593
          },
          "LeashHdg": 0.5775412917137146,
          "LeashPtch": 0.0,
          "RoleName": "Skeleton_Frost_Archmage"
        },
        "HeadRotation": {
          "Rotation": {
            "Pitch": 0.0,
            "Yaw": 0.5775412917137146,
            "Roll": 0.0
          }
        }
      }
    }
  ]
}