{
  "version": 8,
  "blockIdVersion": 11,
  "anchorX": 2,
  "anchorY": 1,
  "anchorZ": -4,
  "blocks": [
    {
      "x": -5,
      "y": 0,
      "z": -4,
      "name": "Rock_Basalt_Brick",
      "rotation": 2
    },
    {
      "x": -5,
      "y": 1,
      "z": -4,
      "name": "Rock_Basalt_Brick",
      "rotation": 2
    },
    {
      "x": -5,
      "y": 2,
      "z": -4,
      "name": "Rock_Basalt_Brick",
      "rotation": 2
    },
    {
      "x": -5,
      "y": 3,
      "z": -4,
      "name": "Rock_Basalt_Brick",
      "rotation": 2
    },
    {
      "x": -5,
      "y": 4,
      "z": -4,
      "name": "Rock_Basalt_Brick",
      "rotation": 2
    },
    {
      "x": -5,
      "y": 5,
      "z": -4,
      "name": "Rock_Basalt_Brick",
      "rotation": 2
    },
    {
      "x": -5,
      "y": 6,
      "z": -4,
      "name": "Rock_Basalt_Brick",
      "rotation": 2
    },
    {
      "x": -5,
      "y": 7,
      "z": -4,
      "name": "Rock_Basalt_Brick",
      "rotation": 2
    },
    {
      "x": -5,
      "y": 0,
      "z": -3,
      "name": "Rock_Basalt_Brick",
      "rotation": 2
    },
    {
      "x": -5,
      "y": 1,
      "z": -3,
      "name": "Rock_Basalt_Brick",
      "rotation": 2
    },
    {
      "x": -5,
      "y": 2,
      "z": -3,
      "name": "Rock_Basalt_Brick",
      "rotation": 2
    },
    {
      "x": -5,
      "y": 3,
      "z": -3,
      "name": "Rock_Basalt_Brick",
      "rotation": 2
    },
    {
      "x": -5,
      "y": 4,
      "z": -3,
      "name": "Rock_Basalt_Brick",
      "rotation": 2
    },
    {
      "x": -5,
      "y": 5,
      "z": -3,
      "name": "Rock_Basalt_Brick",
      "rotation": 2
    },
    {
      "x": -5,
      "y": 6,
      "z": -3,
      "name": "Rock_Basalt_Brick",
      "rotation": 2
    },
    {
      "x": -5,
      "y": 7,
      "z": -3,
      "name": "Rock_Basalt_Brick",
      "rotation": 2
    },
    {
      "x": -5,
      "y": 0,
      "z": -2,
      "name": "Rock_Basalt_Brick",
      "rotation": 2
    },
    {
      "x": -5,
      "y": 1,
      "z": -2,
      "name": "Rock_Basalt_Brick",
      "rotation": 2
    },
    {
      "x": -5,
      "y": 2,
      "z": -2,
      "name": "Rock_Basalt_Brick",
      "rotation": 2
    },
    {
      "x": -5,
      "y": 3,
      "z": -2,
      "name": "Rock_Basalt_Brick",
      "rotation": 2
    },
    {
      "x": -5,
      "y": 4,
      "z": -2,
      "name": "Rock_Basalt_Brick",
      "rotation": 2
    },
    {
      "x": -5,
      "y": 5,
      "z": -2,
      "name": "Rock_Basalt_Brick",
      "rotation": 2
    },
    {
      "x": -5,
      "y": 6,
      "z": -2,
      "name": "Rock_Basalt_Brick",
      "rotation": 2
    },
    {
      "x": -5,
      "y": 7,
      "z": -2,
      "name": "Rock_Basalt_Brick",
      "rotation": 2
    },
    {
      "x": -5,
      "y": 0,
      "z": -1,
      "name": "Rock_Ice"
    },
    {
      "x": -5,
      "y": 1,
      "z": -1,
      "name": "Rock_Ice"
    },
    {
      "x": -5,
      "y": 2,
      "z": -1,
      "name": "Rock_Ice"
    },
    {
      "x": -5,
      "y": 3,
      "z": -1,
      "name": "Rock_Basalt_Brick",
      "rotation": 2
    },
    {
      "x": -5,
      "y": 4,
      "z": -1,
      "name": "Rock_Basalt_Brick",
      "rotation": 2
    },
    {
      "x": -5,
      "y": 5,
      "z": -1,
      "name": "Rock_Basalt_Brick",
      "rotation": 2
    },
    {
      "x": -5,
      "y": 6,
      "z": -1,
      "name": "Rock_Basalt_Brick",
      "rotation": 2
    },
    {
      "x": -5,
      "y": 7,
      "z": -1,
      "name": "Rock_Basalt_Brick",
      "rotation": 2
    },
    {
      "x": -5,
      "y": 0,
      "z": 0,
      "name": "Rock_Ice"
    },
    {
      "x": -5,
      "y": 1,
      "z": 0,
      "name": "Rock_Ice"
    },
    {
      "x": -5,
      "y": 2,
      "z": 0,
      "name": "Rock_Ice"
    },
    {
      "x": -5,
      "y": 3,
      "z": 0,
      "name": "Rock_Ice"
    },
    {
      "x": -5,
      "y": 4,
      "z": 0,
      "name": "Rock_Ice"
    },
    {
      "x": -5,
      "y": 5,
      "z": 0,
      "name": "Rock_Ice"
    },
    {
      "x": -5,
      "y": 6,
      "z": 0,
      "name": "Rock_Ice"
    },
    {
      "x": -5,
      "y": 7,
      "z": 0,
      "name": "Rock_Ice"
    },
    {
      "x": -5,
      "y": 0,
      "z": 1,
      "name": "Rock_Ice"
    },
    {
      "x": -5,
      "y": 1,
      "z": 1,
      "name": "Rock_Ice"
    },
    {
      "x": -5,
      "y": 2,
      "z": 1,
      "name": "Rock_Ice"
    },
    {
      "x": -5,
      "y": 3,
      "z": 1,
      "name": "Rock_Ice"
    },
    {
      "x": -5,
      "y": 4,
      "z": 1,
      "name": "Rock_Ice"
    },
    {
      "x": -5,
      "y": 5,
      "z": 1,
      "name": "Rock_Ice"
    },
    {
      "x": -5,
      "y": 6,
      "z": 1,
      "name": "Rock_Ice"
    },
    {
      "x": -5,
      "y": 7,
      "z": 1,
      "name": "Rock_Ice"
    },
    {
      "x": -5,
      "y": 0,
      "z": 2,
      "name": "Rock_Ice"
    },
    {
      "x": -5,
      "y": 1,
      "z": 2,
      "name": "Rock_Ice"
    },
    {
      "x": -5,
      "y": 2,
      "z": 2,
      "name": "Rock_Ice"
    },
    {
      "x": -5,
      "y": 3,
      "z": 2,
      "name": "Rock_Ice"
    },
    {
      "x": -5,
      "y": 4,
      "z": 2,
      "name": "Rock_Ice"
    },
    {
      "x": -5,
      "y": 5,
      "z": 2,
      "name": "Rock_Ice"
    },
    {
      "x": -5,
      "y": 6,
      "z": 2,
      "name": "Rock_Ice"
    },
    {
      "x": -5,
      "y": 7,
      "z": 2,
      "name": "Rock_Ice"
    },
    {
      "x": -5,
      "y": 0,
      "z": 3,
      "name": "Rock_Ice"
    },
    {
      "x": -5,
      "y": 1,
      "z": 3,
      "name": "Rock_Ice"
    },
    {
      "x": -5,
      "y": 2,
      "z": 3,
      "name": "Rock_Ice"
    },
    {
      "x": -5,
      "y": 3,
      "z": 3,
      "name": "Rock_Ice"
    },
    {
      "x": -5,
      "y": 4,
      "z": 3,
      "name": "Rock_Ice"
    },
    {
      "x": -5,
      "y": 5,
      "z": 3,
      "name": "Rock_Ice"
    },
    {
      "x": -5,
      "y": 6,
      "z": 3,
      "name": "Rock_Ice"
    },
    {
      "x": -5,
      "y": 7,
      "z": 3,
      "name": "Rock_Ice"
    },
    {
      "x": -5,
      "y": 0,
      "z": 4,
      "name": "Rock_Ice"
    },
    {
      "x": -5,
      "y": 1,
      "z": 4,
      "name": "Rock_Ice"
    },
    {
      "x": -5,
      "y": 2,
      "z": 4,
      "name": "Rock_Ice"
    },
    {
      "x": -5,
      "y": 3,
      "z": 4,
      "name": "Rock_Ice"
    },
    {
      "x": -5,
      "y": 4,
      "z": 4,
      "name": "Rock_Ice"
    },
    {
      "x": -5,
      "y": 5,
      "z": 4,
      "name": "Rock_Ice"
    },
    {
      "x": -5,
      "y": 6,
      "z": 4,
      "name": "Rock_Ice"
    },
    {
      "x": -5,
      "y": 7,
      "z": 4,
      "name": "Rock_Ice"
    },
    {
      "x": -5,
      "y": 0,
      "z": 5,
      "name": "Rock_Basalt_Brick",
      "rotation": 2
    },
    {
      "x": -5,
      "y": 1,
      "z": 5,
      "name": "Rock_Basalt_Brick",
      "rotation": 2
    },
    {
      "x": -5,
      "y": 2,
      "z": 5,
      "name": "Rock_Basalt_Brick",
      "rotation": 2
    },
    {
      "x": -5,
      "y": 3,
      "z": 5,
      "name": "Rock_Basalt_Brick",
      "rotation": 2
    },
    {
      "x": -5,
      "y": 4,
      "z": 5,
      "name": "Rock_Basalt_Brick",
      "rotation": 2
    },
    {
      "x": -5,
      "y": 5,
      "z": 5,
      "name": "Rock_Ice"
    },
    {
      "x": -5,
      "y": 6,
      "z": 5,
      "name": "Rock_Ice"
    },
    {
      "x": -5,
      "y": 7,
      "z": 5,
      "name": "Rock_Ice"
    },
    {
      "x": -4,
      "y": 0,
      "z": -4,
      "name": "Rock_Basalt_Brick",
      "rotation": 2
    },
    {
      "x": -4,
      "y": 1,
      "z": -4,
      "name": "Rock_Basalt_Brick",
      "rotation": 2
    },
    {
      "x": -4,
      "y": 2,
      "z": -4,
      "name": "Rock_Basalt_Brick",
      "rotation": 2
    },
    {
      "x": -4,
      "y": 3,
      "z": -4,
      "name": "Rock_Basalt_Brick",
      "rotation": 2
    },
    {
      "x": -4,
      "y": 4,
      "z": -4,
      "name": "Rock_Basalt_Brick",
      "rotation": 2
    },
    {
      "x": -4,
      "y": 5,
      "z": -4,
      "name": "Rock_Basalt_Brick",
      "rotation": 2
    },
    {
      "x": -4,
      "y": 6,
      "z": -4,
      "name": "Rock_Basalt_Brick",
      "rotation": 2
    },
    {
      "x": -4,
      "y": 7,
      "z": -4,
      "name": "Rock_Basalt_Brick",
      "rotation": 2
    },
    {
      "x": -4,
      "y": 0,
      "z": -3,
      "name": "Rock_Ice"
    },
    {
      "x": -4,
      "y": 1,
      "z": -3,
      "name": "Bronze_Pipe_Large"
    },
    {
      "x": -4,
      "y": 2,
      "z": -3,
      "name": "Bronze_Pipe_Large"
    },
    {
      "x": -4,
      "y": 3,
      "z": -3,
      "name": "Bronze_Pipe_Large"
    },
    {
      "x": -4,
      "y": 4,
      "z": -3,
      "name": "Rock_Bronze_Smooth"
    },
    {
      "x": -4,
      "y": 5,
      "z": -3,
      "name": "Empty"
    },
    {
      "x": -4,
      "y": 6,
      "z": -3,
      "name": "Empty"
    },
    {
      "x": -4,
      "y": 7,
      "z": -3,
      "name": "Rock_Basalt_Brick",
      "rotation": 2
    },
    {
      "x": -4,
      "y": 0,
      "z": -2,
      "name": "Rock_Ice"
    },
    {
      "x": -4,
      "y": 1,
      "z": -2,
      "name": "Rock_Ice_Icicles"
    },
    {
      "x": -4,
      "y": 2,
      "z": -2,
      "name": "Empty"
    },
    {
      "x": -4,
      "y": 3,
      "z": -2,
      "name": "Empty"
    },
    {
      "x": -4,
      "y": 4,
      "z": -2,
      "name": "Bronze_Pipe_Large",
      "rotation": 4
    },
    {
      "x": -4,
      "y": 5,
      "z": -2,
      "name": "Empty"
    },
    {
      "x": -4,
      "y": 6,
      "z": -2,
      "name": "Empty"
    },
    {
      "x": -4,
      "y": 7,
      "z": -2,
      "name": "Rock_Basalt_Brick",
      "rotation": 2
    },
    {
      "x": -4,
      "y": 0,
      "z": -1,
      "name": "Soil_Snow"
    },
    {
      "x": -4,
      "y": 1,
      "z": -1,
      "name": "Empty"
    },
    {
      "x": -4,
      "y": 2,
      "z": -1,
      "name": "Empty"
    },
    {
      "x": -4,
      "y": 3,
      "z": -1,
      "name": "Empty"
    },
    {
      "x": -4,
      "y": 4,
      "z": -1,
      "name": "Empty"
    },
    {
      "x": -4,
      "y": 5,
      "z": -1,
      "name": "Empty"
    },
    {
      "x": -4,
      "y": 6,
      "z": -1,
      "name": "Empty"
    },
    {
      "x": -4,
      "y": 7,
      "z": -1,
      "name": "Rock_Basalt_Brick",
      "rotation": 2
    },
    {
      "x": -4,
      "y": 0,
      "z": 0,
      "name": "Soil_Snow"
    },
    {
      "x": -4,
      "y": 1,
      "z": 0,
      "name": "Soil_Snow_Half"
    },
    {
      "x": -4,
      "y": 2,
      "z": 0,
      "name": "Empty"
    },
    {
      "x": -4,
      "y": 3,
      "z": 0,
      "name": "Empty"
    },
    {
      "x": -4,
      "y": 4,
      "z": 0,
      "name": "Empty"
    },
    {
      "x": -4,
      "y": 5,
      "z": 0,
      "name": "Empty"
    },
    {
      "x": -4,
      "y": 6,
      "z": 0,
      "name": "Empty"
    },
    {
      "x": -4,
      "y": 7,
      "z": 0,
      "name": "Rock_Ice"
    },
    {
      "x": -4,
      "y": 0,
      "z": 1,
      "name": "Rock_Ice"
    },
    {
      "x": -4,
      "y": 1,
      "z": 1,
      "name": "Rock_Ice"
    },
    {
      "x": -4,
      "y": 2,
      "z": 1,
      "name": "Rock_Ice"
    },
    {
      "x": -4,
      "y": 3,
      "z": 1,
      "name": "Rock_Ice_Stalactite_Large"
    },
    {
      "x": -4,
      "y": 4,
      "z": 1,
      "name": "Rock_Ice_Stalactite_Large",
      "filler": 1024
    },
    {
      "x": -4,
      "y": 5,
      "z": 1,
      "name": "Empty"
    },
    {
      "x": -4,
      "y": 6,
      "z": 1,
      "name": "Rock_Ice"
    },
    {
      "x": -4,
      "y": 7,
      "z": 1,
      "name": "Rock_Ice"
    },
    {
      "x": -4,
      "y": 0,
      "z": 2,
      "name": "Rock_Ice"
    },
    {
      "x": -4,
      "y": 1,
      "z": 2,
      "name": "Rock_Ice"
    },
    {
      "x": -4,
      "y": 2,
      "z": 2,
      "name": "Rock_Ice"
    },
    {
      "x": -4,
      "y": 3,
      "z": 2,
      "name": "Rock_Ice"
    },
    {
      "x": -4,
      "y": 4,
      "z": 2,
      "name": "Rock_Ice"
    },
    {
      "x": -4,
      "y": 5,
      "z": 2,
      "name": "Rock_Ice"
    },
    {
      "x": -4,
      "y": 6,
      "z": 2,
      "name": "Rock_Ice"
    },
    {
      "x": -4,
      "y": 7,
      "z": 2,
      "name": "Rock_Ice"
    },
    {
      "x": -4,
      "y": 0,
      "z": 3,
      "name": "Rock_Ice"
    },
    {
      "x": -4,
      "y": 1,
      "z": 3,
      "name": "Rock_Ice"
    },
    {
      "x": -4,
      "y": 2,
      "z": 3,
      "name": "Rock_Ice"
    },
    {
      "x": -4,
      "y": 3,
      "z": 3,
      "name": "Rock_Ice"
    },
    {
      "x": -4,
      "y": 4,
      "z": 3,
      "name": "Empty"
    },
    {
      "x": -4,
      "y": 5,
      "z": 3,
      "name": "Rock_Ice_Icicles",
      "rotation": 8
    },
    {
      "x": -4,
      "y": 6,
      "z": 3,
      "name": "Rock_Ice"
    },
    {
      "x": -4,
      "y": 7,
      "z": 3,
      "name": "Rock_Ice"
    },
    {
      "x": -4,
      "y": 0,
      "z": 4,
      "name": "Rock_Ice"
    },
    {
      "x": -4,
      "y": 1,
      "z": 4,
      "name": "Rock_Ice"
    },
    {
      "x": -4,
      "y": 2,
      "z": 4,
      "name": "Rock_Ice_Stalactite_Large"
    },
    {
      "x": -4,
      "y": 3,
      "z": 4,
      "name": "Rock_Ice_Stalactite_Large",
      "filler": 1024
    },
    {
      "x": -4,
      "y": 4,
      "z": 4,
      "name": "Empty"
    },
    {
      "x": -4,
      "y": 5,
      "z": 4,
      "name": "Empty"
    },
    {
      "x": -4,
      "y": 6,
      "z": 4,
      "name": "Empty"
    },
    {
      "x": -4,
      "y": 7,
      "z": 4,
      "name": "Rock_Ice"
    },
    {
      "x": -4,
      "y": 0,
      "z": 5,
      "name": "Rock_Basalt_Brick",
      "rotation": 2
    },
    {
      "x": -4,
      "y": 1,
      "z": 5,
      "name": "Rock_Basalt_Brick",
      "rotation": 2
    },
    {
      "x": -4,
      "y": 2,
      "z": 5,
      "name": "Rock_Basalt_Brick",
      "rotation": 2
    },
    {
      "x": -4,
      "y": 3,
      "z": 5,
      "name": "Rock_Basalt_Brick",
      "rotation": 2
    },
    {
      "x": -4,
      "y": 4,
      "z": 5,
      "name": "Rock_Basalt_Brick",
      "rotation": 2
    },
    {
      "x": -4,
      "y": 5,
      "z": 5,
      "name": "Rock_Basalt_Brick",
      "rotation": 2
    },
    {
      "x": -4,
      "y": 6,
      "z": 5,
      "name": "Rock_Basalt_Brick",
      "rotation": 2
    },
    {
      "x": -4,
      "y": 7,
      "z": 5,
      "name": "Rock_Ice"
    },
    {
      "x": -3,
      "y": 0,
      "z": -4,
      "name": "Rock_Basalt_Brick",
      "rotation": 2
    },
    {
      "x": -3,
      "y": 1,
      "z": -4,
      "name": "Rock_Basalt_Brick",
      "rotation": 2
    },
    {
      "x": -3,
      "y": 2,
      "z": -4,
      "name": "Rock_Basalt_Brick",
      "rotation": 2
    },
    {
      "x": -3,
      "y": 3,
      "z": -4,
      "name": "Rock_Basalt_Brick",
      "rotation": 2
    },
    {
      "x": -3,
      "y": 4,
      "z": -4,
      "name": "Rock_Basalt_Brick",
      "rotation": 2
    },
    {
      "x": -3,
      "y": 5,
      "z": -4,
      "name": "Rock_Basalt_Brick",
      "rotation": 2
    },
    {
      "x": -3,
      "y": 6,
      "z": -4,
      "name": "Rock_Basalt_Brick",
      "rotation": 2
    },
    {
      "x": -3,
      "y": 7,
      "z": -4,
      "name": "Rock_Basalt_Brick",
      "rotation": 2
    },
    {
      "x": -3,
      "y": 0,
      "z": -3,
      "name": "Rock_Ice"
    },
    {
      "x": -3,
      "y": 1,
      "z": -3,
      "name": "Rock_Ice_Stalactite_Large"
    },
    {
      "x": -3,
      "y": 2,
      "z": -3,
      "name": "Rock_Ice_Stalactite_Large",
      "filler": 1024
    },
    {
      "x": -3,
      "y": 3,
      "z": -3,
      "name": "Empty"
    },
    {
      "x": -3,
      "y": 4,
      "z": -3,
      "name": "Empty"
    },
    {
      "x": -3,
      "y": 5,
      "z": -3,
      "name": "Empty"
    },
    {
      "x": -3,
      "y": 6,
      "z": -3,
      "name": "Empty"
    },
    {
      "x": -3,
      "y": 7,
      "z": -3,
      "name": "Rock_Basalt_Brick",
      "rotation": 2
    },
    {
      "x": -3,
      "y": 0,
      "z": -2,
      "name": "Rock_Ice"
    },
    {
      "x": -3,
      "y": 1,
      "z": -2,
      "name": "Empty"
    },
    {
      "x": -3,
      "y": 2,
      "z": -2,
      "name": "Empty"
    },
    {
      "x": -3,
      "y": 3,
      "z": -2,
      "name": "Empty"
    },
    {
      "x": -3,
      "y": 4,
      "z": -2,
      "name": "Empty"
    },
    {
      "x": -3,
      "y": 5,
      "z": -2,
      "name": "Empty"
    },
    {
      "x": -3,
      "y": 6,
      "z": -2,
      "name": "Rock_Ice_Icicles",
      "rotation": 8
    },
    {
      "x": -3,
      "y": 7,
      "z": -2,
      "name": "Rock_Basalt_Brick",
      "rotation": 2
    },
    {
      "x": -3,
      "y": 0,
      "z": -1,
      "name": "Rock_Ice"
    },
    {
      "x": -3,
      "y": 1,
      "z": -1,
      "name": "Empty"
    },
    {
      "x": -3,
      "y": 2,
      "z": -1,
      "name": "Empty"
    },
    {
      "x": -3,
      "y": 3,
      "z": -1,
      "name": "Empty"
    },
    {
      "x": -3,
      "y": 4,
      "z": -1,
      "name": "Empty"
    },
    {
      "x": -3,
      "y": 5,
      "z": -1,
      "name": "Empty"
    },
    {
      "x": -3,
      "y": 6,
      "z": -1,
      "name": "Empty"
    },
    {
      "x": -3,
      "y": 7,
      "z": -1,
      "name": "Rock_Basalt_Brick",
      "rotation": 2
    },
    {
      "x": -3,
      "y": 0,
      "z": 0,
      "name": "Soil_Snow"
    },
    {
      "x": -3,
      "y": 1,
      "z": 0,
      "name": "*Furniture_Ancient_Torch_State_Definitions_Off",
      "rotation": 1
    },
    {
      "x": -3,
      "y": 2,
      "z": 0,
      "name": "Empty"
    },
    {
      "x": -3,
      "y": 3,
      "z": 0,
      "name": "Empty"
    },
    {
      "x": -3,
      "y": 4,
      "z": 0,
      "name": "Empty"
    },
    {
      "x": -3,
      "y": 5,
      "z": 0,
      "name": "Empty"
    },
    {
      "x": -3,
      "y": 6,
      "z": 0,
      "name": "Empty"
    },
    {
      "x": -3,
      "y": 7,
      "z": 0,
      "name": "Rock_Basalt_Brick",
      "rotation": 2
    },
    {
      "x": -3,
      "y": 0,
      "z": 1,
      "name": "Rock_Ice"
    },
    {
      "x": -3,
      "y": 1,
      "z": 1,
      "name": "Rock_Ice"
    },
    {
      "x": -3,
      "y": 2,
      "z": 1,
      "name": "Rock_Ice_Icicles"
    },
    {
      "x": -3,
      "y": 3,
      "z": 1,
      "name": "Empty"
    },
    {
      "x": -3,
      "y": 4,
      "z": 1,
      "name": "Empty"
    },
    {
      "x": -3,
      "y": 5,
      "z": 1,
      "name": "Empty"
    },
    {
      "x": -3,
      "y": 6,
      "z": 1,
      "name": "Empty"
    },
    {
      "x": -3,
      "y": 7,
      "z": 1,
      "name": "Rock_Ice"
    },
    {
      "x": -3,
      "y": 0,
      "z": 2,
      "name": "Rock_Ice"
    },
    {
      "x": -3,
      "y": 1,
      "z": 2,
      "name": "Rock_Ice"
    },
    {
      "x": -3,
      "y": 2,
      "z": 2,
      "name": "Rock_Ice"
    },
    {
      "x": -3,
      "y": 3,
      "z": 2,
      "name": "Empty"
    },
    {
      "x": -3,
      "y": 4,
      "z": 2,
      "name": "Empty"
    },
    {
      "x": -3,
      "y": 5,
      "z": 2,
      "name": "Rock_Ice_Stalactite_Large",
      "filler": 31744,
      "rotation": 8
    },
    {
      "x": -3,
      "y": 6,
      "z": 2,
      "name": "Rock_Ice_Stalactite_Large",
      "rotation": 8
    },
    {
      "x": -3,
      "y": 7,
      "z": 2,
      "name": "Rock_Ice"
    },
    {
      "x": -3,
      "y": 0,
      "z": 3,
      "name": "Soil_Snow"
    },
    {
      "x": -3,
      "y": 1,
      "z": 3,
      "name": "Soil_Snow_Half"
    },
    {
      "x": -3,
      "y": 2,
      "z": 3,
      "name": "Empty"
    },
    {
      "x": -3,
      "y": 3,
      "z": 3,
      "name": "Empty"
    },
    {
      "x": -3,
      "y": 4,
      "z": 3,
      "name": "Empty"
    },
    {
      "x": -3,
      "y": 5,
      "z": 3,
      "name": "Empty"
    },
    {
      "x": -3,
      "y": 6,
      "z": 3,
      "name": "Empty"
    },
    {
      "x": -3,
      "y": 7,
      "z": 3,
      "name": "Rock_Ice"
    },
    {
      "x": -3,
      "y": 0,
      "z": 4,
      "name": "Soil_Snow"
    },
    {
      "x": -3,
      "y": 1,
      "z": 4,
      "name": "Rock_Ice"
    },
    {
      "x": -3,
      "y": 2,
      "z": 4,
      "name": "Empty"
    },
    {
      "x": -3,
      "y": 3,
      "z": 4,
      "name": "Empty"
    },
    {
      "x": -3,
      "y": 4,
      "z": 4,
      "name": "Empty"
    },
    {
      "x": -3,
      "y": 5,
      "z": 4,
      "name": "Empty"
    },
    {
      "x": -3,
      "y": 6,
      "z": 4,
      "name": "Empty"
    },
    {
      "x": -3,
      "y": 7,
      "z": 4,
      "name": "Rock_Ice"
    },
    {
      "x": -3,
      "y": 0,
      "z": 5,
      "name": "Rock_Ice"
    },
    {
      "x": -3,
      "y": 1,
      "z": 5,
      "name": "Rock_Ice"
    },
    {
      "x": -3,
      "y": 2,
      "z": 5,
      "name": "Rock_Ice"
    },
    {
      "x": -3,
      "y": 3,
      "z": 5,
      "name": "Rock_Ice"
    },
    {
      "x": -3,
      "y": 4,
      "z": 5,
      "name": "Rock_Basalt_Brick",
      "rotation": 2
    },
    {
      "x": -3,
      "y": 5,
      "z": 5,
      "name": "Rock_Basalt_Brick",
      "rotation": 2
    },
    {
      "x": -3,
      "y": 6,
      "z": 5,
      "name": "Rock_Basalt_Brick",
      "rotation": 2
    },
    {
      "x": -3,
      "y": 7,
      "z": 5,
      "name": "Rock_Ice"
    },
    {
      "x": -2,
      "y": 0,
      "z": -4,
      "name": "Rock_Basalt_Brick",
      "rotation": 2
    },
    {
      "x": -2,
      "y": 1,
      "z": -4,
      "name": "Rock_Basalt_Brick",
      "rotation": 2
    },
    {
      "x": -2,
      "y": 2,
      "z": -4,
      "name": "Rock_Basalt_Brick",
      "rotation": 2
    },
    {
      "x": -2,
      "y": 3,
      "z": -4,
      "name": "Rock_Basalt_Brick",
      "rotation": 2
    },
    {
      "x": -2,
      "y": 4,
      "z": -4,
      "name": "Rock_Basalt_Brick",
      "rotation": 2
    },
    {
      "x": -2,
      "y": 5,
      "z": -4,
      "name": "Rock_Basalt_Brick",
      "rotation": 2
    },
    {
      "x": -2,
      "y": 6,
      "z": -4,
      "name": "Rock_Basalt_Brick",
      "rotation": 2
    },
    {
      "x": -2,
      "y": 7,
      "z": -4,
      "name": "Rock_Basalt_Brick",
      "rotation": 2
    },
    {
      "x": -2,
      "y": 0,
      "z": -3,
      "name": "Rock_Ice"
    },
    {
      "x": -2,
      "y": 1,
      "z": -3,
      "name": "Deco_Bone_Pile"
    },
    {
      "x": -2,
      "y": 2,
      "z": -3,
      "name": "Empty"
    },
    {
      "x": -2,
      "y": 3,
      "z": -3,
      "name": "Empty"
    },
    {
      "x": -2,
      "y": 4,
      "z": -3,
      "name": "Empty"
    },
    {
      "x": -2,
      "y": 5,
      "z": -3,
      "name": "Empty"
    },
    {
      "x": -2,
      "y": 6,
      "z": -3,
      "name": "Wood_Deadwood_Planks_Half",
      "rotation": 8
    },
    {
      "x": -2,
      "y": 7,
      "z": -3,
      "name": "Rock_Basalt_Brick",
      "rotation": 2
    },
    {
      "x": -2,
      "y": 0,
      "z": -2,
      "name": "Rock_Ice"
    },
    {
      "x": -2,
      "y": 1,
      "z": -2,
      "name": "Empty"
    },
    {
      "x": -2,
      "y": 2,
      "z": -2,
      "name": "Empty"
    },
    {
      "x": -2,
      "y": 3,
      "z": -2,
      "name": "Empty"
    },
    {
      "x": -2,
      "y": 4,
      "z": -2,
      "name": "Empty"
    },
    {
      "x": -2,
      "y": 5,
      "z": -2,
      "name": "Empty"
    },
    {
      "x": -2,
      "y": 6,
      "z": -2,
      "name": "Wood_Deadwood_Planks_Half",
      "rotation": 8
    },
    {
      "x": -2,
      "y": 7,
      "z": -2,
      "name": "Rock_Basalt_Brick",
      "rotation": 2
    },
    {
      "x": -2,
      "y": 0,
      "z": -1,
      "name": "Rock_Ice"
    },
    {
      "x": -2,
      "y": 1,
      "z": -1,
      "name": "Empty"
    },
    {
      "x": -2,
      "y": 2,
      "z": -1,
      "name": "Empty"
    },
    {
      "x": -2,
      "y": 3,
      "z": -1,
      "name": "Empty"
    },
    {
      "x": -2,
      "y": 4,
      "z": -1,
      "name": "Empty"
    },
    {
      "x": -2,
      "y": 5,
      "z": -1,
      "name": "Empty"
    },
    {
      "x": -2,
      "y": 6,
      "z": -1,
      "name": "Wood_Deadwood_Planks_Half",
      "rotation": 8
    },
    {
      "x": -2,
      "y": 7,
      "z": -1,
      "name": "Rock_Basalt_Brick",
      "rotation": 2
    },
    {
      "x": -2,
      "y": 0,
      "z": 0,
      "name": "Rock_Ice"
    },
    {
      "x": -2,
      "y": 1,
      "z": 0,
      "name": "Empty"
    },
    {
      "x": -2,
      "y": 2,
      "z": 0,
      "name": "Empty"
    },
    {
      "x": -2,
      "y": 3,
      "z": 0,
      "name": "Empty"
    },
    {
      "x": -2,
      "y": 4,
      "z": 0,
      "name": "Empty"
    },
    {
      "x": -2,
      "y": 5,
      "z": 0,
      "name": "Empty"
    },
    {
      "x": -2,
      "y": 6,
      "z": 0,
      "name": "Wood_Deadwood_Planks_Half",
      "rotation": 8
    },
    {
      "x": -2,
      "y": 7,
      "z": 0,
      "name": "Rock_Basalt_Brick",
      "rotation": 2
    },
    {
      "x": -2,
      "y": 0,
      "z": 1,
      "name": "Rock_Ice"
    },
    {
      "x": -2,
      "y": 1,
      "z": 1,
      "name": "Empty"
    },
    {
      "x": -2,
      "y": 2,
      "z": 1,
      "name": "Empty"
    },
    {
      "x": -2,
      "y": 3,
      "z": 1,
      "name": "Empty"
    },
    {
      "x": -2,
      "y": 4,
      "z": 1,
      "name": "Empty"
    },
    {
      "x": -2,
      "y": 5,
      "z": 1,
      "name": "Empty"
    },
    {
      "x": -2,
      "y": 6,
      "z": 1,
      "name": "Wood_Deadwood_Planks_Half",
      "rotation": 8
    },
    {
      "x": -2,
      "y": 7,
      "z": 1,
      "name": "Rock_Basalt_Brick",
      "rotation": 2
    },
    {
      "x": -2,
      "y": 0,
      "z": 2,
      "name": "Soil_Snow"
    },
    {
      "x": -2,
      "y": 1,
      "z": 2,
      "name": "Soil_Snow_Half"
    },
    {
      "x": -2,
      "y": 2,
      "z": 2,
      "name": "Empty"
    },
    {
      "x": -2,
      "y": 3,
      "z": 2,
      "name": "Empty"
    },
    {
      "x": -2,
      "y": 4,
      "z": 2,
      "name": "Empty"
    },
    {
      "x": -2,
      "y": 5,
      "z": 2,
      "name": "Empty"
    },
    {
      "x": -2,
      "y": 6,
      "z": 2,
      "name": "Wood_Deadwood_Planks_Half",
      "rotation": 8
    },
    {
      "x": -2,
      "y": 7,
      "z": 2,
      "name": "Rock_Basalt_Brick",
      "rotation": 2
    },
    {
      "x": -2,
      "y": 0,
      "z": 3,
      "name": "Soil_Snow"
    },
    {
      "x": -2,
      "y": 1,
      "z": 3,
      "name": "Soil_Snow_Half"
    },
    {
      "x": -2,
      "y": 2,
      "z": 3,
      "name": "Empty"
    },
    {
      "x": -2,
      "y": 3,
      "z": 3,
      "name": "Empty"
    },
    {
      "x": -2,
      "y": 4,
      "z": 3,
      "name": "Empty"
    },
    {
      "x": -2,
      "y": 5,
      "z": 3,
      "name": "Empty"
    },
    {
      "x": -2,
      "y": 6,
      "z": 3,
      "name": "Wood_Deadwood_Planks_Half",
      "rotation": 8
    },
    {
      "x": -2,
      "y": 7,
      "z": 3,
      "name": "Rock_Ice"
    },
    {
      "x": -2,
      "y": 0,
      "z": 4,
      "name": "Soil_Snow"
    },
    {
      "x": -2,
      "y": 1,
      "z": 4,
      "name": "Soil_Snow_Half"
    },
    {
      "x": -2,
      "y": 2,
      "z": 4,
      "name": "Empty"
    },
    {
      "x": -2,
      "y": 3,
      "z": 4,
      "name": "Empty"
    },
    {
      "x": -2,
      "y": 4,
      "z": 4,
      "name": "Empty"
    },
    {
      "x": -2,
      "y": 5,
      "z": 4,
      "name": "Empty"
    },
    {
      "x": -2,
      "y": 6,
      "z": 4,
      "name": "Wood_Deadwood_Planks_Half",
      "rotation": 8
    },
    {
      "x": -2,
      "y": 7,
      "z": 4,
      "name": "Rock_Ice"
    },
    {
      "x": -2,
      "y": 0,
      "z": 5,
      "name": "Rock_Ice"
    },
    {
      "x": -2,
      "y": 1,
      "z": 5,
      "name": "Rock_Ice"
    },
    {
      "x": -2,
      "y": 2,
      "z": 5,
      "name": "Rock_Ice"
    },
    {
      "x": -2,
      "y": 3,
      "z": 5,
      "name": "Rock_Ice"
    },
    {
      "x": -2,
      "y": 4,
      "z": 5,
      "name": "Rock_Ice"
    },
    {
      "x": -2,
      "y": 5,
      "z": 5,
      "name": "Rock_Ice"
    },
    {
      "x": -2,
      "y": 6,
      "z": 5,
      "name": "Rock_Ice"
    },
    {
      "x": -2,
      "y": 7,
      "z": 5,
      "name": "Rock_Ice"
    },
    {
      "x": -1,
      "y": 0,
      "z": -4,
      "name": "Rock_Basalt_Brick",
      "rotation": 2
    },
    {
      "x": -1,
      "y": 1,
      "z": -4,
      "name": "Rock_Basalt_Brick",
      "rotation": 2
    },
    {
      "x": -1,
      "y": 2,
      "z": -4,
      "name": "Rock_Basalt_Brick",
      "rotation": 2
    },
    {
      "x": -1,
      "y": 3,
      "z": -4,
      "name": "Rock_Basalt_Brick",
      "rotation": 2
    },
    {
      "x": -1,
      "y": 4,
      "z": -4,
      "name": "Rock_Basalt_Brick",
      "rotation": 2
    },
    {
      "x": -1,
      "y": 5,
      "z": -4,
      "name": "Rock_Basalt_Brick",
      "rotation": 2
    },
    {
      "x": -1,
      "y": 6,
      "z": -4,
      "name": "Rock_Basalt_Brick",
      "rotation": 2
    },
    {
      "x": -1,
      "y": 7,
      "z": -4,
      "name": "Rock_Basalt_Brick",
      "rotation": 2
    },
    {
      "x": -1,
      "y": 0,
      "z": -3,
      "name": "Soil_Snow"
    },
    {
      "x": -1,
      "y": 1,
      "z": -3,
      "name": "Rock_Ice_Icicles"
    },
    {
      "x": -1,
      "y": 2,
      "z": -3,
      "name": "Empty"
    },
    {
      "x": -1,
      "y": 3,
      "z": -3,
      "name": "Empty"
    },
    {
      "x": -1,
      "y": 4,
      "z": -3,
      "name": "Empty"
    },
    {
      "x": -1,
      "y": 5,
      "z": -3,
      "name": "Empty"
    },
    {
      "x": -1,
      "y": 6,
      "z": -3,
      "name": "Empty"
    },
    {
      "x": -1,
      "y": 7,
      "z": -3,
      "name": "Rock_Basalt_Brick",
      "rotation": 2
    },
    {
      "x": -1,
      "y": 0,
      "z": -2,
      "name": "Rock_Ice"
    },
    {
      "x": -1,
      "y": 1,
      "z": -2,
      "name": "Empty"
    },
    {
      "x": -1,
      "y": 2,
      "z": -2,
      "name": "Empty"
    },
    {
      "x": -1,
      "y": 3,
      "z": -2,
      "name": "Empty"
    },
    {
      "x": -1,
      "y": 4,
      "z": -2,
      "name": "Empty"
    },
    {
      "x": -1,
      "y": 5,
      "z": -2,
      "name": "Empty"
    },
    {
      "x": -1,
      "y": 6,
      "z": -2,
      "name": "Empty"
    },
    {
      "x": -1,
      "y": 7,
      "z": -2,
      "name": "Rock_Basalt_Brick",
      "rotation": 2
    },
    {
      "x": -1,
      "y": 0,
      "z": -1,
      "name": "Rock_Ice"
    },
    {
      "x": -1,
      "y": 1,
      "z": -1,
      "name": "Empty"
    },
    {
      "x": -1,
      "y": 2,
      "z": -1,
      "name": "Empty"
    },
    {
      "x": -1,
      "y": 3,
      "z": -1,
      "name": "Empty"
    },
    {
      "x": -1,
      "y": 4,
      "z": -1,
      "name": "Empty"
    },
    {
      "x": -1,
      "y": 5,
      "z": -1,
      "name": "Empty"
    },
    {
      "x": -1,
      "y": 6,
      "z": -1,
      "name": "Empty"
    },
    {
      "x": -1,
      "y": 7,
      "z": -1,
      "name": "Rock_Basalt_Brick",
      "rotation": 2
    },
    {
      "x": -1,
      "y": 0,
      "z": 0,
      "name": "Rock_Ice"
    },
    {
      "x": -1,
      "y": 1,
      "z": 0,
      "name": "Deco_Bone_Pile"
    },
    {
      "x": -1,
      "y": 2,
      "z": 0,
      "name": "Empty"
    },
    {
      "x": -1,
      "y": 3,
      "z": 0,
      "name": "Empty"
    },
    {
      "x": -1,
      "y": 4,
      "z": 0,
      "name": "Empty"
    },
    {
      "x": -1,
      "y": 5,
      "z": 0,
      "name": "Empty"
    },
    {
      "x": -1,
      "y": 6,
      "z": 0,
      "name": "Empty"
    },
    {
      "x": -1,
      "y": 7,
      "z": 0,
      "name": "Rock_Basalt_Brick",
      "rotation": 2
    },
    {
      "x": -1,
      "y": 0,
      "z": 1,
      "name": "Rock_Ice"
    },
    {
      "x": -1,
      "y": 1,
      "z": 1,
      "name": "Deco_Bone_Skulls"
    },
    {
      "x": -1,
      "y": 2,
      "z": 1,
      "name": "Empty"
    },
    {
      "x": -1,
      "y": 3,
      "z": 1,
      "name": "Empty"
    },
    {
      "x": -1,
      "y": 4,
      "z": 1,
      "name": "Empty"
    },
    {
      "x": -1,
      "y": 5,
      "z": 1,
      "name": "Empty"
    },
    {
      "x": -1,
      "y": 6,
      "z": 1,
      "name": "Rock_Ice_Icicles",
      "rotation": 8
    },
    {
      "x": -1,
      "y": 7,
      "z": 1,
      "name": "Rock_Basalt_Brick",
      "rotation": 2
    },
    {
      "x": -1,
      "y": 0,
      "z": 2,
      "name": "Soil_Snow"
    },
    {
      "x": -1,
      "y": 1,
      "z": 2,
      "name": "Rock_Ice_Icicles"
    },
    {
      "x": -1,
      "y": 2,
      "z": 2,
      "name": "Empty"
    },
    {
      "x": -1,
      "y": 3,
      "z": 2,
      "name": "Empty"
    },
    {
      "x": -1,
      "y": 4,
      "z": 2,
      "name": "Empty"
    },
    {
      "x": -1,
      "y": 5,
      "z": 2,
      "name": "Empty"
    },
    {
      "x": -1,
      "y": 6,
      "z": 2,
      "name": "Empty"
    },
    {
      "x": -1,
      "y": 7,
      "z": 2,
      "name": "Rock_Ice"
    },
    {
      "x": -1,
      "y": 0,
      "z": 3,
      "name": "Soil_Snow"
    },
    {
      "x": -1,
      "y": 1,
      "z": 3,
      "name": "Soil_Snow_Half"
    },
    {
      "x": -1,
      "y": 2,
      "z": 3,
      "name": "Empty"
    },
    {
      "x": -1,
      "y": 3,
      "z": 3,
      "name": "Empty"
    },
    {
      "x": -1,
      "y": 4,
      "z": 3,
      "name": "Empty"
    },
    {
      "x": -1,
      "y": 5,
      "z": 3,
      "name": "Empty"
    },
    {
      "x": -1,
      "y": 6,
      "z": 3,
      "name": "Empty"
    },
    {
      "x": -1,
      "y": 7,
      "z": 3,
      "name": "Rock_Ice"
    },
    {
      "x": -1,
      "y": 0,
      "z": 4,
      "name": "Rock_Ice"
    },
    {
      "x": -1,
      "y": 1,
      "z": 4,
      "name": "Soil_Snow"
    },
    {
      "x": -1,
      "y": 2,
      "z": 4,
      "name": "Empty"
    },
    {
      "x": -1,
      "y": 3,
      "z": 4,
      "name": "Empty"
    },
    {
      "x": -1,
      "y": 4,
      "z": 4,
      "name": "Empty"
    },
    {
      "x": -1,
      "y": 5,
      "z": 4,
      "name": "Rock_Ice_Icicles",
      "rotation": 8
    },
    {
      "x": -1,
      "y": 6,
      "z": 4,
      "name": "Rock_Ice"
    },
    {
      "x": -1,
      "y": 7,
      "z": 4,
      "name": "Rock_Ice"
    },
    {
      "x": -1,
      "y": 0,
      "z": 5,
      "name": "Rock_Ice"
    },
    {
      "x": -1,
      "y": 1,
      "z": 5,
      "name": "Rock_Ice"
    },
    {
      "x": -1,
      "y": 2,
      "z": 5,
      "name": "Rock_Ice"
    },
    {
      "x": -1,
      "y": 3,
      "z": 5,
      "name": "Rock_Ice"
    },
    {
      "x": -1,
      "y": 4,
      "z": 5,
      "name": "Rock_Ice"
    },
    {
      "x": -1,
      "y": 5,
      "z": 5,
      "name": "Rock_Ice"
    },
    {
      "x": -1,
      "y": 6,
      "z": 5,
      "name": "Rock_Ice"
    },
    {
      "x": -1,
      "y": 7,
      "z": 5,
      "name": "Rock_Ice"
    },
    {
      "x": 0,
      "y": 0,
      "z": -4,
      "name": "*Rock_Basalt_Brick_Stairs_State_Definitions_Inverted_Corner_Right",
      "rotation": 1
    },
    {
      "x": 0,
      "y": 1,
      "z": -4,
      "name": "*Furniture_Frostbitten_Factory_Vault_Large_State_Definitions_CloseDoorIn"
    },
    {
      "x": 0,
      "y": 2,
      "z": -4,
      "name": "*Furniture_Frostbitten_Factory_Vault_Large_State_Definitions_CloseDoorIn",
      "filler": 1024
    },
    {
      "x": 0,
      "y": 3,
      "z": -4,
      "name": "*Furniture_Frostbitten_Factory_Vault_Large_State_Definitions_CloseDoorIn",
      "filler": 2048
    },
    {
      "x": 0,
      "y": 4,
      "z": -4,
      "name": "*Furniture_Frostbitten_Factory_Vault_Large_State_Definitions_CloseDoorIn",
      "filler": 3072
    },
    {
      "x": 0,
      "y": 5,
      "z": -4,
      "name": "Rock_Basalt_Brick",
      "rotation": 2
    },
    {
      "x": 0,
      "y": 6,
      "z": -4,
      "name": "Rock_Basalt_Brick",
      "rotation": 2
    },
    {
      "x": 0,
      "y": 7,
      "z": -4,
      "name": "Rock_Basalt_Brick",
      "rotation": 2
    },
    {
      "x": 0,
      "y": 0,
      "z": -3,
      "name": "Soil_Snow"
    },
    {
      "x": 0,
      "y": 1,
      "z": -3,
      "name": "Empty"
    },
    {
      "x": 0,
      "y": 2,
      "z": -3,
      "name": "Empty"
    },
    {
      "x": 0,
      "y": 3,
      "z": -3,
      "name": "Empty"
    },
    {
      "x": 0,
      "y": 4,
      "z": -3,
      "name": "Empty"
    },
    {
      "x": 0,
      "y": 5,
      "z": -3,
      "name": "Empty"
    },
    {
      "x": 0,
      "y": 6,
      "z": -3,
      "name": "Empty"
    },
    {
      "x": 0,
      "y": 7,
      "z": -3,
      "name": "Rock_Basalt_Brick",
      "rotation": 2
    },
    {
      "x": 0,
      "y": 0,
      "z": -2,
      "name": "Rock_Ice"
    },
    {
      "x": 0,
      "y": 1,
      "z": -2,
      "name": "Empty"
    },
    {
      "x": 0,
      "y": 2,
      "z": -2,
      "name": "Empty"
    },
    {
      "x": 0,
      "y": 3,
      "z": -2,
      "name": "Empty"
    },
    {
      "x": 0,
      "y": 4,
      "z": -2,
      "name": "Empty"
    },
    {
      "x": 0,
      "y": 5,
      "z": -2,
      "name": "Empty"
    },
    {
      "x": 0,
      "y": 6,
      "z": -2,
      "name": "Empty"
    },
    {
      "x": 0,
      "y": 7,
      "z": -2,
      "name": "Rock_Basalt_Brick",
      "rotation": 2
    },
    {
      "x": 0,
      "y": 0,
      "z": -1,
      "name": "Rock_Ice"
    },
    {
      "x": 0,
      "y": 1,
      "z": -1,
      "name": "Empty"
    },
    {
      "x": 0,
      "y": 2,
      "z": -1,
      "name": "Empty"
    },
    {
      "x": 0,
      "y": 3,
      "z": -1,
      "name": "Empty"
    },
    {
      "x": 0,
      "y": 4,
      "z": -1,
      "name": "Empty"
    },
    {
      "x": 0,
      "y": 5,
      "z": -1,
      "name": "Empty"
    },
    {
      "x": 0,
      "y": 6,
      "z": -1,
      "name": "Rock_Ice_Icicles",
      "rotation": 8
    },
    {
      "x": 0,
      "y": 7,
      "z": -1,
      "name": "Rock_Basalt_Brick",
      "rotation": 2
    },
    {
      "x": 0,
      "y": 0,
      "z": 0,
      "name": "Rock_Ice"
    },
    {
      "x": 0,
      "y": 1,
      "z": 0,
      "name": "Empty"
    },
    {
      "x": 0,
      "y": 2,
      "z": 0,
      "name": "Empty"
    },
    {
      "x": 0,
      "y": 3,
      "z": 0,
      "name": "Empty"
    },
    {
      "x": 0,
      "y": 4,
      "z": 0,
      "name": "Empty"
    },
    {
      "x": 0,
      "y": 5,
      "z": 0,
      "name": "Empty"
    },
    {
      "x": 0,
      "y": 6,
      "z": 0,
      "name": "Empty"
    },
    {
      "x": 0,
      "y": 7,
      "z": 0,
      "name": "Rock_Basalt_Brick",
      "rotation": 2
    },
    {
      "x": 0,
      "y": 0,
      "z": 1,
      "name": "Soil_Snow"
    },
    {
      "x": 0,
      "y": 1,
      "z": 1,
      "name": "Empty"
    },
    {
      "x": 0,
      "y": 2,
      "z": 1,
      "name": "Empty"
    },
    {
      "x": 0,
      "y": 3,
      "z": 1,
      "name": "Empty"
    },
    {
      "x": 0,
      "y": 4,
      "z": 1,
      "name": "Empty"
    },
    {
      "x": 0,
      "y": 5,
      "z": 1,
      "name": "Empty"
    },
    {
      "x": 0,
      "y": 6,
      "z": 1,
      "name": "Empty"
    },
    {
      "x": 0,
      "y": 7,
      "z": 1,
      "name": "Rock_Basalt_Brick",
      "rotation": 2
    },
    {
      "x": 0,
      "y": 0,
      "z": 2,
      "name": "Soil_Snow"
    },
    {
      "x": 0,
      "y": 1,
      "z": 2,
      "name": "Soil_Snow_Half"
    },
    {
      "x": 0,
      "y": 2,
      "z": 2,
      "name": "Empty"
    },
    {
      "x": 0,
      "y": 3,
      "z": 2,
      "name": "Empty"
    },
    {
      "x": 0,
      "y": 4,
      "z": 2,
      "name": "Empty"
    },
    {
      "x": 0,
      "y": 5,
      "z": 2,
      "name": "Empty"
    },
    {
      "x": 0,
      "y": 6,
      "z": 2,
      "name": "Empty"
    },
    {
      "x": 0,
      "y": 7,
      "z": 2,
      "name": "Rock_Ice"
    },
    {
      "x": 0,
      "y": 0,
      "z": 3,
      "name": "Rock_Ice"
    },
    {
      "x": 0,
      "y": 1,
      "z": 3,
      "name": "Soil_Snow"
    },
    {
      "x": 0,
      "y": 2,
      "z": 3,
      "name": "Rock_Ice_Icicles"
    },
    {
      "x": 0,
      "y": 3,
      "z": 3,
      "name": "Empty"
    },
    {
      "x": 0,
      "y": 4,
      "z": 3,
      "name": "Empty"
    },
    {
      "x": 0,
      "y": 5,
      "z": 3,
      "name": "Rock_Ice_Stalactite_Large",
      "filler": 31744,
      "rotation": 8
    },
    {
      "x": 0,
      "y": 6,
      "z": 3,
      "name": "Rock_Ice_Stalactite_Large",
      "rotation": 8
    },
    {
      "x": 0,
      "y": 7,
      "z": 3,
      "name": "Rock_Ice"
    },
    {
      "x": 0,
      "y": 0,
      "z": 4,
      "name": "Rock_Ice"
    },
    {
      "x": 0,
      "y": 1,
      "z": 4,
      "name": "Rock_Ice"
    },
    {
      "x": 0,
      "y": 2,
      "z": 4,
      "name": "Rock_Ice"
    },
    {
      "x": 0,
      "y": 3,
      "z": 4,
      "name": "Rock_Ice"
    },
    {
      "x": 0,
      "y": 4,
      "z": 4,
      "name": "Rock_Ice"
    },
    {
      "x": 0,
      "y": 5,
      "z": 4,
      "name": "Rock_Ice"
    },
    {
      "x": 0,
      "y": 6,
      "z": 4,
      "name": "Rock_Ice"
    },
    {
      "x": 0,
      "y": 7,
      "z": 4,
      "name": "Rock_Ice"
    },
    {
      "x": 0,
      "y": 0,
      "z": 5,
      "name": "Rock_Ice"
    },
    {
      "x": 0,
      "y": 1,
      "z": 5,
      "name": "Rock_Ice"
    },
    {
      "x": 0,
      "y": 2,
      "z": 5,
      "name": "Rock_Ice"
    },
    {
      "x": 0,
      "y": 3,
      "z": 5,
      "name": "Rock_Ice"
    },
    {
      "x": 0,
      "y": 4,
      "z": 5,
      "name": "Rock_Ice"
    },
    {
      "x": 0,
      "y": 5,
      "z": 5,
      "name": "Rock_Ice"
    },
    {
      "x": 0,
      "y": 6,
      "z": 5,
      "name": "Rock_Ice"
    },
    {
      "x": 0,
      "y": 7,
      "z": 5,
      "name": "Rock_Ice"
    },
    {
      "x": 1,
      "y": 0,
      "z": -4,
      "name": "Rock_Basalt_Brick_Stairs"
    },
    {
      "x": 1,
      "y": 1,
      "z": -4,
      "name": "*Furniture_Frostbitten_Factory_Vault_Large_State_Definitions_CloseDoorIn",
      "filler": 1
    },
    {
      "x": 1,
      "y": 2,
      "z": -4,
      "name": "*Furniture_Frostbitten_Factory_Vault_Large_State_Definitions_CloseDoorIn",
      "filler": 1025
    },
    {
      "x": 1,
      "y": 3,
      "z": -4,
      "name": "*Furniture_Frostbitten_Factory_Vault_Large_State_Definitions_CloseDoorIn",
      "filler": 2049
    },
    {
      "x": 1,
      "y": 4,
      "z": -4,
      "name": "*Furniture_Frostbitten_Factory_Vault_Large_State_Definitions_CloseDoorIn",
      "filler": 3073
    },
    {
      "x": 1,
      "y": 5,
      "z": -4,
      "name": "Rock_Basalt_Brick",
      "rotation": 2
    },
    {
      "x": 1,
      "y": 6,
      "z": -4,
      "name": "Rock_Basalt_Brick",
      "rotation": 2
    },
    {
      "x": 1,
      "y": 7,
      "z": -4,
      "name": "Rock_Basalt_Brick",
      "rotation": 2
    },
    {
      "x": 1,
      "y": 0,
      "z": -3,
      "name": "Soil_Snow"
    },
    {
      "x": 1,
      "y": 1,
      "z": -3,
      "name": "Empty"
    },
    {
      "x": 1,
      "y": 2,
      "z": -3,
      "name": "Empty"
    },
    {
      "x": 1,
      "y": 3,
      "z": -3,
      "name": "Empty"
    },
    {
      "x": 1,
      "y": 4,
      "z": -3,
      "name": "Empty"
    },
    {
      "x": 1,
      "y": 5,
      "z": -3,
      "name": "Empty"
    },
    {
      "x": 1,
      "y": 6,
      "z": -3,
      "name": "Empty"
    },
    {
      "x": 1,
      "y": 7,
      "z": -3,
      "name": "Rock_Basalt_Brick",
      "rotation": 2
    },
    {
      "x": 1,
      "y": 0,
      "z": -2,
      "name": "Soil_Snow"
    },
    {
      "x": 1,
      "y": 1,
      "z": -2,
      "name": "Empty"
    },
    {
      "x": 1,
      "y": 2,
      "z": -2,
      "name": "Empty"
    },
    {
      "x": 1,
      "y": 3,
      "z": -2,
      "name": "Empty"
    },
    {
      "x": 1,
      "y": 4,
      "z": -2,
      "name": "Empty"
    },
    {
      "x": 1,
      "y": 5,
      "z": -2,
      "name": "Empty"
    },
    {
      "x": 1,
      "y": 6,
      "z": -2,
      "name": "Rock_Ice_Icicles",
      "rotation": 8
    },
    {
      "x": 1,
      "y": 7,
      "z": -2,
      "name": "Rock_Basalt_Brick",
      "rotation": 2
    },
    {
      "x": 1,
      "y": 0,
      "z": -1,
      "name": "Rock_Ice"
    },
    {
      "x": 1,
      "y": 1,
      "z": -1,
      "name": "Empty"
    },
    {
      "x": 1,
      "y": 2,
      "z": -1,
      "name": "Empty"
    },
    {
      "x": 1,
      "y": 3,
      "z": -1,
      "name": "Empty"
    },
    {
      "x": 1,
      "y": 4,
      "z": -1,
      "name": "Empty"
    },
    {
      "x": 1,
      "y": 5,
      "z": -1,
      "name": "Empty"
    },
    {
      "x": 1,
      "y": 6,
      "z": -1,
      "name": "Empty"
    },
    {
      "x": 1,
      "y": 7,
      "z": -1,
      "name": "Rock_Basalt_Brick",
      "rotation": 2
    },
    {
      "x": 1,
      "y": 0,
      "z": 0,
      "name": "Rock_Ice"
    },
    {
      "x": 1,
      "y": 1,
      "z": 0,
      "name": "Empty"
    },
    {
      "x": 1,
      "y": 2,
      "z": 0,
      "name": "Empty"
    },
    {
      "x": 1,
      "y": 3,
      "z": 0,
      "name": "Empty"
    },
    {
      "x": 1,
      "y": 4,
      "z": 0,
      "name": "Empty"
    },
    {
      "x": 1,
      "y": 5,
      "z": 0,
      "name": "Empty"
    },
    {
      "x": 1,
      "y": 6,
      "z": 0,
      "name": "Empty"
    },
    {
      "x": 1,
      "y": 7,
      "z": 0,
      "name": "Rock_Basalt_Brick",
      "rotation": 2
    },
    {
      "x": 1,
      "y": 0,
      "z": 1,
      "name": "Soil_Snow"
    },
    {
      "x": 1,
      "y": 1,
      "z": 1,
      "name": "Empty"
    },
    {
      "x": 1,
      "y": 2,
      "z": 1,
      "name": "Empty"
    },
    {
      "x": 1,
      "y": 3,
      "z": 1,
      "name": "Empty"
    },
    {
      "x": 1,
      "y": 4,
      "z": 1,
      "name": "Empty"
    },
    {
      "x": 1,
      "y": 5,
      "z": 1,
      "name": "Empty"
    },
    {
      "x": 1,
      "y": 6,
      "z": 1,
      "name": "Empty"
    },
    {
      "x": 1,
      "y": 7,
      "z": 1,
      "name": "Rock_Basalt_Brick",
      "rotation": 2
    },
    {
      "x": 1,
      "y": 0,
      "z": 2,
      "name": "Rock_Ice"
    },
    {
      "x": 1,
      "y": 1,
      "z": 2,
      "name": "Soil_Snow"
    },
    {
      "x": 1,
      "y": 2,
      "z": 2,
      "name": "Empty"
    },
    {
      "x": 1,
      "y": 3,
      "z": 2,
      "name": "Empty"
    },
    {
      "x": 1,
      "y": 4,
      "z": 2,
      "name": "Empty"
    },
    {
      "x": 1,
      "y": 5,
      "z": 2,
      "name": "Empty"
    },
    {
      "x": 1,
      "y": 6,
      "z": 2,
      "name": "Empty"
    },
    {
      "x": 1,
      "y": 7,
      "z": 2,
      "name": "Rock_Basalt_Brick",
      "rotation": 2
    },
    {
      "x": 1,
      "y": 0,
      "z": 3,
      "name": "Rock_Ice"
    },
    {
      "x": 1,
      "y": 1,
      "z": 3,
      "name": "Rock_Ice"
    },
    {
      "x": 1,
      "y": 2,
      "z": 3,
      "name": "Rock_Ice"
    },
    {
      "x": 1,
      "y": 3,
      "z": 3,
      "name": "Empty"
    },
    {
      "x": 1,
      "y": 4,
      "z": 3,
      "name": "Empty"
    },
    {
      "x": 1,
      "y": 5,
      "z": 3,
      "name": "Empty"
    },
    {
      "x": 1,
      "y": 6,
      "z": 3,
      "name": "Rock_Ice_Icicles",
      "rotation": 8
    },
    {
      "x": 1,
      "y": 7,
      "z": 3,
      "name": "Rock_Ice"
    },
    {
      "x": 1,
      "y": 0,
      "z": 4,
      "name": "Rock_Ice"
    },
    {
      "x": 1,
      "y": 1,
      "z": 4,
      "name": "Rock_Ice"
    },
    {
      "x": 1,
      "y": 2,
      "z": 4,
      "name": "Rock_Ice"
    },
    {
      "x": 1,
      "y": 3,
      "z": 4,
      "name": "Rock_Ice"
    },
    {
      "x": 1,
      "y": 4,
      "z": 4,
      "name": "Rock_Ice"
    },
    {
      "x": 1,
      "y": 5,
      "z": 4,
      "name": "Rock_Ice"
    },
    {
      "x": 1,
      "y": 6,
      "z": 4,
      "name": "Rock_Ice"
    },
    {
      "x": 1,
      "y": 7,
      "z": 4,
      "name": "Rock_Ice"
    },
    {
      "x": 1,
      "y": 0,
      "z": 5,
      "name": "Rock_Ice"
    },
    {
      "x": 1,
      "y": 1,
      "z": 5,
      "name": "Rock_Ice"
    },
    {
      "x": 1,
      "y": 2,
      "z": 5,
      "name": "Rock_Ice"
    },
    {
      "x": 1,
      "y": 3,
      "z": 5,
      "name": "Rock_Ice"
    },
    {
      "x": 1,
      "y": 4,
      "z": 5,
      "name": "Rock_Ice"
    },
    {
      "x": 1,
      "y": 5,
      "z": 5,
      "name": "Rock_Ice"
    },
    {
      "x": 1,
      "y": 6,
      "z": 5,
      "name": "Rock_Ice"
    },
    {
      "x": 1,
      "y": 7,
      "z": 5,
      "name": "Rock_Ice"
    },
    {
      "x": 2,
      "y": 0,
      "z": -4,
      "name": "Rock_Basalt_Brick_Stairs"
    },
    {
      "x": 2,
      "y": 1,
      "z": -4,
      "name": "*Furniture_Frostbitten_Factory_Vault_Large_State_Definitions_CloseDoorOut",
      "filler": 31,
      "rotation": 2
    },
    {
      "x": 2,
      "y": 2,
      "z": -4,
      "name": "*Furniture_Frostbitten_Factory_Vault_Large_State_Definitions_CloseDoorOut",
      "filler": 1055,
      "rotation": 2
    },
    {
      "x": 2,
      "y": 3,
      "z": -4,
      "name": "*Furniture_Frostbitten_Factory_Vault_Large_State_Definitions_CloseDoorOut",
      "filler": 2079,
      "rotation": 2
    },
    {
      "x": 2,
      "y": 4,
      "z": -4,
      "name": "*Furniture_Frostbitten_Factory_Vault_Large_State_Definitions_CloseDoorOut",
      "filler": 3103,
      "rotation": 2
    },
    {
      "x": 2,
      "y": 5,
      "z": -4,
      "name": "Rock_Basalt_Brick",
      "rotation": 2
    },
    {
      "x": 2,
      "y": 6,
      "z": -4,
      "name": "Rock_Basalt_Brick",
      "rotation": 2
    },
    {
      "x": 2,
      "y": 7,
      "z": -4,
      "name": "Rock_Basalt_Brick",
      "rotation": 2
    },
    {
      "x": 2,
      "y": 0,
      "z": -3,
      "name": "Soil_Snow"
    },
    {
      "x": 2,
      "y": 1,
      "z": -3,
      "name": "Empty"
    },
    {
      "x": 2,
      "y": 2,
      "z": -3,
      "name": "Empty"
    },
    {
      "x": 2,
      "y": 3,
      "z": -3,
      "name": "Empty"
    },
    {
      "x": 2,
      "y": 4,
      "z": -3,
      "name": "Empty"
    },
    {
      "x": 2,
      "y": 5,
      "z": -3,
      "name": "Empty"
    },
    {
      "x": 2,
      "y": 6,
      "z": -3,
      "name": "Empty"
    },
    {
      "x": 2,
      "y": 7,
      "z": -3,
      "name": "Rock_Basalt_Brick",
      "rotation": 2
    },
    {
      "x": 2,
      "y": 0,
      "z": -2,
      "name": "Soil_Snow"
    },
    {
      "x": 2,
      "y": 1,
      "z": -2,
      "name": "Empty"
    },
    {
      "x": 2,
      "y": 2,
      "z": -2,
      "name": "Empty"
    },
    {
      "x": 2,
      "y": 3,
      "z": -2,
      "name": "Empty"
    },
    {
      "x": 2,
      "y": 4,
      "z": -2,
      "name": "Empty"
    },
    {
      "x": 2,
      "y": 5,
      "z": -2,
      "name": "Empty"
    },
    {
      "x": 2,
      "y": 6,
      "z": -2,
      "name": "Empty"
    },
    {
      "x": 2,
      "y": 7,
      "z": -2,
      "name": "Rock_Basalt_Brick",
      "rotation": 2
    },
    {
      "x": 2,
      "y": 0,
      "z": -1,
      "name": "Rock_Ice"
    },
    {
      "x": 2,
      "y": 1,
      "z": -1,
      "name": "Rock_Ice_Icicles"
    },
    {
      "x": 2,
      "y": 2,
      "z": -1,
      "name": "Empty"
    },
    {
      "x": 2,
      "y": 3,
      "z": -1,
      "name": "Empty"
    },
    {
      "x": 2,
      "y": 4,
      "z": -1,
      "name": "Empty"
    },
    {
      "x": 2,
      "y": 5,
      "z": -1,
      "name": "Empty"
    },
    {
      "x": 2,
      "y": 6,
      "z": -1,
      "name": "Empty"
    },
    {
      "x": 2,
      "y": 7,
      "z": -1,
      "name": "Rock_Basalt_Brick",
      "rotation": 2
    },
    {
      "x": 2,
      "y": 0,
      "z": 0,
      "name": "Rock_Ice"
    },
    {
      "x": 2,
      "y": 1,
      "z": 0,
      "name": "Empty"
    },
    {
      "x": 2,
      "y": 2,
      "z": 0,
      "name": "Empty"
    },
    {
      "x": 2,
      "y": 3,
      "z": 0,
      "name": "Empty"
    },
    {
      "x": 2,
      "y": 4,
      "z": 0,
      "name": "Empty"
    },
    {
      "x": 2,
      "y": 5,
      "z": 0,
      "name": "Empty"
    },
    {
      "x": 2,
      "y": 6,
      "z": 0,
      "name": "Empty"
    },
    {
      "x": 2,
      "y": 7,
      "z": 0,
      "name": "Rock_Basalt_Brick",
      "rotation": 2
    },
    {
      "x": 2,
      "y": 0,
      "z": 1,
      "name": "Rock_Ice"
    },
    {
      "x": 2,
      "y": 1,
      "z": 1,
      "name": "Empty"
    },
    {
      "x": 2,
      "y": 2,
      "z": 1,
      "name": "Empty"
    },
    {
      "x": 2,
      "y": 3,
      "z": 1,
      "name": "Empty"
    },
    {
      "x": 2,
      "y": 4,
      "z": 1,
      "name": "Empty"
    },
    {
      "x": 2,
      "y": 5,
      "z": 1,
      "name": "Empty"
    },
    {
      "x": 2,
      "y": 6,
      "z": 1,
      "name": "Rock_Ice_Icicles",
      "rotation": 8
    },
    {
      "x": 2,
      "y": 7,
      "z": 1,
      "name": "Rock_Basalt_Brick",
      "rotation": 2
    },
    {
      "x": 2,
      "y": 0,
      "z": 2,
      "name": "Soil_Snow"
    },
    {
      "x": 2,
      "y": 1,
      "z": 2,
      "name": "Soil_Snow_Half"
    },
    {
      "x": 2,
      "y": 2,
      "z": 2,
      "name": "Empty"
    },
    {
      "x": 2,
      "y": 3,
      "z": 2,
      "name": "Empty"
    },
    {
      "x": 2,
      "y": 4,
      "z": 2,
      "name": "Empty"
    },
    {
      "x": 2,
      "y": 5,
      "z": 2,
      "name": "Empty"
    },
    {
      "x": 2,
      "y": 6,
      "z": 2,
      "name": "Empty"
    },
    {
      "x": 2,
      "y": 7,
      "z": 2,
      "name": "Rock_Basalt_Brick",
      "rotation": 2
    },
    {
      "x": 2,
      "y": 0,
      "z": 3,
      "name": "Rock_Ice"
    },
    {
      "x": 2,
      "y": 1,
      "z": 3,
      "name": "Soil_Snow"
    },
    {
      "x": 2,
      "y": 2,
      "z": 3,
      "name": "*Furniture_Ancient_Torch_State_Definitions_Off",
      "rotation": 2
    },
    {
      "x": 2,
      "y": 3,
      "z": 3,
      "name": "Empty"
    },
    {
      "x": 2,
      "y": 4,
      "z": 3,
      "name": "Empty"
    },
    {
      "x": 2,
      "y": 5,
      "z": 3,
      "name": "Empty"
    },
    {
      "x": 2,
      "y": 6,
      "z": 3,
      "name": "Empty"
    },
    {
      "x": 2,
      "y": 7,
      "z": 3,
      "name": "Rock_Ice"
    },
    {
      "x": 2,
      "y": 0,
      "z": 4,
      "name": "Rock_Ice"
    },
    {
      "x": 2,
      "y": 1,
      "z": 4,
      "name": "Soil_Snow"
    },
    {
      "x": 2,
      "y": 2,
      "z": 4,
      "name": "Rock_Ice_Stalactite_Large"
    },
    {
      "x": 2,
      "y": 3,
      "z": 4,
      "name": "Rock_Ice_Stalactite_Large",
      "filler": 1024
    },
    {
      "x": 2,
      "y": 4,
      "z": 4,
      "name": "Empty"
    },
    {
      "x": 2,
      "y": 5,
      "z": 4,
      "name": "Rock_Ice_Stalactite_Large",
      "filler": 31744,
      "rotation": 8
    },
    {
      "x": 2,
      "y": 6,
      "z": 4,
      "name": "Rock_Ice_Stalactite_Large",
      "rotation": 8
    },
    {
      "x": 2,
      "y": 7,
      "z": 4,
      "name": "Rock_Ice"
    },
    {
      "x": 2,
      "y": 0,
      "z": 5,
      "name": "Rock_Ice"
    },
    {
      "x": 2,
      "y": 1,
      "z": 5,
      "name": "Rock_Ice"
    },
    {
      "x": 2,
      "y": 2,
      "z": 5,
      "name": "Rock_Ice"
    },
    {
      "x": 2,
      "y": 3,
      "z": 5,
      "name": "Rock_Ice"
    },
    {
      "x": 2,
      "y": 4,
      "z": 5,
      "name": "Rock_Ice"
    },
    {
      "x": 2,
      "y": 5,
      "z": 5,
      "name": "Rock_Ice"
    },
    {
      "x": 2,
      "y": 6,
      "z": 5,
      "name": "Rock_Ice"
    },
    {
      "x": 2,
      "y": 7,
      "z": 5,
      "name": "Rock_Ice"
    },
    {
      "x": 3,
      "y": 0,
      "z": -4,
      "name": "*Rock_Basalt_Brick_Stairs_State_Definitions_Inverted_Corner_Left",
      "rotation": 3
    },
    {
      "x": 3,
      "y": 1,
      "z": -4,
      "name": "*Furniture_Frostbitten_Factory_Vault_Large_State_Definitions_CloseDoorOut",
      "rotation": 2
    },
    {
      "x": 3,
      "y": 2,
      "z": -4,
      "name": "*Furniture_Frostbitten_Factory_Vault_Large_State_Definitions_CloseDoorOut",
      "filler": 1024,
      "rotation": 2
    },
    {
      "x": 3,
      "y": 3,
      "z": -4,
      "name": "*Furniture_Frostbitten_Factory_Vault_Large_State_Definitions_CloseDoorOut",
      "filler": 2048,
      "rotation": 2
    },
    {
      "x": 3,
      "y": 4,
      "z": -4,
      "name": "*Furniture_Frostbitten_Factory_Vault_Large_State_Definitions_CloseDoorOut",
      "filler": 3072,
      "rotation": 2
    },
    {
      "x": 3,
      "y": 5,
      "z": -4,
      "name": "Rock_Basalt_Brick",
      "rotation": 2
    },
    {
      "x": 3,
      "y": 6,
      "z": -4,
      "name": "Rock_Basalt_Brick",
      "rotation": 2
    },
    {
      "x": 3,
      "y": 7,
      "z": -4,
      "name": "Rock_Basalt_Brick",
      "rotation": 2
    },
    {
      "x": 3,
      "y": 0,
      "z": -3,
      "name": "Soil_Snow"
    },
    {
      "x": 3,
      "y": 1,
      "z": -3,
      "name": "Deco_Bone_Pile"
    },
    {
      "x": 3,
      "y": 2,
      "z": -3,
      "name": "Empty"
    },
    {
      "x": 3,
      "y": 3,
      "z": -3,
      "name": "Empty"
    },
    {
      "x": 3,
      "y": 4,
      "z": -3,
      "name": "Empty"
    },
    {
      "x": 3,
      "y": 5,
      "z": -3,
      "name": "Empty"
    },
    {
      "x": 3,
      "y": 6,
      "z": -3,
      "name": "Wood_Deadwood_Planks_Half",
      "rotation": 8
    },
    {
      "x": 3,
      "y": 7,
      "z": -3,
      "name": "Rock_Basalt_Brick",
      "rotation": 2
    },
    {
      "x": 3,
      "y": 0,
      "z": -2,
      "name": "Rock_Ice"
    },
    {
      "x": 3,
      "y": 1,
      "z": -2,
      "name": "Empty"
    },
    {
      "x": 3,
      "y": 2,
      "z": -2,
      "name": "Empty"
    },
    {
      "x": 3,
      "y": 3,
      "z": -2,
      "name": "Empty"
    },
    {
      "x": 3,
      "y": 4,
      "z": -2,
      "name": "Empty"
    },
    {
      "x": 3,
      "y": 5,
      "z": -2,
      "name": "Empty"
    },
    {
      "x": 3,
      "y": 6,
      "z": -2,
      "name": "Wood_Deadwood_Planks_Half",
      "rotation": 8
    },
    {
      "x": 3,
      "y": 7,
      "z": -2,
      "name": "Rock_Basalt_Brick",
      "rotation": 2
    },
    {
      "x": 3,
      "y": 0,
      "z": -1,
      "name": "Rock_Ice"
    },
    {
      "x": 3,
      "y": 1,
      "z": -1,
      "name": "Empty"
    },
    {
      "x": 3,
      "y": 2,
      "z": -1,
      "name": "Empty"
    },
    {
      "x": 3,
      "y": 3,
      "z": -1,
      "name": "Empty"
    },
    {
      "x": 3,
      "y": 4,
      "z": -1,
      "name": "Empty"
    },
    {
      "x": 3,
      "y": 5,
      "z": -1,
      "name": "Empty"
    },
    {
      "x": 3,
      "y": 6,
      "z": -1,
      "name": "Wood_Deadwood_Planks_Half",
      "rotation": 8
    },
    {
      "x": 3,
      "y": 7,
      "z": -1,
      "name": "Rock_Basalt_Brick",
      "rotation": 2
    },
    {
      "x": 3,
      "y": 0,
      "z": 0,
      "name": "Rock_Ice"
    },
    {
      "x": 3,
      "y": 1,
      "z": 0,
      "name": "Empty"
    },
    {
      "x": 3,
      "y": 2,
      "z": 0,
      "name": "Empty"
    },
    {
      "x": 3,
      "y": 3,
      "z": 0,
      "name": "Empty"
    },
    {
      "x": 3,
      "y": 4,
      "z": 0,
      "name": "Empty"
    },
    {
      "x": 3,
      "y": 5,
      "z": 0,
      "name": "Empty"
    },
    {
      "x": 3,
      "y": 6,
      "z": 0,
      "name": "Wood_Deadwood_Planks_Half",
      "rotation": 8
    },
    {
      "x": 3,
      "y": 7,
      "z": 0,
      "name": "Rock_Basalt_Brick",
      "rotation": 2
    },
    {
      "x": 3,
      "y": 0,
      "z": 1,
      "name": "Rock_Ice"
    },
    {
      "x": 3,
      "y": 1,
      "z": 1,
      "name": "Empty"
    },
    {
      "x": 3,
      "y": 2,
      "z": 1,
      "name": "Empty"
    },
    {
      "x": 3,
      "y": 3,
      "z": 1,
      "name": "Empty"
    },
    {
      "x": 3,
      "y": 4,
      "z": 1,
      "name": "Empty"
    },
    {
      "x": 3,
      "y": 5,
      "z": 1,
      "name": "Empty"
    },
    {
      "x": 3,
      "y": 6,
      "z": 1,
      "name": "Wood_Deadwood_Planks_Half",
      "rotation": 8
    },
    {
      "x": 3,
      "y": 7,
      "z": 1,
      "name": "Rock_Basalt_Brick",
      "rotation": 2
    },
    {
      "x": 3,
      "y": 0,
      "z": 2,
      "name": "Soil_Snow"
    },
    {
      "x": 3,
      "y": 1,
      "z": 2,
      "name": "Empty"
    },
    {
      "x": 3,
      "y": 2,
      "z": 2,
      "name": "Empty"
    },
    {
      "x": 3,
      "y": 3,
      "z": 2,
      "name": "Empty"
    },
    {
      "x": 3,
      "y": 4,
      "z": 2,
      "name": "Empty"
    },
    {
      "x": 3,
      "y": 5,
      "z": 2,
      "name": "Empty"
    },
    {
      "x": 3,
      "y": 6,
      "z": 2,
      "name": "Wood_Deadwood_Planks_Half",
      "rotation": 8
    },
    {
      "x": 3,
      "y": 7,
      "z": 2,
      "name": "Rock_Basalt_Brick",
      "rotation": 2
    },
    {
      "x": 3,
      "y": 0,
      "z": 3,
      "name": "Soil_Snow"
    },
    {
      "x": 3,
      "y": 1,
      "z": 3,
      "name": "Soil_Snow_Half"
    },
    {
      "x": 3,
      "y": 2,
      "z": 3,
      "name": "Empty"
    },
    {
      "x": 3,
      "y": 3,
      "z": 3,
      "name": "Empty"
    },
    {
      "x": 3,
      "y": 4,
      "z": 3,
      "name": "Empty"
    },
    {
      "x": 3,
      "y": 5,
      "z": 3,
      "name": "Empty"
    },
    {
      "x": 3,
      "y": 6,
      "z": 3,
      "name": "Wood_Deadwood_Planks_Half",
      "rotation": 8
    },
    {
      "x": 3,
      "y": 7,
      "z": 3,
      "name": "Rock_Basalt_Brick",
      "rotation": 2
    },
    {
      "x": 3,
      "y": 0,
      "z": 4,
      "name": "Soil_Snow"
    },
    {
      "x": 3,
      "y": 1,
      "z": 4,
      "name": "Rock_Ice_Icicles"
    },
    {
      "x": 3,
      "y": 2,
      "z": 4,
      "name": "Empty"
    },
    {
      "x": 3,
      "y": 3,
      "z": 4,
      "name": "Empty"
    },
    {
      "x": 3,
      "y": 4,
      "z": 4,
      "name": "Empty"
    },
    {
      "x": 3,
      "y": 5,
      "z": 4,
      "name": "Empty"
    },
    {
      "x": 3,
      "y": 6,
      "z": 4,
      "name": "Wood_Deadwood_Planks_Half",
      "rotation": 8
    },
    {
      "x": 3,
      "y": 7,
      "z": 4,
      "name": "Rock_Basalt_Brick",
      "rotation": 2
    },
    {
      "x": 3,
      "y": 0,
      "z": 5,
      "name": "Rock_Ice"
    },
    {
      "x": 3,
      "y": 1,
      "z": 5,
      "name": "Rock_Ice"
    },
    {
      "x": 3,
      "y": 2,
      "z": 5,
      "name": "Rock_Ice"
    },
    {
      "x": 3,
      "y": 3,
      "z": 5,
      "name": "Rock_Ice"
    },
    {
      "x": 3,
      "y": 4,
      "z": 5,
      "name": "Rock_Ice"
    },
    {
      "x": 3,
      "y": 5,
      "z": 5,
      "name": "Rock_Ice"
    },
    {
      "x": 3,
      "y": 6,
      "z": 5,
      "name": "Rock_Ice"
    },
    {
      "x": 3,
      "y": 7,
      "z": 5,
      "name": "Rock_Ice"
    },
    {
      "x": 4,
      "y": 0,
      "z": -4,
      "name": "Rock_Basalt_Brick",
      "rotation": 2
    },
    {
      "x": 4,
      "y": 1,
      "z": -4,
      "name": "Rock_Basalt_Brick",
      "rotation": 2
    },
    {
      "x": 4,
      "y": 2,
      "z": -4,
      "name": "Rock_Basalt_Brick",
      "rotation": 2
    },
    {
      "x": 4,
      "y": 3,
      "z": -4,
      "name": "Rock_Basalt_Brick",
      "rotation": 2
    },
    {
      "x": 4,
      "y": 4,
      "z": -4,
      "name": "Rock_Basalt_Brick",
      "rotation": 2
    },
    {
      "x": 4,
      "y": 5,
      "z": -4,
      "name": "Rock_Basalt_Brick",
      "rotation": 2
    },
    {
      "x": 4,
      "y": 6,
      "z": -4,
      "name": "Rock_Basalt_Brick",
      "rotation": 2
    },
    {
      "x": 4,
      "y": 7,
      "z": -4,
      "name": "Rock_Basalt_Brick",
      "rotation": 2
    },
    {
      "x": 4,
      "y": 0,
      "z": -3,
      "name": "Soil_Snow"
    },
    {
      "x": 4,
      "y": 1,
      "z": -3,
      "name": "Empty"
    },
    {
      "x": 4,
      "y": 2,
      "z": -3,
      "name": "Empty"
    },
    {
      "x": 4,
      "y": 3,
      "z": -3,
      "name": "Empty"
    },
    {
      "x": 4,
      "y": 4,
      "z": -3,
      "name": "Empty"
    },
    {
      "x": 4,
      "y": 5,
      "z": -3,
      "name": "Empty"
    },
    {
      "x": 4,
      "y": 6,
      "z": -3,
      "name": "Rock_Ice_Icicles",
      "rotation": 8
    },
    {
      "x": 4,
      "y": 7,
      "z": -3,
      "name": "Rock_Basalt_Brick",
      "rotation": 2
    },
    {
      "x": 4,
      "y": 0,
      "z": -2,
      "name": "Rock_Ice"
    },
    {
      "x": 4,
      "y": 1,
      "z": -2,
      "name": "Rock_Ice_Stalactite_Large"
    },
    {
      "x": 4,
      "y": 2,
      "z": -2,
      "name": "Rock_Ice_Stalactite_Large",
      "filler": 1024
    },
    {
      "x": 4,
      "y": 3,
      "z": -2,
      "name": "Empty"
    },
    {
      "x": 4,
      "y": 4,
      "z": -2,
      "name": "Empty"
    },
    {
      "x": 4,
      "y": 5,
      "z": -2,
      "name": "Empty"
    },
    {
      "x": 4,
      "y": 6,
      "z": -2,
      "name": "Empty"
    },
    {
      "x": 4,
      "y": 7,
      "z": -2,
      "name": "Rock_Basalt_Brick",
      "rotation": 2
    },
    {
      "x": 4,
      "y": 0,
      "z": -1,
      "name": "Rock_Ice"
    },
    {
      "x": 4,
      "y": 1,
      "z": -1,
      "name": "Rock_Ice"
    },
    {
      "x": 4,
      "y": 2,
      "z": -1,
      "name": "Empty"
    },
    {
      "x": 4,
      "y": 3,
      "z": -1,
      "name": "Empty"
    },
    {
      "x": 4,
      "y": 4,
      "z": -1,
      "name": "Empty"
    },
    {
      "x": 4,
      "y": 5,
      "z": -1,
      "name": "Empty"
    },
    {
      "x": 4,
      "y": 6,
      "z": -1,
      "name": "Empty"
    },
    {
      "x": 4,
      "y": 7,
      "z": -1,
      "name": "Rock_Ice"
    },
    {
      "x": 4,
      "y": 0,
      "z": 0,
      "name": "Rock_Ice"
    },
    {
      "x": 4,
      "y": 1,
      "z": 0,
      "name": "Deco_Bone_Pile"
    },
    {
      "x": 4,
      "y": 2,
      "z": 0,
      "name": "Empty"
    },
    {
      "x": 4,
      "y": 3,
      "z": 0,
      "name": "Empty"
    },
    {
      "x": 4,
      "y": 4,
      "z": 0,
      "name": "Empty"
    },
    {
      "x": 4,
      "y": 5,
      "z": 0,
      "name": "Empty"
    },
    {
      "x": 4,
      "y": 6,
      "z": 0,
      "name": "Empty"
    },
    {
      "x": 4,
      "y": 7,
      "z": 0,
      "name": "Rock_Ice"
    },
    {
      "x": 4,
      "y": 0,
      "z": 1,
      "name": "Rock_Ice"
    },
    {
      "x": 4,
      "y": 1,
      "z": 1,
      "name": "Empty"
    },
    {
      "x": 4,
      "y": 2,
      "z": 1,
      "name": "Empty"
    },
    {
      "x": 4,
      "y": 3,
      "z": 1,
      "name": "Empty"
    },
    {
      "x": 4,
      "y": 4,
      "z": 1,
      "name": "Empty"
    },
    {
      "x": 4,
      "y": 5,
      "z": 1,
      "name": "Empty"
    },
    {
      "x": 4,
      "y": 6,
      "z": 1,
      "name": "Empty"
    },
    {
      "x": 4,
      "y": 7,
      "z": 1,
      "name": "Rock_Basalt_Brick",
      "rotation": 2
    },
    {
      "x": 4,
      "y": 0,
      "z": 2,
      "name": "Soil_Snow"
    },
    {
      "x": 4,
      "y": 1,
      "z": 2,
      "name": "Empty"
    },
    {
      "x": 4,
      "y": 2,
      "z": 2,
      "name": "Empty"
    },
    {
      "x": 4,
      "y": 3,
      "z": 2,
      "name": "Empty"
    },
    {
      "x": 4,
      "y": 4,
      "z": 2,
      "name": "Empty"
    },
    {
      "x": 4,
      "y": 5,
      "z": 2,
      "name": "Empty"
    },
    {
      "x": 4,
      "y": 6,
      "z": 2,
      "name": "Empty"
    },
    {
      "x": 4,
      "y": 7,
      "z": 2,
      "name": "Rock_Basalt_Brick",
      "rotation": 2
    },
    {
      "x": 4,
      "y": 0,
      "z": 3,
      "name": "Soil_Snow"
    },
    {
      "x": 4,
      "y": 1,
      "z": 3,
      "name": "Empty"
    },
    {
      "x": 4,
      "y": 2,
      "z": 3,
      "name": "Empty"
    },
    {
      "x": 4,
      "y": 3,
      "z": 3,
      "name": "Empty"
    },
    {
      "x": 4,
      "y": 4,
      "z": 3,
      "name": "Empty"
    },
    {
      "x": 4,
      "y": 5,
      "z": 3,
      "name": "Rock_Ice_Stalactite_Large",
      "filler": 31744,
      "rotation": 8
    },
    {
      "x": 4,
      "y": 6,
      "z": 3,
      "name": "Rock_Ice_Stalactite_Large",
      "rotation": 8
    },
    {
      "x": 4,
      "y": 7,
      "z": 3,
      "name": "Rock_Basalt_Brick",
      "rotation": 2
    },
    {
      "x": 4,
      "y": 0,
      "z": 4,
      "name": "Soil_Snow"
    },
    {
      "x": 4,
      "y": 1,
      "z": 4,
      "name": "Soil_Snow_Half"
    },
    {
      "x": 4,
      "y": 2,
      "z": 4,
      "name": "Empty"
    },
    {
      "x": 4,
      "y": 3,
      "z": 4,
      "name": "Empty"
    },
    {
      "x": 4,
      "y": 4,
      "z": 4,
      "name": "Empty"
    },
    {
      "x": 4,
      "y": 5,
      "z": 4,
      "name": "Empty"
    },
    {
      "x": 4,
      "y": 6,
      "z": 4,
      "name": "Empty"
    },
    {
      "x": 4,
      "y": 7,
      "z": 4,
      "name": "Rock_Basalt_Brick",
      "rotation": 2
    },
    {
      "x": 4,
      "y": 0,
      "z": 5,
      "name": "Rock_Ice"
    },
    {
      "x": 4,
      "y": 1,
      "z": 5,
      "name": "Rock_Ice"
    },
    {
      "x": 4,
      "y": 2,
      "z": 5,
      "name": "Rock_Ice"
    },
    {
      "x": 4,
      "y": 3,
      "z": 5,
      "name": "Rock_Basalt_Brick",
      "rotation": 2
    },
    {
      "x": 4,
      "y": 4,
      "z": 5,
      "name": "Rock_Basalt_Brick",
      "rotation": 2
    },
    {
      "x": 4,
      "y": 5,
      "z": 5,
      "name": "Rock_Basalt_Brick",
      "rotation": 2
    },
    {
      "x": 4,
      "y": 6,
      "z": 5,
      "name": "Rock_Basalt_Brick",
      "rotation": 2
    },
    {
      "x": 4,
      "y": 7,
      "z": 5,
      "name": "Rock_Basalt_Brick",
      "rotation": 2
    },
    {
      "x": 5,
      "y": 0,
      "z": -4,
      "name": "Rock_Basalt_Brick",
      "rotation": 2
    },
    {
      "x": 5,
      "y": 1,
      "z": -4,
      "name": "Rock_Basalt_Brick",
      "rotation": 2
    },
    {
      "x": 5,
      "y": 2,
      "z": -4,
      "name": "Rock_Basalt_Brick",
      "rotation": 2
    },
    {
      "x": 5,
      "y": 3,
      "z": -4,
      "name": "Rock_Basalt_Brick",
      "rotation": 2
    },
    {
      "x": 5,
      "y": 4,
      "z": -4,
      "name": "Rock_Basalt_Brick",
      "rotation": 2
    },
    {
      "x": 5,
      "y": 5,
      "z": -4,
      "name": "Rock_Basalt_Brick",
      "rotation": 2
    },
    {
      "x": 5,
      "y": 6,
      "z": -4,
      "name": "Rock_Basalt_Brick",
      "rotation": 2
    },
    {
      "x": 5,
      "y": 7,
      "z": -4,
      "name": "Rock_Basalt_Brick",
      "rotation": 2
    },
    {
      "x": 5,
      "y": 0,
      "z": -3,
      "name": "Rock_Ice"
    },
    {
      "x": 5,
      "y": 1,
      "z": -3,
      "name": "Rock_Ice"
    },
    {
      "x": 5,
      "y": 2,
      "z": -3,
      "name": "Rock_Ice_Icicles"
    },
    {
      "x": 5,
      "y": 3,
      "z": -3,
      "name": "Empty"
    },
    {
      "x": 5,
      "y": 4,
      "z": -3,
      "name": "Empty"
    },
    {
      "x": 5,
      "y": 5,
      "z": -3,
      "name": "Empty"
    },
    {
      "x": 5,
      "y": 6,
      "z": -3,
      "name": "Empty"
    },
    {
      "x": 5,
      "y": 7,
      "z": -3,
      "name": "Rock_Basalt_Brick",
      "rotation": 2
    },
    {
      "x": 5,
      "y": 0,
      "z": -2,
      "name": "Rock_Ice"
    },
    {
      "x": 5,
      "y": 1,
      "z": -2,
      "name": "Rock_Ice"
    },
    {
      "x": 5,
      "y": 2,
      "z": -2,
      "name": "Rock_Ice"
    },
    {
      "x": 5,
      "y": 3,
      "z": -2,
      "name": "Empty"
    },
    {
      "x": 5,
      "y": 4,
      "z": -2,
      "name": "Empty"
    },
    {
      "x": 5,
      "y": 5,
      "z": -2,
      "name": "Empty"
    },
    {
      "x": 5,
      "y": 6,
      "z": -2,
      "name": "Rock_Ice_Icicles",
      "rotation": 8
    },
    {
      "x": 5,
      "y": 7,
      "z": -2,
      "name": "Rock_Ice"
    },
    {
      "x": 5,
      "y": 0,
      "z": -1,
      "name": "Rock_Ice"
    },
    {
      "x": 5,
      "y": 1,
      "z": -1,
      "name": "Rock_Ice"
    },
    {
      "x": 5,
      "y": 2,
      "z": -1,
      "name": "Rock_Ice"
    },
    {
      "x": 5,
      "y": 3,
      "z": -1,
      "name": "Rock_Ice_Icicles"
    },
    {
      "x": 5,
      "y": 4,
      "z": -1,
      "name": "Rock_Ice_Stalactite_Large",
      "filler": 31744,
      "rotation": 8
    },
    {
      "x": 5,
      "y": 5,
      "z": -1,
      "name": "Rock_Ice_Stalactite_Large",
      "rotation": 8
    },
    {
      "x": 5,
      "y": 6,
      "z": -1,
      "name": "Rock_Ice"
    },
    {
      "x": 5,
      "y": 7,
      "z": -1,
      "name": "Rock_Ice"
    },
    {
      "x": 5,
      "y": 0,
      "z": 0,
      "name": "Rock_Ice"
    },
    {
      "x": 5,
      "y": 1,
      "z": 0,
      "name": "Rock_Ice"
    },
    {
      "x": 5,
      "y": 2,
      "z": 0,
      "name": "Rock_Ice_Icicles"
    },
    {
      "x": 5,
      "y": 3,
      "z": 0,
      "name": "Empty"
    },
    {
      "x": 5,
      "y": 4,
      "z": 0,
      "name": "Empty"
    },
    {
      "x": 5,
      "y": 5,
      "z": 0,
      "name": "Rock_Ice_Stalactite_Large",
      "filler": 31744,
      "rotation": 8
    },
    {
      "x": 5,
      "y": 6,
      "z": 0,
      "name": "Rock_Ice_Stalactite_Large",
      "rotation": 8
    },
    {
      "x": 5,
      "y": 7,
      "z": 0,
      "name": "Rock_Ice"
    },
    {
      "x": 5,
      "y": 0,
      "z": 1,
      "name": "Soil_Snow"
    },
    {
      "x": 5,
      "y": 1,
      "z": 1,
      "name": "Empty"
    },
    {
      "x": 5,
      "y": 2,
      "z": 1,
      "name": "Empty"
    },
    {
      "x": 5,
      "y": 3,
      "z": 1,
      "name": "Empty"
    },
    {
      "x": 5,
      "y": 4,
      "z": 1,
      "name": "Empty"
    },
    {
      "x": 5,
      "y": 5,
      "z": 1,
      "name": "Empty"
    },
    {
      "x": 5,
      "y": 6,
      "z": 1,
      "name": "Empty"
    },
    {
      "x": 5,
      "y": 7,
      "z": 1,
      "name": "Rock_Ice"
    },
    {
      "x": 5,
      "y": 0,
      "z": 2,
      "name": "Soil_Snow"
    },
    {
      "x": 5,
      "y": 1,
      "z": 2,
      "name": "Rock_Ice_Stalactite_Large"
    },
    {
      "x": 5,
      "y": 2,
      "z": 2,
      "name": "Rock_Ice_Stalactite_Large",
      "filler": 1024
    },
    {
      "x": 5,
      "y": 3,
      "z": 2,
      "name": "Empty"
    },
    {
      "x": 5,
      "y": 4,
      "z": 2,
      "name": "Empty"
    },
    {
      "x": 5,
      "y": 5,
      "z": 2,
      "name": "Empty"
    },
    {
      "x": 5,
      "y": 6,
      "z": 2,
      "name": "Rock_Ice_Icicles",
      "rotation": 8
    },
    {
      "x": 5,
      "y": 7,
      "z": 2,
      "name": "Rock_Basalt_Brick",
      "rotation": 2
    },
    {
      "x": 5,
      "y": 0,
      "z": 3,
      "name": "Soil_Snow"
    },
    {
      "x": 5,
      "y": 1,
      "z": 3,
      "name": "Block_Spawner_Block",
      "components": {
        "Components": {
          "PlacedByInteraction": {
            "WhoPlacedUuid": {
              "$binary": "B1yBGZcjQ2KREo5yyLGY0g==",
              "$type": "04"
            }
          },
          "BlockSpawner": {
            "BlockSpawnerId": "Zone3_Outlander_Tier3"
          }
        }
      },
      "rotation": 3
    },
    {
      "x": 5,
      "y": 2,
      "z": 3,
      "name": "Empty"
    },
    {
      "x": 5,
      "y": 3,
      "z": 3,
      "name": "Empty"
    },
    {
      "x": 5,
      "y": 4,
      "z": 3,
      "name": "Empty"
    },
    {
      "x": 5,
      "y": 5,
      "z": 3,
      "name": "Empty"
    },
    {
      "x": 5,
      "y": 6,
      "z": 3,
      "name": "Empty"
    },
    {
      "x": 5,
      "y": 7,
      "z": 3,
      "name": "Rock_Basalt_Brick",
      "rotation": 2
    },
    {
      "x": 5,
      "y": 0,
      "z": 4,
      "name": "Soil_Snow"
    },
    {
      "x": 5,
      "y": 1,
      "z": 4,
      "name": "Bronze_Pipe_Large"
    },
    {
      "x": 5,
      "y": 2,
      "z": 4,
      "name": "Bronze_Pipe_Large"
    },
    {
      "x": 5,
      "y": 3,
      "z": 4,
      "name": "Bronze_Pipe_Large"
    },
    {
      "x": 5,
      "y": 4,
      "z": 4,
      "name": "Bronze_Pipe_Large"
    },
    {
      "x": 5,
      "y": 5,
      "z": 4,
      "name": "Bronze_Pipe_Large"
    },
    {
      "x": 5,
      "y": 6,
      "z": 4,
      "name": "Bronze_Pipe_Large"
    },
    {
      "x": 5,
      "y": 7,
      "z": 4,
      "name": "Rock_Basalt_Brick",
      "rotation": 2
    },
    {
      "x": 5,
      "y": 0,
      "z": 5,
      "name": "Rock_Ice"
    },
    {
      "x": 5,
      "y": 1,
      "z": 5,
      "name": "Rock_Basalt_Brick",
      "rotation": 2
    },
    {
      "x": 5,
      "y": 2,
      "z": 5,
      "name": "Rock_Basalt_Brick",
      "rotation": 2
    },
    {
      "x": 5,
      "y": 3,
      "z": 5,
      "name": "Rock_Basalt_Brick",
      "rotation": 2
    },
    {
      "x": 5,
      "y": 4,
      "z": 5,
      "name": "Rock_Basalt_Brick",
      "rotation": 2
    },
    {
      "x": 5,
      "y": 5,
      "z": 5,
      "name": "Rock_Basalt_Brick",
      "rotation": 2
    },
    {
      "x": 5,
      "y": 6,
      "z": 5,
      "name": "Rock_Basalt_Brick",
      "rotation": 2
    },
    {
      "x": 5,
      "y": 7,
      "z": 5,
      "name": "Rock_Basalt_Brick",
      "rotation": 2
    },
    {
      "x": 6,
      "y": 0,
      "z": -4,
      "name": "Rock_Basalt_Brick",
      "rotation": 2
    },
    {
      "x": 6,
      "y": 1,
      "z": -4,
      "name": "Rock_Basalt_Brick",
      "rotation": 2
    },
    {
      "x": 6,
      "y": 2,
      "z": -4,
      "name": "Rock_Basalt_Brick",
      "rotation": 2
    },
    {
      "x": 6,
      "y": 3,
      "z": -4,
      "name": "Rock_Basalt_Brick",
      "rotation": 2
    },
    {
      "x": 6,
      "y": 4,
      "z": -4,
      "name": "Rock_Basalt_Brick",
      "rotation": 2
    },
    {
      "x": 6,
      "y": 5,
      "z": -4,
      "name": "Rock_Basalt_Brick",
      "rotation": 2
    },
    {
      "x": 6,
      "y": 6,
      "z": -4,
      "name": "Rock_Basalt_Brick",
      "rotation": 2
    },
    {
      "x": 6,
      "y": 7,
      "z": -4,
      "name": "Rock_Basalt_Brick",
      "rotation": 2
    },
    {
      "x": 6,
      "y": 0,
      "z": -3,
      "name": "Rock_Ice"
    },
    {
      "x": 6,
      "y": 1,
      "z": -3,
      "name": "Rock_Ice"
    },
    {
      "x": 6,
      "y": 2,
      "z": -3,
      "name": "Rock_Ice"
    },
    {
      "x": 6,
      "y": 3,
      "z": -3,
      "name": "Rock_Ice"
    },
    {
      "x": 6,
      "y": 4,
      "z": -3,
      "name": "Rock_Basalt_Brick",
      "rotation": 2
    },
    {
      "x": 6,
      "y": 5,
      "z": -3,
      "name": "Rock_Basalt_Brick",
      "rotation": 2
    },
    {
      "x": 6,
      "y": 6,
      "z": -3,
      "name": "Rock_Basalt_Brick",
      "rotation": 2
    },
    {
      "x": 6,
      "y": 7,
      "z": -3,
      "name": "Rock_Basalt_Brick",
      "rotation": 2
    },
    {
      "x": 6,
      "y": 0,
      "z": -2,
      "name": "Rock_Ice"
    },
    {
      "x": 6,
      "y": 1,
      "z": -2,
      "name": "Rock_Ice"
    },
    {
      "x": 6,
      "y": 2,
      "z": -2,
      "name": "Rock_Ice"
    },
    {
      "x": 6,
      "y": 3,
      "z": -2,
      "name": "Rock_Ice"
    },
    {
      "x": 6,
      "y": 4,
      "z": -2,
      "name": "Rock_Ice"
    },
    {
      "x": 6,
      "y": 5,
      "z": -2,
      "name": "Rock_Ice"
    },
    {
      "x": 6,
      "y": 6,
      "z": -2,
      "name": "Rock_Ice"
    },
    {
      "x": 6,
      "y": 7,
      "z": -2,
      "name": "Rock_Ice"
    },
    {
      "x": 6,
      "y": 0,
      "z": -1,
      "name": "Rock_Ice"
    },
    {
      "x": 6,
      "y": 1,
      "z": -1,
      "name": "Rock_Ice"
    },
    {
      "x": 6,
      "y": 2,
      "z": -1,
      "name": "Rock_Ice"
    },
    {
      "x": 6,
      "y": 3,
      "z": -1,
      "name": "Rock_Ice"
    },
    {
      "x": 6,
      "y": 4,
      "z": -1,
      "name": "Rock_Ice"
    },
    {
      "x": 6,
      "y": 5,
      "z": -1,
      "name": "Rock_Ice"
    },
    {
      "x": 6,
      "y": 6,
      "z": -1,
      "name": "Rock_Ice"
    },
    {
      "x": 6,
      "y": 7,
      "z": -1,
      "name": "Rock_Ice"
    },
    {
      "x": 6,
      "y": 0,
      "z": 0,
      "name": "Rock_Ice"
    },
    {
      "x": 6,
      "y": 1,
      "z": 0,
      "name": "Rock_Ice"
    },
    {
      "x": 6,
      "y": 2,
      "z": 0,
      "name": "Rock_Ice"
    },
    {
      "x": 6,
      "y": 3,
      "z": 0,
      "name": "Rock_Ice"
    },
    {
      "x": 6,
      "y": 4,
      "z": 0,
      "name": "Rock_Ice"
    },
    {
      "x": 6,
      "y": 5,
      "z": 0,
      "name": "Rock_Ice"
    },
    {
      "x": 6,
      "y": 6,
      "z": 0,
      "name": "Rock_Ice"
    },
    {
      "x": 6,
      "y": 7,
      "z": 0,
      "name": "Rock_Ice"
    },
    {
      "x": 6,
      "y": 0,
      "z": 1,
      "name": "Rock_Ice"
    },
    {
      "x": 6,
      "y": 1,
      "z": 1,
      "name": "Rock_Ice"
    },
    {
      "x": 6,
      "y": 2,
      "z": 1,
      "name": "Rock_Ice"
    },
    {
      "x": 6,
      "y": 3,
      "z": 1,
      "name": "Rock_Basalt_Brick",
      "rotation": 2
    },
    {
      "x": 6,
      "y": 4,
      "z": 1,
      "name": "Rock_Basalt_Brick",
      "rotation": 2
    },
    {
      "x": 6,
      "y": 5,
      "z": 1,
      "name": "Rock_Basalt_Brick",
      "rotation": 2
    },
    {
      "x": 6,
      "y": 6,
      "z": 1,
      "name": "Rock_Basalt_Brick",
      "rotation": 2
    },
    {
      "x": 6,
      "y": 7,
      "z": 1,
      "name": "Rock_Basalt_Brick",
      "rotation": 2
    },
    {
      "x": 6,
      "y": 0,
      "z": 2,
      "name": "Rock_Basalt_Brick",
      "rotation": 2
    },
    {
      "x": 6,
      "y": 1,
      "z": 2,
      "name": "Rock_Basalt_Brick",
      "rotation": 2
    },
    {
      "x": 6,
      "y": 2,
      "z": 2,
      "name": "Rock_Basalt_Brick",
      "rotation": 2
    },
    {
      "x": 6,
      "y": 3,
      "z": 2,
      "name": "Rock_Basalt_Brick",
      "rotation": 2
    },
    {
      "x": 6,
      "y": 4,
      "z": 2,
      "name": "Rock_Basalt_Brick",
      "rotation": 2
    },
    {
      "x": 6,
      "y": 5,
      "z": 2,
      "name": "Rock_Basalt_Brick",
      "rotation": 2
    },
    {
      "x": 6,
      "y": 6,
      "z": 2,
      "name": "Rock_Basalt_Brick",
      "rotation": 2
    },
    {
      "x": 6,
      "y": 7,
      "z": 2,
      "name": "Rock_Basalt_Brick",
      "rotation": 2
    },
    {
      "x": 6,
      "y": 0,
      "z": 3,
      "name": "Rock_Basalt_Brick",
      "rotation": 2
    },
    {
      "x": 6,
      "y": 1,
      "z": 3,
      "name": "Rock_Basalt_Brick",
      "rotation": 2
    },
    {
      "x": 6,
      "y": 2,
      "z": 3,
      "name": "Rock_Basalt_Brick",
      "rotation": 2
    },
    {
      "x": 6,
      "y": 3,
      "z": 3,
      "name": "Rock_Basalt_Brick",
      "rotation": 2
    },
    {
      "x": 6,
      "y": 4,
      "z": 3,
      "name": "Rock_Basalt_Brick",
      "rotation": 2
    },
    {
      "x": 6,
      "y": 5,
      "z": 3,
      "name": "Rock_Basalt_Brick",
      "rotation": 2
    },
    {
      "x": 6,
      "y": 6,
      "z": 3,
      "name": "Rock_Basalt_Brick",
      "rotation": 2
    },
    {
      "x": 6,
      "y": 7,
      "z": 3,
      "name": "Rock_Basalt_Brick",
      "rotation": 2
    },
    {
      "x": 6,
      "y": 0,
      "z": 4,
      "name": "Rock_Basalt_Brick",
      "rotation": 2
    },
    {
      "x": 6,
      "y": 1,
      "z": 4,
      "name": "Rock_Basalt_Brick",
      "rotation": 2
    },
    {
      "x": 6,
      "y": 2,
      "z": 4,
      "name": "Rock_Basalt_Brick",
      "rotation": 2
    },
    {
      "x": 6,
      "y": 3,
      "z": 4,
      "name": "Rock_Basalt_Brick",
      "rotation": 2
    },
    {
      "x": 6,
      "y": 4,
      "z": 4,
      "name": "Rock_Basalt_Brick",
      "rotation": 2
    },
    {
      "x": 6,
      "y": 5,
      "z": 4,
      "name": "Rock_Basalt_Brick",
      "rotation": 2
    },
    {
      "x": 6,
      "y": 6,
      "z": 4,
      "name": "Rock_Basalt_Brick",
      "rotation": 2
    },
    {
      "x": 6,
      "y": 7,
      "z": 4,
      "name": "Rock_Basalt_Brick",
      "rotation": 2
    },
    {
      "x": 6,
      "y": 0,
      "z": 5,
      "name": "Rock_Basalt_Brick",
      "rotation": 2
    },
    {
      "x": 6,
      "y": 1,
      "z": 5,
      "name": "Rock_Basalt_Brick",
      "rotation": 2
    },
    {
      "x": 6,
      "y": 2,
      "z": 5,
      "name": "Rock_Basalt_Brick",
      "rotation": 2
    },
    {
      "x": 6,
      "y": 3,
      "z": 5,
      "name": "Rock_Basalt_Brick",
      "rotation": 2
    },
    {
      "x": 6,
      "y": 4,
      "z": 5,
      "name": "Rock_Basalt_Brick",
      "rotation": 2
    },
    {
      "x": 6,
      "y": 5,
      "z": 5,
      "name": "Rock_Basalt_Brick",
      "rotation": 2
    },
    {
      "x": 6,
      "y": 6,
      "z": 5,
      "name": "Rock_Basalt_Brick",
      "rotation": 2
    },
    {
      "x": 6,
      "y": 7,
      "z": 5,
      "name": "Rock_Basalt_Brick",
      "rotation": 2
    }
  ],
  "entities": [
    {
      "Components": {
        "EffectController": {},
        "DisplayName": {
          "DisplayName": {
            "MessageId": "server.npcRoles.Skeleton_Frost_Knight.name",
            "Bold": null,
            "Italic": null,
            "Monospace": null,
            "Underline": null
          }
        },
        "UIComponentList": {},
        "Transform": {
          "Position": {
            "X": -1.5,
            "Y": 1.0,
            "Z": -0.5
          },
          "Rotation": {
            "Pitch": 0.0,
            "Yaw": -1.2328214645385742,
            "Roll": 0.0
          }
        },
        "Velocity": {
          "Velocity": {
            "X": 0.0,
            "Y": 0.0,
            "Z": 0.0
          }
        },
        "PrefabCopyable": {},
        "Interactions": {
          "Interactions": {
            "Use": "*UseNPC"
          }
        },
        "Model": {
          "Model": {
            "Id": "Skeleton_Frost_Knight",
            "Scale": 1.0,
            "Static": false
          }
        },
        "UUID": {
          "UUID": {
            "$binary": "gCMERRt8NZae7SnFqbcmMQ==",
            "$type": "04"
          }
        },
        "EntityStats": {
          "Version": 5,
          "Stats": {
            "Oxygen": {
              "Id": "Oxygen",
              "Value": 100.0
            },
            "Mana": {
              "Id": "Mana",
              "Value": 0.0
            },
            "Health": {
              "Id": "Health",
              "Value": 74.0
            },
            "GlidingActive": {
              "Id": "GlidingActive",
              "Value": 0.0
            },
            "Immunity": {
              "Id": "Immunity",
              "Value": 0.0
            },
            "Stamina": {
              "Id": "Stamina",
              "Value": 10.0
            },
            "SignatureCharges": {
              "Id": "SignatureCharges",
              "Value": 0.0
            },
            "Ammo": {
              "Id": "Ammo",
              "Value": 0.0
            },
            "Unknown": {
              "Id": "Unknown",
              "Value": 0.0
            },
            "SignatureEnergy": {
              "Id": "SignatureEnergy",
              "Value": 0.0
            },
            "DeployablePreview": {
              "Id": "DeployablePreview",
              "Value": 0.0
            },
            "StaminaRegenDelay": {
              "Id": "StaminaRegenDelay",
              "Value": 0.0
            },
            "MagicCharges": {
              "Id": "MagicCharges",
              "Value": 0.0
            }
          }
        },
        "NPC": {
          "Version": 5,
          "UUID": {
            "$binary": "LsQ8QofCPyyO8RwRT3T+yw==",
            "$type": "04"
          },
          "Inventory": {
            "Version": 4,
            "Storage": {
              "Id": "Empty"
            },
            "Armor": {
              "Id": "Simple",
              "Capacity": 4,
              "Items": {}
            },
            "HotBar": {
              "Id": "Simple",
              "Capacity": 3,
              "Items": {
                "0": {
                  "Id": "Weapon_Sword_Frost",
                  "Quantity": 1,
                  "Durability": 80.0,
                  "MaxDurability": 80.0,
                  "OverrideDroppedItemAnimation": false
                }
              }
            },
            "Utility": {
              "Id": "Simple",
              "Capacity": 2,
              "Items": {
                "0": {
                  "Id": "Furniture_Crude_Torch",
                  "Quantity": 1,
                  "Durability": 0.0,
                  "MaxDurability": 0.0,
                  "OverrideDroppedItemAnimation": false
                }
              }
            },
            "Backpack": {
              "Id": "Empty"
            },
            "ActiveHotbarSlot": 0,
            "Tool": {
              "Id": "Empty"
            },
            "ActiveToolsSlot": -1,
            "ActiveUtilitySlot": -1,
            "SortType": "Name"
          },
          "HvrPhs": 0.0,
          "HvrHght": 0.0,
          "MdlScl": 1.0,
          "SpawnInstant": "0001-01-01T12:00:00Z",
          "WorldgenId": 0,
          "PathManager": {},
          "LeashPos": {
            "X": 62.5,
            "Y": 56.0,
            "Z": 3.5
          },
          "LeashHdg": -1.2328214645385742,
          "LeashPtch": 0.0,
          "RoleName": "Skeleton_Frost_Knight"
        },
        "HeadRotation": {
          "Rotation": {
            "Pitch": 0.0,
            "Yaw": -1.2328214645385742,
            "Roll": 0.0
          }
        }
      }
    },
    {
      "Components": {
        "EffectController": {},
        "DisplayName": {
          "DisplayName": {
            "MessageId": "server.npcRoles.Skeleton_Frost_Knight.name",
            "Bold": null,
            "Italic": null,
            "Monospace": null,
            "Underline": null
          }
        },
        "UIComponentList": {},
        "Transform": {
          "Position": {
            "X": 3.5,
            "Y": 1.0,
            "Z": 1.5
          },
          "Rotation": {
            "Pitch": 0.0,
            "Yaw": 0.48885634541511536,
            "Roll": 0.0
          }
        },
        "Velocity": {
          "Velocity": {
            "X": 0.0,
            "Y": 0.0,
            "Z": 0.0
          }
        },
        "PrefabCopyable": {},
        "Interactions": {
          "Interactions": {
            "Use": "*UseNPC"
          }
        },
        "Model": {
          "Model": {
            "Id": "Skeleton_Frost_Knight",
            "Scale": 1.0,
            "Static": false
          }
        },
        "UUID": {
          "UUID": {
            "$binary": "gDdESC1bOsuXVudyyyGaDA==",
            "$type": "04"
          }
        },
        "EntityStats": {
          "Version": 5,
          "Stats": {
            "Oxygen": {
              "Id": "Oxygen",
              "Value": 100.0
            },
            "Mana": {
              "Id": "Mana",
              "Value": 0.0
            },
            "Health": {
              "Id": "Health",
              "Value": 74.0
            },
            "GlidingActive": {
              "Id": "GlidingActive",
              "Value": 0.0
            },
            "Immunity": {
              "Id": "Immunity",
              "Value": 0.0
            },
            "Stamina": {
              "Id": "Stamina",
              "Value": 10.0
            },
            "SignatureCharges": {
              "Id": "SignatureCharges",
              "Value": 0.0
            },
            "Ammo": {
              "Id": "Ammo",
              "Value": 0.0
            },
            "Unknown": {
              "Id": "Unknown",
              "Value": 0.0
            },
            "SignatureEnergy": {
              "Id": "SignatureEnergy",
              "Value": 0.0
            },
            "DeployablePreview": {
              "Id": "DeployablePreview",
              "Value": 0.0
            },
            "StaminaRegenDelay": {
              "Id": "StaminaRegenDelay",
              "Value": 0.0
            },
            "MagicCharges": {
              "Id": "MagicCharges",
              "Value": 0.0
            }
          }
        },
        "NPC": {
          "Version": 5,
          "UUID": {
            "$binary": "jDmJRawqPH2sxDtp5E7qaw==",
            "$type": "04"
          },
          "Inventory": {
            "Version": 4,
            "Storage": {
              "Id": "Empty"
            },
            "Armor": {
              "Id": "Simple",
              "Capacity": 4,
              "Items": {}
            },
            "HotBar": {
              "Id": "Simple",
              "Capacity": 3,
              "Items": {
                "0": {
                  "Id": "Weapon_Sword_Frost",
                  "Quantity": 1,
                  "Durability": 80.0,
                  "MaxDurability": 80.0,
                  "OverrideDroppedItemAnimation": false
                }
              }
            },
            "Utility": {
              "Id": "Simple",
              "Capacity": 2,
              "Items": {
                "0": {
                  "Id": "Furniture_Crude_Torch",
                  "Quantity": 1,
                  "Durability": 0.0,
                  "MaxDurability": 0.0,
                  "OverrideDroppedItemAnimation": false
                }
              }
            },
            "Backpack": {
              "Id": "Empty"
            },
            "ActiveHotbarSlot": 0,
            "Tool": {
              "Id": "Empty"
            },
            "ActiveToolsSlot": -1,
            "ActiveUtilitySlot": -1,
            "SortType": "Name"
          },
          "HvrPhs": 0.0,
          "HvrHght": 0.0,
          "MdlScl": 1.0,
          "SpawnInstant": "0001-01-01T12:00:00Z",
          "WorldgenId": 0,
          "PathManager": {},
          "LeashPos": {
            "X": 67.5,
            "Y": 56.0,
            "Z": 5.5
          },
          "LeashHdg": 0.48885634541511536,
          "LeashPtch": 0.0,
          "RoleName": "Skeleton_Frost_Knight"
        },
        "HeadRotation": {
          "Rotation": {
            "Pitch": 0.0,
            "Yaw": 0.48885634541511536,
            "Roll": 0.0
          }
        }
      }
    }
  ]
}