{
  "version": 8,
  "blockIdVersion": 11,
  "anchorX": 4,
  "anchorY": 1,
  "anchorZ": -4,
  "blocks": [
    {
      "x": -3,
      "y": 0,
      "z": -4,
      "name": "Rock_Basalt",
      "rotation": 3
    },
    {
      "x": -3,
      "y": 13,
      "z": -4,
      "name": "Rock_Basalt_Brick"
    },
    {
      "x": -3,
      "y": 0,
      "z": -3,
      "name": "Rock_Basalt",
      "rotation": 3
    },
    {
      "x": -3,
      "y": 12,
      "z": -3,
      "name": "Rock_Basalt_Brick_Stairs",
      "rotation": 9
    },
    {
      "x": -3,
      "y": 13,
      "z": -3,
      "name": "Rock_Basalt_Brick"
    },
    {
      "x": -3,
      "y": 0,
      "z": -2,
      "name": "Rock_Basalt",
      "rotation": 3
    },
    {
      "x": -3,
      "y": 13,
      "z": -2,
      "name": "Rock_Basalt_Brick"
    },
    {
      "x": -3,
      "y": 0,
      "z": -1,
      "name": "Rock_Basalt",
      "rotation": 3
    },
    {
      "x": -3,
      "y": 6,
      "z": -1,
      "name": "Deco_Iron_Bars_Platforms"
    },
    {
      "x": -3,
      "y": 7,
      "z": -1,
      "name": "Deco_Bronze_Railing"
    },
    {
      "x": -3,
      "y": 13,
      "z": -1,
      "name": "Rock_Basalt_Brick"
    },
    {
      "x": -3,
      "y": 0,
      "z": 0,
      "name": "Rock_Basalt",
      "rotation": 3
    },
    {
      "x": -3,
      "y": 6,
      "z": 0,
      "name": "Deco_Iron_Bars_Platforms"
    },
    {
      "x": -3,
      "y": 13,
      "z": 0,
      "name": "Rock_Basalt_Brick"
    },
    {
      "x": -3,
      "y": 0,
      "z": 1,
      "name": "Rock_Basalt",
      "rotation": 3
    },
    {
      "x": -3,
      "y": 6,
      "z": 1,
      "name": "Deco_Iron_Bars_Platforms"
    },
    {
      "x": -3,
      "y": 13,
      "z": 1,
      "name": "Rock_Basalt_Brick"
    },
    {
      "x": -3,
      "y": 0,
      "z": 2,
      "name": "Rock_Basalt",
      "rotation": 3
    },
    {
      "x": -3,
      "y": 6,
      "z": 2,
      "name": "Deco_Iron_Bars_Platforms"
    },
    {
      "x": -3,
      "y": 7,
      "z": 2,
      "name": "Deco_Bronze_Railing"
    },
    {
      "x": -3,
      "y": 13,
      "z": 2,
      "name": "Rock_Basalt_Brick"
    },
    {
      "x": -3,
      "y": 0,
      "z": 3,
      "name": "Rock_Basalt",
      "rotation": 3
    },
    {
      "x": -3,
      "y": 13,
      "z": 3,
      "name": "Rock_Basalt_Brick"
    },
    {
      "x": -3,
      "y": 0,
      "z": 4,
      "name": "Rock_Basalt_Brick",
      "rotation": 3
    },
    {
      "x": -3,
      "y": 1,
      "z": 4,
      "name": "Rock_Basalt_Brick",
      "rotation": 3
    },
    {
      "x": -3,
      "y": 2,
      "z": 4,
      "name": "Rock_Basalt_Brick",
      "rotation": 3
    },
    {
      "x": -3,
      "y": 3,
      "z": 4,
      "name": "Rock_Basalt_Brick",
      "rotation": 3
    },
    {
      "x": -3,
      "y": 4,
      "z": 4,
      "name": "Rock_Basalt_Brick",
      "rotation": 3
    },
    {
      "x": -3,
      "y": 5,
      "z": 4,
      "name": "Rock_Basalt_Brick",
      "rotation": 3
    },
    {
      "x": -3,
      "y": 6,
      "z": 4,
      "name": "Rock_Basalt_Brick",
      "rotation": 3
    },
    {
      "x": -3,
      "y": 7,
      "z": 4,
      "name": "Rock_Basalt_Brick",
      "rotation": 3
    },
    {
      "x": -3,
      "y": 8,
      "z": 4,
      "name": "Rock_Basalt_Brick",
      "rotation": 3
    },
    {
      "x": -3,
      "y": 9,
      "z": 4,
      "name": "Rock_Basalt_Brick",
      "rotation": 3
    },
    {
      "x": -3,
      "y": 10,
      "z": 4,
      "name": "Rock_Basalt_Brick",
      "rotation": 3
    },
    {
      "x": -3,
      "y": 11,
      "z": 4,
      "name": "Rock_Basalt_Brick",
      "rotation": 3
    },
    {
      "x": -3,
      "y": 12,
      "z": 4,
      "name": "Rock_Basalt_Brick",
      "rotation": 3
    },
    {
      "x": -3,
      "y": 13,
      "z": 4,
      "name": "Rock_Basalt_Brick"
    },
    {
      "x": -2,
      "y": 0,
      "z": -4,
      "name": "Rock_Basalt_Brick",
      "rotation": 3
    },
    {
      "x": -2,
      "y": 13,
      "z": -4,
      "name": "Rock_Basalt_Brick"
    },
    {
      "x": -2,
      "y": 0,
      "z": -3,
      "name": "Rock_Basalt_Brick",
      "rotation": 3
    },
    {
      "x": -2,
      "y": 1,
      "z": -3,
      "name": "Rock_Basalt_Brick_Pillar_Base",
      "rotation": 3
    },
    {
      "x": -2,
      "y": 2,
      "z": -3,
      "name": "Rock_Basalt_Brick_Pillar_Middle",
      "rotation": 3
    },
    {
      "x": -2,
      "y": 3,
      "z": -3,
      "name": "Rock_Basalt_Brick_Pillar_Middle",
      "rotation": 3
    },
    {
      "x": -2,
      "y": 4,
      "z": -3,
      "name": "Rock_Basalt_Brick_Pillar_Middle",
      "rotation": 3
    },
    {
      "x": -2,
      "y": 5,
      "z": -3,
      "name": "Rock_Basalt_Brick_Pillar_Middle",
      "rotation": 3
    },
    {
      "x": -2,
      "y": 6,
      "z": -3,
      "name": "Rock_Basalt_Brick_Pillar_Middle",
      "rotation": 3
    },
    {
      "x": -2,
      "y": 7,
      "z": -3,
      "name": "Rock_Basalt_Brick_Pillar_Middle",
      "rotation": 3
    },
    {
      "x": -2,
      "y": 8,
      "z": -3,
      "name": "Rock_Basalt_Brick_Pillar_Middle",
      "rotation": 3
    },
    {
      "x": -2,
      "y": 9,
      "z": -3,
      "name": "Rock_Basalt_Brick_Pillar_Middle",
      "rotation": 3
    },
    {
      "x": -2,
      "y": 10,
      "z": -3,
      "name": "Rock_Basalt_Brick_Pillar_Middle",
      "rotation": 3
    },
    {
      "x": -2,
      "y": 11,
      "z": -3,
      "name": "Rock_Basalt_Brick_Pillar_Base",
      "rotation": 11
    },
    {
      "x": -2,
      "y": 12,
      "z": -3,
      "name": "Rock_Basalt_Brick",
      "rotation": 3
    },
    {
      "x": -2,
      "y": 13,
      "z": -3,
      "name": "Rock_Basalt_Brick"
    },
    {
      "x": -2,
      "y": 0,
      "z": -2,
      "name": "Rock_Basalt_Brick",
      "rotation": 3
    },
    {
      "x": -2,
      "y": 1,
      "z": -2,
      "name": "Deco_Book_Pile_Small"
    },
    {
      "x": -2,
      "y": 13,
      "z": -2,
      "name": "Rock_Basalt_Brick"
    },
    {
      "x": -2,
      "y": 0,
      "z": -1,
      "name": "Rock_Basalt_Brick",
      "rotation": 3
    },
    {
      "x": -2,
      "y": 6,
      "z": -1,
      "name": "Deco_Iron_Bars_Platforms"
    },
    {
      "x": -2,
      "y": 7,
      "z": -1,
      "name": "Deco_Bronze_Railing"
    },
    {
      "x": -2,
      "y": 13,
      "z": -1,
      "name": "Rock_Basalt_Brick"
    },
    {
      "x": -2,
      "y": 0,
      "z": 0,
      "name": "Rock_Basalt_Brick",
      "rotation": 3
    },
    {
      "x": -2,
      "y": 6,
      "z": 0,
      "name": "Deco_Iron_Bars_Platforms"
    },
    {
      "x": -2,
      "y": 12,
      "z": 0,
      "name": "Rock_Ice_Icicles",
      "rotation": 8
    },
    {
      "x": -2,
      "y": 13,
      "z": 0,
      "name": "Rock_Basalt_Brick"
    },
    {
      "x": -2,
      "y": 0,
      "z": 1,
      "name": "Rock_Basalt_Brick",
      "rotation": 3
    },
    {
      "x": -2,
      "y": 6,
      "z": 1,
      "name": "Deco_Iron_Bars_Platforms"
    },
    {
      "x": -2,
      "y": 13,
      "z": 1,
      "name": "Rock_Basalt_Brick"
    },
    {
      "x": -2,
      "y": 0,
      "z": 2,
      "name": "Rock_Basalt_Brick",
      "rotation": 3
    },
    {
      "x": -2,
      "y": 6,
      "z": 2,
      "name": "Deco_Iron_Bars_Platforms"
    },
    {
      "x": -2,
      "y": 7,
      "z": 2,
      "name": "Deco_Bronze_Railing"
    },
    {
      "x": -2,
      "y": 13,
      "z": 2,
      "name": "Rock_Basalt_Brick"
    },
    {
      "x": -2,
      "y": 0,
      "z": 3,
      "name": "Rock_Basalt_Brick",
      "rotation": 3
    },
    {
      "x": -2,
      "y": 1,
      "z": 3,
      "name": "Furniture_Ancient_Barrel"
    },
    {
      "x": -2,
      "y": 3,
      "z": 3,
      "name": "Furniture_Ancient_Platform",
      "rotation": 1
    },
    {
      "x": -2,
      "y": 4,
      "z": 3,
      "name": "Deco_SpiderWeb",
      "support": 15,
      "rotation": 2
    },
    {
      "x": -2,
      "y": 11,
      "z": 3,
      "name": "Deco_SpiderWeb_Flat",
      "support": 15,
      "rotation": 6
    },
    {
      "x": -2,
      "y": 12,
      "z": 3,
      "name": "Deco_SpiderWeb_Full",
      "support": 15
    },
    {
      "x": -2,
      "y": 13,
      "z": 3,
      "name": "Rock_Basalt_Brick"
    },
    {
      "x": -2,
      "y": 0,
      "z": 4,
      "name": "Rock_Basalt_Brick",
      "rotation": 3
    },
    {
      "x": -2,
      "y": 1,
      "z": 4,
      "name": "Rock_Basalt_Brick",
      "rotation": 3
    },
    {
      "x": -2,
      "y": 2,
      "z": 4,
      "name": "Rock_Basalt_Brick",
      "rotation": 3
    },
    {
      "x": -2,
      "y": 3,
      "z": 4,
      "name": "Rock_Basalt_Brick",
      "rotation": 3
    },
    {
      "x": -2,
      "y": 4,
      "z": 4,
      "name": "Rock_Basalt_Brick",
      "rotation": 3
    },
    {
      "x": -2,
      "y": 5,
      "z": 4,
      "name": "Rock_Basalt_Brick",
      "rotation": 3
    },
    {
      "x": -2,
      "y": 6,
      "z": 4,
      "name": "Rock_Basalt_Brick",
      "rotation": 3
    },
    {
      "x": -2,
      "y": 7,
      "z": 4,
      "name": "Rock_Basalt_Brick",
      "rotation": 3
    },
    {
      "x": -2,
      "y": 8,
      "z": 4,
      "name": "Rock_Basalt_Brick",
      "rotation": 3
    },
    {
      "x": -2,
      "y": 9,
      "z": 4,
      "name": "Rock_Basalt_Brick",
      "rotation": 3
    },
    {
      "x": -2,
      "y": 10,
      "z": 4,
      "name": "Rock_Basalt_Brick",
      "rotation": 3
    },
    {
      "x": -2,
      "y": 11,
      "z": 4,
      "name": "Rock_Basalt_Brick",
      "rotation": 3
    },
    {
      "x": -2,
      "y": 12,
      "z": 4,
      "name": "Rock_Basalt_Brick",
      "rotation": 3
    },
    {
      "x": -2,
      "y": 13,
      "z": 4,
      "name": "Rock_Basalt_Brick"
    },
    {
      "x": -1,
      "y": 0,
      "z": -4,
      "name": "Rock_Basalt",
      "rotation": 3
    },
    {
      "x": -1,
      "y": 13,
      "z": -4,
      "name": "Rock_Basalt_Brick"
    },
    {
      "x": -1,
      "y": 0,
      "z": -3,
      "name": "Rock_Basalt",
      "rotation": 3
    },
    {
      "x": -1,
      "y": 12,
      "z": -3,
      "name": "Rock_Basalt_Brick_Stairs",
      "rotation": 11
    },
    {
      "x": -1,
      "y": 13,
      "z": -3,
      "name": "Rock_Basalt_Brick"
    },
    {
      "x": -1,
      "y": 0,
      "z": -2,
      "name": "Rock_Basalt",
      "rotation": 3
    },
    {
      "x": -1,
      "y": 13,
      "z": -2,
      "name": "Rock_Basalt_Brick"
    },
    {
      "x": -1,
      "y": 0,
      "z": -1,
      "name": "Rock_Basalt",
      "rotation": 3
    },
    {
      "x": -1,
      "y": 6,
      "z": -1,
      "name": "Deco_Iron_Bars_Platforms"
    },
    {
      "x": -1,
      "y": 7,
      "z": -1,
      "name": "Deco_Bronze_Railing"
    },
    {
      "x": -1,
      "y": 13,
      "z": -1,
      "name": "Rock_Basalt_Brick"
    },
    {
      "x": -1,
      "y": 0,
      "z": 0,
      "name": "Rock_Basalt",
      "rotation": 3
    },
    {
      "x": -1,
      "y": 6,
      "z": 0,
      "name": "Deco_Iron_Bars_Platforms"
    },
    {
      "x": -1,
      "y": 13,
      "z": 0,
      "name": "Rock_Basalt_Brick"
    },
    {
      "x": -1,
      "y": 0,
      "z": 1,
      "name": "Rock_Basalt",
      "rotation": 3
    },
    {
      "x": -1,
      "y": 6,
      "z": 1,
      "name": "Deco_Iron_Bars_Platforms"
    },
    {
      "x": -1,
      "y": 13,
      "z": 1,
      "name": "Rock_Basalt_Brick"
    },
    {
      "x": -1,
      "y": 0,
      "z": 2,
      "name": "Rock_Basalt",
      "rotation": 3
    },
    {
      "x": -1,
      "y": 1,
      "z": 2,
      "name": "Rubble_Basalt_Medium",
      "support": 15
    },
    {
      "x": -1,
      "y": 6,
      "z": 2,
      "name": "Deco_Iron_Bars_Platforms"
    },
    {
      "x": -1,
      "y": 7,
      "z": 2,
      "name": "Deco_Bronze_Railing"
    },
    {
      "x": -1,
      "y": 12,
      "z": 2,
      "name": "Deco_SpiderWeb_Flat",
      "support": 15,
      "rotation": 8
    },
    {
      "x": -1,
      "y": 13,
      "z": 2,
      "name": "Rock_Basalt_Brick"
    },
    {
      "x": -1,
      "y": 0,
      "z": 3,
      "name": "Rock_Basalt",
      "rotation": 3
    },
    {
      "x": -1,
      "y": 1,
      "z": 3,
      "name": "Deco_Iron_Stack",
      "support": 15
    },
    {
      "x": -1,
      "y": 3,
      "z": 3,
      "name": "Furniture_Ancient_Platform",
      "rotation": 1
    },
    {
      "x": -1,
      "y": 4,
      "z": 3,
      "name": "Deco_Book_Pile_Small",
      "rotation": 2
    },
    {
      "x": -1,
      "y": 10,
      "z": 3,
      "name": "Deco_SpiderWeb",
      "support": 15,
      "rotation": 8
    },
    {
      "x": -1,
      "y": 11,
      "z": 3,
      "name": "Deco_SpiderWeb_Full",
      "support": 15
    },
    {
      "x": -1,
      "y": 12,
      "z": 3,
      "name": "Deco_SpiderWeb_Full",
      "support": 15
    },
    {
      "x": -1,
      "y": 13,
      "z": 3,
      "name": "Rock_Basalt_Brick"
    },
    {
      "x": -1,
      "y": 0,
      "z": 4,
      "name": "Rock_Basalt_Brick",
      "rotation": 3
    },
    {
      "x": -1,
      "y": 1,
      "z": 4,
      "name": "Rock_Basalt_Brick",
      "rotation": 3
    },
    {
      "x": -1,
      "y": 2,
      "z": 4,
      "name": "Rock_Basalt_Brick",
      "rotation": 3
    },
    {
      "x": -1,
      "y": 3,
      "z": 4,
      "name": "Rock_Basalt_Brick",
      "rotation": 3
    },
    {
      "x": -1,
      "y": 4,
      "z": 4,
      "name": "Rock_Basalt_Brick",
      "rotation": 3
    },
    {
      "x": -1,
      "y": 5,
      "z": 4,
      "name": "Rock_Basalt_Brick",
      "rotation": 3
    },
    {
      "x": -1,
      "y": 6,
      "z": 4,
      "name": "Rock_Basalt_Brick",
      "rotation": 3
    },
    {
      "x": -1,
      "y": 7,
      "z": 4,
      "name": "Rock_Basalt_Brick",
      "rotation": 3
    },
    {
      "x": -1,
      "y": 8,
      "z": 4,
      "name": "Rock_Basalt_Brick",
      "rotation": 3
    },
    {
      "x": -1,
      "y": 9,
      "z": 4,
      "name": "Rock_Basalt_Brick",
      "rotation": 3
    },
    {
      "x": -1,
      "y": 10,
      "z": 4,
      "name": "Rock_Basalt_Brick",
      "rotation": 3
    },
    {
      "x": -1,
      "y": 11,
      "z": 4,
      "name": "Rock_Basalt_Brick",
      "rotation": 3
    },
    {
      "x": -1,
      "y": 12,
      "z": 4,
      "name": "Rock_Basalt_Brick",
      "rotation": 3
    },
    {
      "x": -1,
      "y": 13,
      "z": 4,
      "name": "Rock_Basalt_Brick"
    },
    {
      "x": 0,
      "y": 0,
      "z": -4,
      "name": "Rock_Basalt",
      "rotation": 3
    },
    {
      "x": 0,
      "y": 13,
      "z": -4,
      "name": "Rock_Basalt_Brick"
    },
    {
      "x": 0,
      "y": 0,
      "z": -3,
      "name": "Rock_Basalt",
      "rotation": 3
    },
    {
      "x": 0,
      "y": 12,
      "z": -3,
      "name": "Rock_Basalt_Brick_Half",
      "rotation": 11
    },
    {
      "x": 0,
      "y": 13,
      "z": -3,
      "name": "Rock_Basalt_Brick"
    },
    {
      "x": 0,
      "y": 0,
      "z": -2,
      "name": "Rock_Basalt",
      "rotation": 3
    },
    {
      "x": 0,
      "y": 13,
      "z": -2,
      "name": "Rock_Basalt_Brick"
    },
    {
      "x": 0,
      "y": 0,
      "z": -1,
      "name": "Rock_Basalt",
      "rotation": 3
    },
    {
      "x": 0,
      "y": 6,
      "z": -1,
      "name": "Deco_Iron_Bars_Platforms"
    },
    {
      "x": 0,
      "y": 7,
      "z": -1,
      "name": "Deco_Bronze_Railing"
    },
    {
      "x": 0,
      "y": 8,
      "z": -1,
      "name": "Deco_Iron_Chain_Small"
    },
    {
      "x": 0,
      "y": 9,
      "z": -1,
      "name": "Deco_Iron_Chain_Small"
    },
    {
      "x": 0,
      "y": 10,
      "z": -1,
      "name": "Deco_Iron_Chain_Small"
    },
    {
      "x": 0,
      "y": 11,
      "z": -1,
      "name": "Deco_Iron_Chain_Small"
    },
    {
      "x": 0,
      "y": 12,
      "z": -1,
      "name": "Deco_Iron_Chain_Small"
    },
    {
      "x": 0,
      "y": 13,
      "z": -1,
      "name": "Rock_Basalt_Brick"
    },
    {
      "x": 0,
      "y": 0,
      "z": 0,
      "name": "Rock_Basalt",
      "rotation": 3
    },
    {
      "x": 0,
      "y": 6,
      "z": 0,
      "name": "Deco_Iron_Bars_Platforms"
    },
    {
      "x": 0,
      "y": 13,
      "z": 0,
      "name": "Rock_Basalt_Brick"
    },
    {
      "x": 0,
      "y": 0,
      "z": 1,
      "name": "Rock_Basalt",
      "rotation": 3
    },
    {
      "x": 0,
      "y": 6,
      "z": 1,
      "name": "Deco_Iron_Bars_Platforms"
    },
    {
      "x": 0,
      "y": 13,
      "z": 1,
      "name": "Rock_Basalt_Brick"
    },
    {
      "x": 0,
      "y": 0,
      "z": 2,
      "name": "Rock_Basalt",
      "rotation": 3
    },
    {
      "x": 0,
      "y": 6,
      "z": 2,
      "name": "Deco_Iron_Bars_Platforms"
    },
    {
      "x": 0,
      "y": 7,
      "z": 2,
      "name": "Deco_Bronze_Railing"
    },
    {
      "x": 0,
      "y": 8,
      "z": 2,
      "name": "Deco_Iron_Chain_Small"
    },
    {
      "x": 0,
      "y": 9,
      "z": 2,
      "name": "Deco_Iron_Chain_Small"
    },
    {
      "x": 0,
      "y": 10,
      "z": 2,
      "name": "Deco_Iron_Chain_Small"
    },
    {
      "x": 0,
      "y": 11,
      "z": 2,
      "name": "Deco_Iron_Chain_Small"
    },
    {
      "x": 0,
      "y": 12,
      "z": 2,
      "name": "Deco_Iron_Chain_Small"
    },
    {
      "x": 0,
      "y": 13,
      "z": 2,
      "name": "Rock_Basalt_Brick"
    },
    {
      "x": 0,
      "y": 0,
      "z": 3,
      "name": "Rock_Basalt",
      "rotation": 3
    },
    {
      "x": 0,
      "y": 1,
      "z": 3,
      "name": "Deco_Iron_Stack",
      "support": 15
    },
    {
      "x": 0,
      "y": 2,
      "z": 3,
      "name": "Deco_Iron_Stack",
      "support": 15
    },
    {
      "x": 0,
      "y": 9,
      "z": 3,
      "name": "Wood_Deadwood_Planks_Half",
      "rotation": 6
    },
    {
      "x": 0,
      "y": 10,
      "z": 3,
      "name": "Rock_Bronze_Smooth"
    },
    {
      "x": 0,
      "y": 11,
      "z": 3,
      "name": "Bronze_Pipe_Large"
    },
    {
      "x": 0,
      "y": 12,
      "z": 3,
      "name": "Bronze_Pipe_Large"
    },
    {
      "x": 0,
      "y": 13,
      "z": 3,
      "name": "Rock_Basalt_Brick"
    },
    {
      "x": 0,
      "y": 0,
      "z": 4,
      "name": "Rock_Basalt_Brick",
      "rotation": 3
    },
    {
      "x": 0,
      "y": 1,
      "z": 4,
      "name": "Rock_Basalt_Brick",
      "rotation": 3
    },
    {
      "x": 0,
      "y": 2,
      "z": 4,
      "name": "Rock_Basalt_Brick",
      "rotation": 3
    },
    {
      "x": 0,
      "y": 3,
      "z": 4,
      "name": "Rock_Basalt_Brick",
      "rotation": 3
    },
    {
      "x": 0,
      "y": 4,
      "z": 4,
      "name": "Rock_Basalt_Brick",
      "rotation": 3
    },
    {
      "x": 0,
      "y": 5,
      "z": 4,
      "name": "Rock_Basalt_Brick",
      "rotation": 3
    },
    {
      "x": 0,
      "y": 6,
      "z": 4,
      "name": "Rock_Basalt_Brick",
      "rotation": 3
    },
    {
      "x": 0,
      "y": 7,
      "z": 4,
      "name": "Rock_Basalt_Brick",
      "rotation": 3
    },
    {
      "x": 0,
      "y": 8,
      "z": 4,
      "name": "Rock_Basalt_Brick",
      "rotation": 3
    },
    {
      "x": 0,
      "y": 9,
      "z": 4,
      "name": "Rock_Basalt_Brick",
      "rotation": 3
    },
    {
      "x": 0,
      "y": 10,
      "z": 4,
      "name": "Rock_Basalt_Brick",
      "rotation": 3
    },
    {
      "x": 0,
      "y": 11,
      "z": 4,
      "name": "Rock_Basalt_Brick",
      "rotation": 3
    },
    {
      "x": 0,
      "y": 12,
      "z": 4,
      "name": "Rock_Basalt_Brick",
      "rotation": 3
    },
    {
      "x": 0,
      "y": 13,
      "z": 4,
      "name": "Rock_Basalt_Brick"
    },
    {
      "x": 1,
      "y": 0,
      "z": -4,
      "name": "Rock_Basalt",
      "rotation": 3
    },
    {
      "x": 1,
      "y": 13,
      "z": -4,
      "name": "Rock_Basalt_Brick"
    },
    {
      "x": 1,
      "y": 0,
      "z": -3,
      "name": "Rock_Basalt",
      "rotation": 3
    },
    {
      "x": 1,
      "y": 1,
      "z": -3,
      "name": "Rubble_Basalt",
      "support": 15
    },
    {
      "x": 1,
      "y": 12,
      "z": -3,
      "name": "Rock_Basalt_Brick_Stairs",
      "rotation": 9
    },
    {
      "x": 1,
      "y": 13,
      "z": -3,
      "name": "Rock_Basalt_Brick"
    },
    {
      "x": 1,
      "y": 0,
      "z": -2,
      "name": "Rock_Basalt",
      "rotation": 3
    },
    {
      "x": 1,
      "y": 13,
      "z": -2,
      "name": "Rock_Basalt_Brick"
    },
    {
      "x": 1,
      "y": 0,
      "z": -1,
      "name": "Rock_Basalt",
      "rotation": 3
    },
    {
      "x": 1,
      "y": 6,
      "z": -1,
      "name": "Deco_Iron_Bars_Platforms"
    },
    {
      "x": 1,
      "y": 7,
      "z": -1,
      "name": "Deco_Bronze_Railing"
    },
    {
      "x": 1,
      "y": 13,
      "z": -1,
      "name": "Rock_Basalt_Brick"
    },
    {
      "x": 1,
      "y": 0,
      "z": 0,
      "name": "Rock_Basalt",
      "rotation": 3
    },
    {
      "x": 1,
      "y": 6,
      "z": 0,
      "name": "Deco_Iron_Bars_Platforms"
    },
    {
      "x": 1,
      "y": 13,
      "z": 0,
      "name": "Rock_Basalt_Brick"
    },
    {
      "x": 1,
      "y": 0,
      "z": 1,
      "name": "Rock_Basalt",
      "rotation": 3
    },
    {
      "x": 1,
      "y": 1,
      "z": 1,
      "name": "Rubble_Basalt",
      "support": 15
    },
    {
      "x": 1,
      "y": 6,
      "z": 1,
      "name": "Deco_Iron_Bars_Platforms"
    },
    {
      "x": 1,
      "y": 13,
      "z": 1,
      "name": "Rock_Basalt_Brick"
    },
    {
      "x": 1,
      "y": 0,
      "z": 2,
      "name": "Rock_Basalt",
      "rotation": 3
    },
    {
      "x": 1,
      "y": 1,
      "z": 2,
      "name": "Furniture_Ancient_Barrel"
    },
    {
      "x": 1,
      "y": 6,
      "z": 2,
      "name": "Deco_Iron_Bars_Platforms"
    },
    {
      "x": 1,
      "y": 7,
      "z": 2,
      "name": "Deco_Bronze_Railing"
    },
    {
      "x": 1,
      "y": 13,
      "z": 2,
      "name": "Rock_Basalt_Brick"
    },
    {
      "x": 1,
      "y": 0,
      "z": 3,
      "name": "Rock_Basalt",
      "rotation": 3
    },
    {
      "x": 1,
      "y": 1,
      "z": 3,
      "name": "Furniture_Ancient_Crate",
      "rotation": 2
    },
    {
      "x": 1,
      "y": 2,
      "z": 3,
      "name": "Furniture_Ancient_Crate",
      "rotation": 2
    },
    {
      "x": 1,
      "y": 11,
      "z": 3,
      "name": "Deco_SpiderWeb_Flat",
      "support": 15,
      "rotation": 6
    },
    {
      "x": 1,
      "y": 12,
      "z": 3,
      "name": "Deco_SpiderWeb",
      "support": 15,
      "rotation": 8
    },
    {
      "x": 1,
      "y": 13,
      "z": 3,
      "name": "Rock_Basalt_Brick"
    },
    {
      "x": 1,
      "y": 0,
      "z": 4,
      "name": "Rock_Basalt_Brick",
      "rotation": 3
    },
    {
      "x": 1,
      "y": 1,
      "z": 4,
      "name": "Rock_Basalt_Brick",
      "rotation": 3
    },
    {
      "x": 1,
      "y": 2,
      "z": 4,
      "name": "Rock_Basalt_Brick",
      "rotation": 3
    },
    {
      "x": 1,
      "y": 3,
      "z": 4,
      "name": "Rock_Basalt_Brick",
      "rotation": 3
    },
    {
      "x": 1,
      "y": 4,
      "z": 4,
      "name": "Rock_Basalt_Brick",
      "rotation": 3
    },
    {
      "x": 1,
      "y": 5,
      "z": 4,
      "name": "Rock_Basalt_Brick",
      "rotation": 3
    },
    {
      "x": 1,
      "y": 6,
      "z": 4,
      "name": "Rock_Basalt_Brick",
      "rotation": 3
    },
    {
      "x": 1,
      "y": 7,
      "z": 4,
      "name": "Rock_Basalt_Brick",
      "rotation": 3
    },
    {
      "x": 1,
      "y": 8,
      "z": 4,
      "name": "Rock_Basalt_Brick",
      "rotation": 3
    },
    {
      "x": 1,
      "y": 9,
      "z": 4,
      "name": "Rock_Basalt_Brick",
      "rotation": 3
    },
    {
      "x": 1,
      "y": 10,
      "z": 4,
      "name": "Rock_Basalt_Brick",
      "rotation": 3
    },
    {
      "x": 1,
      "y": 11,
      "z": 4,
      "name": "Rock_Basalt_Brick",
      "rotation": 3
    },
    {
      "x": 1,
      "y": 12,
      "z": 4,
      "name": "Rock_Basalt_Brick",
      "rotation": 3
    },
    {
      "x": 1,
      "y": 13,
      "z": 4,
      "name": "Rock_Basalt_Brick"
    },
    {
      "x": 2,
      "y": 0,
      "z": -4,
      "name": "Rock_Basalt_Brick",
      "rotation": 3
    },
    {
      "x": 2,
      "y": 13,
      "z": -4,
      "name": "Rock_Basalt_Brick"
    },
    {
      "x": 2,
      "y": 0,
      "z": -3,
      "name": "Rock_Basalt_Brick",
      "rotation": 3
    },
    {
      "x": 2,
      "y": 1,
      "z": -3,
      "name": "Rock_Basalt_Brick_Pillar_Base",
      "rotation": 3
    },
    {
      "x": 2,
      "y": 2,
      "z": -3,
      "name": "Rock_Basalt_Brick_Pillar_Middle",
      "rotation": 3
    },
    {
      "x": 2,
      "y": 3,
      "z": -3,
      "name": "Rock_Basalt_Brick_Pillar_Middle",
      "rotation": 3
    },
    {
      "x": 2,
      "y": 4,
      "z": -3,
      "name": "Rock_Basalt_Brick_Pillar_Middle",
      "rotation": 3
    },
    {
      "x": 2,
      "y": 5,
      "z": -3,
      "name": "Rock_Basalt_Brick_Pillar_Middle",
      "rotation": 3
    },
    {
      "x": 2,
      "y": 6,
      "z": -3,
      "name": "Rock_Basalt_Brick_Pillar_Middle",
      "rotation": 3
    },
    {
      "x": 2,
      "y": 7,
      "z": -3,
      "name": "Rock_Basalt_Brick_Pillar_Middle",
      "rotation": 3
    },
    {
      "x": 2,
      "y": 8,
      "z": -3,
      "name": "Rock_Basalt_Brick_Pillar_Middle",
      "rotation": 3
    },
    {
      "x": 2,
      "y": 9,
      "z": -3,
      "name": "Rock_Basalt_Brick_Pillar_Middle",
      "rotation": 3
    },
    {
      "x": 2,
      "y": 10,
      "z": -3,
      "name": "Rock_Basalt_Brick_Pillar_Middle",
      "rotation": 3
    },
    {
      "x": 2,
      "y": 11,
      "z": -3,
      "name": "Rock_Basalt_Brick_Pillar_Base",
      "rotation": 11
    },
    {
      "x": 2,
      "y": 12,
      "z": -3,
      "name": "Rock_Basalt_Brick",
      "rotation": 3
    },
    {
      "x": 2,
      "y": 13,
      "z": -3,
      "name": "Rock_Basalt_Brick"
    },
    {
      "x": 2,
      "y": 0,
      "z": -2,
      "name": "Rock_Basalt_Brick",
      "rotation": 3
    },
    {
      "x": 2,
      "y": 13,
      "z": -2,
      "name": "Rock_Basalt_Brick"
    },
    {
      "x": 2,
      "y": 0,
      "z": -1,
      "name": "Rock_Basalt_Brick",
      "rotation": 3
    },
    {
      "x": 2,
      "y": 6,
      "z": -1,
      "name": "Deco_Iron_Bars_Platforms"
    },
    {
      "x": 2,
      "y": 7,
      "z": -1,
      "name": "Deco_Bronze_Railing"
    },
    {
      "x": 2,
      "y": 13,
      "z": -1,
      "name": "Rock_Basalt_Brick"
    },
    {
      "x": 2,
      "y": 0,
      "z": 0,
      "name": "Rock_Basalt_Brick",
      "rotation": 3
    },
    {
      "x": 2,
      "y": 6,
      "z": 0,
      "name": "Deco_Iron_Bars_Platforms"
    },
    {
      "x": 2,
      "y": 13,
      "z": 0,
      "name": "Rock_Basalt_Brick"
    },
    {
      "x": 2,
      "y": 0,
      "z": 1,
      "name": "Rock_Basalt_Brick",
      "rotation": 3
    },
    {
      "x": 2,
      "y": 6,
      "z": 1,
      "name": "Deco_Iron_Bars_Platforms"
    },
    {
      "x": 2,
      "y": 13,
      "z": 1,
      "name": "Rock_Basalt_Brick"
    },
    {
      "x": 2,
      "y": 0,
      "z": 2,
      "name": "Rock_Basalt_Brick",
      "rotation": 3
    },
    {
      "x": 2,
      "y": 1,
      "z": 2,
      "name": "Furniture_Ancient_Crate",
      "rotation": 2
    },
    {
      "x": 2,
      "y": 6,
      "z": 2,
      "name": "Deco_Iron_Bars_Platforms"
    },
    {
      "x": 2,
      "y": 7,
      "z": 2,
      "name": "Deco_Bronze_Railing"
    },
    {
      "x": 2,
      "y": 13,
      "z": 2,
      "name": "Rock_Basalt_Brick"
    },
    {
      "x": 2,
      "y": 0,
      "z": 3,
      "name": "Rock_Basalt_Brick",
      "rotation": 3
    },
    {
      "x": 2,
      "y": 1,
      "z": 3,
      "name": "Furniture_Ancient_Crate",
      "rotation": 2
    },
    {
      "x": 2,
      "y": 2,
      "z": 3,
      "name": "Furniture_Ancient_Crate",
      "rotation": 2
    },
    {
      "x": 2,
      "y": 6,
      "z": 3,
      "name": "Wood_Deadwood_Planks_Half",
      "rotation": 6
    },
    {
      "x": 2,
      "y": 7,
      "z": 3,
      "name": "Rock_Bronze_Smooth"
    },
    {
      "x": 2,
      "y": 8,
      "z": 3,
      "name": "Bronze_Pipe_Large"
    },
    {
      "x": 2,
      "y": 9,
      "z": 3,
      "name": "Bronze_Pipe_Large"
    },
    {
      "x": 2,
      "y": 10,
      "z": 3,
      "name": "Bronze_Pipe_Large"
    },
    {
      "x": 2,
      "y": 11,
      "z": 3,
      "name": "Bronze_Pipe_Large"
    },
    {
      "x": 2,
      "y": 12,
      "z": 3,
      "name": "Bronze_Pipe_Large"
    },
    {
      "x": 2,
      "y": 13,
      "z": 3,
      "name": "Rock_Basalt_Brick"
    },
    {
      "x": 2,
      "y": 0,
      "z": 4,
      "name": "Rock_Basalt_Brick",
      "rotation": 3
    },
    {
      "x": 2,
      "y": 1,
      "z": 4,
      "name": "Rock_Basalt_Brick",
      "rotation": 3
    },
    {
      "x": 2,
      "y": 2,
      "z": 4,
      "name": "Rock_Basalt_Brick",
      "rotation": 3
    },
    {
      "x": 2,
      "y": 3,
      "z": 4,
      "name": "Rock_Basalt_Brick",
      "rotation": 3
    },
    {
      "x": 2,
      "y": 4,
      "z": 4,
      "name": "Rock_Basalt_Brick",
      "rotation": 3
    },
    {
      "x": 2,
      "y": 5,
      "z": 4,
      "name": "Rock_Basalt_Brick",
      "rotation": 3
    },
    {
      "x": 2,
      "y": 6,
      "z": 4,
      "name": "Rock_Basalt_Brick",
      "rotation": 3
    },
    {
      "x": 2,
      "y": 7,
      "z": 4,
      "name": "Rock_Basalt_Brick",
      "rotation": 3
    },
    {
      "x": 2,
      "y": 8,
      "z": 4,
      "name": "Rock_Basalt_Brick",
      "rotation": 3
    },
    {
      "x": 2,
      "y": 9,
      "z": 4,
      "name": "Rock_Basalt_Brick",
      "rotation": 3
    },
    {
      "x": 2,
      "y": 10,
      "z": 4,
      "name": "Rock_Basalt_Brick",
      "rotation": 3
    },
    {
      "x": 2,
      "y": 11,
      "z": 4,
      "name": "Rock_Basalt_Brick",
      "rotation": 3
    },
    {
      "x": 2,
      "y": 12,
      "z": 4,
      "name": "Rock_Basalt_Brick",
      "rotation": 3
    },
    {
      "x": 2,
      "y": 13,
      "z": 4,
      "name": "Rock_Basalt_Brick"
    },
    {
      "x": 3,
      "y": 0,
      "z": -4,
      "name": "Rock_Basalt",
      "rotation": 3
    },
    {
      "x": 3,
      "y": 13,
      "z": -4,
      "name": "Rock_Basalt_Brick"
    },
    {
      "x": 3,
      "y": 0,
      "z": -3,
      "name": "Rock_Basalt",
      "rotation": 3
    },
    {
      "x": 3,
      "y": 12,
      "z": -3,
      "name": "Rock_Basalt_Brick_Stairs",
      "rotation": 11
    },
    {
      "x": 3,
      "y": 13,
      "z": -3,
      "name": "Rock_Basalt_Brick"
    },
    {
      "x": 3,
      "y": 0,
      "z": -2,
      "name": "Rock_Basalt",
      "rotation": 3
    },
    {
      "x": 3,
      "y": 13,
      "z": -2,
      "name": "Rock_Basalt_Brick"
    },
    {
      "x": 3,
      "y": 0,
      "z": -1,
      "name": "Rock_Basalt",
      "rotation": 3
    },
    {
      "x": 3,
      "y": 6,
      "z": -1,
      "name": "Deco_Iron_Bars_Platforms"
    },
    {
      "x": 3,
      "y": 7,
      "z": -1,
      "name": "Deco_Bronze_Railing"
    },
    {
      "x": 3,
      "y": 12,
      "z": -1,
      "name": "Rock_Ice_Icicles",
      "rotation": 8
    },
    {
      "x": 3,
      "y": 13,
      "z": -1,
      "name": "Rock_Basalt_Brick"
    },
    {
      "x": 3,
      "y": 0,
      "z": 0,
      "name": "Rock_Basalt",
      "rotation": 3
    },
    {
      "x": 3,
      "y": 6,
      "z": 0,
      "name": "Deco_Iron_Bars_Platforms"
    },
    {
      "x": 3,
      "y": 13,
      "z": 0,
      "name": "Rock_Basalt_Brick"
    },
    {
      "x": 3,
      "y": 0,
      "z": 1,
      "name": "Rock_Basalt",
      "rotation": 3
    },
    {
      "x": 3,
      "y": 6,
      "z": 1,
      "name": "Deco_Iron_Bars_Platforms"
    },
    {
      "x": 3,
      "y": 13,
      "z": 1,
      "name": "Rock_Basalt_Brick"
    },
    {
      "x": 3,
      "y": 0,
      "z": 2,
      "name": "Rock_Basalt",
      "rotation": 3
    },
    {
      "x": 3,
      "y": 1,
      "z": 2,
      "name": "Furniture_Ancient_Barrel"
    },
    {
      "x": 3,
      "y": 6,
      "z": 2,
      "name": "Deco_Iron_Bars_Platforms"
    },
    {
      "x": 3,
      "y": 7,
      "z": 2,
      "name": "Deco_Bronze_Railing"
    },
    {
      "x": 3,
      "y": 13,
      "z": 2,
      "name": "Rock_Basalt_Brick"
    },
    {
      "x": 3,
      "y": 0,
      "z": 3,
      "name": "Rock_Basalt",
      "rotation": 3
    },
    {
      "x": 3,
      "y": 1,
      "z": 3,
      "name": "Furniture_Ancient_Crate",
      "rotation": 2
    },
    {
      "x": 3,
      "y": 2,
      "z": 3,
      "name": "Deco_SpiderWeb",
      "support": 15,
      "rotation": 2
    },
    {
      "x": 3,
      "y": 11,
      "z": 3,
      "name": "Deco_SpiderWeb_Flat",
      "support": 15,
      "rotation": 6
    },
    {
      "x": 3,
      "y": 12,
      "z": 3,
      "name": "Deco_SpiderWeb_Full",
      "support": 15
    },
    {
      "x": 3,
      "y": 13,
      "z": 3,
      "name": "Rock_Basalt_Brick"
    },
    {
      "x": 3,
      "y": 0,
      "z": 4,
      "name": "Rock_Basalt_Brick",
      "rotation": 3
    },
    {
      "x": 3,
      "y": 1,
      "z": 4,
      "name": "Rock_Basalt_Brick",
      "rotation": 3
    },
    {
      "x": 3,
      "y": 2,
      "z": 4,
      "name": "Rock_Basalt_Brick",
      "rotation": 3
    },
    {
      "x": 3,
      "y": 3,
      "z": 4,
      "name": "Rock_Basalt_Brick",
      "rotation": 3
    },
    {
      "x": 3,
      "y": 4,
      "z": 4,
      "name": "Rock_Basalt_Brick",
      "rotation": 3
    },
    {
      "x": 3,
      "y": 5,
      "z": 4,
      "name": "Rock_Basalt_Brick",
      "rotation": 3
    },
    {
      "x": 3,
      "y": 6,
      "z": 4,
      "name": "Rock_Basalt_Brick",
      "rotation": 3
    },
    {
      "x": 3,
      "y": 7,
      "z": 4,
      "name": "Rock_Basalt_Brick",
      "rotation": 3
    },
    {
      "x": 3,
      "y": 8,
      "z": 4,
      "name": "Rock_Basalt_Brick",
      "rotation": 3
    },
    {
      "x": 3,
      "y": 9,
      "z": 4,
      "name": "Rock_Basalt_Brick",
      "rotation": 3
    },
    {
      "x": 3,
      "y": 10,
      "z": 4,
      "name": "Rock_Basalt_Brick",
      "rotation": 3
    },
    {
      "x": 3,
      "y": 11,
      "z": 4,
      "name": "Rock_Basalt_Brick",
      "rotation": 3
    },
    {
      "x": 3,
      "y": 12,
      "z": 4,
      "name": "Rock_Basalt_Brick",
      "rotation": 3
    },
    {
      "x": 3,
      "y": 13,
      "z": 4,
      "name": "Rock_Basalt_Brick"
    },
    {
      "x": 4,
      "y": 0,
      "z": -4,
      "name": "Rock_Basalt",
      "rotation": 3
    },
    {
      "x": 4,
      "y": 1,
      "z": -4,
      "name": "Empty"
    },
    {
      "x": 4,
      "y": 13,
      "z": -4,
      "name": "Rock_Basalt_Brick"
    },
    {
      "x": 4,
      "y": 0,
      "z": -3,
      "name": "Rock_Basalt",
      "rotation": 3
    },
    {
      "x": 4,
      "y": 12,
      "z": -3,
      "name": "Rock_Basalt_Brick_Half",
      "rotation": 11
    },
    {
      "x": 4,
      "y": 13,
      "z": -3,
      "name": "Rock_Basalt_Brick"
    },
    {
      "x": 4,
      "y": 0,
      "z": -2,
      "name": "Rock_Basalt",
      "rotation": 3
    },
    {
      "x": 4,
      "y": 1,
      "z": -2,
      "name": "Rubble_Basalt",
      "support": 15
    },
    {
      "x": 4,
      "y": 13,
      "z": -2,
      "name": "Rock_Basalt_Brick"
    },
    {
      "x": 4,
      "y": 0,
      "z": -1,
      "name": "Rock_Basalt",
      "rotation": 3
    },
    {
      "x": 4,
      "y": 6,
      "z": -1,
      "name": "Deco_Iron_Bars_Platforms"
    },
    {
      "x": 4,
      "y": 7,
      "z": -1,
      "name": "Deco_Bronze_Railing"
    },
    {
      "x": 4,
      "y": 13,
      "z": -1,
      "name": "Rock_Basalt_Brick"
    },
    {
      "x": 4,
      "y": 0,
      "z": 0,
      "name": "Rock_Basalt",
      "rotation": 3
    },
    {
      "x": 4,
      "y": 6,
      "z": 0,
      "name": "Deco_Iron_Bars_Platforms"
    },
    {
      "x": 4,
      "y": 13,
      "z": 0,
      "name": "Rock_Basalt_Brick"
    },
    {
      "x": 4,
      "y": 0,
      "z": 1,
      "name": "Rock_Basalt",
      "rotation": 3
    },
    {
      "x": 4,
      "y": 6,
      "z": 1,
      "name": "Deco_Iron_Bars_Platforms"
    },
    {
      "x": 4,
      "y": 13,
      "z": 1,
      "name": "Rock_Basalt_Brick"
    },
    {
      "x": 4,
      "y": 0,
      "z": 2,
      "name": "Rock_Basalt",
      "rotation": 3
    },
    {
      "x": 4,
      "y": 6,
      "z": 2,
      "name": "Deco_Iron_Bars_Platforms"
    },
    {
      "x": 4,
      "y": 7,
      "z": 2,
      "name": "Deco_Bronze_Railing"
    },
    {
      "x": 4,
      "y": 13,
      "z": 2,
      "name": "Rock_Basalt_Brick"
    },
    {
      "x": 4,
      "y": 0,
      "z": 3,
      "name": "Rock_Basalt",
      "rotation": 3
    },
    {
      "x": 4,
      "y": 1,
      "z": 3,
      "name": "Furniture_Ancient_Crate",
      "rotation": 2
    },
    {
      "x": 4,
      "y": 12,
      "z": 3,
      "name": "Deco_SpiderWeb_Flat",
      "support": 15,
      "rotation": 6
    },
    {
      "x": 4,
      "y": 13,
      "z": 3,
      "name": "Rock_Basalt_Brick"
    },
    {
      "x": 4,
      "y": 0,
      "z": 4,
      "name": "Rock_Basalt_Brick",
      "rotation": 3
    },
    {
      "x": 4,
      "y": 1,
      "z": 4,
      "name": "Rock_Basalt_Brick",
      "rotation": 3
    },
    {
      "x": 4,
      "y": 2,
      "z": 4,
      "name": "Rock_Basalt_Brick",
      "rotation": 3
    },
    {
      "x": 4,
      "y": 3,
      "z": 4,
      "name": "Rock_Basalt_Brick",
      "rotation": 3
    },
    {
      "x": 4,
      "y": 4,
      "z": 4,
      "name": "Rock_Basalt_Brick",
      "rotation": 3
    },
    {
      "x": 4,
      "y": 5,
      "z": 4,
      "name": "Rock_Basalt_Brick",
      "rotation": 3
    },
    {
      "x": 4,
      "y": 6,
      "z": 4,
      "name": "Rock_Basalt_Brick",
      "rotation": 3
    },
    {
      "x": 4,
      "y": 7,
      "z": 4,
      "name": "Rock_Basalt_Brick",
      "rotation": 3
    },
    {
      "x": 4,
      "y": 8,
      "z": 4,
      "name": "Rock_Basalt_Brick",
      "rotation": 3
    },
    {
      "x": 4,
      "y": 9,
      "z": 4,
      "name": "Rock_Basalt_Brick",
      "rotation": 3
    },
    {
      "x": 4,
      "y": 10,
      "z": 4,
      "name": "Rock_Basalt_Brick",
      "rotation": 3
    },
    {
      "x": 4,
      "y": 11,
      "z": 4,
      "name": "Rock_Basalt_Brick",
      "rotation": 3
    },
    {
      "x": 4,
      "y": 12,
      "z": 4,
      "name": "Rock_Basalt_Brick",
      "rotation": 3
    },
    {
      "x": 4,
      "y": 13,
      "z": 4,
      "name": "Rock_Basalt_Brick"
    }
  ],
  "entities": [
    {
      "Components": {
        "EffectController": {},
        "DisplayName": {
          "DisplayName": {
            "MessageId": "server.npcRoles.Skeleton_Frost_Fighter.name",
            "Bold": null,
            "Italic": null,
            "Monospace": null,
            "Underline": null
          }
        },
        "UIComponentList": {},
        "Transform": {
          "Position": {
            "X": 2.011450474486594,
            "Y": 7.0,
            "Z": 1.2373827362553964
          },
          "Rotation": {
            "Pitch": 0.0,
            "Yaw": -0.7033259868621826,
            "Roll": 0.0
          }
        },
        "Velocity": {
          "Velocity": {
            "X": 0.0,
            "Y": 0.0,
            "Z": 0.0
          }
        },
        "PrefabCopyable": {},
        "Interactions": {
          "Interactions": {
            "Use": "*UseNPC"
          }
        },
        "Model": {
          "Model": {
            "Id": "Skeleton_Frost_Fighter",
            "Scale": 1.0,
            "Static": false
          }
        },
        "UUID": {
          "UUID": {
            "$binary": "i27ZxdsVMbWiCqr3N76FPQ==",
            "$type": "04"
          }
        },
        "EntityStats": {
          "Version": 5,
          "Stats": {
            "Oxygen": {
              "Id": "Oxygen",
              "Value": 100.0
            },
            "Mana": {
              "Id": "Mana",
              "Value": 0.0
            },
            "Health": {
              "Id": "Health",
              "Value": 74.0
            },
            "GlidingActive": {
              "Id": "GlidingActive",
              "Value": 0.0
            },
            "Immunity": {
              "Id": "Immunity",
              "Value": 0.0
            },
            "Stamina": {
              "Id": "Stamina",
              "Value": 10.0
            },
            "SignatureCharges": {
              "Id": "SignatureCharges",
              "Value": 0.0
            },
            "Ammo": {
              "Id": "Ammo",
              "Value": 0.0
            },
            "Unknown": {
              "Id": "Unknown",
              "Value": 0.0
            },
            "SignatureEnergy": {
              "Id": "SignatureEnergy",
              "Value": 0.0
            },
            "DeployablePreview": {
              "Id": "DeployablePreview",
              "Value": 0.0
            },
            "StaminaRegenDelay": {
              "Id": "StaminaRegenDelay",
              "Value": 0.0
            },
            "MagicCharges": {
              "Id": "MagicCharges",
              "Value": 0.0
            }
          }
        },
        "NPC": {
          "Version": 5,
          "UUID": {
            "$binary": "ur98Gwq/MXGGHGWlP1gKPQ==",
            "$type": "04"
          },
          "Inventory": {
            "Version": 4,
            "Storage": {
              "Id": "Empty"
            },
            "Armor": {
              "Id": "Simple",
              "Capacity": 4,
              "Items": {}
            },
            "HotBar": {
              "Id": "Simple",
              "Capacity": 3,
              "Items": {
                "0": {
                  "Id": "Weapon_Club_Iron_Rusty",
                  "Quantity": 1,
                  "Durability": 81.0,
                  "MaxDurability": 81.0,
                  "OverrideDroppedItemAnimation": false
                }
              }
            },
            "Utility": {
              "Id": "Simple",
              "Capacity": 2,
              "Items": {
                "0": {
                  "Id": "Furniture_Crude_Torch",
                  "Quantity": 1,
                  "Durability": 0.0,
                  "MaxDurability": 0.0,
                  "OverrideDroppedItemAnimation": false
                }
              }
            },
            "Backpack": {
              "Id": "Empty"
            },
            "ActiveHotbarSlot": 0,
            "Tool": {
              "Id": "Empty"
            },
            "ActiveToolsSlot": -1,
            "ActiveUtilitySlot": -1,
            "SortType": "Name"
          },
          "HvrPhs": 0.0,
          "HvrHght": 0.0,
          "MdlScl": 1.0,
          "SpawnInstant": "0001-01-01T12:00:00Z",
          "WorldgenId": 0,
          "PathManager": {},
          "LeashPos": {
            "X": 97.0114504744866,
            "Y": 62.0,
            "Z": 5.237382736255396
          },
          "LeashHdg": -0.7033259868621826,
          "LeashPtch": 0.0,
          "RoleName": "Skeleton_Frost_Fighter"
        },
        "HeadRotation": {
          "Rotation": {
            "Pitch": 0.0,
            "Yaw": -0.7033259868621826,
            "Roll": 0.0
          }
        }
      }
    }
  ]
}