{
  "version": 8,
  "blockIdVersion": 11,
  "anchorX": 4,
  "anchorY": 1,
  "anchorZ": -4,
  "blocks": [
    {
      "x": -3,
      "y": 0,
      "z": -4,
      "name": "Rock_Basalt",
      "rotation": 3
    },
    {
      "x": -3,
      "y": 13,
      "z": -4,
      "name": "Rock_Basalt_Brick"
    },
    {
      "x": -3,
      "y": 0,
      "z": -3,
      "name": "Rock_Basalt",
      "rotation": 3
    },
    {
      "x": -3,
      "y": 1,
      "z": -3,
      "name": "Deco_Book_Pile_Small",
      "rotation": 3
    },
    {
      "x": -3,
      "y": 12,
      "z": -3,
      "name": "Rock_Basalt_Brick_Stairs",
      "rotation": 9
    },
    {
      "x": -3,
      "y": 13,
      "z": -3,
      "name": "Rock_Basalt_Brick"
    },
    {
      "x": -3,
      "y": 0,
      "z": -2,
      "name": "Rock_Basalt",
      "rotation": 3
    },
    {
      "x": -3,
      "y": 13,
      "z": -2,
      "name": "Rock_Basalt_Brick"
    },
    {
      "x": -3,
      "y": 0,
      "z": -1,
      "name": "Rock_Basalt",
      "rotation": 3
    },
    {
      "x": -3,
      "y": 1,
      "z": -1,
      "name": "Rubble_Basalt",
      "support": 15
    },
    {
      "x": -3,
      "y": 6,
      "z": -1,
      "name": "Deco_Iron_Bars_Platforms"
    },
    {
      "x": -3,
      "y": 7,
      "z": -1,
      "name": "Deco_Bronze_Railing"
    },
    {
      "x": -3,
      "y": 13,
      "z": -1,
      "name": "Rock_Basalt_Brick"
    },
    {
      "x": -3,
      "y": 0,
      "z": 0,
      "name": "Rock_Basalt",
      "rotation": 3
    },
    {
      "x": -3,
      "y": 6,
      "z": 0,
      "name": "Deco_Iron_Bars_Platforms"
    },
    {
      "x": -3,
      "y": 13,
      "z": 0,
      "name": "Rock_Basalt_Brick"
    },
    {
      "x": -3,
      "y": 0,
      "z": 1,
      "name": "Rock_Basalt",
      "rotation": 3
    },
    {
      "x": -3,
      "y": 6,
      "z": 1,
      "name": "Deco_Iron_Bars_Platforms"
    },
    {
      "x": -3,
      "y": 13,
      "z": 1,
      "name": "Rock_Basalt_Brick"
    },
    {
      "x": -3,
      "y": 0,
      "z": 2,
      "name": "Rock_Basalt",
      "rotation": 3
    },
    {
      "x": -3,
      "y": 6,
      "z": 2,
      "name": "Deco_Iron_Bars_Platforms"
    },
    {
      "x": -3,
      "y": 7,
      "z": 2,
      "name": "Deco_Bronze_Railing"
    },
    {
      "x": -3,
      "y": 13,
      "z": 2,
      "name": "Rock_Basalt_Brick"
    },
    {
      "x": -3,
      "y": 0,
      "z": 3,
      "name": "Rock_Basalt",
      "rotation": 3
    },
    {
      "x": -3,
      "y": 1,
      "z": 3,
      "name": "Furniture_Ancient_Wardrobe",
      "rotation": 2
    },
    {
      "x": -3,
      "y": 2,
      "z": 3,
      "name": "Furniture_Ancient_Wardrobe",
      "filler": 1024,
      "rotation": 2
    },
    {
      "x": -3,
      "y": 3,
      "z": 3,
      "name": "Deco_SpiderWeb",
      "support": 15,
      "rotation": 8
    },
    {
      "x": -3,
      "y": 4,
      "z": 3,
      "name": "Rock_Bronze_Smooth"
    },
    {
      "x": -3,
      "y": 5,
      "z": 3,
      "name": "Bronze_Pipe_Large"
    },
    {
      "x": -3,
      "y": 6,
      "z": 3,
      "name": "Bronze_Pipe_Large"
    },
    {
      "x": -3,
      "y": 7,
      "z": 3,
      "name": "Bronze_Pipe_Large"
    },
    {
      "x": -3,
      "y": 8,
      "z": 3,
      "name": "Bronze_Pipe_Large"
    },
    {
      "x": -3,
      "y": 9,
      "z": 3,
      "name": "Bronze_Pipe_Large"
    },
    {
      "x": -3,
      "y": 10,
      "z": 3,
      "name": "Rock_Bronze_Smooth"
    },
    {
      "x": -3,
      "y": 11,
      "z": 3,
      "name": "Deco_SpiderWeb_Flat",
      "support": 15,
      "rotation": 6
    },
    {
      "x": -3,
      "y": 12,
      "z": 3,
      "name": "Deco_SpiderWeb_Full",
      "support": 15
    },
    {
      "x": -3,
      "y": 13,
      "z": 3,
      "name": "Rock_Basalt_Brick"
    },
    {
      "x": -3,
      "y": 0,
      "z": 4,
      "name": "Rock_Basalt_Brick",
      "rotation": 3
    },
    {
      "x": -3,
      "y": 1,
      "z": 4,
      "name": "Rock_Basalt_Brick",
      "rotation": 3
    },
    {
      "x": -3,
      "y": 2,
      "z": 4,
      "name": "Rock_Basalt_Brick",
      "rotation": 3
    },
    {
      "x": -3,
      "y": 3,
      "z": 4,
      "name": "Rock_Basalt_Brick",
      "rotation": 3
    },
    {
      "x": -3,
      "y": 4,
      "z": 4,
      "name": "Rock_Basalt_Brick",
      "rotation": 3
    },
    {
      "x": -3,
      "y": 5,
      "z": 4,
      "name": "Rock_Basalt_Brick",
      "rotation": 3
    },
    {
      "x": -3,
      "y": 6,
      "z": 4,
      "name": "Rock_Basalt_Brick",
      "rotation": 3
    },
    {
      "x": -3,
      "y": 7,
      "z": 4,
      "name": "Rock_Basalt_Brick",
      "rotation": 3
    },
    {
      "x": -3,
      "y": 8,
      "z": 4,
      "name": "Rock_Basalt_Brick",
      "rotation": 3
    },
    {
      "x": -3,
      "y": 9,
      "z": 4,
      "name": "Rock_Basalt_Brick",
      "rotation": 3
    },
    {
      "x": -3,
      "y": 10,
      "z": 4,
      "name": "Rock_Basalt_Brick",
      "rotation": 3
    },
    {
      "x": -3,
      "y": 11,
      "z": 4,
      "name": "Rock_Basalt_Brick",
      "rotation": 3
    },
    {
      "x": -3,
      "y": 12,
      "z": 4,
      "name": "Rock_Basalt_Brick",
      "rotation": 3
    },
    {
      "x": -3,
      "y": 13,
      "z": 4,
      "name": "Rock_Basalt_Brick"
    },
    {
      "x": -2,
      "y": 0,
      "z": -4,
      "name": "Rock_Basalt_Brick",
      "rotation": 3
    },
    {
      "x": -2,
      "y": 13,
      "z": -4,
      "name": "Rock_Basalt_Brick"
    },
    {
      "x": -2,
      "y": 0,
      "z": -3,
      "name": "Rock_Basalt_Brick",
      "rotation": 3
    },
    {
      "x": -2,
      "y": 1,
      "z": -3,
      "name": "Rock_Basalt_Brick_Pillar_Base",
      "rotation": 3
    },
    {
      "x": -2,
      "y": 2,
      "z": -3,
      "name": "Rock_Basalt_Brick_Pillar_Middle",
      "rotation": 3
    },
    {
      "x": -2,
      "y": 3,
      "z": -3,
      "name": "Rock_Basalt_Brick_Pillar_Middle",
      "rotation": 3
    },
    {
      "x": -2,
      "y": 4,
      "z": -3,
      "name": "Rock_Basalt_Brick_Pillar_Middle",
      "rotation": 3
    },
    {
      "x": -2,
      "y": 5,
      "z": -3,
      "name": "Rock_Basalt_Brick_Pillar_Middle",
      "rotation": 3
    },
    {
      "x": -2,
      "y": 6,
      "z": -3,
      "name": "Rock_Basalt_Brick_Pillar_Middle",
      "rotation": 3
    },
    {
      "x": -2,
      "y": 7,
      "z": -3,
      "name": "Rock_Basalt_Brick_Pillar_Middle",
      "rotation": 3
    },
    {
      "x": -2,
      "y": 8,
      "z": -3,
      "name": "Rock_Basalt_Brick_Pillar_Middle",
      "rotation": 3
    },
    {
      "x": -2,
      "y": 9,
      "z": -3,
      "name": "Rock_Basalt_Brick_Pillar_Middle",
      "rotation": 3
    },
    {
      "x": -2,
      "y": 10,
      "z": -3,
      "name": "Rock_Basalt_Brick_Pillar_Middle",
      "rotation": 3
    },
    {
      "x": -2,
      "y": 11,
      "z": -3,
      "name": "Rock_Basalt_Brick_Pillar_Base",
      "rotation": 11
    },
    {
      "x": -2,
      "y": 12,
      "z": -3,
      "name": "Rock_Basalt_Brick",
      "rotation": 3
    },
    {
      "x": -2,
      "y": 13,
      "z": -3,
      "name": "Rock_Basalt_Brick"
    },
    {
      "x": -2,
      "y": 0,
      "z": -2,
      "name": "Rock_Basalt_Brick",
      "rotation": 3
    },
    {
      "x": -2,
      "y": 1,
      "z": -2,
      "name": "Rubble_Basalt_Medium",
      "support": 15
    },
    {
      "x": -2,
      "y": 13,
      "z": -2,
      "name": "Rock_Basalt_Brick"
    },
    {
      "x": -2,
      "y": 0,
      "z": -1,
      "name": "Rock_Basalt_Brick",
      "rotation": 3
    },
    {
      "x": -2,
      "y": 6,
      "z": -1,
      "name": "Deco_Iron_Bars_Platforms"
    },
    {
      "x": -2,
      "y": 7,
      "z": -1,
      "name": "Deco_Bronze_Railing"
    },
    {
      "x": -2,
      "y": 13,
      "z": -1,
      "name": "Rock_Basalt_Brick"
    },
    {
      "x": -2,
      "y": 0,
      "z": 0,
      "name": "Rock_Basalt_Brick",
      "rotation": 3
    },
    {
      "x": -2,
      "y": 6,
      "z": 0,
      "name": "Deco_Iron_Bars_Platforms"
    },
    {
      "x": -2,
      "y": 12,
      "z": 0,
      "name": "Rock_Ice_Icicles",
      "rotation": 8
    },
    {
      "x": -2,
      "y": 13,
      "z": 0,
      "name": "Rock_Basalt_Brick"
    },
    {
      "x": -2,
      "y": 0,
      "z": 1,
      "name": "Rock_Basalt_Brick",
      "rotation": 3
    },
    {
      "x": -2,
      "y": 6,
      "z": 1,
      "name": "Deco_Iron_Bars_Platforms"
    },
    {
      "x": -2,
      "y": 13,
      "z": 1,
      "name": "Rock_Basalt_Brick_Half",
      "rotation": 4
    },
    {
      "x": -2,
      "y": 0,
      "z": 2,
      "name": "Rock_Basalt_Brick",
      "rotation": 3
    },
    {
      "x": -2,
      "y": 6,
      "z": 2,
      "name": "Deco_Iron_Bars_Platforms"
    },
    {
      "x": -2,
      "y": 7,
      "z": 2,
      "name": "Deco_Bronze_Railing"
    },
    {
      "x": -2,
      "y": 13,
      "z": 2,
      "name": "Rock_Basalt_Brick"
    },
    {
      "x": -2,
      "y": 0,
      "z": 3,
      "name": "Rock_Basalt_Brick",
      "rotation": 3
    },
    {
      "x": -2,
      "y": 1,
      "z": 3,
      "name": "Furniture_Ancient_Wardrobe",
      "filler": 1,
      "rotation": 2
    },
    {
      "x": -2,
      "y": 2,
      "z": 3,
      "name": "Furniture_Ancient_Wardrobe",
      "filler": 1025,
      "rotation": 2
    },
    {
      "x": -2,
      "y": 3,
      "z": 3,
      "name": "Deco_SpiderWeb_Full",
      "support": 15
    },
    {
      "x": -2,
      "y": 4,
      "z": 3,
      "name": "Bronze_Pipe_Large",
      "rotation": 5
    },
    {
      "x": -2,
      "y": 5,
      "z": 3,
      "name": "Deco_SpiderWeb_Full",
      "support": 15
    },
    {
      "x": -2,
      "y": 6,
      "z": 3,
      "name": "Deco_SpiderWeb_Flat",
      "support": 15,
      "rotation": 6
    },
    {
      "x": -2,
      "y": 12,
      "z": 3,
      "name": "Deco_SpiderWeb_Full",
      "support": 15
    },
    {
      "x": -2,
      "y": 13,
      "z": 3,
      "name": "Rock_Basalt_Brick"
    },
    {
      "x": -2,
      "y": 0,
      "z": 4,
      "name": "Rock_Basalt_Brick",
      "rotation": 3
    },
    {
      "x": -2,
      "y": 1,
      "z": 4,
      "name": "Rock_Basalt_Brick",
      "rotation": 3
    },
    {
      "x": -2,
      "y": 2,
      "z": 4,
      "name": "Rock_Basalt_Brick",
      "rotation": 3
    },
    {
      "x": -2,
      "y": 3,
      "z": 4,
      "name": "Rock_Basalt_Brick",
      "rotation": 3
    },
    {
      "x": -2,
      "y": 4,
      "z": 4,
      "name": "Rock_Basalt_Brick",
      "rotation": 3
    },
    {
      "x": -2,
      "y": 5,
      "z": 4,
      "name": "Rock_Basalt_Brick",
      "rotation": 3
    },
    {
      "x": -2,
      "y": 6,
      "z": 4,
      "name": "Rock_Basalt_Brick",
      "rotation": 3
    },
    {
      "x": -2,
      "y": 7,
      "z": 4,
      "name": "Rock_Basalt_Brick",
      "rotation": 3
    },
    {
      "x": -2,
      "y": 8,
      "z": 4,
      "name": "Rock_Basalt_Brick",
      "rotation": 3
    },
    {
      "x": -2,
      "y": 9,
      "z": 4,
      "name": "Rock_Basalt_Brick",
      "rotation": 3
    },
    {
      "x": -2,
      "y": 10,
      "z": 4,
      "name": "Rock_Basalt_Brick",
      "rotation": 3
    },
    {
      "x": -2,
      "y": 11,
      "z": 4,
      "name": "Rock_Basalt_Brick",
      "rotation": 3
    },
    {
      "x": -2,
      "y": 12,
      "z": 4,
      "name": "Rock_Basalt_Brick",
      "rotation": 3
    },
    {
      "x": -2,
      "y": 13,
      "z": 4,
      "name": "Rock_Basalt_Brick"
    },
    {
      "x": -1,
      "y": 0,
      "z": -4,
      "name": "Rock_Basalt",
      "rotation": 3
    },
    {
      "x": -1,
      "y": 13,
      "z": -4,
      "name": "Rock_Basalt_Brick"
    },
    {
      "x": -1,
      "y": 0,
      "z": -3,
      "name": "Rock_Basalt",
      "rotation": 3
    },
    {
      "x": -1,
      "y": 12,
      "z": -3,
      "name": "Rock_Basalt_Brick_Stairs",
      "rotation": 11
    },
    {
      "x": -1,
      "y": 13,
      "z": -3,
      "name": "Rock_Basalt_Brick"
    },
    {
      "x": -1,
      "y": 0,
      "z": -2,
      "name": "Rock_Basalt",
      "rotation": 3
    },
    {
      "x": -1,
      "y": 11,
      "z": -2,
      "name": "Rock_Ice_Stalactite_Large",
      "filler": 31744,
      "rotation": 8
    },
    {
      "x": -1,
      "y": 12,
      "z": -2,
      "name": "Rock_Ice_Stalactite_Large",
      "rotation": 8
    },
    {
      "x": -1,
      "y": 13,
      "z": -2,
      "name": "Rock_Basalt_Brick"
    },
    {
      "x": -1,
      "y": 0,
      "z": -1,
      "name": "Rock_Basalt",
      "rotation": 3
    },
    {
      "x": -1,
      "y": 6,
      "z": -1,
      "name": "Deco_Iron_Bars_Platforms"
    },
    {
      "x": -1,
      "y": 7,
      "z": -1,
      "name": "Deco_Bronze_Railing"
    },
    {
      "x": -1,
      "y": 13,
      "z": -1,
      "name": "Rock_Basalt_Brick"
    },
    {
      "x": -1,
      "y": 0,
      "z": 0,
      "name": "Soil_Snow"
    },
    {
      "x": -1,
      "y": 6,
      "z": 0,
      "name": "Deco_Iron_Bars_Platforms"
    },
    {
      "x": -1,
      "y": 13,
      "z": 0,
      "name": "Rock_Basalt_Brick_Half",
      "rotation": 8
    },
    {
      "x": -1,
      "y": 0,
      "z": 1,
      "name": "Soil_Snow"
    },
    {
      "x": -1,
      "y": 6,
      "z": 1,
      "name": "Deco_Iron_Bars_Platforms"
    },
    {
      "x": -1,
      "y": 13,
      "z": 1,
      "name": "Empty"
    },
    {
      "x": -1,
      "y": 0,
      "z": 2,
      "name": "Rock_Basalt",
      "rotation": 3
    },
    {
      "x": -1,
      "y": 6,
      "z": 2,
      "name": "Deco_Iron_Bars_Platforms"
    },
    {
      "x": -1,
      "y": 7,
      "z": 2,
      "name": "Deco_Bronze_Railing"
    },
    {
      "x": -1,
      "y": 13,
      "z": 2,
      "name": "Rock_Basalt_Brick_Half",
      "rotation": 6
    },
    {
      "x": -1,
      "y": 0,
      "z": 3,
      "name": "Rock_Basalt",
      "rotation": 3
    },
    {
      "x": -1,
      "y": 1,
      "z": 3,
      "name": "Bronze_Pipe_Large"
    },
    {
      "x": -1,
      "y": 2,
      "z": 3,
      "name": "Bronze_Pipe_Large"
    },
    {
      "x": -1,
      "y": 3,
      "z": 3,
      "name": "Bronze_Pipe_Large"
    },
    {
      "x": -1,
      "y": 4,
      "z": 3,
      "name": "Rock_Bronze_Smooth"
    },
    {
      "x": -1,
      "y": 5,
      "z": 3,
      "name": "Deco_SpiderWeb_Flat",
      "support": 15,
      "rotation": 6
    },
    {
      "x": -1,
      "y": 12,
      "z": 3,
      "name": "Deco_SpiderWeb_Flat",
      "support": 15,
      "rotation": 6
    },
    {
      "x": -1,
      "y": 13,
      "z": 3,
      "name": "Rock_Basalt_Brick"
    },
    {
      "x": -1,
      "y": 0,
      "z": 4,
      "name": "Rock_Basalt_Brick",
      "rotation": 3
    },
    {
      "x": -1,
      "y": 1,
      "z": 4,
      "name": "Rock_Basalt_Brick",
      "rotation": 3
    },
    {
      "x": -1,
      "y": 2,
      "z": 4,
      "name": "Rock_Basalt_Brick",
      "rotation": 3
    },
    {
      "x": -1,
      "y": 3,
      "z": 4,
      "name": "Rock_Basalt_Brick",
      "rotation": 3
    },
    {
      "x": -1,
      "y": 4,
      "z": 4,
      "name": "Rock_Basalt_Brick",
      "rotation": 3
    },
    {
      "x": -1,
      "y": 5,
      "z": 4,
      "name": "Rock_Basalt_Brick",
      "rotation": 3
    },
    {
      "x": -1,
      "y": 6,
      "z": 4,
      "name": "Rock_Basalt_Brick",
      "rotation": 3
    },
    {
      "x": -1,
      "y": 7,
      "z": 4,
      "name": "Rock_Basalt_Brick",
      "rotation": 3
    },
    {
      "x": -1,
      "y": 8,
      "z": 4,
      "name": "Rock_Basalt_Brick",
      "rotation": 3
    },
    {
      "x": -1,
      "y": 9,
      "z": 4,
      "name": "Rock_Basalt_Brick",
      "rotation": 3
    },
    {
      "x": -1,
      "y": 10,
      "z": 4,
      "name": "Rock_Basalt_Brick",
      "rotation": 3
    },
    {
      "x": -1,
      "y": 11,
      "z": 4,
      "name": "Rock_Basalt_Brick",
      "rotation": 3
    },
    {
      "x": -1,
      "y": 12,
      "z": 4,
      "name": "Rock_Basalt_Brick",
      "rotation": 3
    },
    {
      "x": -1,
      "y": 13,
      "z": 4,
      "name": "Rock_Basalt_Brick"
    },
    {
      "x": 0,
      "y": 0,
      "z": -4,
      "name": "Rock_Basalt",
      "rotation": 3
    },
    {
      "x": 0,
      "y": 13,
      "z": -4,
      "name": "Rock_Basalt_Brick"
    },
    {
      "x": 0,
      "y": 0,
      "z": -3,
      "name": "Rock_Basalt",
      "rotation": 3
    },
    {
      "x": 0,
      "y": 1,
      "z": -3,
      "name": "Deco_SpiderWeb_Flat",
      "support": 15
    },
    {
      "x": 0,
      "y": 12,
      "z": -3,
      "name": "Rock_Basalt_Brick_Half",
      "rotation": 11
    },
    {
      "x": 0,
      "y": 13,
      "z": -3,
      "name": "Rock_Basalt_Brick"
    },
    {
      "x": 0,
      "y": 0,
      "z": -2,
      "name": "Rock_Basalt",
      "rotation": 3
    },
    {
      "x": 0,
      "y": 13,
      "z": -2,
      "name": "Rock_Basalt_Brick"
    },
    {
      "x": 0,
      "y": 0,
      "z": -1,
      "name": "Soil_Snow"
    },
    {
      "x": 0,
      "y": 6,
      "z": -1,
      "name": "Deco_Iron_Bars_Platforms"
    },
    {
      "x": 0,
      "y": 7,
      "z": -1,
      "name": "Deco_Bronze_Railing"
    },
    {
      "x": 0,
      "y": 8,
      "z": -1,
      "name": "Deco_Iron_Chain_Small"
    },
    {
      "x": 0,
      "y": 9,
      "z": -1,
      "name": "Deco_Iron_Chain_Small"
    },
    {
      "x": 0,
      "y": 10,
      "z": -1,
      "name": "Deco_Iron_Chain_Small"
    },
    {
      "x": 0,
      "y": 11,
      "z": -1,
      "name": "Deco_Iron_Chain_Small"
    },
    {
      "x": 0,
      "y": 12,
      "z": -1,
      "name": "Deco_Iron_Chain_Small"
    },
    {
      "x": 0,
      "y": 13,
      "z": -1,
      "name": "Rock_Basalt_Brick"
    },
    {
      "x": 0,
      "y": 0,
      "z": 0,
      "name": "Rock_Ice"
    },
    {
      "x": 0,
      "y": 6,
      "z": 0,
      "name": "Deco_Iron_Bars_Platforms"
    },
    {
      "x": 0,
      "y": 13,
      "z": 0,
      "name": "Rock_Basalt_Brick"
    },
    {
      "x": 0,
      "y": 0,
      "z": 1,
      "name": "Soil_Snow"
    },
    {
      "x": 0,
      "y": 6,
      "z": 1,
      "name": "Deco_Iron_Bars_Platforms"
    },
    {
      "x": 0,
      "y": 13,
      "z": 1,
      "name": "Rock_Basalt_Brick_Half",
      "rotation": 7
    },
    {
      "x": 0,
      "y": 0,
      "z": 2,
      "name": "Soil_Snow"
    },
    {
      "x": 0,
      "y": 6,
      "z": 2,
      "name": "Deco_Iron_Bars_Platforms"
    },
    {
      "x": 0,
      "y": 7,
      "z": 2,
      "name": "Deco_Bronze_Railing"
    },
    {
      "x": 0,
      "y": 8,
      "z": 2,
      "name": "Deco_Iron_Chain_Small"
    },
    {
      "x": 0,
      "y": 9,
      "z": 2,
      "name": "Deco_Iron_Chain_Small"
    },
    {
      "x": 0,
      "y": 10,
      "z": 2,
      "name": "Deco_Iron_Chain_Small"
    },
    {
      "x": 0,
      "y": 11,
      "z": 2,
      "name": "Deco_Iron_Chain_Small"
    },
    {
      "x": 0,
      "y": 12,
      "z": 2,
      "name": "Deco_Iron_Chain_Small"
    },
    {
      "x": 0,
      "y": 13,
      "z": 2,
      "name": "Rock_Basalt_Brick"
    },
    {
      "x": 0,
      "y": 0,
      "z": 3,
      "name": "Rock_Basalt",
      "rotation": 3
    },
    {
      "x": 0,
      "y": 1,
      "z": 3,
      "name": "Furniture_Ancient_Barrel"
    },
    {
      "x": 0,
      "y": 3,
      "z": 3,
      "name": "Deco_SpiderWeb_Flat",
      "support": 15,
      "rotation": 6
    },
    {
      "x": 0,
      "y": 11,
      "z": 3,
      "name": "Deco_SpiderWeb",
      "support": 15,
      "rotation": 8
    },
    {
      "x": 0,
      "y": 12,
      "z": 3,
      "name": "Deco_SpiderWeb_Full",
      "support": 15
    },
    {
      "x": 0,
      "y": 13,
      "z": 3,
      "name": "Rock_Basalt_Brick"
    },
    {
      "x": 0,
      "y": 0,
      "z": 4,
      "name": "Rock_Basalt_Brick",
      "rotation": 3
    },
    {
      "x": 0,
      "y": 1,
      "z": 4,
      "name": "Rock_Basalt_Brick",
      "rotation": 3
    },
    {
      "x": 0,
      "y": 2,
      "z": 4,
      "name": "Rock_Basalt_Brick",
      "rotation": 3
    },
    {
      "x": 0,
      "y": 3,
      "z": 4,
      "name": "Rock_Basalt_Brick",
      "rotation": 3
    },
    {
      "x": 0,
      "y": 4,
      "z": 4,
      "name": "Rock_Basalt_Brick",
      "rotation": 3
    },
    {
      "x": 0,
      "y": 5,
      "z": 4,
      "name": "Rock_Basalt_Brick",
      "rotation": 3
    },
    {
      "x": 0,
      "y": 6,
      "z": 4,
      "name": "Rock_Basalt_Brick",
      "rotation": 3
    },
    {
      "x": 0,
      "y": 7,
      "z": 4,
      "name": "Rock_Basalt_Brick",
      "rotation": 3
    },
    {
      "x": 0,
      "y": 8,
      "z": 4,
      "name": "Rock_Basalt_Brick",
      "rotation": 3
    },
    {
      "x": 0,
      "y": 9,
      "z": 4,
      "name": "Rock_Basalt_Brick",
      "rotation": 3
    },
    {
      "x": 0,
      "y": 10,
      "z": 4,
      "name": "Rock_Basalt_Brick",
      "rotation": 3
    },
    {
      "x": 0,
      "y": 11,
      "z": 4,
      "name": "Rock_Basalt_Brick",
      "rotation": 3
    },
    {
      "x": 0,
      "y": 12,
      "z": 4,
      "name": "Rock_Basalt_Brick",
      "rotation": 3
    },
    {
      "x": 0,
      "y": 13,
      "z": 4,
      "name": "Rock_Basalt_Brick"
    },
    {
      "x": 1,
      "y": 0,
      "z": -4,
      "name": "Rock_Basalt",
      "rotation": 3
    },
    {
      "x": 1,
      "y": 13,
      "z": -4,
      "name": "Rock_Basalt_Brick"
    },
    {
      "x": 1,
      "y": 0,
      "z": -3,
      "name": "Rock_Basalt",
      "rotation": 3
    },
    {
      "x": 1,
      "y": 1,
      "z": -3,
      "name": "Deco_SpiderWeb_Full",
      "support": 15
    },
    {
      "x": 1,
      "y": 12,
      "z": -3,
      "name": "Rock_Basalt_Brick_Stairs",
      "rotation": 9
    },
    {
      "x": 1,
      "y": 13,
      "z": -3,
      "name": "Rock_Basalt_Brick"
    },
    {
      "x": 1,
      "y": 0,
      "z": -2,
      "name": "Soil_Snow"
    },
    {
      "x": 1,
      "y": 13,
      "z": -2,
      "name": "Rock_Basalt_Brick"
    },
    {
      "x": 1,
      "y": 0,
      "z": -1,
      "name": "Soil_Snow"
    },
    {
      "x": 1,
      "y": 6,
      "z": -1,
      "name": "Deco_Iron_Bars_Platforms"
    },
    {
      "x": 1,
      "y": 7,
      "z": -1,
      "name": "Deco_Bronze_Railing"
    },
    {
      "x": 1,
      "y": 13,
      "z": -1,
      "name": "Rock_Basalt_Brick"
    },
    {
      "x": 1,
      "y": 0,
      "z": 0,
      "name": "Rock_Ice"
    },
    {
      "x": 1,
      "y": 1,
      "z": 0,
      "name": "Rock_Ice_Icicles"
    },
    {
      "x": 1,
      "y": 6,
      "z": 0,
      "name": "Deco_Iron_Bars_Platforms"
    },
    {
      "x": 1,
      "y": 13,
      "z": 0,
      "name": "Empty"
    },
    {
      "x": 1,
      "y": 0,
      "z": 1,
      "name": "Rock_Ice"
    },
    {
      "x": 1,
      "y": 6,
      "z": 1,
      "name": "Deco_Iron_Bars_Platforms"
    },
    {
      "x": 1,
      "y": 13,
      "z": 1,
      "name": "Rock_Basalt_Brick_Half",
      "rotation": 5
    },
    {
      "x": 1,
      "y": 0,
      "z": 2,
      "name": "Soil_Snow"
    },
    {
      "x": 1,
      "y": 6,
      "z": 2,
      "name": "Deco_Iron_Bars_Platforms"
    },
    {
      "x": 1,
      "y": 7,
      "z": 2,
      "name": "Deco_Bronze_Railing"
    },
    {
      "x": 1,
      "y": 13,
      "z": 2,
      "name": "Rock_Basalt_Brick"
    },
    {
      "x": 1,
      "y": 0,
      "z": 3,
      "name": "Rock_Basalt",
      "rotation": 3
    },
    {
      "x": 1,
      "y": 1,
      "z": 3,
      "name": "Bronze_Pipe_Large"
    },
    {
      "x": 1,
      "y": 2,
      "z": 3,
      "name": "Bronze_Pipe_Large"
    },
    {
      "x": 1,
      "y": 3,
      "z": 3,
      "name": "Bronze_Pipe_Large"
    },
    {
      "x": 1,
      "y": 4,
      "z": 3,
      "name": "Bronze_Pipe_Large"
    },
    {
      "x": 1,
      "y": 5,
      "z": 3,
      "name": "Bronze_Pipe_Large"
    },
    {
      "x": 1,
      "y": 6,
      "z": 3,
      "name": "Bronze_Pipe_Large"
    },
    {
      "x": 1,
      "y": 7,
      "z": 3,
      "name": "Bronze_Pipe_Large"
    },
    {
      "x": 1,
      "y": 8,
      "z": 3,
      "name": "Bronze_Pipe_Large"
    },
    {
      "x": 1,
      "y": 9,
      "z": 3,
      "name": "Bronze_Pipe_Large"
    },
    {
      "x": 1,
      "y": 10,
      "z": 3,
      "name": "Bronze_Pipe_Large"
    },
    {
      "x": 1,
      "y": 11,
      "z": 3,
      "name": "Bronze_Pipe_Large"
    },
    {
      "x": 1,
      "y": 12,
      "z": 3,
      "name": "Bronze_Pipe_Large"
    },
    {
      "x": 1,
      "y": 13,
      "z": 3,
      "name": "Rock_Basalt_Brick"
    },
    {
      "x": 1,
      "y": 0,
      "z": 4,
      "name": "Rock_Basalt_Brick",
      "rotation": 3
    },
    {
      "x": 1,
      "y": 1,
      "z": 4,
      "name": "Rock_Basalt_Brick",
      "rotation": 3
    },
    {
      "x": 1,
      "y": 2,
      "z": 4,
      "name": "Rock_Basalt_Brick",
      "rotation": 3
    },
    {
      "x": 1,
      "y": 3,
      "z": 4,
      "name": "Rock_Basalt_Brick",
      "rotation": 3
    },
    {
      "x": 1,
      "y": 4,
      "z": 4,
      "name": "Rock_Basalt_Brick",
      "rotation": 3
    },
    {
      "x": 1,
      "y": 5,
      "z": 4,
      "name": "Rock_Basalt_Brick",
      "rotation": 3
    },
    {
      "x": 1,
      "y": 6,
      "z": 4,
      "name": "Rock_Basalt_Brick",
      "rotation": 3
    },
    {
      "x": 1,
      "y": 7,
      "z": 4,
      "name": "Rock_Basalt_Brick",
      "rotation": 3
    },
    {
      "x": 1,
      "y": 8,
      "z": 4,
      "name": "Rock_Basalt_Brick",
      "rotation": 3
    },
    {
      "x": 1,
      "y": 9,
      "z": 4,
      "name": "Rock_Basalt_Brick",
      "rotation": 3
    },
    {
      "x": 1,
      "y": 10,
      "z": 4,
      "name": "Rock_Basalt_Brick",
      "rotation": 3
    },
    {
      "x": 1,
      "y": 11,
      "z": 4,
      "name": "Rock_Basalt_Brick",
      "rotation": 3
    },
    {
      "x": 1,
      "y": 12,
      "z": 4,
      "name": "Rock_Basalt_Brick",
      "rotation": 3
    },
    {
      "x": 1,
      "y": 13,
      "z": 4,
      "name": "Rock_Basalt_Brick"
    },
    {
      "x": 2,
      "y": 0,
      "z": -4,
      "name": "Rock_Basalt_Brick",
      "rotation": 3
    },
    {
      "x": 2,
      "y": 1,
      "z": -4,
      "name": "Deco_SpiderWeb_Flat",
      "support": 15
    },
    {
      "x": 2,
      "y": 13,
      "z": -4,
      "name": "Rock_Basalt_Brick"
    },
    {
      "x": 2,
      "y": 0,
      "z": -3,
      "name": "Rock_Basalt_Brick",
      "rotation": 3
    },
    {
      "x": 2,
      "y": 1,
      "z": -3,
      "name": "Rock_Basalt_Brick_Pillar_Base",
      "rotation": 3
    },
    {
      "x": 2,
      "y": 2,
      "z": -3,
      "name": "Rock_Basalt_Brick_Pillar_Middle",
      "rotation": 3
    },
    {
      "x": 2,
      "y": 3,
      "z": -3,
      "name": "Rock_Basalt_Brick_Pillar_Middle",
      "rotation": 3
    },
    {
      "x": 2,
      "y": 4,
      "z": -3,
      "name": "Rock_Basalt_Brick_Pillar_Middle",
      "rotation": 3
    },
    {
      "x": 2,
      "y": 5,
      "z": -3,
      "name": "Rock_Basalt_Brick_Pillar_Middle",
      "rotation": 3
    },
    {
      "x": 2,
      "y": 6,
      "z": -3,
      "name": "Rock_Basalt_Brick_Pillar_Middle",
      "rotation": 3
    },
    {
      "x": 2,
      "y": 7,
      "z": -3,
      "name": "Rock_Basalt_Brick_Pillar_Middle",
      "rotation": 3
    },
    {
      "x": 2,
      "y": 8,
      "z": -3,
      "name": "Rock_Basalt_Brick_Pillar_Middle",
      "rotation": 3
    },
    {
      "x": 2,
      "y": 9,
      "z": -3,
      "name": "Rock_Basalt_Brick_Pillar_Middle",
      "rotation": 3
    },
    {
      "x": 2,
      "y": 10,
      "z": -3,
      "name": "Rock_Basalt_Brick_Pillar_Middle",
      "rotation": 3
    },
    {
      "x": 2,
      "y": 11,
      "z": -3,
      "name": "Rock_Basalt_Brick_Pillar_Base",
      "rotation": 11
    },
    {
      "x": 2,
      "y": 12,
      "z": -3,
      "name": "Rock_Basalt_Brick",
      "rotation": 3
    },
    {
      "x": 2,
      "y": 13,
      "z": -3,
      "name": "Rock_Basalt_Brick"
    },
    {
      "x": 2,
      "y": 0,
      "z": -2,
      "name": "Soil_Snow"
    },
    {
      "x": 2,
      "y": 1,
      "z": -2,
      "name": "Deco_SpiderWeb_Flat",
      "support": 15
    },
    {
      "x": 2,
      "y": 13,
      "z": -2,
      "name": "Rock_Basalt_Brick"
    },
    {
      "x": 2,
      "y": 0,
      "z": -1,
      "name": "Rock_Ice"
    },
    {
      "x": 2,
      "y": 6,
      "z": -1,
      "name": "Deco_Iron_Bars_Platforms"
    },
    {
      "x": 2,
      "y": 7,
      "z": -1,
      "name": "Deco_Bronze_Railing"
    },
    {
      "x": 2,
      "y": 13,
      "z": -1,
      "name": "Rock_Basalt_Brick"
    },
    {
      "x": 2,
      "y": 0,
      "z": 0,
      "name": "Rock_Ice"
    },
    {
      "x": 2,
      "y": 1,
      "z": 0,
      "name": "Rock_Ice_Stalactite_Large"
    },
    {
      "x": 2,
      "y": 2,
      "z": 0,
      "name": "Rock_Ice_Stalactite_Large",
      "filler": 1024
    },
    {
      "x": 2,
      "y": 6,
      "z": 0,
      "name": "Deco_Iron_Bars_Platforms"
    },
    {
      "x": 2,
      "y": 13,
      "z": 0,
      "name": "Rock_Basalt_Brick_Half",
      "rotation": 4
    },
    {
      "x": 2,
      "y": 0,
      "z": 1,
      "name": "Rock_Ice"
    },
    {
      "x": 2,
      "y": 6,
      "z": 1,
      "name": "Deco_Iron_Bars_Platforms"
    },
    {
      "x": 2,
      "y": 13,
      "z": 1,
      "name": "Empty"
    },
    {
      "x": 2,
      "y": 0,
      "z": 2,
      "name": "Soil_Snow"
    },
    {
      "x": 2,
      "y": 1,
      "z": 2,
      "name": "Rock_Ice_Icicles"
    },
    {
      "x": 2,
      "y": 6,
      "z": 2,
      "name": "Deco_Iron_Bars_Platforms"
    },
    {
      "x": 2,
      "y": 7,
      "z": 2,
      "name": "Deco_Bronze_Railing"
    },
    {
      "x": 2,
      "y": 13,
      "z": 2,
      "name": "Rock_Basalt_Brick"
    },
    {
      "x": 2,
      "y": 0,
      "z": 3,
      "name": "Rock_Basalt_Brick",
      "rotation": 3
    },
    {
      "x": 2,
      "y": 1,
      "z": 3,
      "name": "Furniture_Ancient_Bench",
      "rotation": 2
    },
    {
      "x": 2,
      "y": 10,
      "z": 3,
      "name": "Deco_SpiderWeb_Flat",
      "support": 15,
      "rotation": 6
    },
    {
      "x": 2,
      "y": 11,
      "z": 3,
      "name": "Deco_SpiderWeb",
      "support": 15,
      "rotation": 8
    },
    {
      "x": 2,
      "y": 12,
      "z": 3,
      "name": "Deco_SpiderWeb_Full",
      "support": 15
    },
    {
      "x": 2,
      "y": 13,
      "z": 3,
      "name": "Rock_Basalt_Brick"
    },
    {
      "x": 2,
      "y": 0,
      "z": 4,
      "name": "Rock_Basalt_Brick",
      "rotation": 3
    },
    {
      "x": 2,
      "y": 1,
      "z": 4,
      "name": "Rock_Basalt_Brick",
      "rotation": 3
    },
    {
      "x": 2,
      "y": 2,
      "z": 4,
      "name": "Rock_Basalt_Brick",
      "rotation": 3
    },
    {
      "x": 2,
      "y": 3,
      "z": 4,
      "name": "Rock_Basalt_Brick",
      "rotation": 3
    },
    {
      "x": 2,
      "y": 4,
      "z": 4,
      "name": "Rock_Basalt_Brick",
      "rotation": 3
    },
    {
      "x": 2,
      "y": 5,
      "z": 4,
      "name": "Rock_Basalt_Brick",
      "rotation": 3
    },
    {
      "x": 2,
      "y": 6,
      "z": 4,
      "name": "Rock_Basalt_Brick",
      "rotation": 3
    },
    {
      "x": 2,
      "y": 7,
      "z": 4,
      "name": "Rock_Basalt_Brick",
      "rotation": 3
    },
    {
      "x": 2,
      "y": 8,
      "z": 4,
      "name": "Rock_Basalt_Brick",
      "rotation": 3
    },
    {
      "x": 2,
      "y": 9,
      "z": 4,
      "name": "Rock_Basalt_Brick",
      "rotation": 3
    },
    {
      "x": 2,
      "y": 10,
      "z": 4,
      "name": "Rock_Basalt_Brick",
      "rotation": 3
    },
    {
      "x": 2,
      "y": 11,
      "z": 4,
      "name": "Rock_Basalt_Brick",
      "rotation": 3
    },
    {
      "x": 2,
      "y": 12,
      "z": 4,
      "name": "Rock_Basalt_Brick",
      "rotation": 3
    },
    {
      "x": 2,
      "y": 13,
      "z": 4,
      "name": "Rock_Basalt_Brick"
    },
    {
      "x": 3,
      "y": 0,
      "z": -4,
      "name": "Rock_Basalt",
      "rotation": 3
    },
    {
      "x": 3,
      "y": 13,
      "z": -4,
      "name": "Rock_Basalt_Brick"
    },
    {
      "x": 3,
      "y": 0,
      "z": -3,
      "name": "Rock_Basalt",
      "rotation": 3
    },
    {
      "x": 3,
      "y": 1,
      "z": -3,
      "name": "Rubble_Basalt",
      "support": 15
    },
    {
      "x": 3,
      "y": 12,
      "z": -3,
      "name": "Rock_Basalt_Brick_Stairs",
      "rotation": 11
    },
    {
      "x": 3,
      "y": 13,
      "z": -3,
      "name": "Rock_Basalt_Brick"
    },
    {
      "x": 3,
      "y": 0,
      "z": -2,
      "name": "Soil_Snow"
    },
    {
      "x": 3,
      "y": 13,
      "z": -2,
      "name": "Rock_Basalt_Brick"
    },
    {
      "x": 3,
      "y": 0,
      "z": -1,
      "name": "Rock_Ice"
    },
    {
      "x": 3,
      "y": 1,
      "z": -1,
      "name": "Rock_Ice_Icicles"
    },
    {
      "x": 3,
      "y": 6,
      "z": -1,
      "name": "Deco_Iron_Bars_Platforms"
    },
    {
      "x": 3,
      "y": 7,
      "z": -1,
      "name": "Deco_Bronze_Railing"
    },
    {
      "x": 3,
      "y": 13,
      "z": -1,
      "name": "Rock_Basalt_Brick"
    },
    {
      "x": 3,
      "y": 0,
      "z": 0,
      "name": "Rock_Ice"
    },
    {
      "x": 3,
      "y": 6,
      "z": 0,
      "name": "Deco_Iron_Bars_Platforms"
    },
    {
      "x": 3,
      "y": 12,
      "z": 0,
      "name": "Rock_Ice_Icicles",
      "rotation": 8
    },
    {
      "x": 3,
      "y": 13,
      "z": 0,
      "name": "Rock_Basalt_Brick"
    },
    {
      "x": 3,
      "y": 0,
      "z": 1,
      "name": "Soil_Snow"
    },
    {
      "x": 3,
      "y": 6,
      "z": 1,
      "name": "Deco_Iron_Bars_Platforms"
    },
    {
      "x": 3,
      "y": 13,
      "z": 1,
      "name": "Rock_Basalt_Brick_Half",
      "rotation": 7
    },
    {
      "x": 3,
      "y": 0,
      "z": 2,
      "name": "Rock_Basalt",
      "rotation": 3
    },
    {
      "x": 3,
      "y": 6,
      "z": 2,
      "name": "Deco_Iron_Bars_Platforms"
    },
    {
      "x": 3,
      "y": 7,
      "z": 2,
      "name": "Deco_Bronze_Railing"
    },
    {
      "x": 3,
      "y": 13,
      "z": 2,
      "name": "Rock_Basalt_Brick"
    },
    {
      "x": 3,
      "y": 0,
      "z": 3,
      "name": "Rock_Basalt",
      "rotation": 3
    },
    {
      "x": 3,
      "y": 1,
      "z": 3,
      "name": "Furniture_Ancient_Bench",
      "filler": 1,
      "rotation": 2
    },
    {
      "x": 3,
      "y": 12,
      "z": 3,
      "name": "Deco_SpiderWeb_Flat",
      "support": 15,
      "rotation": 6
    },
    {
      "x": 3,
      "y": 13,
      "z": 3,
      "name": "Rock_Basalt_Brick"
    },
    {
      "x": 3,
      "y": 0,
      "z": 4,
      "name": "Rock_Basalt_Brick",
      "rotation": 3
    },
    {
      "x": 3,
      "y": 1,
      "z": 4,
      "name": "Rock_Basalt_Brick",
      "rotation": 3
    },
    {
      "x": 3,
      "y": 2,
      "z": 4,
      "name": "Rock_Basalt_Brick",
      "rotation": 3
    },
    {
      "x": 3,
      "y": 3,
      "z": 4,
      "name": "Rock_Basalt_Brick",
      "rotation": 3
    },
    {
      "x": 3,
      "y": 4,
      "z": 4,
      "name": "Rock_Basalt_Brick",
      "rotation": 3
    },
    {
      "x": 3,
      "y": 5,
      "z": 4,
      "name": "Rock_Basalt_Brick",
      "rotation": 3
    },
    {
      "x": 3,
      "y": 6,
      "z": 4,
      "name": "Rock_Basalt_Brick",
      "rotation": 3
    },
    {
      "x": 3,
      "y": 7,
      "z": 4,
      "name": "Rock_Basalt_Brick",
      "rotation": 3
    },
    {
      "x": 3,
      "y": 8,
      "z": 4,
      "name": "Rock_Basalt_Brick",
      "rotation": 3
    },
    {
      "x": 3,
      "y": 9,
      "z": 4,
      "name": "Rock_Basalt_Brick",
      "rotation": 3
    },
    {
      "x": 3,
      "y": 10,
      "z": 4,
      "name": "Rock_Basalt_Brick",
      "rotation": 3
    },
    {
      "x": 3,
      "y": 11,
      "z": 4,
      "name": "Rock_Basalt_Brick",
      "rotation": 3
    },
    {
      "x": 3,
      "y": 12,
      "z": 4,
      "name": "Rock_Basalt_Brick",
      "rotation": 3
    },
    {
      "x": 3,
      "y": 13,
      "z": 4,
      "name": "Rock_Basalt_Brick"
    },
    {
      "x": 4,
      "y": 0,
      "z": -4,
      "name": "Rock_Basalt",
      "rotation": 3
    },
    {
      "x": 4,
      "y": 1,
      "z": -4,
      "name": "Empty"
    },
    {
      "x": 4,
      "y": 13,
      "z": -4,
      "name": "Rock_Basalt_Brick"
    },
    {
      "x": 4,
      "y": 0,
      "z": -3,
      "name": "Rock_Basalt",
      "rotation": 3
    },
    {
      "x": 4,
      "y": 12,
      "z": -3,
      "name": "Rock_Basalt_Brick_Half",
      "rotation": 11
    },
    {
      "x": 4,
      "y": 13,
      "z": -3,
      "name": "Rock_Basalt_Brick"
    },
    {
      "x": 4,
      "y": 0,
      "z": -2,
      "name": "Rock_Basalt",
      "rotation": 3
    },
    {
      "x": 4,
      "y": 13,
      "z": -2,
      "name": "Rock_Basalt_Brick"
    },
    {
      "x": 4,
      "y": 0,
      "z": -1,
      "name": "Soil_Snow"
    },
    {
      "x": 4,
      "y": 6,
      "z": -1,
      "name": "Deco_Iron_Bars_Platforms"
    },
    {
      "x": 4,
      "y": 7,
      "z": -1,
      "name": "Deco_Bronze_Railing"
    },
    {
      "x": 4,
      "y": 13,
      "z": -1,
      "name": "Rock_Basalt_Brick"
    },
    {
      "x": 4,
      "y": 0,
      "z": 0,
      "name": "Soil_Snow"
    },
    {
      "x": 4,
      "y": 6,
      "z": 0,
      "name": "Deco_Iron_Bars_Platforms"
    },
    {
      "x": 4,
      "y": 13,
      "z": 0,
      "name": "Rock_Basalt_Brick"
    },
    {
      "x": 4,
      "y": 0,
      "z": 1,
      "name": "Rock_Basalt",
      "rotation": 3
    },
    {
      "x": 4,
      "y": 6,
      "z": 1,
      "name": "Deco_Iron_Bars_Platforms"
    },
    {
      "x": 4,
      "y": 13,
      "z": 1,
      "name": "Rock_Basalt_Brick"
    },
    {
      "x": 4,
      "y": 0,
      "z": 2,
      "name": "Rock_Basalt",
      "rotation": 3
    },
    {
      "x": 4,
      "y": 6,
      "z": 2,
      "name": "Deco_Iron_Bars_Platforms"
    },
    {
      "x": 4,
      "y": 7,
      "z": 2,
      "name": "Deco_Bronze_Railing"
    },
    {
      "x": 4,
      "y": 13,
      "z": 2,
      "name": "Rock_Basalt_Brick"
    },
    {
      "x": 4,
      "y": 0,
      "z": 3,
      "name": "Rock_Basalt",
      "rotation": 3
    },
    {
      "x": 4,
      "y": 1,
      "z": 3,
      "name": "Rubble_Basalt",
      "support": 15
    },
    {
      "x": 4,
      "y": 13,
      "z": 3,
      "name": "Rock_Basalt_Brick"
    },
    {
      "x": 4,
      "y": 0,
      "z": 4,
      "name": "Rock_Basalt_Brick",
      "rotation": 3
    },
    {
      "x": 4,
      "y": 1,
      "z": 4,
      "name": "Rock_Basalt_Brick",
      "rotation": 3
    },
    {
      "x": 4,
      "y": 2,
      "z": 4,
      "name": "Rock_Basalt_Brick",
      "rotation": 3
    },
    {
      "x": 4,
      "y": 3,
      "z": 4,
      "name": "Rock_Basalt_Brick",
      "rotation": 3
    },
    {
      "x": 4,
      "y": 4,
      "z": 4,
      "name": "Rock_Basalt_Brick",
      "rotation": 3
    },
    {
      "x": 4,
      "y": 5,
      "z": 4,
      "name": "Rock_Basalt_Brick",
      "rotation": 3
    },
    {
      "x": 4,
      "y": 6,
      "z": 4,
      "name": "Rock_Basalt_Brick",
      "rotation": 3
    },
    {
      "x": 4,
      "y": 7,
      "z": 4,
      "name": "Rock_Basalt_Brick",
      "rotation": 3
    },
    {
      "x": 4,
      "y": 8,
      "z": 4,
      "name": "Rock_Basalt_Brick",
      "rotation": 3
    },
    {
      "x": 4,
      "y": 9,
      "z": 4,
      "name": "Rock_Basalt_Brick",
      "rotation": 3
    },
    {
      "x": 4,
      "y": 10,
      "z": 4,
      "name": "Rock_Basalt_Brick",
      "rotation": 3
    },
    {
      "x": 4,
      "y": 11,
      "z": 4,
      "name": "Rock_Basalt_Brick",
      "rotation": 3
    },
    {
      "x": 4,
      "y": 12,
      "z": 4,
      "name": "Rock_Basalt_Brick",
      "rotation": 3
    },
    {
      "x": 4,
      "y": 13,
      "z": 4,
      "name": "Rock_Basalt_Brick"
    }
  ]
}